Workbook

Sheet Executive Summary
A1: Executive Summary
A2: Coconut Grove
A3: July 2026
A6: Operations Manager | B6: Danielle Cebrero
A7: Assistant Property Manager: | G7: Square Feet: | H7: 50133
G8: % Leased: | H8: 0.9414
G9: % Occupied: | H9: 0.9414
A12: CASH | B12: Monthly Actual | C12: Monthly Budget | D12: Variance | E12: % Change | F12: YTD Actual | G12: YTD Budget | H12: Variance | I12: % Change
A13: Total Income | B13: 349463.18 | C13: 340807 | D13: =+B13-C13 -> 8656.18 | E13: =IF(C13=0,"N/A",D13/C13) -> 0.025399068 | F13: 2174866.4 | G13: 2216321 | H13: =+F13-G13 -> -41454.62 | I13: =IF(G13=0,"N/A",H13/G13) -> -0.018704249
A14: Total Operating Expenses | B14: 133031.77 | C14: 128388.91 | D14: =+C14-B14 -> -4642.86 | E14: =IF(C14=0,"N/A",D14/C14) -> -0.036162469 | F14: 904761.01 | G14: 1032963.5 | H14: =+G14-F14 -> 128202.46 | I14: =IF(G14=0,"N/A",H14/G14) -> 0.12411132
A15: Net Operating Income | B15: =+B13-B14 -> 216431.41 | C15: =+C13-C14 -> 212418.09 | D15: =+B15-C15 -> 4013.32 | E15: =IF(C15=0,"N/A",D15/C15) -> 0.018893494 | F15: =+F13-F14 -> 1270105.4 | G15: =+G13-G14 -> 1183357.5 | H15: =+F15-G15 -> 86747.84 | I15: =IF(G15=0,"N/A",H15/G15) -> 0.073306535
A16: Total Owners Expense | B16: 250837.22 | C16: 5025 | D16: =C16-B16 -> -245812.22 | E16: =IF(C16=0,"N/A",D16/C16) -> -48.917855 | F16: -105682.96 | G16: 45075 | H16: =G16-F16 -> 150757.96 | I16: =IF(G16=0,"N/A",H16/G16) -> 3.3446026
A17: Adjusted Net Operating Income | B17: =+B15-B16 -> -34405.81 | C17: =+C15-C16 -> 207393.09 | D17: =+D15+D16 -> -241798.9 | E17: =IF(C17=0,"N/A",D17/C17) -> -1.1658966 | F17: =+F15-F16 -> 1375788.3 | G17: =+G15-G16 -> 1138282.5 | H17: =+H15+H16 -> 237505.8 | I17: =IF(G17=0,"N/A",H17/G17) -> 0.20865277
A18: Corporate G&A Expenses | B18: 10629.09 | C18: 18458 | D18: =C18-B18 -> 7828.91 | E18: =IF(C18=0,"N/A",D18/C18) -> 0.42414725 | F18: 111321.52 | G18: 120858 | H18: =+G18-F18 -> 9536.48 | I18: =IF(G18=0,"N/A",H18/G18) -> 0.078906485
A19: Interest Expense | B19: 145075.09 | C19: 160833 | D19: =C19-B19 -> 15757.91 | E19: =IF(C19=0,"N/A",D19/C19) -> 0.097976846 | F19: 997163.89 | G19: 1125831 | H19: =+G19-F19 -> 128667.11 | I19: =IF(G19=0,"N/A",H19/G19) -> 0.11428634
A20: Net Income after G&A & Interest | B20: =+B17-B18-B19 -> -190109.99 | C20: =+C17-C18-C19 -> 28102.09 | D20: =+D17+D18+D19 -> -218212.08 | E20: =IF(C20=0,"N/A",D20/C20) -> -7.7649769 | F20: =+F17-F18-F19 -> 267302.92 | G20: =+G17-G18-G19 -> -108406.47 | H20: =+H17+H18+H19 -> 375709.39 | I20: =IF(G20=0,"N/A",H20/G20) -> -3.4657469
A21: Revenue (per cash income statement)
A22: MTD Revenue variance is over budget due to: - $12K Parking Rent higher than anticipated This is offset by: -($3.5K) PCR slightly less than anticipated
A23: YTD Revenue variance is under budget due to: - ($65.5k) Humpy's PYC deferral - ($22K) PYC credits - ($5K) PCR less than anticipated Offset by: - $51K Parking Rent higher than anticipated | J23: =65+22-51 -> 36
A24: Operating Expenses (per cash income statement)
A25: MTD Expenses variance is under budget due to: - ($14K) Site Furnishing (unbudgeted repair/replacement of trash receptacles) This is offset by: -$10K Timing of Trash and Electric invoices
A26: YTD Expenses are under budget due to: - $26K Timing of Security invoices. Management is holding payment due to non-compliant insurance. Release in July and August - $27K Timing of Parking Lot Repairs - SVN is gathering bids - $21K Timing of Trash Invoices due to change in vendor - $27K Unused contingency for Plumbing, Landscape Consumables - $26K Water/Sewer less than anticipated Offset by: - ($10.3K) Property Insurance higher than allocated - ($17K) Site Furnishing (unbudgeted repair/replacement of trash receptacles) | J26: =26+27+21+27+26-10-17 -> 100 | K26: =16+27+21+20+26-10-17 -> 83 | L26: =83-128 -> -45 | M26: =43652+159+9294+4177+16851 -> 74133 | N26: =26+24+10+23-13-15+4+5 -> 64 | P26: =43652+1559.45+9294.52+4177.85+5166.54 -> 63850.36
A27: Owner Expenses
A28: MTD Owner expenses are over budget due to: -($3K) Legal Fees - Fosters -($4K) Professional Fees Please see the "Fosters Rebuild Costs" tab for more details.
A29: YTD Owner expenses are over budget due to: -($5K) Legal Fees - Fosters -($10K) Professional Fees - Paracorp, Tax Prep, and ICSC This is offset by: -$4K Marketing -$5K Utilities and Licensing Please see the "Fosters Rebuild Costs" tab for more details.
A31: New Leases
A32: Chong Quin Hot Pot (old Outback space) | B32: Term: 10 years w/2 5-yr Options Rent: $13,000 YR 1-2 with increases in years 3 & 6 Possession Date: 10/28/25 RCD: 6/25/26 (240 days after possession date) Lease has been fully executed and tenant is designing space for permitting. Tenant has finalized plans and submitting to County for permits. Satisfaction of Contingencies letter sent 10/28/25. Tenant has paid first month's rent and Security Deposit. Tenant has submitted plans and is in Health Department for permitting. Minor issue surfaced on enclosing the patio and mechanical drawings have been resubmitted to the County of Hawaii, EPIC. Paper plans were also sent express mail to Kona for hand delivery and processing at the State of Hawaii, Department of Health, Sanitation Branch. The EPIC review was completed fairly quick and returned to tenant in early March. Tenant submitted revised plans to the County and structural and fire comments were received back. Tenant is addressing both issues with their architect.
A33: Executed Renewals (12 months from current period)
A34: ABC Store 75 (SF 3,000) | B34: Lease Expiration Date: 12/31/2030 Rent: $8.00 PSF Option: Tenant has one (1) remaining, five (5) year option. Notice due 120 days prior to expiration. Notes: Tenant exercised one of its remaining two options to extend the term at $8/PSF. Second Amendment was executed on 7/17/25. New lease term commenced 1/1/2026.
A35: Kona Gear (SF 962) | B35: Lease Expiration Date: 3/31/2029 Rent: $6.70 PSF for 3 years/$80.40 PSF, plus NNNs Percentage Rent: Remains at 10%, including the 1% marketing fee Option: Tenant has one (1) remaining, three (3) year option with a 3% Base Rent increase. Termination Option: 150-day notice with a $10,000 termination fee/buyout. Notes: New lease term commenced 4/1/2026.
A36: Café Kona (SF 994) | B36: Lease Expiration Date: 8/31/2031 Rent: $3.85 PSF until Foster's opens (approximately 10/26), then increases 3%. Option: Tenant has one (1) remaining, five (5) year option at FMV. Notice due 180 days prior to expiration. Notes: New lease term commences 9/1/2026. - 5 year option - Landlord approved FMV Rent - flat until Foster's open, then 3% increase w/annual increases thereafter. - Parking - Landlord denied request to have his customers to get 1 hour free with validation then half-off and no complimentary parking for owner's vehicles. - Eric Kim would like to be added to the lease (all guarantors remain in place). Landlord approved and management requesting his financials. - Waive 2024 PYC - $7K - 2025 PYC is a credit of $3,700 - Management will tell him we are waiving billing for both and clear it up internally. - Exclusive Use as a tenant that "operates a primary coffee shop or cafe concept" - Landlord approved primary coffee shop, no other tenant with more than 50% sales from coffee, we will NOT agree to the word "cafe" in the exclusion.
A37: Renewals (12 months from current period)
A38: Big Island Running (525 sf) | B38: Renewal Period: 11/1/24-10/31/2029 Rent: $2,625/mo. - $5.00 psf, Annual 3% Increases Option: One (1), Five (5) year option Management sent tenant LOI on January 11, 2024. Off is One (1), Five (5) year renewal at $6.00 PSF with 3% Annual Increases. Offer included One (1), Five (5) Year Option at FMV. Tenant countered at $5.00 PSF. Landlord agreed and Amendment was signed on 2/7/2024.
A39: Gypsea Gelato (SF 500) | B39: Lease Expiration Date: 5/31/2027 Rent: $5.46 PSF Option: Tenant has zero (0) remaining options. Notes: Management reached out to tenant to discuss renewal.
A40: Gross Sales Reporting (Trends & Issues)
A41: Gross Sales increased for the following tenants: - Big Island Running: In July 2026, tenant generated $57,003 in sales, reflecting a 23% increase over June and 14% over prior year - ABC Stores: In July 2026, tenant generated $600,118 in sales, reflecting an 11% increase over June and 3% over prior year - Ocean's: In July 2026, tenant generated $136,150 in sales, reflecting an 8% increase over June and 16% over prior year - Gypsea Gelato: In July 2026, tenant generated $59,806 in sales, reflecting a 3% increase from June, but a 1% decrease from prior year - Taka Sushi: n July 2026, tenant generated $59,432 in sales, reflecting a 9% increase over June and 14.5% over prior year Gross Sales decreased for the following tenants: - Kona Gear: In July 2026, tenant generated $98,254 in sales, reflecting an 6% decrease from June and 3% less than prior year - Island Lava Java: In July 2026, tenant generated $409,811 in sales, reflecting a 3% increase from June, but an 18% decrease from prior year
A42: Tenant Issues
A43: Parking: Parking rates were updated mid year and we have seen consistent growth in Parking Revenue since the change. Parking revenue is up almost 100% from $18k in 2024 to $35k in 2025. Parking complaints have greatly reduced. Now the Village Businesses are concerned parking rates are too high in the Village. A portion of the 2024 parking revenue was applied to tenant accounts to help offset NNN charges. Coconut Grove Marketplace is very competitive. The parking ordinance (Bill 133) did not pass and City Council will not be limiting parking rates. Parklinq has added parking rates to all entrance signs. Humpy's and Laverne's: Third Amendment has been fully executed. Beginning July 1, 2025, and expiring on August 31, 2026, the Monthly Gross Rent that shall be due and payable shall equal the greater of (i) ten percent (10%) of gross sales plus sales tax on that amount and (ii) twenty-five thousand and 0/100 dollars ($25,000.00) each month (the “New Conditional Rent”). On September 1, 2026, Tenant shall resume paying Monthly Minimum Rent, Percentage Rent, and all Additional Rent due under the Lease. Landlord applied $11k security deposit to Humpy's outstanding balance. The remaining balance of $110,521.46 will be deferred through 8/31/26. Humpy's is looking to assign lease/sell the business; CEO of TS Restaurants liked the space and location. SVN waiting to hear back. Fosters - Kitchen fire occurred 7/1/25. Kona Pele and Tasty Kona were affected but were able to reopen within a day or two. Management worked with several vendors in both tenant spaces to mitigate damage. Kona Haven was able to reopen on 7/3/25. Fosters is undergoing insurance investigation and may be closed for several months. The cause of the fire seems to be from a fryer spark. Rents will be paid via the Insurance companies in the meantime. Final insurance inspection completed and rebuilding process will begin. Fosters has complained about parking and sent a breach of contract notice to Landlord. Response was sent to tenant's attorney on 9/12. The insurance company has released rent and NNN through the end of 2025. Demo has been completed and restoration planning has begun. Fosters is still complaining about parking and may use in renegotiation of opening back up. Landlord is negotiating restructure with tenant. Roof work has been completed. Estimated reopening date is November 2026.
A44: Foster's Fire
A45: Foster's Kitchen fire incident was reported on 7/1/25, and Foster's has been closed since that date. Tasty Kona and Café Kona were closed until 7/5/25 due to water damage and electrical concerns. The fire and water damage remediation work has been completed, and the restoration proposals are being reviewed by the adjuster. Insurance payment of $250K was received to cover rent from the date of the incident to December 2025 as well as some of the cleaning and demo work. Management received an additional $190k to cover restoration costs and 2026 rent and impounds. Contract was signed and payments have been mailed to Premier Hawaii Restoration, BH Properties and Bargreen. Roof work has been completed. We have received a new bid and are awaiting one more, and we will revise the estimates after receipt and review of the new bids. Estimated reopening date is November 2026.
...

Sheet Tenant Delinquency
A1: Executive Summary
A2: Coconut Grove
A3: ='Executive Summary'!A3 -> July 2026
A6: Operations Manager: | B6: Danielle Cebrero | G6: Square Feet: | H6: ='Executive Summary'!H7 -> 50133
A7: Assistant Property Manager: | B7: Audrey Verrette | G7: % Leased: | H7: 0.9414
G8: %Occupied | H8: 0.9414
A10: Tenant Delinquency
A12: Tenant | B12: Over $2,500 | C12: Action Taken / Legal Update
A13: Lucasie | B13: 3120.13 | C13: Balance due reflects 2026 NNN short pays and 2025 PYC offset by 2024 PYC credit. Working with Nir Levav to pay the remaining balance. | P13: 39
A14: Humpy's | B14: -39301.31 | C14: Credit reflects 2025 PYC reversal . The balance is being deferred as part of the amendment.
A15: Lavernes | B15: 0 | C15: Balance due reflects July rents paid in August. Tenant has a $0.00 balance
A16: Chong Hot Pot | B16: 5073.45 | C16: Balance due reflects June and July charges offset by Pre-paid Rent. Tenant has not paid August either. They are disputing their Rent Commencement Date. Management continues to follow up.
A17: Total | B17: =SUM(B13:B15) -> -36181.18
A42: Sales are up for December at Coconut Grove Marketplace: - Big Island Running: $80,252 for December 2025, Up 8.7% from December 2024. - Cafe Kona: $33,801 for December 2025, Up 1.7% from December 2024. - ABC Stores: $537,658 for December 2025, Up 2.6% from December 2024. - Kona Gear: $80,995 for December 2025, Up 9.2% from December 2024. - Kanaka Kava: $29,195 for December 2025, Up 1.5% from December 2024. - Ocean's: $142,623 for December 2025, Down 2.7% from December 2024. - Island Lava Java: $473,006 for December 2025, Down 3.8% from December 2024. - Gecko Girlz: $55,513 for December 2025, Up 10.5% from December 2024. - Taka Sushi: $64,208 for December 2025, Up 2.4% from December 2024.
A44: Parking: Parking rates were updated mid year and we have seen consistent growth in Parking Revenue since the change. Parking revenue is up almost 100% from $18k in 2024 to $35k in 2025. Parking complaints have greatly reduced. Now the Village Businesses are concerned parking rates are too high in the Village. A portion of the 2024 parking revenue was applied to tenant accounts to help offset NNN charges. Coconut Grove Marketplace is very competitive. There is a parking ordinance being circulated through the County Council limiting rates to be charged. Humpy's and Laverne's: Third Amendment has been fully executed. Beginning July 1, 2025, and expiring on August 31, 2026, the Monthly Gross Rent that shall be due and payable shall equal the greater of (i) ten percent (10%) of gross sales plus sales tax on that amount and (ii) twenty-five thousand and 0/100 dollars ($25,000.00) each month (the “New Conditional Rent”). On September 1, 2026, Tenant shall resume paying Monthly Minimum Rent, Percentage Rent, and all Additional Rent due under the Lease. Landlord applied $11k security deposit to Humpy's outstanding balance. The remaining balance of $110,521.46 will be deferred through 8/31/26. Humpy's is looking to assign lease/sell the business; CEO of TS Restaurants liked the space and location. SVN waiting to hear back. Fosters - Kitchen fire occurred 7/1/25. Kona Pele and Tasty Kona were affected but were able to reopen within a day or two. Management worked with several vendors in both tenant spaces to mitigate damage. Kona Haven was able to reopen on 7/3/25. Fosters is undergoing insurance investigation and may be closed for several months. The cause of the fire seems to be from a fryer spark. Rents will be paid via the Insurance companies in the meantime. Final insurance inspection completed and rebuilding process will begin. Fosters has complained about parking and sent a breach of contract notice to Landlord. Response was sent to tenant's attorney on 9/12. The insurance company has released rent and NNN through the end of 2025. Demo has been completed and restoration planning has begun. Fosters is still complaining about parking and may use in renegotiation of opening back up. Landlord is negotiating restructure with tenant. Outback - PYC is resolved, termination fee was received, premises was returned to Landlord October 2025. Kona Gear - SVN has replaced ceiling tiles and will keep track of any new leaks.

Sheet COVID 19-Rent Recovery
A2: Covid 10 - Deferred Rent Notes
A3: Coconut Grove
A4: ='Executive Summary'!A3 -> July 2026
A7: Operations Manager: | B7: Danielle Cebrero | G7: Square Feet: | H7: 50133
A8: Assistant Property Manager: | B8: Audrey Verrette | G8: % Leased: | H8: ='Executive Summary'!H8 -> 0.9414
A12: Tenant | B12: Outstanding | D12: Rent Recovery Agreement
A13: Taka Sushi | B13: =R13 -> 7974.45 | D13: Past due balance due to delayed opening. Tenant will pay back $26,581.50 beginning January 1, 2023 over the remainder of the term at $443.03/mo. | M13: RRC CALC. | N13: 26581.5 | O13: =N13/60 -> 443.025 | P13: 42 | Q13: =O13*P13 -> 18607.05 | R13: =N13-Q13 -> 7974.45
A14: Total: | B14: =SUM(B13:B13) -> 7974.45

Sheet Tenant COI Tracking 
A1: Executive Summary
A2: Coconut Grove
A3: ='Executive Summary'!A3 -> July 2026
A8: Operations Manager: | B8: Danielle Cebrero | E8: Square Feet: | G8: 50133
A9: Assistant Property Manager: | B9: Audrey Verrette | E9: % Leased: | G9: 0.9414
E10: % Occupied: | G10: 0.9414
A12: Group | B12: Tracked | C12: COI on File | D12: COI in Compliance | E12: DOC on File | F12: DOC in Compliance | G12: Notes
A14: Coconut Grove Retail XIII LLC | B14: ABC Stores #75 | C14: Yes | D14: Yes | E14: Yes | F14: Yes
A15: Coconut Grove Retail XIII LLC | B15: Big Island Running Company | C15: Yes | D15: Yes | E15: Yes | F15: No | G15: Tenant DOC expired. Management following up on renewal.
A16: Coconut Grove Retail XIII LLC | B16: Kona Haven USA Corp./Cafe Kona | C16: Yes | D16: Yes | E16: Yes | F16: No | G16: Tenant DOC expired. Management following up on renewal.
A17: Coconut Grove Retail XIII LLC | B17: Colors of Paradise Gallery | C17: yes | D17: yes | E17: yes | F17: yes
A18: Coconut Grove Retail XIII LLC | B18: Foster's Kitchen | C18: Yes | D18: Yes | E18: Yes | F18: Yes
A19: Coconut Grove Retail XIII LLC | B19: Gecko Girlz | C19: Yes | D19: Yes | E19: Yes | F19: No | G19: Tenant DOC expired. Management following up on renewal.
A20: Coconut Grove Retail XIII LLC | B20: Gypsea Gelato | C20: Yes | D20: Yes | E20: Yes | F20: Yes
A21: Coconut Grove Retail XIII LLC | B21: Humpy's Big Island Alehouse | C21: Yes | D21: No | E21: Yes | F21: No | G21: Tenant COI and endorsement pages are expired. Management following up on renewal.
A22: Coconut Grove Retail XIII LLC | B22: Island Lava Java | C22: Yes | D22: Yes | E22: Yes | F22: Yes
A23: Coconut Grove Retail XIII LLC | B23: Jack's Diving Locker | C23: Yes | D23: No | E23: Yes | F23: Yes | G23: Tenant COI expired. Management following up on renewal.
A24: Coconut Grove Retail XIII LLC | B24: Kanaka Kava, Inc. | C24: Yes | D24: No | E24: Yes | F24: No | G24: Tenant COI expired. Management following up on renewal.
A25: Coconut Grove Retail XIII LLC | B25: Kona Gear | C25: Yes | D25: Yes | E25: Yes | F25: No | G25: Tenant DOC/ WOS expired. Management following up on renewal.
A26: Coconut Grove Retail XIII LLC | B26: Lucasie | C26: Yes | D26: No | E26: Yes | F26: Yes | G26: Tenant is in compliance with the exception of Auto Coverage. Management to follow up on policy.
A27: Coconut Grove Retail XIII LLC | B27: Laverne's | C27: Yes | D27: No | E27: Yes | F27: No | G27: Tenant COI and endorsement pages are expired. Management following up on renewal.
A28: Coconut Grove Retail XIII LLC | B28: Oceans Sports Bar and Grill | C28: Yes | D28: Yes | E28: Yes | F28: Yes
A29: Coconut Grove Retail XIII LLC | B29: Q Pot Kona | C29: Yes | D29: Yes | E29: Yes | F29: Yes
A30: Coconut Grove Retail XIII LLC | B30: Taka Sushi | C30: Yes | D30: Yes | E30: Yes | F30: No | G30: Additional endorsement pages expired. Management following up on renewal.
A44: Parking: Parking rates were updated mid year and we have seen consistent growth in Parking Revenue since the change. Parking revenue is up almost 100% from $18k in 2024 to $35k in 2025. Parking complaints have greatly reduced. Now the Village Businesses are concerned parking rates are too high in the Village. A portion of the 2024 parking revenue was applied to tenant accounts to help offset NNN charges. Coconut Grove Marketplace is very competitive. There is a parking ordinance being circulated through the County Council limiting rates to be charged. Humpy's and Laverne's: Third Amendment has been fully executed. Beginning July 1, 2025, and expiring on August 31, 2026, the Monthly Gross Rent that shall be due and payable shall equal the greater of (i) ten percent (10%) of gross sales plus sales tax on that amount and (ii) twenty-five thousand and 0/100 dollars ($25,000.00) each month (the “New Conditional Rent”). On September 1, 2026, Tenant shall resume paying Monthly Minimum Rent, Percentage Rent, and all Additional Rent due under the Lease. Landlord applied $11k security deposit to Humpy's outstanding balance. The remaining balance of $110,521.46 will be deferred through 8/31/26. Humpy's is looking to assign lease/sell the business; CEO of TS Restaurants liked the space and location. SVN waiting to hear back. Fosters - Kitchen fire occurred 7/1/25. Kona Pele and Tasty Kona were affected but were able to reopen within a day or two. Management worked with several vendors in both tenant spaces to mitigate damage. Kona Haven was able to reopen on 7/3/25. Fosters is undergoing insurance investigation and may be closed for several months. The cause of the fire seems to be from a fryer spark. Rents will be paid via the Insurance companies in the meantime. Final insurance inspection completed and rebuilding process will begin. Fosters has complained about parking and sent a breach of contract notice to Landlord. Response was sent to tenant's attorney on 9/12. The insurance company has released rent and NNN through the end of 2025. Demo has been completed and restoration planning has begun. Fosters is still complaining about parking and may use in renegotiation of opening back up. Landlord is negotiating restructure with tenant. Outback - PYC is resolved, termination fee was received, premises was returned to Landlord October 2025. Kona Gear - SVN has replaced ceiling tiles and will keep track of any new leaks.

Sheet Tenant Maintenance Tracking
A1: Executive Summary
A2: Coconut Grove
A3: ='Executive Summary'!A3 -> July 2026
A6: Operations Manager: | B6: Danielle Cebrero | C6: Square Feet: | D6: 50133
A7: Assistant Property Manager: | B7: Audrey Verrette | C7: % Leased: | D7: 0.8141
C8: %Occupied: | D8: 0.8141 | E8: c
A10: Tenant | B10: Service | C10: Doc on File | D10: Doc in Compliance | E10: Notes
A12: Cafe Kona | B12: Hood | C12: No | D12: No | E12: Management requested docs from tenant.
A13: Jack's Dive Locker | B13: HVAC | C13: Yes | D13: No | E13: Management requested docs from tenant.
A14: Foster's Kitchen | B14: Grease Interceptor | C14: No | D14: No | E14: Management requested docs from tenant.
A15: Foster's Kitchen | B15: Hood | C15: No | D15: No | E15: Management requested docs from tenant.
A16: Gecko Girlz | B16: Grease Interceptor | C16: Yes | D16: No | E16: Management requested docs from tenant.
A17: Humpy's Big Island Alehouse | B17: Grease Interceptor | C17: No | D17: No | E17: Management requested docs from tenant.
A18: Humpy's Big Island Alehouse | B18: Hood | C18: No | D18: No | E18: Management requested docs from tenant.
A19: Island Lava Java | B19: Hood | C19: No | D19: No | E19: Management requested docs from tenant.
A20: Kanaka Kava, Inc. | B20: Grease Interceptor | C20: No | D20: No | E20: Management requested docs from tenant.
A21: Laverne's | B21: Grease Interceptor | C21: No | D21: No | E21: Management requested docs from tenant.
A22: Laverne's | B22: Hood | C22: No | D22: No | E22: Management requested docs from tenant.
... A28: Taka Sushi | B28: Hood | C28: Yes | D28: No | E28: Management requested docs from tenant.
A42: Sales are up for December at Coconut Grove Marketplace: - Big Island Running: $80,252 for December 2025, Up 8.7% from December 2024. - Cafe Kona: $33,801 for December 2025, Up 1.7% from December 2024. - ABC Stores: $537,658 for December 2025, Up 2.6% from December 2024. - Kona Gear: $80,995 for December 2025, Up 9.2% from December 2024. - Kanaka Kava: $29,195 for December 2025, Up 1.5% from December 2024. - Ocean's: $142,623 for December 2025, Down 2.7% from December 2024. - Island Lava Java: $473,006 for December 2025, Down 3.8% from December 2024. - Gecko Girlz: $55,513 for December 2025, Up 10.5% from December 2024. - Taka Sushi: $64,208 for December 2025, Up 2.4% from December 2024.
A44: Parking: Parking rates were updated mid year and we have seen consistent growth in Parking Revenue since the change. Parking revenue is up almost 100% from $18k in 2024 to $35k in 2025. Parking complaints have greatly reduced. Now the Village Businesses are concerned parking rates are too high in the Village. A portion of the 2024 parking revenue was applied to tenant accounts to help offset NNN charges. Coconut Grove Marketplace is very competitive. There is a parking ordinance being circulated through the County Council limiting rates to be charged. Humpy's and Laverne's: Third Amendment has been fully executed. Beginning July 1, 2025, and expiring on August 31, 2026, the Monthly Gross Rent that shall be due and payable shall equal the greater of (i) ten percent (10%) of gross sales plus sales tax on that amount and (ii) twenty-five thousand and 0/100 dollars ($25,000.00) each month (the “New Conditional Rent”). On September 1, 2026, Tenant shall resume paying Monthly Minimum Rent, Percentage Rent, and all Additional Rent due under the Lease. Landlord applied $11k security deposit to Humpy's outstanding balance. The remaining balance of $110,521.46 will be deferred through 8/31/26. Humpy's is looking to assign lease/sell the business; CEO of TS Restaurants liked the space and location. SVN waiting to hear back. Fosters - Kitchen fire occurred 7/1/25. Kona Pele and Tasty Kona were affected but were able to reopen within a day or two. Management worked with several vendors in both tenant spaces to mitigate damage. Kona Haven was able to reopen on 7/3/25. Fosters is undergoing insurance investigation and may be closed for several months. The cause of the fire seems to be from a fryer spark. Rents will be paid via the Insurance companies in the meantime. Final insurance inspection completed and rebuilding process will begin. Fosters has complained about parking and sent a breach of contract notice to Landlord. Response was sent to tenant's attorney on 9/12. The insurance company has released rent and NNN through the end of 2025. Demo has been completed and restoration planning has begun. Fosters is still complaining about parking and may use in renegotiation of opening back up. Landlord is negotiating restructure with tenant. Outback - PYC is resolved, termination fee was received, premises was returned to Landlord October 2025. Kona Gear - SVN has replaced ceiling tiles and will keep track of any new leaks.

Sheet Fosters Rebuild Costs
A1: Executive Summary
A2: Coconut Grove
A3: ='Executive Summary'!A3 -> July 2026
A6: Operations Manager: | B6: Danielle Cebrero | C6: Square Feet: | D6: 50133
A7: Assistant Property Manager: | C7: % Leased: | D7: 0.9414
C8: %Occupied: | D8: 0.9414
A11: Payments Received
A12: 45964 | B12: 250000
A13: 46080 | B13: 190223.76
A14: 46090 | B14: 861186.79
A15: Total | B15: =SUM(B12:B14) -> 1301410.6
A18: Expenses to Date
A19: Fosters Mechanical fee | B19: 2094.24
A20: Dry off panel board from water, turn on circuit breakers 50% Dep | B20: 16906.75
A21: Diagnose a problem | B21: 393.4
A22: Foster Fire Claim | B22: 1947.64
A23: Foster Restoration | B23: 68652
A24: Foster Restoration | B24: 3597.72
A25: Café Kona Restoration | B25: 8609.08
A26: Foster Insurance claim | B26: 1162.3
A27: Foster Restoration | B27: 129574.83
A28: Kitchen Equipment | B28: 197088.93
A29: Premier Restoration | B29: 18717.43
A30: Additional Kitchen Equipment | B30: 110000
... A33: SCL Builders Deposit | B33: 230591.1
A34: Total | B34: =SUM(B19:B33) -> 798690.42
A36: Future Expenses
A37: Balance of Initial Contract | B37: 138028.21
A38: Anticipated Additional Work | B38: 125000
A39: Construction Management Fee | B39: 32471.29
A42: Total | B42: =SUM(B37:B40) -> 295499.5
A44: Rent and NNN To Date
A45: 46198 | B45: 25907.06
A46: 46228 | B46: 25907.06
A47: 46259 | B47: 25907.06
A48: 46290 | B48: 25907.06
A49: 46320 | B49: 25907.06
A50: 46351 | B50: 25907.06
A51: 46381 | B51: 25907.06
A52: 46048 | B52: 23777.97
...
