Workbook
Name _Builtin0: #N/A

Sheet Notes
B2: Bell Medical Note
B3: Fire Inspections
B5: Parking Lot
B6: Roof
B7: Vendor Changes
B14: Notes to Owner
B15: Notes for 2025
B20: Misc | C20: Management Agreement Commenced June 1, 2025

Sheet Variance
A1: Particulars | B1: 46023 | G1: 46054 | L1: 46082 | Q1: 46113 | V1: 46143 | Z1: 46199 | AF1: 46229 | AM1: YTD
B2: Budget | C2: Payment | D2: Variance | E2: Comments | G2: Budget | H2: Payment | I2: Variance | J2: Comments | L2: Budget | M2: Payment | N2: Variance | O2: Comments | Q2: Budget | R2: Payment | S2: Variance | T2: Comments | V2: Budget | W2: Payment | X2: Variance | Y2: Comments | AA2: Budget | AB2: Payment | AC2: Variance | AD2: Comments | AG2: Budget | AH2: Payment | AI2: Variance | AJ2: Comments | AL2: Budget | AM2: Payment | AN2: Variance | AO2: Comments
A3: Occupational Medicine for Business & Industry | B3: =VLOOKUP(A3,'Final Data'!$A$2:$M$5,2,) -> 14636.695 | C3: =16099.35 -> 16099.35 | D3: =C3-B3 -> 1462.6547 | E3: LAT $1,405.81 not budgeted STX $56.85 budget vs actual | G3: =VLOOKUP(A3,'Final Data'!$A$2:$M$5,3,) -> 14636.695 | H3: 14058.13 | I3: =H3-G3 -> -578.56529 | J3: NNN ($578.57) Short Payment | L3: =VLOOKUP(A3,'Final Data'!$A$2:$M$5,4,) -> 14636.695 | M3: 14636.69 | N3: =M3-L3 -> -0.0052891294 | Q3: 15046.718 | R3: 14058.13 | S3: =R3-Q3 -> -988.58769 | T3: BAS ($398.08) & NNN ($590.51) Short Pmt | V3: =VLOOKUP(A3,'Final Data'!$A$1:$M$5,6,0) -> 15046.718 | W3: 14456.21 | X3: =W3-V3 -> -590.50769 | Y3: NNN ($590.51) Short Pmt | AA3: =VLOOKUP(A3,'Final Data'!$A$1:$G$5,7,0) -> 15046.718 | AB3: 0 | AC3: =AB3-AA3 -> -15046.718 | AD3: BAS ($13,667.36) & NNN ($1,379.36) No Pmt | AG3: =VLOOKUP(A3,'Final Data'!$A$1:$H$5,8,0) -> 15046.718 | AH3: 37147.74 | AI3: =AH3-AG3 -> 22101.022 | AJ3: BAS $14,065.44 04/26 & 06/26 past due paid NNN $7,977.15 02/26 to 06/26 past due paid SLS $58.44 Budget vs Pmt | AL3: =B3+G3+L3+Q3+V3+AA3+AG3 -> 104096.96 | AM3: =C3+H3+M3+R3+W3+AB3+AH3 -> 110456.25 | AN3: =AM3-AL3 -> 6359.2934 | AO3: LAT $1,405.81 not budgeted in Jan'26 STX $115.29 Budget vs Pmt in Jan'26 & July'26 NNN $4,838.20 Budget vs Pmt in June'26 & July'26
A4: Arizona Sports & Spine Physicians | B4: =VLOOKUP(A4,'Final Data'!$A$2:$M$5,2,) -> 4893.7841 | C4: 0 | D4: =C4-B4 -> -4893.7841 | E4: no payment in 01/26 | G4: =VLOOKUP(A4,'Final Data'!$A$2:$M$5,3,) -> 4893.7841 | H4: 5000 | I4: =H4-G4 -> 106.21589 | J4: BAS $4,374.81 & NNN $537.98 for Jan'26 CAM $87.21 Over Payment BAS ($4,374.81) & NNN ($518) for Feb'26 | L4: =VLOOKUP(A4,'Final Data'!$A$2:$M$5,4,) -> 4963.3882 | M4: 6000 | N4: =M4-L4 -> 1036.6118 | O4: BAS $4,374.81 & NNN $537.98 past due paid for Feb'26 BAS($3,816.38) &NNN($79) Short Pmt S.Tax $20.00 budget vs Pmt in Mar'26 | Q4: 5028.642 | R4: =6000 -> 6000 | S4: =R4-Q4 -> 971.35799 | T4: BAS $3,816.38 03/26 past due paid STX $79.07 received BAS ($2,943.63) Short Pmt S.Tax $20.00 budget vs Pmt in Apr'26 | V4: =VLOOKUP(A4,'Final Data'!$A$1:$M$5,6,0) -> 5028.642 | W4: 0 | X4: =W4-V4 -> -5028.642 | Y4: BAS ($4,505.74) & NNN ($522.90) No Pmt | AA4: =VLOOKUP(A4,'Final Data'!$A$1:$G$5,7,0) -> 5028.642 | AB4: 2000 | AC4: =AB4-AA4 -> -3028.642 | AD4: BAS $2,000.00 04/26 past due paid BAS ($4,505.74) & NNN ($522.90) No Pmt | AG4: =VLOOKUP(A4,'Final Data'!$A$1:$H$5,8,0) -> 5028.642 | AH4: 8000 | AI4: =AH4-AG4 -> 2971.358 | AJ4: BAS $2,846.80 & NNN $240.41 04/26 & 05/26 Past due paid CAM ($48.18) Short Pmt STX $19.53 Budget vs Pmt CAM (87.00) Budget vs Pmt | AL4: =B4+G4+L4+Q4+V4+AA4+AG4 -> 34865.524 | AM4: =C4+H4+M4+R4+W4+AB4+AH4 -> 27000 | AN4: =AM4-AL4 -> -7865.5244 | AO4: BAS ($7,108.31) Short Pmt in Apr'26 to July'26 STX $96.81 Budget vs Pmt from Jan'26 to July'26 NNN ($805.39) No Pmt in May'26 to July'26 CAM ($48.18) Short Pmt in July'26
A5: Arizona Trim Clinic | Q5: 0 | R5: 2223.52 | S5: =R5-Q5 -> 2223.52 | T5: BAS $2,223.52 Not budgeted (New TT) | V5: =IFERROR(VLOOKUP(A5,'Final Data'!$A$1:$M$5,6,0),0) -> 0 | W5: 0 | X5: =W5-V5 -> 0 | AA5: 0 | AB5: 0 | AC5: =AB5-AA5 -> 0 | AG5: 0 | AH5: 3043.08 | AI5: =AH5-AG5 -> 3043.08 | AJ5: BAS $629.64 & NNN $2,413.44 Not budgeted (NEW TT) | AL5: =B5+G5+L5+Q5+V5+AA5+AG5 -> 0 | AM5: =C5+H5+M5+R5+W5+AB5+AH5 -> 5266.6 | AN5: =AM5-AL5 -> 5266.6 | AO5: BAS $2,853.16 Not budgeted (New TT) in Apr'26 & July'26 NNN $2,413.44 Not budgeted (NEW TT) in July'26
A6: Vacant | B6: =VLOOKUP(A6,'Final Data'!$A$2:$M$5,2,) -> 0 | C6: 0 | D6: =C6-B6 -> 0 | G6: =VLOOKUP(A6,'Final Data'!$A$2:$M$5,3,) -> 0 | L6: =VLOOKUP(A6,'Final Data'!$A$2:$M$5,4,) -> 0 | V6: =VLOOKUP(A6,'Final Data'!$A$1:$M$5,6,0) -> 15426.241 | W6: 0 | X6: =W6-V6 -> -15426.241 | Y6: BAS ($9,550.56) & NNN ($5,875.68) No Pmt - Vacant | AA6: =VLOOKUP(A6,'Final Data'!$A$1:$G$5,7,0) -> 15426.241 | AB6: 0 | AC6: =AB6-AA6 -> -15426.241 | AD6: BAS ($9,550.56) & NNN ($5,875.68) No Pmt - Vacant | AG6: =VLOOKUP(A6,'Final Data'!$A$1:$H$5,8,0) -> 15426.241 | AH6: 0 | AI6: =AH6-AG6 -> -15426.241 | AJ6: BAS ($9,550.56) & NNN ($5,875.68) No Pmt - Vacant | AL6: =B6+G6+L6+Q6+V6+AA6+AG6 -> 46278.722 | AM6: =C6+H6+M6+R6+W6+AB6+AH6 -> 0 | AN6: =AM6-AL6 -> -46278.722 | AO6: BAS ($28,651.70) & NNN ($17,627.00) No Pmt - Vacant in May'26 to July'26
A7: Vacant | B7: =VLOOKUP(A7,'Final Data'!$A$2:$M$5,2,) -> 0 | C7: 0 | D7: =C7-B7 -> 0 | G7: =VLOOKUP(A7,'Final Data'!$A$2:$M$5,3,) -> 0 | AG7: =VLOOKUP(A7,'Final Data'!$A$1:$H$5,8,0) -> 15426.241 | AL7: =B7 -> 0 | AM7: =C7 -> 0 | AN7: =AM7-AL7 -> 0
B9: =SUM(B3:B7) -> 19530.479 | C9: =SUM(C3:C7) -> 16099.35 | D9: =SUM(D3:D7) -> -3431.1294 | G9: =SUM(G3:G7) -> 19530.479 | H9: =SUM(H3:H7) -> 19058.13 | I9: =SUM(I3:I7) -> -472.3494 | L9: =SUM(L3:L7) -> 19600.083 | M9: =SUM(M3:M7) -> 20636.69 | N9: =SUM(N3:N7) -> 1036.6065 | Q9: =SUM(Q3:Q7) -> 20075.36 | R9: =SUM(R3:R7) -> 22281.65 | S9: =SUM(S3:S7) -> 2206.2903 | V9: =SUM(V3:V7) -> 35501.6 | W9: =SUM(W3:W7) -> 14456.21 | X9: =SUM(X3:X7) -> -21045.39 | AA9: =SUM(AA3:AA7) -> 35501.6 | AB9: =SUM(AB3:AB7) -> 2000 | AC9: =SUM(AC3:AC7) -> -33501.6 | AG9: =SUM(AG3:AG6) -> 35501.6 | AH9: =SUM(AH3:AH6) -> 48190.82 | AI9: =SUM(AI3:AI6) -> 12689.22 | AL9: =SUM(AL3:AL7) -> 185241.2 | AM9: =SUM(AM3:AM7) -> 142722.85 | AN9: =SUM(AN3:AN7) -> -42518.353
G10: 19531 | H10: 19058.13 | I10: -472.87 | L10: 19601 | M10: 20636.68 | N10: 1035.69 | Q10: 20076 | R10: 22281.65 | S10: 2205.65 | V10: 35502 | W10: 14456.21 | X10: -21045.79 | AA10: 35502 | AB10: 2000 | AC10: 33502 | AG10: 35502 | AH10: 48190.82 | AI10: 12688.82 | AL10: 185245 | AM10: 142722.85 | AN10: -42522.15
G11: =G9-G10 -> -0.52060374 | H11: =H9-H10 -> 0 | I11: =I9-I10 -> 0.52060374 | L11: =L9-L10 -> -0.91652632 | M11: =M9-M10 -> 0.01 | N11: =N9-N10 -> 0.91652632 | Q11: =Q9-Q10 -> -0.64030374 | R11: =R9-R10 -> 0 | S11: =S9-S10 -> 0.64030374 | V11: =V9-V10 -> -0.39975271 | W11: =W9-W10 -> 0 | X11: =X9-X10 -> 0.39975271 | AA11: =AA9-AA10 -> -0.39975271 | AB11: =AB9-AB10 -> 0 | AC11: =AC9+AC10 -> 0.39975271 | AG11: =AG10-AG9 -> 0.39975271 | AH11: =AH10-AH9 -> 0 | AI11: =AI10-AI9 -> -0.39975271 | AL11: =AL9-AL10 -> -3.7972957 | AM11: =AM9-AM10 -> 0 | AN11: =AN9-AN10 -> 3.7972957

Sheet Final Data
A1: Row Labels | B1: Sum of Jan | C1: Sum of Feb | D1: Sum of Mar | E1: Sum of Apr | F1: Sum of May | G1: Sum of Jun | H1: Sum of Jul | I1: Sum of Aug | J1: Sum of Sept | K1: Sum of Oct | L1: Sum of Nov | M1: Sum of Dec
A2: Arizona Sports & Spine Physicians | B2: 4893.7841 | C2: 4893.7841 | D2: 4963.3882 | E2: 5028.642 | F2: 5028.642 | G2: 5028.642 | H2: 5028.642 | I2: 5028.642 | J2: 5028.642 | K2: 5028.642 | L2: 5028.642 | M2: 5028.642
A3: Occupational Medicine for Business & Industry | B3: 14636.695 | C3: 14636.695 | D3: 14636.695 | E3: 15046.718 | F3: 15046.718 | G3: 15046.718 | H3: 15046.718 | I3: 15046.718 | J3: 15046.718 | K3: 15046.718 | L3: 15046.718 | M3: 15046.718
A4: Vacant | B4: 0 | C4: 0 | D4: 0 | E4: 0 | F4: 15426.241 | G4: 15426.241 | H4: 15426.241 | I4: 15426.241 | J4: 15426.241 | K4: 15426.241 | L4: 15426.241 | M4: 15426.241
A5: Grand Total | B5: 19530.479 | C5: 19530.479 | D5: 19600.083 | E5: 20075.36 | F5: 35501.6 | G5: 35501.6 | H5: 35501.6 | I5: 35501.6 | J5: 35501.6 | K5: 35501.6 | L5: 35501.6 | M5: 35501.6

Sheet Detail1
A1: Details for Sum of Feb - Tenant: Arizona Sports & Spine Physicians
A3: Tenant | B3: Charge | C3: Jan | D3: Feb | E3: Mar | F3: Apr | G3: May | H3: Jun | I3: Jul | J3: Aug | K3: Sept | L3: Oct | M3: Nov | N3: Dec
A4: Arizona Sports & Spine Physicians | B4: SGN | C4: 119.82 | D4: 119.82 | E4: 119.82 | F4: 119.82 | G4: 119.82 | H4: 119.82 | I4: 119.82 | J4: 119.82 | K4: 119.82 | L4: 119.82 | M4: 119.82 | N4: 119.82
A5: Arizona Sports & Spine Physicians | B5: BAS | C5: 4374.81 | D5: 4374.81 | E5: 4442.3868 | F5: 4505.74 | G5: 4505.74 | H5: 4505.74 | I5: 4505.74 | J5: 4505.74 | K5: 4505.74 | L5: 4505.74 | M5: 4505.74 | N5: 4505.74
A6: Arizona Sports & Spine Physicians | B6: INS | C6: 0 | D6: 0 | E6: 0 | F6: 0 | G6: 0 | H6: 0 | I6: 0 | J6: 0 | K6: 0 | L6: 0 | M6: 0 | N6: 0
A7: Arizona Sports & Spine Physicians | B7: RET | C7: 0 | D7: 0 | E7: 0 | F7: 0 | G7: 0 | H7: 0 | I7: 0 | J7: 0 | K7: 0 | L7: 0 | M7: 0 | N7: 0
A8: Arizona Sports & Spine Physicians | B8: ADM | C8: 0 | D8: 0 | E8: 0 | F8: 0 | G8: 0 | H8: 0 | I8: 0 | J8: 0 | K8: 0 | L8: 0 | M8: 0 | N8: 0
A9: Arizona Sports & Spine Physicians | B9: CAM | C9: 256.61671 | D9: 256.61671 | E9: 256.61671 | F9: 256.61671 | G9: 256.61671 | H9: 256.61671 | I9: 256.61671 | J9: 256.61671 | K9: 256.61671 | L9: 256.61671 | M9: 256.61671 | N9: 256.61671
A10: Arizona Sports & Spine Physicians | B10: NCA | C10: 0 | D10: 0 | E10: 0 | F10: 0 | G10: 0 | H10: 0 | I10: 0 | J10: 0 | K10: 0 | L10: 0 | M10: 0 | N10: 0
A11: Arizona Sports & Spine Physicians | B11: SLS | C11: 142.5374 | D11: 142.5374 | E11: 144.5647 | F11: 146.4653 | G11: 146.4653 | H11: 146.4653 | I11: 146.4653 | J11: 146.4653 | K11: 146.4653 | L11: 146.4653 | M11: 146.4653 | N11: 146.4653
B18: SGN | C18: 119.82 | D18: 119.82 | E18: =D18-C18 -> 0
B19: BAS | C19: 4374.81 | D19: 4374.81 | E19: =D19-C19 -> 0
B20: INS | C20: 0 | E20: =D20-C20 -> 0
B21: RET | C21: 0 | E21: =D21-C21 -> 0
B22: ADM | C22: 0 | E22: =D22-C22 -> 0
B23: CAM | C23: 256.61671 | D23: 343.83 | E23: =D23-C23 -> 87.213294
B24: NCA | C24: 0 | E24: =D24-C24 -> 0
B25: SLS | C25: 142.5374 | D25: 161.54 | E25: =D25-C25 -> 19.002599
C26: 148.74

Sheet Pivot
A3: Row Labels | B3: Sum of Jan | C3: Sum of Feb | D3: Sum of Mar | E3: Sum of Apr | F3: Sum of May | G3: Sum of Jun | H3: Sum of Jul | I3: Sum of Aug | J3: Sum of Sept | K3: Sum of Oct | L3: Sum of Nov | M3: Sum of Dec
A4: Arizona Sports & Spine Physicians | B4: 4893.7841 | C4: 4893.7841 | D4: 4963.3882 | E4: 5028.642 | F4: 5028.642 | G4: 5028.642 | H4: 5028.642 | I4: 5028.642 | J4: 5028.642 | K4: 5028.642 | L4: 5028.642 | M4: 5028.642
A5: Occupational Medicine for Business & Industry | B5: 14636.695 | C5: 14636.695 | D5: 14636.695 | E5: 15046.718 | F5: 15046.718 | G5: 15046.718 | H5: 15046.718 | I5: 15046.718 | J5: 15046.718 | K5: 15046.718 | L5: 15046.718 | M5: 15046.718
A6: Vacant | B6: 0 | C6: 0 | D6: 0 | E6: 0 | F6: 15426.241 | G6: 15426.241 | H6: 15426.241 | I6: 15426.241 | J6: 15426.241 | K6: 15426.241 | L6: 15426.241 | M6: 15426.241
A7: Grand Total | B7: 19530.479 | C7: 19530.479 | D7: 19600.083 | E7: 20075.36 | F7: 35501.6 | G7: 35501.6 | H7: 35501.6 | I7: 35501.6 | J7: 35501.6 | K7: 35501.6 | L7: 35501.6 | M7: 35501.6

Sheet DATA
A1: Tenant | B1: Charge | C1: Jan | D1: Feb | E1: Mar | F1: Apr | G1: May | H1: Jun | I1: Jul | J1: Aug | K1: Sept | L1: Oct | M1: Nov | N1: Dec
A2: Occupational Medicine for Business & Industry | B2: BAS | C2: 13269.28 | D2: 13269.28 | E2: 13269.28 | F2: 13667.36 | G2: 13667.36 | H2: 13667.36 | I2: 13667.36 | J2: 13667.36 | K2: 13667.36 | L2: 13667.36 | M2: 13667.36 | N2: 13667.36
A3: Arizona Sports & Spine Physicians | B3: BAS | C3: 4374.81 | D3: 4374.81 | E3: 4442.3868 | F3: 4505.74 | G3: 4505.74 | H3: 4505.74 | I3: 4505.74 | J3: 4505.74 | K3: 4505.74 | L3: 4505.74 | M3: 4505.74 | N3: 4505.74
A4: Vacant | B4: BAS | C4: 0 | D4: 0 | E4: 0 | F4: 0 | G4: 1217.46 | H4: 1217.46 | I4: 1217.46 | J4: 1217.46 | K4: 1217.46 | L4: 1217.46 | M4: 1217.46 | N4: 1217.46
A5: Vacant | B5: BAS | C5: 0 | D5: 0 | E5: 0 | F5: 0 | G5: 8333.1 | H5: 8333.1 | I5: 8333.1 | J5: 8333.1 | K5: 8333.1 | L5: 8333.1 | M5: 8333.1 | N5: 8333.1
A6: Occupational Medicine for Business & Industry | B6: CAM | C6: 611.19378 | D6: 611.19378 | E6: 611.19378 | F6: 611.19378 | G6: 611.19378 | H6: 611.19378 | I6: 611.19378 | J6: 611.19378 | K6: 611.19378 | L6: 611.19378 | M6: 611.19378 | N6: 611.19378
A7: Arizona Sports & Spine Physicians | B7: CAM | C7: 256.61671 | D7: 256.61671 | E7: 256.61671 | F7: 256.61671 | G7: 256.61671 | H7: 256.61671 | I7: 256.61671 | J7: 256.61671 | K7: 256.61671 | L7: 256.61671 | M7: 256.61671 | N7: 256.61671
A8: Vacant | B8: CAM | C8: 0 | D8: 0 | E8: 0 | F8: 0 | G8: 269.86053 | H8: 269.86053 | I8: 269.86053 | J8: 269.86053 | K8: 269.86053 | L8: 269.86053 | M8: 269.86053 | N8: 269.86053
A9: Vacant | B9: CAM | C9: 0 | D9: 0 | E9: 0 | F9: 0 | G9: 1847.1036 | H9: 1847.1036 | I9: 1847.1036 | J9: 1847.1036 | K9: 1847.1036 | L9: 1847.1036 | M9: 1847.1036 | N9: 1847.1036
A10: Occupational Medicine for Business & Industry | B10: SLS | C10: 426.31151 | D10: 426.31151 | E10: 426.31151 | F10: 438.25391 | G10: 438.25391 | H10: 438.25391 | I10: 438.25391 | J10: 438.25391 | K10: 438.25391 | L10: 438.25391 | M10: 438.25391 | N10: 438.25391
A11: Arizona Sports & Spine Physicians | B11: SLS | C11: 142.5374 | D11: 142.5374 | E11: 144.5647 | F11: 146.4653 | G11: 146.4653 | H11: 146.4653 | I11: 146.4653 | J11: 146.4653 | K11: 146.4653 | L11: 146.4653 | M11: 146.4653 | N11: 146.4653
A12: Vacant | B12: SLS | G12: 57.275646 | H12: 57.275646 | I12: 57.275646 | J12: 57.275646 | K12: 57.275646 | L12: 57.275646 | M12: 57.275646 | N12: 57.275646
A13: Vacant | B13: SLS | G13: 392.03233 | H13: 392.03233 | I13: 392.03233 | J13: 392.03233 | K13: 392.03233 | L13: 392.03233 | M13: 392.03233 | N13: 392.03233
A14: Occupational Medicine for Business & Industry | B14: NCA | C14: 0 | D14: 0 | E14: 0 | F14: 0 | G14: 0 | H14: 0 | I14: 0 | J14: 0 | K14: 0 | L14: 0 | M14: 0 | N14: 0
A15: Arizona Sports & Spine Physicians | B15: NCA | C15: 0 | D15: 0 | E15: 0 | F15: 0 | G15: 0 | H15: 0 | I15: 0 | J15: 0 | K15: 0 | L15: 0 | M15: 0 | N15: 0
A16: Vacant | B16: NCA | C16: 0 | D16: 0 | E16: 0 | F16: 0 | G16: 254.46363 | H16: 254.46363 | I16: 254.46363 | J16: 254.46363 | K16: 254.46363 | L16: 254.46363 | M16: 254.46363 | N16: 254.46363
A17: Vacant | B17: NCA | C17: 0 | D17: 0 | E17: 0 | F17: 0 | G17: 1741.7171 | H17: 1741.7171 | I17: 1741.7171 | J17: 1741.7171 | K17: 1741.7171 | L17: 1741.7171 | M17: 1741.7171 | N17: 1741.7171
A18: Occupational Medicine for Business & Industry | B18: ADM | C18: 0 | D18: 0 | E18: 0 | F18: 0 | G18: 0 | H18: 0 | I18: 0 | J18: 0 | K18: 0 | L18: 0 | M18: 0 | N18: 0
A19: Arizona Sports & Spine Physicians | B19: ADM | C19: 0 | D19: 0 | E19: 0 | F19: 0 | G19: 0 | H19: 0 | I19: 0 | J19: 0 | K19: 0 | L19: 0 | M19: 0 | N19: 0
A20: Vacant | B20: ADM | C20: 0 | D20: 0 | E20: 0 | F20: 0 | G20: 0 | H20: 0 | I20: 0 | J20: 0 | K20: 0 | L20: 0 | M20: 0 | N20: 0
A21: Vacant | B21: ADM | C21: 0 | D21: 0 | E21: 0 | F21: 0 | G21: 0 | H21: 0 | I21: 0 | J21: 0 | K21: 0 | L21: 0 | M21: 0 | N21: 0
A22: Occupational Medicine for Business & Industry | B22: RET | C22: 0 | D22: 0 | E22: 0 | F22: 0 | G22: 0 | H22: 0 | I22: 0 | J22: 0 | K22: 0 | L22: 0 | M22: 0 | N22: 0
A23: Arizona Sports & Spine Physicians | B23: RET | C23: 0 | D23: 0 | E23: 0 | F23: 0 | G23: 0 | H23: 0 | I23: 0 | J23: 0 | K23: 0 | L23: 0 | M23: 0 | N23: 0
A24: Vacant | B24: RET | C24: 0 | D24: 0 | E24: 0 | F24: 0 | G24: 144.20178 | H24: 144.20178 | I24: 144.20178 | J24: 144.20178 | K24: 144.20178 | L24: 144.20178 | M24: 144.20178 | N24: 144.20178
A25: Vacant | B25: RET | C25: 0 | D25: 0 | E25: 0 | F25: 0 | G25: 987.01215 | H25: 987.01215 | I25: 987.01215 | J25: 987.01215 | K25: 987.01215 | L25: 987.01215 | M25: 987.01215 | N25: 987.01215
... A33: Vacant | B33: SGN | C33: 0 | D33: 0 | E33: 0 | F33: 0 | G33: 0 | H33: 0 | I33: 0 | J33: 0 | K33: 0 | L33: 0 | M33: 0 | N33: 0
C36: 161.54 | E36: 4963.39 | F36: 245.07 | I36: 166
I37: =I36-I11 -> 19.534699
C39: =C36-C11 -> 19.002599 | F39: =F11-F36 -> -98.604699
C42: 4505.74
C43: 5378.49
C44: =C43-C42 -> 872.75

Sheet Summary
A2: ATHENA PROPERTY MANAGEMENT
A3: BELL MEDICAL
A4: PROJECT NO. 802 | T4: Date Revised: | U4: =TODAY() -> 46235
A5: 01/01/26-12/31/26
A6: 2026 OPERATING BUDGET
A8: GENERAL | O8: 2026 | P8: 2025 FORECAST TOTALS | Q8: 2025 BUDGET TOTALS | R8: VARIANCE | T8: DENOM. | U8: COST
A9: LEDGER | B9: DESCRIPTION | C9: JAN | D9: FEB | E9: MARCH | F9: APRIL | G9: MAY | H9: JUNE | I9: JULY | J9: AUGUST | K9: SEPT | L9: OCT | M9: NOV | N9: DEC | O9: BUDGET | R9: 2026 BUDGET vs. | S9: % CHANGE | T9: SQUARE | U9: PER
A10: CODE | O10: TOTALS | R10: 2025 FORECAST | T10: FOOTG. | U10: SQ. FT. | AE10: As of 9/13
B12: INCOME
A13: 40100 | B13: Rental Income | C13: =Rent!E23 -> 17644.09 | D13: =Rent!F23 -> 17644.09 | E13: =Rent!G23 -> 17711.667 | F13: =Rent!H23 -> 18173.1 | G13: =Rent!I23 -> 27723.66 | H13: =Rent!J23 -> 27723.66 | I13: =Rent!K23 -> 27723.66 | J13: =Rent!L23 -> 27723.66 | ... N13: =Rent!P23 -> 27723.66 | O13: =SUM(C13:N13) -> 292962.23 | P13: 197127 | Q13: 208938 | R13: =O13-P13 -> 95835.227 | T13: =Rent!$C$23 -> 12474 | U13: =O13/T13 -> 23.485829
A14: 40140 | B14: Common Area | C14: =CAM!E25 -> 867.81048 | D14: =CAM!F25 -> 867.81048 | E14: =CAM!G25 -> 867.81048 | F14: =CAM!H25 -> 867.81048 | G14: =CAM!I25 -> 2984.7746 | H14: =CAM!J25 -> 2984.7746 | I14: =CAM!K25 -> 2984.7746 | J14: =CAM!L25 -> 2984.7746 | ... N14: =CAM!P25 -> 2984.7746 | O14: =SUM(C14:N14) -> 27349.439 | P14: 3781 | Q14: 4044 | R14: =O14-P14 -> 23568.439 | T14: =Rent!$C$23 -> 12474 | U14: =O14/T14 -> 2.1925156
A15: 41300 | B15: State and County Rental Tax 3% | C15: ='Sales Tax'!E35 -> 568.84891 | D15: ='Sales Tax'!F35 -> 568.84891 | E15: ='Sales Tax'!G35 -> 570.87622 | F15: ='Sales Tax'!H35 -> 584.71921 | G15: ='Sales Tax'!I35 -> 1034.0272 | H15: ='Sales Tax'!J35 -> 1034.0272 | I15: ='Sales Tax'!K35 -> 1034.0272 | J15: ='Sales Tax'!L35 -> 1034.0272 | ... N15: ='Sales Tax'!P35 -> 1034.0272 | O15: =SUM(C15:N15) -> 10565.511 | P15: 5959 | Q15: 6386 | R15: =O15-P15 -> 4606.5108 | T15: =Rent!$C$23 -> 12474
A16: 40150 | B16: Prior Year CAM | C16: 0 | D16: 0 | E16: 0 | F16: 0 | G16: 0 | H16: 0 | I16: 0 | J16: 0 | K16: 0 | L16: 0 | M16: 0 | N16: 0 | O16: =SUM(C16:N16) -> 0 | P16: -831 | Q16: 0 | R16: =O16-P16 -> 831 | U16: 0
A17: 40170 | B17: Building CAM | C17: ='Building Expenses'!E26 -> 0 | D17: ='Building Expenses'!F26 -> 0 | E17: ='Building Expenses'!G26 -> 0 | F17: ='Building Expenses'!H26 -> 0 | G17: ='Building Expenses'!I26 -> 1996.1807 | H17: ='Building Expenses'!J26 -> 1996.1807 | I17: ='Building Expenses'!K26 -> 1996.1807 | J17: ='Building Expenses'!L26 -> 1996.1807 | ... N17: ='Building Expenses'!P26 -> 1996.1807 | O17: =SUM(C17:N17) -> 15969.446 | P17: 0 | Q17: 0 | R17: =O17-P17 -> 15969.446 | T17: =Rent!$C$23 -> 12474 | U17: =O17/T17 -> 1.2802185
A18: 40230 | B18: Insurance Income | C18: =Ins.!E25 -> 0 | D18: =Ins.!F25 -> 0 | E18: =Ins.!G25 -> 0 | F18: =Ins.!H25 -> 0 | G18: =Ins.!I25 -> 182.01376 | H18: =Ins.!J25 -> 182.01376 | I18: =Ins.!K25 -> 182.01376 | J18: =Ins.!L25 -> 182.01376 | ... N18: =Ins.!P25 -> 182.01376 | O18: =SUM(C18:N18) -> 1456.1101 | P18: 0 | Q18: 0 | R18: =O18-P18 -> 1456.1101 | T18: =Rent!$C$23 -> 12474 | U18: =O18/T18 -> 0.11673161
A19: 40240 | B19: Property Tax Income | C19: ='RE Tax'!E24 -> 0 | D19: ='RE Tax'!F24 -> 0 | E19: ='RE Tax'!G24 -> 0 | F19: ='RE Tax'!H24 -> 0 | G19: ='RE Tax'!I24 -> 1131.2139 | H19: ='RE Tax'!J24 -> 1131.2139 | I19: ='RE Tax'!K24 -> 1131.2139 | J19: ='RE Tax'!L24 -> 1131.2139 | ... N19: ='RE Tax'!P24 -> 1131.2139 | O19: =SUM(C19:N19) -> 9049.7114 | P19: 0 | Q19: 0 | R19: =O19-P19 -> 9049.7114 | T19: =Rent!$C$23 -> 12474 | U19: =O19/T19 -> 0.72548592
A20: 40390 | B20: Administrative Fee Income | C20: ='Admin Fee'!E26 -> 0 | D20: ='Admin Fee'!F26 -> 0 | E20: ='Admin Fee'!G26 -> 0 | F20: ='Admin Fee'!H26 -> 0 | G20: ='Admin Fee'!I26 -> 0 | H20: ='Admin Fee'!J26 -> 0 | I20: ='Admin Fee'!K26 -> 0 | J20: ='Admin Fee'!L26 -> 0 | ... N20: ='Admin Fee'!P26 -> 0 | O20: =SUM(C20:N20) -> 0 | P20: 0 | Q20: 0 | R20: =O20-P20 -> 0 | T20: =Rent!$C$23 -> 12474 | U20: =O20/T20 -> 0
A21: 40500 | B21: Sign Income | C21: =Signage!E21 -> 449.73 | D21: =Signage!F21 -> 449.73 | E21: =Signage!G21 -> 449.73 | F21: =Signage!H21 -> 449.73 | G21: =Signage!I21 -> 449.73 | H21: =Signage!J21 -> 449.73 | I21: =Signage!K21 -> 449.73 | J21: =Signage!L21 -> 449.73 | ... N21: =Signage!P21 -> 449.73 | O21: =SUM(C21:N21) -> 5396.76 | P21: 0 | Q21: 0 | R21: =O21-P21 -> 5396.76 | T21: =Rent!$C$23 -> 12474 | U21: =O21/T21 -> 0.43264069
A22: 40143 | B22: Deferred CAM Recovery | C22: ='Rent Deferral Recovery'!D30 -> 0 | D22: ='Rent Deferral Recovery'!E30 -> 0 | E22: ='Rent Deferral Recovery'!F30 -> 0 | F22: ='Rent Deferral Recovery'!G30 -> 0 | G22: ='Rent Deferral Recovery'!H30 -> 0 | H22: ='Rent Deferral Recovery'!I30 -> 0 | I22: ='Rent Deferral Recovery'!J30 -> 0 | J22: ='Rent Deferral Recovery'!K30 -> 0 | ... N22: ='Rent Deferral Recovery'!O30 -> 0 | O22: =SUM(C22:N22) -> 0 | P22: 0 | Q22: 0 | R22: =O22-P22 -> 0 | T22: =Rent!$C$23 -> 12474 | U22: =O22/T22 -> 0
A23: 40600 | B23: Late Charge Income | C23: 0 | D23: 0 | E23: 0 | F23: 0 | G23: 0 | H23: 0 | I23: 0 | J23: 0 | K23: 0 | L23: 0 | M23: 0 | N23: 0 | O23: =SUM(C23:N23) -> 0 | P23: 0 | Q23: 0 | R23: =O23-P23 -> 0 | T23: =Rent!$C$23 -> 12474 | U23: =O23/T23 -> 0
A24: 40220 | B24: Rent Abatement | O24: =SUM(C24:N24) -> 0 | P24: 0 | Q24: 0 | R24: =O24-P24 -> 0
A25: 40250 | B25: Miscellaneous Income | O25: =SUM(C25:N25) -> 0 | P25: 2857 | Q25: 0 | R25: =O25-P25 -> -2857
B27: TOTAL INCOME | C27: =SUM(C13:C25) -> 19530.479 | D27: =SUM(D13:D25) -> 19530.479 | E27: =SUM(E13:E25) -> 19600.083 | F27: =SUM(F13:F25) -> 20075.36 | G27: =SUM(G13:G25) -> 35501.6 | H27: =SUM(H13:H25) -> 35501.6 | I27: =SUM(I13:I25) -> 35501.6 | J27: =SUM(J13:J25) -> 35501.6 | ... R27: =SUM(R13:R25) -> 153856.2 | S27: =R27/O27 -> 0.42413933 | U27: =SUM(U13:U25) -> 28.233421
B29: COMMON AREA EXPENSES
A31: 50150 | B31: Landscape- Tree Trimming | C31: 0 | D31: 0 | E31: 0 | F31: 0 | G31: 0 | H31: 0 | J31: 4000 | K31: 0 | M31: 0 | N31: 0 | O31: =SUM(C31:N31) -> 4000 | P31: 3745 | Q31: 2400 | R31: =O31-P31 -> 255 | T31: =CAM!C$25 -> 12474 | U31: =O31/T31 -> 0.32066699
A32: 50160 | B32: Landscape - Consumables | C32: 125 | D32: =C32 -> 125 | E32: =D32 -> 125 | F32: =E32 -> 125 | G32: =F32 -> 125 | H32: =G32 -> 125 | I32: =H32 -> 125 | J32: =I32 -> 125 | K32: =J32 -> 125 | ... N32: =M32 -> 125 | O32: =SUM(C32:N32) -> 1500 | P32: 586 | Q32: 0 | R32: =O32-P32 -> 914
A33: 50190 | B33: Sprinkler Repairs | E33: 50 | H33: 50 | L33: 50 | O33: =SUM(C33:N33) -> 150 | P33: 36 | Q33: 150 | R33: =O33-P33 -> 114 | T33: =CAM!C$25 -> 12474 | U33: 0
A34: 50170 | B34: Landscape Maintenance | C34: 676 | D34: =C34 -> 676 | E34: =D34 -> 676 | F34: =E34 -> 676 | G34: =F34 -> 676 | H34: =G34 -> 676 | I34: =H34 -> 676 | J34: =I34 -> 676 | K34: =J34 -> 676 | ... N34: =M34 -> 676 | O34: =SUM(C34:N34) -> 8112 | P34: 7980 | Q34: 7980 | R34: =O34-P34 -> 132 | T34: =CAM!C$25 -> 12474 | U34: =O34/T34 -> 0.65031265
A35: 50510 | B35: Parking Lot Light Maintenance | C35: 0 | F35: =C35 -> 0 | I35: =F35 -> 0 | L35: 75 | O35: =SUM(C35:N35) -> 75 | P35: 700 | Q35: 0 | R35: =O35-P35 -> -625 | T35: =CAM!C$25 -> 12474 | U35: =O35/T35 -> 0.006012506
A36: 50540 | B36: Parking Lot Repairs | C36: 0 | D36: 0 | E36: 0 | F36: 0 | G36: 0 | H36: 0 | I36: 0 | J36: 0 | K36: 0 | L36: 0 | M36: 0 | N36: 0 | O36: =SUM(C36:N36) -> 0 | P36: 245 | Q36: 0 | R36: =O36-P36 -> -245 | T36: =CAM!C$25 -> 12474 | U36: =O36/T36 -> 0
A37: 50512 | B37: Building - Lighting Maint & Repairs | C37: 50 | F37: =C37 -> 50 | I37: =F37 -> 50 | L37: =I37 -> 50 | O37: =SUM(C37:N37) -> 200 | P37: 180 | Q37: 300 | R37: =O37-P37 -> 20
A38: 50530 | B38: Parking Lot Light Repairs | C38: 225 | E38: =D38 -> 0 | F38: =C38 -> 225 | I38: =F38 -> 225 | J38: 0 | K38: =J38 -> 0 | L38: =I38 -> 225 | M38: 0 | N38: =M38 -> 0 | O38: =SUM(C38:N38) -> 900 | P38: 924 | Q38: 900 | R38: =O38-P38 -> -24 | T38: =CAM!C$25 -> 12474 | U38: =O38/T38 -> 0.072150072
A39: 51030 | B39: Misc Maint & Repairs | O39: =SUM(C39:N39) -> 0 | P39: 210 | Q39: 0 | R39: =O39-P39 -> -210
A40: 51020 | B40: General Maintenance | E40: 275 | H40: =E40 -> 275 | K40: =H40 -> 275 | N40: =K40 -> 275 | O40: =SUM(C40:N40) -> 1100 | P40: 1407 | Q40: 600 | R40: =O40-P40 -> -307 | T40: =CAM!C$25 -> 12474 | U40: =O40/T40 -> 0.088183422
A41: 51040 | B41: Janitorial | C41: 650 | D41: =C41 -> 650 | E41: =D41 -> 650 | F41: =E41 -> 650 | G41: =F41 -> 650 | H41: =G41 -> 650 | I41: =H41 -> 650 | J41: =I41 -> 650 | K41: =J41 -> 650 | ... N41: =M41 -> 650 | O41: =SUM(C41:N41) -> 7800 | P41: 7800 | Q41: 7800 | R41: =O41-P41 -> 0 | T41: =CAM!C$25 -> 12474 | U41: =O41/T41 -> 0.62530063 | V41: no increase for 2026
A42: 52010 | B42: Janitorial Supplies | C42: 75 | F42: 75 | I42: 75 | L42: 75 | O42: =SUM(C42:N42) -> 300 | P42: 185 | Q42: 300 | R42: =O42-P42 -> 115 | T42: =CAM!C$25 -> 12474 | U42: =O42/T42 -> 0.024050024
A43: 51050 | B43: Pest Control | C43: 184 | D43: 85 | E43: 85 | F43: 184 | G43: 85 | H43: 85 | I43: 184 | J43: 85 | K43: 85 | L43: 184 | M43: 85 | N43: 85 | O43: =SUM(C43:N43) -> 1416 | P43: 1416 | Q43: 1416 | R43: =O43-P43 -> 0 | T43: =CAM!C$25 -> 12474 | U43: =O43/T43 -> 0.11351611 | V43: monthly pest/quarterly rodent
A44: 51160 | B44: Security | C44: =650+115 -> 765 | D44: =C44 -> 765 | E44: =D44 -> 765 | F44: =E44 -> 765 | G44: =F44 -> 765 | H44: =G44 -> 765 | I44: =H44 -> 765 | J44: =I44 -> 765 | K44: =J44 -> 765 | ... N44: =M44 -> 765 | O44: =SUM(C44:N44) -> 9180 | P44: =7888+645 -> 8533 | Q44: 7284 | R44: =O44-P44 -> 647 | T44: =CAM!C$25 -> 12474 | U44: =O44/T44 -> 0.73593074 | V44: $621 Security; $115 Internet
A45: 51080 | B45: Management Fee | C45: 1500 | D45: =C45 -> 1500 | E45: =D45 -> 1500 | F45: =E45 -> 1500 | G45: =F45 -> 1500 | H45: =G45 -> 1500 | I45: 1500 | J45: =I45 -> 1500 | K45: =J45 -> 1500 | L45: =K45 -> 1500 | M45: =L45 -> 1500 | N45: =M45 -> 1500 | O45: =SUM(C45:N45) -> 18000 | P45: 14914 | Q45: 13776 | R45: =O45-P45 -> 3086 | T45: =CAM!C$25 -> 12474 | U45: =O45/T45 -> 1.4430014 | V45: $1,500 flat fee
A46: 51100 | B46: Sidewalk Maintenance | C46: 0 | D46: 0 | E46: 875 | F46: 0 | G46: 0 | H46: =E46 -> 875 | I46: 0 | J46: 0 | K46: =H46 -> 875 | L46: 0 | M46: 0 | N46: =K46 -> 875 | O46: =SUM(C46:N46) -> 3500 | P46: 0 | Q46: 0 | R46: =O46-P46 -> 3500 | T46: =CAM!C$25 -> 12474 | U46: =O46/T46 -> 0.28058361
...

Sheet Cap-EX
B3: AMORTIZED PROJECTS
B5: DESCRIPTION | C5: GL CODE | D5: TOTAL PROJECT COST | F5: COST PER YR | G5: # OF YEARS | H5: DATES | K5: NOTES
B6: Restroom Remodel | C6: =Summary!A56 -> 51400 | D6: =1431*5 -> 7155 | F6: =D6/G6 -> 1431 | G6: 5 | H6: 2021-2025
B7: Paint | C7: =Summary!A57 -> 51220 | D7: =2509*5 -> 12545 | F7: =D7/G7 -> 2509 | G7: 5 | H7: 2025-2029
B13: CAP-EX
C15: ACTUAL | D15: ACTUAL | E15: FORECAST | F15: BUDGET | G15: PROJECTED | H15: PROJECTED | I15: PROJECTED | J15: PROJECTED | M15: past / project future projects
B16: DESCRIPTION | C16: 2022 | D16: 2023 | E16: 2024 | F16: 2025 | G16: 2026 | H16: 2027 | I16: 2028 | J16: 2029 | K16: NOTES
B17: Monument Sign upgrade
B18: Electrical/Lighting
B19: Roof
B20: Paint
B21: Landscape
B22: HVAC
B23: Plumbing
B24: Parking lot Slurry
B28: MAINTENANCE TRACKING
B30: DESCRIPTION | D30: COMPLETED | E30: DUE | G30: VENDOR | I30: NOTES
B31: 5-Year Fire Inspection | F31: TBD
B32: Slurry Seal | F32: TBD
B33: Roof | F33: TBD
B34: Paint | F34: TBD
B35: LED | F35: TBD

Sheet Rent
P1: =Summary!T4 -> Date Revised: | Q1: =Summary!U4 -> 46235 | R1: =Summary!V4 -> 0
A2: =Summary!$A2 -> ATHENA PROPERTY MANAGEMENT
A3: =Summary!$A3 -> BELL MEDICAL
A4: =Summary!$A4 -> PROJECT NO. 802
A5: =Summary!$A5 -> 01/01/26-12/31/26
A6: =Summary!$A6 -> 2026 OPERATING BUDGET
A9: TENANT | B9: SUITE | C9: SQUARE | D9: RATE | E9: JAN | F9: FEB | G9: MARCH | H9: APRIL | I9: MAY | J9: JUNE | K9: JULY | L9: AUGUST | M9: SEPT | N9: OCT | O9: NOV | P9: DEC | Q9: TOTALS | R9: NOTES
B10: # | C10: FOOTAGE
A12: BASE RENT
A15: Occupational Medicine for Business & Industry | B15: 100A | C15: 5659 | D15: =P15*12/C15 -> 28.981855 | E15: 13269.28 | F15: =E15 -> 13269.28 | G15: =F15 -> 13269.28 | H15: 13667.36 | I15: =H15 -> 13667.36 | J15: =I15 -> 13667.36 | K15: =J15 -> 13667.36 | L15: =K15 -> 13667.36 | M15: =L15 -> 13667.36 | N15: =M15 -> 13667.36 | O15: =N15 -> 13667.36 | P15: =O15 -> 13667.36 | Q15: =SUM(E15:P15) -> 162814.08 | R15: Rent increase effective 4/1/2026 for $13,667.36 or $2.42 PSF.
A16: Arizona Sports & Spine Physicians | B16: 101A | C16: 1967 | D16: =P16*12/C16 -> 27.487992 | E16: 4374.81 | F16: =E16 -> 4374.81 | G16: =(4374.81*15/31)+(4505.74*16/31) -> 4442.3868 | H16: 4505.74 | I16: =H16 -> 4505.74 | J16: =I16 -> 4505.74 | K16: =J16 -> 4505.74 | L16: =K16 -> 4505.74 | M16: =L16 -> 4505.74 | N16: =M16 -> 4505.74 | O16: =N16 -> 4505.74 | P16: =O16 -> 4505.74 | Q16: =SUM(E16:P16) -> 53743.667 | R16: Rent increase effective 3/16/2026 for $4,505.74 or $2.29 PSF.
A17: Vacant | B17: 100B | C17: 618 | D17: =P17*12/C17 -> 23.64 | E17: 0 | F17: =E17 -> 0 | G17: =F17 -> 0 | H17: =G17 -> 0 | I17: =C17*1.97 -> 1217.46 | J17: =I17 -> 1217.46 | K17: =J17 -> 1217.46 | L17: =K17 -> 1217.46 | M17: =L17 -> 1217.46 | N17: =M17 -> 1217.46 | O17: =N17 -> 1217.46 | P17: =O17 -> 1217.46 | Q17: =SUM(E17:P17) -> 9739.68 | R17: Anticipate Rents Starting May
A18: Vacant | B18: 101B/102B | C18: 4230 | D18: =P18*12/C18 -> 23.64 | E18: 0 | F18: =E18 -> 0 | G18: =F18 -> 0 | H18: =G18 -> 0 | I18: =C18*1.97 -> 8333.1 | J18: =I18 -> 8333.1 | K18: =J18 -> 8333.1 | L18: =K18 -> 8333.1 | M18: =L18 -> 8333.1 | N18: =M18 -> 8333.1 | O18: =N18 -> 8333.1 | P18: =O18 -> 8333.1 | Q18: =SUM(E18:P18) -> 66664.8 | R18: Anticipate Rents Starting May
A23: TOTALS | C23: =SUM(C14:C22) -> 12474 | E23: =SUM(E14:E22) -> 17644.09 | F23: =SUM(F14:F22) -> 17644.09 | G23: =SUM(G14:G22) -> 17711.667 | H23: =SUM(H14:H22) -> 18173.1 | I23: =SUM(I14:I22) -> 27723.66 | J23: =SUM(J14:J22) -> 27723.66 | K23: =SUM(K14:K22) -> 27723.66 | L23: =SUM(L14:L22) -> 27723.66 | ... Q23: =SUM(Q14:Q22) -> 292962.23
D26: NMK Tie-out | E26: =E23-Summary!C13 -> 0 | F26: =F23-Summary!D13 -> 0 | G26: =G23-Summary!E13 -> 0 | H26: =H23-Summary!F13 -> 0 | I26: =I23-Summary!G13 -> 0 | J26: =J23-Summary!H13 -> 0 | K26: =K23-Summary!I13 -> 0 | L26: =L23-Summary!J13 -> 0 | ... Q26: =Q23-Summary!O13 -> 0
A28: TOTAL LESS VACANCY | C28: =C23-C17-C18 -> 7626

Sheet Rent Deferral Recovery
O1: =Summary!T4 -> Date Revised: | P1: =Summary!U4 -> 46235 | Q1: =Summary!V4 -> 0
A2: =Summary!$A2 -> ATHENA PROPERTY MANAGEMENT
A3: =Summary!$A3 -> BELL MEDICAL
A4: =Summary!$A4 -> PROJECT NO. 802
A5: =Summary!$A5 -> 01/01/26-12/31/26
A6: =Summary!$A6 -> 2026 OPERATING BUDGET
A9: TENANT | B9: SUITE | C9: SQUARE | D9: JAN | E9: FEB | F9: MARCH | G9: APRIL | H9: MAY | I9: JUNE | J9: JULY | K9: AUGUST | L9: SEPT | M9: OCT | N9: NOV | O9: DEC | P9: TOTALS
B10: # | C10: FOOTAGE
A12: DEFERRED RENT RECOVERY
A14: None at this time | D14: 0 | E14: 0 | F14: 0 | G14: 0 | H14: 0 | I14: 0 | J14: 0 | K14: 0 | L14: 0 | M14: 0 | N14: 0 | O14: 0 | P14: =SUM(D14:O14) -> 0
A19: TOTALS | C19: =SUM(C14:C14) -> 0 | D19: =SUM(D14:D14) -> 0 | E19: =SUM(E14:E14) -> 0 | F19: =SUM(F14:F14) -> 0 | G19: =SUM(G14:G14) -> 0 | H19: =SUM(H14:H14) -> 0 | I19: =SUM(I14:I14) -> 0 | J19: =SUM(J14:J14) -> 0 | ... P19: =SUM(P14:P14) -> 0
A25: TENANT | B25: SUITE | C25: SQUARE | D25: JAN | E25: FEB | F25: MARCH | G25: APRIL | H25: MAY | I25: JUNE | J25: JULY | K25: AUGUST | L25: SEPT | M25: OCT | N25: NOV | O25: DEC | P25: TOTALS
B26: # | C26: FOOTAGE
A28: DEFERRED CAM RECOVERY
A30: None at this time | D30: 0 | E30: 0 | F30: 0 | G30: 0 | H30: 0 | I30: 0 | J30: 0 | K30: 0 | L30: 0 | M30: 0 | N30: 0 | O30: 0 | P30: =SUM(D30:O30) -> 0
A35: TOTALS | C35: =SUM(C30:C30) -> 0 | D35: =SUM(D30:D30) -> 0 | E35: =SUM(E30:E30) -> 0 | F35: =SUM(F30:F30) -> 0 | G35: =SUM(G30:G30) -> 0 | H35: =SUM(H30:H30) -> 0 | I35: =SUM(I30:I30) -> 0 | J35: =SUM(J30:J30) -> 0 | ... P35: =SUM(P30:P30) -> 0

Sheet CAM
P1: =Summary!T4 -> Date Revised: | Q1: =Summary!U4 -> 46235
A2: =Summary!$A2 -> ATHENA PROPERTY MANAGEMENT
A3: =Summary!$A3 -> BELL MEDICAL
A4: =Summary!$A4 -> PROJECT NO. 802
A5: =Summary!$A5 -> 01/01/26-12/31/26
A6: =Summary!$A6 -> 2026 OPERATING BUDGET
A9: TENANT | B9: SUITE | C9: SQUARE | D9: % OF | E9: JAN | F9: FEB | G9: MARCH | H9: APRIL | I9: MAY | J9: JUNE | K9: JULY | L9: AUGUST | M9: SEPT | N9: OCT | O9: NOV | P9: DEC | Q9: TOTALS | R9: 2015 | S9: TOTALS (2014) | T9: 2014 | U9: Cost PSF
B10: # | C10: FOOTAGE | D10: TOTAL
A12: COMMON AREA MAINTENANCE
A15: =Rent!A15 -> Occupational Medicine for Business & Industry | B15: =Rent!B15 -> 100A | C15: =Rent!C15 -> 5659 | D15: =C15/$C$25 -> 0.45366362 | E15: =IF(Rent!E15=0,0,('Tenant Charges'!$F11)) -> 611.19378 | F15: =IF(Rent!F15=0,0,('Tenant Charges'!$F11)) -> 611.19378 | G15: =IF(Rent!G15=0,0,('Tenant Charges'!$F11)) -> 611.19378 | H15: =IF(Rent!H15=0,0,('Tenant Charges'!$F11)) -> 611.19378 | I15: =IF(Rent!I15=0,0,('Tenant Charges'!$F11)) -> 611.19378 | J15: =IF(Rent!J15=0,0,('Tenant Charges'!$F11)) -> 611.19378 | K15: =IF(Rent!K15=0,0,('Tenant Charges'!$F11)) -> 611.19378 | L15: =IF(Rent!L15=0,0,('Tenant Charges'!$F11)) -> 611.19378 | ... P15: =IF(Rent!P15=0,0,('Tenant Charges'!$F11)) -> 611.19378 | Q15: =SUM(E15:P15) -> 7334.3253 | R15: =Q15/C15 -> 1.2960462 | S15: =262.76*12 -> 3153.12 | T15: =S15/C15 -> 0.55718678 | U15: =Q15/C15 -> 1.2960462
A16: =Rent!A16 -> Arizona Sports & Spine Physicians | B16: =Rent!B16 -> 101A | C16: =Rent!C16 -> 1967 | D16: =C16/$C$25 -> 0.15768799 | E16: =IF(Rent!E16=0,0,('Tenant Charges'!$F12)) -> 256.61671 | F16: =IF(Rent!F16=0,0,('Tenant Charges'!$F12)) -> 256.61671 | G16: =IF(Rent!G16=0,0,('Tenant Charges'!$F12)) -> 256.61671 | H16: =IF(Rent!H16=0,0,('Tenant Charges'!$F12)) -> 256.61671 | I16: =IF(Rent!I16=0,0,('Tenant Charges'!$F12)) -> 256.61671 | J16: =IF(Rent!J16=0,0,('Tenant Charges'!$F12)) -> 256.61671 | K16: =IF(Rent!K16=0,0,('Tenant Charges'!$F12)) -> 256.61671 | L16: =IF(Rent!L16=0,0,('Tenant Charges'!$F12)) -> 256.61671 | ... P16: =IF(Rent!P16=0,0,('Tenant Charges'!$F12)) -> 256.61671 | Q16: =SUM(E16:P16) -> 3079.4005 | R16: =Q16/C16 -> 1.5655315 | S16: 0 | T16: =S16/C16 -> 0 | U16: =Q16/C16 -> 1.5655315
A17: =Rent!A17 -> Vacant | B17: =Rent!B17 -> 100B | C17: =Rent!C17 -> 618 | D17: =C17/$C$25 -> 0.04954305 | E17: =IF(Rent!E17=0,0,('Tenant Charges'!$F13)) -> 0 | F17: =IF(Rent!F17=0,0,('Tenant Charges'!$F13)) -> 0 | G17: =IF(Rent!G17=0,0,('Tenant Charges'!$F13)) -> 0 | H17: =IF(Rent!H17=0,0,('Tenant Charges'!$F13)) -> 0 | I17: =IF(Rent!I17=0,0,('Tenant Charges'!$F13)) -> 269.86053 | J17: =IF(Rent!J17=0,0,('Tenant Charges'!$F13)) -> 269.86053 | K17: =IF(Rent!K17=0,0,('Tenant Charges'!$F13)) -> 269.86053 | L17: =IF(Rent!L17=0,0,('Tenant Charges'!$F13)) -> 269.86053 | ... P17: =IF(Rent!P17=0,0,('Tenant Charges'!$F13)) -> 269.86053 | Q17: =SUM(E17:P17) -> 2158.8842 | R17: =Q17/C17 -> 3.4933402 | S17: 1 | T17: =S17/C17 -> 0.001618123 | U17: =Q17/C17 -> 3.4933402
A18: =Rent!A18 -> Vacant | B18: =Rent!B18 -> 101B/102B | C18: =Rent!C18 -> 4230 | D18: =C18/$C$25 -> 0.33910534 | E18: =IF(Rent!E18=0,0,('Tenant Charges'!$F14)) -> 0 | F18: =IF(Rent!F18=0,0,('Tenant Charges'!$F14)) -> 0 | G18: =IF(Rent!G18=0,0,('Tenant Charges'!$F14)) -> 0 | H18: =IF(Rent!H18=0,0,('Tenant Charges'!$F14)) -> 0 | I18: =IF(Rent!I18=0,0,('Tenant Charges'!$F14)) -> 1847.1036 | J18: =IF(Rent!J18=0,0,('Tenant Charges'!$F14)) -> 1847.1036 | K18: =IF(Rent!K18=0,0,('Tenant Charges'!$F14)) -> 1847.1036 | L18: =IF(Rent!L18=0,0,('Tenant Charges'!$F14)) -> 1847.1036 | ... P18: =IF(Rent!P18=0,0,('Tenant Charges'!$F14)) -> 1847.1036 | Q18: =SUM(E18:P18) -> 14776.829 | R18: =Q18/C18 -> 3.4933402 | S18: 2 | T18: =S18/C18 -> 0.00047281324 | U18: =Q18/C18 -> 3.4933402
A25: TOTALS | C25: =SUM(C14:C23) -> 12474 | D25: =SUM(D14:D23) -> 1 | E25: =SUM(E14:E23) -> 867.81048 | F25: =SUM(F14:F23) -> 867.81048 | G25: =SUM(G14:G23) -> 867.81048 | H25: =SUM(H14:H23) -> 867.81048 | I25: =SUM(I14:I23) -> 2984.7746 | J25: =SUM(J14:J23) -> 2984.7746 | ... Q25: =SUM(Q14:Q23) -> 27349.439
O27: TOTAL CAM | Q27: =Summary!O59 -> 67042
A28: TOTAL OCCUPIED | C28: =C15+C16 -> 7626 | O28: RECAPTURE | Q28: =Q25/Q27 -> 0.40794486
D31: NMK Tie-out | E31: =E25-Summary!C14 -> 0 | F31: =F25-Summary!D14 -> 0 | G31: =G25-Summary!E14 -> 0 | H31: =H25-Summary!F14 -> 0 | I31: =I25-Summary!G14 -> 0 | J31: =J25-Summary!H14 -> 0 | K31: =K25-Summary!I14 -> 0 | L31: =L25-Summary!J14 -> 0 | ... Q31: =Q25-Summary!O14 -> 0

Sheet Building Expenses
P1: =Summary!T4 -> Date Revised: | Q1: =Summary!U4 -> 46235 | R1: =Summary!V4 -> 0
A2: =Summary!$A2 -> ATHENA PROPERTY MANAGEMENT
A3: =Summary!$A3 -> BELL MEDICAL
A4: =Summary!$A4 -> PROJECT NO. 802
A5: =Summary!$A5 -> 01/01/26-12/31/26
A6: =Summary!$A6 -> 2026 OPERATING BUDGET
D8: SQ FT
A9: TENANT | B9: SUITE | C9: SQUARE | D9: % OF | E9: JAN | F9: FEB | G9: MARCH | H9: APRIL | I9: MAY | J9: JUNE | K9: JULY | L9: AUGUST | M9: SEPT | N9: OCT | O9: NOV | P9: DEC | Q9: TOTALS
B10: # | C10: FOOTAGE | D10: TOTAL | R10: Cost PSF
A12: BUILDING EXPENSES
A15: =Rent!A15 -> Occupational Medicine for Business & Industry | B15: =Rent!B15 -> 100A | C15: =Rent!C15 -> 5659 | D15: =C15/$C$26 -> 0.45366362 | E15: =IF(Rent!E15=0,0,('Tenant Charges'!$G11)) -> 0 | F15: =IF(Rent!F15=0,0,('Tenant Charges'!$G11)) -> 0 | G15: =IF(Rent!G15=0,0,('Tenant Charges'!$G11)) -> 0 | H15: =IF(Rent!H15=0,0,('Tenant Charges'!$G11)) -> 0 | I15: =IF(Rent!I15=0,0,('Tenant Charges'!$G11)) -> 0 | J15: =IF(Rent!J15=0,0,('Tenant Charges'!$G11)) -> 0 | K15: =IF(Rent!K15=0,0,('Tenant Charges'!$G11)) -> 0 | L15: =IF(Rent!L15=0,0,('Tenant Charges'!$G11)) -> 0 | ... P15: =IF(Rent!P15=0,0,('Tenant Charges'!$G11)) -> 0 | Q15: =SUM(E15:P15) -> 0 | R15: =Q15/C15 -> 0
A16: =Rent!A16 -> Arizona Sports & Spine Physicians | B16: =Rent!B16 -> 101A | C16: =Rent!C16 -> 1967 | D16: =C16/$C$26 -> 0.15768799 | E16: =IF(Rent!E16=0,0,('Tenant Charges'!$G12)) -> 0 | F16: =IF(Rent!F16=0,0,('Tenant Charges'!$G12)) -> 0 | G16: =IF(Rent!G16=0,0,('Tenant Charges'!$G12)) -> 0 | H16: =IF(Rent!H16=0,0,('Tenant Charges'!$G12)) -> 0 | I16: =IF(Rent!I16=0,0,('Tenant Charges'!$G12)) -> 0 | J16: =IF(Rent!J16=0,0,('Tenant Charges'!$G12)) -> 0 | K16: =IF(Rent!K16=0,0,('Tenant Charges'!$G12)) -> 0 | L16: =IF(Rent!L16=0,0,('Tenant Charges'!$G12)) -> 0 | ... P16: =IF(Rent!P16=0,0,('Tenant Charges'!$G12)) -> 0 | Q16: =SUM(E16:P16) -> 0 | R16: =Q16/C16 -> 0
A17: =Rent!A17 -> Vacant | B17: =Rent!B17 -> 100B | C17: =Rent!C17 -> 618 | D17: =C17/$C$26 -> 0.04954305 | E17: =IF(Rent!E17=0,0,('Tenant Charges'!$G13)) -> 0 | F17: =IF(Rent!F17=0,0,('Tenant Charges'!$G13)) -> 0 | G17: =IF(Rent!G17=0,0,('Tenant Charges'!$G13)) -> 0 | H17: =IF(Rent!H17=0,0,('Tenant Charges'!$G13)) -> 0 | I17: =IF(Rent!I17=0,0,('Tenant Charges'!$G13)) -> 254.46363 | J17: =IF(Rent!J17=0,0,('Tenant Charges'!$G13)) -> 254.46363 | K17: =IF(Rent!K17=0,0,('Tenant Charges'!$G13)) -> 254.46363 | L17: =IF(Rent!L17=0,0,('Tenant Charges'!$G13)) -> 254.46363 | ... P17: =IF(Rent!P17=0,0,('Tenant Charges'!$G13)) -> 254.46363 | Q17: =SUM(E17:P17) -> 2035.7091 | R17: =Q17/C17 -> 3.2940276
A18: =Rent!A18 -> Vacant | B18: =Rent!B18 -> 101B/102B | C18: =Rent!C18 -> 4230 | D18: =C18/$C$26 -> 0.33910534 | E18: =IF(Rent!E18=0,0,('Tenant Charges'!$G14)) -> 0 | F18: =IF(Rent!F18=0,0,('Tenant Charges'!$G14)) -> 0 | G18: =IF(Rent!G18=0,0,('Tenant Charges'!$G14)) -> 0 | H18: =IF(Rent!H18=0,0,('Tenant Charges'!$G14)) -> 0 | I18: =IF(Rent!I18=0,0,('Tenant Charges'!$G14)) -> 1741.7171 | J18: =IF(Rent!J18=0,0,('Tenant Charges'!$G14)) -> 1741.7171 | K18: =IF(Rent!K18=0,0,('Tenant Charges'!$G14)) -> 1741.7171 | L18: =IF(Rent!L18=0,0,('Tenant Charges'!$G14)) -> 1741.7171 | ... P18: =IF(Rent!P18=0,0,('Tenant Charges'!$G14)) -> 1741.7171 | Q18: =SUM(E18:P18) -> 13933.737 | R18: =Q18/C18 -> 3.2940276
A26: TOTALS | C26: =SUM(C14:C25) -> 12474 | D26: =SUM(D14:D25) -> 1 | E26: =SUM(E14:E25) -> 0 | F26: =SUM(F14:F25) -> 0 | G26: =SUM(G14:G25) -> 0 | H26: =SUM(H14:H25) -> 0 | I26: =SUM(I14:I25) -> 1996.1807 | J26: =SUM(J14:J25) -> 1996.1807 | ... Q26: =SUM(Q14:Q25) -> 15969.446
O28: TOTAL BLDG | Q28: =Summary!O72 -> 38926
O29: RECAPTURE | Q29: =Q26/Q28 -> 0.4102514
D31: NMK Tie-out | E31: =E26-Summary!C17 -> 0 | F31: =F26-Summary!D17 -> 0 | G31: =G26-Summary!E17 -> 0 | H31: =H26-Summary!F17 -> 0 | I31: =I26-Summary!G17 -> 0 | J31: =J26-Summary!H17 -> 0 | K31: =K26-Summary!I17 -> 0 | L31: =L26-Summary!J17 -> 0 | ... Q31: =Q26-Summary!O17 -> 0

Sheet Admin Fee
P1: =Summary!T4 -> Date Revised: | Q1: =Summary!U4 -> 46235
A2: =Summary!$A2 -> ATHENA PROPERTY MANAGEMENT
A3: =Summary!$A3 -> BELL MEDICAL
A4: =Summary!$A4 -> PROJECT NO. 802
A5: =Summary!$A5 -> 01/01/26-12/31/26
A6: =Summary!$A6 -> 2026 OPERATING BUDGET
A9: TENANT | B9: SUITE | C9: SQUARE | D9: RATE | E9: JAN | F9: FEB | G9: MARCH | H9: APRIL | I9: MAY | J9: JUNE | K9: JULY | L9: AUGUST | M9: SEPT | N9: OCT | O9: NOV | P9: DEC | Q9: TOTALS
B10: # | C10: FOOTAGE | R10: Cost PSF
A12: ADMINISTRATIVE FEES
A15: =Rent!A15 -> Occupational Medicine for Business & Industry | B15: =Rent!B15 -> 100A | C15: =Rent!C15 -> 5659 | D15: 0 | E15: =IF(Rent!E15=0,0,'Tenant Charges'!$H11) -> 0 | F15: =IF(Rent!F15=0,0,'Tenant Charges'!$H11) -> 0 | G15: =IF(Rent!G15=0,0,'Tenant Charges'!$H11) -> 0 | H15: =IF(Rent!H15=0,0,'Tenant Charges'!$H11) -> 0 | I15: =IF(Rent!I15=0,0,'Tenant Charges'!$H11) -> 0 | J15: =IF(Rent!J15=0,0,'Tenant Charges'!$H11) -> 0 | K15: =IF(Rent!K15=0,0,'Tenant Charges'!$H11) -> 0 | L15: =IF(Rent!L15=0,0,'Tenant Charges'!$H11) -> 0 | ... P15: =IF(Rent!P15=0,0,'Tenant Charges'!$H11) -> 0 | Q15: =SUM(E15:P15) -> 0 | R15: =Q15/C15 -> 0
A16: =Rent!A16 -> Arizona Sports & Spine Physicians | B16: =Rent!B16 -> 101A | C16: =Rent!C16 -> 1967 | D16: 0 | E16: =IF(Rent!E16=0,0,'Tenant Charges'!$H12) -> 0 | F16: =IF(Rent!F16=0,0,'Tenant Charges'!$H12) -> 0 | G16: =IF(Rent!G16=0,0,'Tenant Charges'!$H12) -> 0 | H16: =IF(Rent!H16=0,0,'Tenant Charges'!$H12) -> 0 | I16: =IF(Rent!I16=0,0,'Tenant Charges'!$H12) -> 0 | J16: =IF(Rent!J16=0,0,'Tenant Charges'!$H12) -> 0 | K16: =IF(Rent!K16=0,0,'Tenant Charges'!$H12) -> 0 | L16: =IF(Rent!L16=0,0,'Tenant Charges'!$H12) -> 0 | ... P16: =IF(Rent!P16=0,0,'Tenant Charges'!$H12) -> 0 | Q16: =SUM(E16:P16) -> 0 | R16: =Q16/C16 -> 0
A17: =Rent!A17 -> Vacant | B17: =Rent!B17 -> 100B | C17: =Rent!C17 -> 618 | D17: 1 | E17: =IF(Rent!E17=0,0,'Tenant Charges'!$H13) -> 0 | F17: =IF(Rent!F17=0,0,'Tenant Charges'!$H13) -> 0 | G17: =IF(Rent!G17=0,0,'Tenant Charges'!$H13) -> 0 | H17: =IF(Rent!H17=0,0,'Tenant Charges'!$H13) -> 0 | I17: =IF(Rent!I17=0,0,'Tenant Charges'!$H13) -> 0 | J17: =IF(Rent!J17=0,0,'Tenant Charges'!$H13) -> 0 | K17: =IF(Rent!K17=0,0,'Tenant Charges'!$H13) -> 0 | L17: =IF(Rent!L17=0,0,'Tenant Charges'!$H13) -> 0 | ... P17: =IF(Rent!P17=0,0,'Tenant Charges'!$H13) -> 0 | Q17: =SUM(E17:P17) -> 0 | R17: =Q17/C17 -> 0
A18: =Rent!A18 -> Vacant | B18: =Rent!B18 -> 101B/102B | C18: =Rent!C18 -> 4230 | D18: 2 | E18: =IF(Rent!E18=0,0,'Tenant Charges'!$H14) -> 0 | F18: =IF(Rent!F18=0,0,'Tenant Charges'!$H14) -> 0 | G18: =IF(Rent!G18=0,0,'Tenant Charges'!$H14) -> 0 | H18: =IF(Rent!H18=0,0,'Tenant Charges'!$H14) -> 0 | I18: =IF(Rent!I18=0,0,'Tenant Charges'!$H14) -> 0 | J18: =IF(Rent!J18=0,0,'Tenant Charges'!$H14) -> 0 | K18: =IF(Rent!K18=0,0,'Tenant Charges'!$H14) -> 0 | L18: =IF(Rent!L18=0,0,'Tenant Charges'!$H14) -> 0 | ... P18: =IF(Rent!P18=0,0,'Tenant Charges'!$H14) -> 0 | Q18: =SUM(E18:P18) -> 0 | R18: =Q18/C18 -> 0
A26: TOTALS | C26: =SUM(C14:C25) -> 12474 | E26: =SUM(E14:E25) -> 0 | F26: =SUM(F14:F25) -> 0 | G26: =SUM(G14:G25) -> 0 | H26: =SUM(H14:H25) -> 0 | I26: =SUM(I14:I25) -> 0 | J26: =SUM(J14:J25) -> 0 | K26: =SUM(K14:K25) -> 0 | L26: =SUM(L14:L25) -> 0 | ... Q26: =SUM(Q14:Q25) -> 0
O28: TOTAL ADM | Q28: =Summary!O20 -> 0
O29: RECAPTURE | Q29: =IFERROR(Q26/Q28,0) -> 0
D31: NMK Tie-out | E31: =E26-Summary!C20 -> 0 | F31: =F26-Summary!D20 -> 0 | G31: =G26-Summary!E20 -> 0 | H31: =H26-Summary!F20 -> 0 | I31: =I26-Summary!G20 -> 0 | J31: =J26-Summary!H20 -> 0 | K31: =K26-Summary!I20 -> 0 | L31: =L26-Summary!J20 -> 0 | ... Q31: =Q26-Summary!O20 -> 0

Sheet RE Tax
P1: =Summary!T4 -> Date Revised: | Q1: =Summary!U4 -> 46235 | R1: =Summary!V4 -> 0
A2: =Summary!$A2 -> ATHENA PROPERTY MANAGEMENT
A3: =Summary!$A3 -> BELL MEDICAL
A4: =Summary!$A4 -> PROJECT NO. 802
A5: =Summary!$A5 -> 01/01/26-12/31/26
A6: =Summary!$A6 -> 2026 OPERATING BUDGET
A9: TENANT | B9: SUITE | C9: SQUARE | D9: PRORATA | E9: JAN | F9: FEB | G9: MARCH | H9: APRIL | I9: MAY | J9: JUNE | K9: JULY | L9: AUGUST | M9: SEPT | N9: OCT | O9: NOV | P9: DEC | Q9: TOTALS
B10: # | C10: FOOTAGE | D10: SHARE | R10: Cost PSF
A12: RE Tax
A15: =Rent!A15 -> Occupational Medicine for Business & Industry | B15: =Rent!B15 -> 100A | C15: =Rent!C15 -> 5659 | D15: =C15/$C$24 -> 0.45366362 | E15: =IF(Rent!E15=0,0,('Tenant Charges'!$I11)) -> 0 | F15: =IF(Rent!F15=0,0,('Tenant Charges'!$I11)) -> 0 | G15: =IF(Rent!G15=0,0,('Tenant Charges'!$I11)) -> 0 | H15: =IF(Rent!H15=0,0,('Tenant Charges'!$I11)) -> 0 | I15: =IF(Rent!I15=0,0,('Tenant Charges'!$I11)) -> 0 | J15: =IF(Rent!J15=0,0,('Tenant Charges'!$I11)) -> 0 | K15: =IF(Rent!K15=0,0,('Tenant Charges'!$I11)) -> 0 | L15: =IF(Rent!L15=0,0,('Tenant Charges'!$I11)) -> 0 | ... P15: =IF(Rent!P15=0,0,('Tenant Charges'!$I11)) -> 0 | Q15: =SUM(E15:P15) -> 0 | R15: =Q15/C15 -> 0
A16: =Rent!A16 -> Arizona Sports & Spine Physicians | B16: =Rent!B16 -> 101A | C16: =Rent!C16 -> 1967 | D16: =C16/$C$24 -> 0.15768799 | E16: =IF(Rent!E16=0,0,('Tenant Charges'!$I12)) -> 0 | F16: =IF(Rent!F16=0,0,('Tenant Charges'!$I12)) -> 0 | G16: =IF(Rent!G16=0,0,('Tenant Charges'!$I12)) -> 0 | H16: =IF(Rent!H16=0,0,('Tenant Charges'!$I12)) -> 0 | I16: =IF(Rent!I16=0,0,('Tenant Charges'!$I12)) -> 0 | J16: =IF(Rent!J16=0,0,('Tenant Charges'!$I12)) -> 0 | K16: =IF(Rent!K16=0,0,('Tenant Charges'!$I12)) -> 0 | L16: =IF(Rent!L16=0,0,('Tenant Charges'!$I12)) -> 0 | ... P16: =IF(Rent!P16=0,0,('Tenant Charges'!$I12)) -> 0 | Q16: =SUM(E16:P16) -> 0 | R16: =Q16/C16 -> 0
A17: =Rent!A17 -> Vacant | B17: =Rent!B17 -> 100B | C17: =Rent!C17 -> 618 | D17: =C17/$C$24 -> 0.04954305 | E17: =IF(Rent!E17=0,0,('Tenant Charges'!$I13)) -> 0 | F17: =IF(Rent!F17=0,0,('Tenant Charges'!$I13)) -> 0 | G17: =IF(Rent!G17=0,0,('Tenant Charges'!$I13)) -> 0 | H17: =IF(Rent!H17=0,0,('Tenant Charges'!$I13)) -> 0 | I17: =IF(Rent!I17=0,0,('Tenant Charges'!$I13)) -> 144.20178 | J17: =IF(Rent!J17=0,0,('Tenant Charges'!$I13)) -> 144.20178 | K17: =IF(Rent!K17=0,0,('Tenant Charges'!$I13)) -> 144.20178 | L17: =IF(Rent!L17=0,0,('Tenant Charges'!$I13)) -> 144.20178 | ... P17: =IF(Rent!P17=0,0,('Tenant Charges'!$I13)) -> 144.20178 | Q17: =SUM(E17:P17) -> 1153.6142 | R17: =Q17/C17 -> 1.8666896
A18: =Rent!A18 -> Vacant | B18: =Rent!B18 -> 101B/102B | C18: =Rent!C18 -> 4230 | D18: =C18/$C$24 -> 0.33910534 | E18: =IF(Rent!E18=0,0,('Tenant Charges'!$I14)) -> 0 | F18: =IF(Rent!F18=0,0,('Tenant Charges'!$I14)) -> 0 | G18: =IF(Rent!G18=0,0,('Tenant Charges'!$I14)) -> 0 | H18: =IF(Rent!H18=0,0,('Tenant Charges'!$I14)) -> 0 | I18: =IF(Rent!I18=0,0,('Tenant Charges'!$I14)) -> 987.01215 | J18: =IF(Rent!J18=0,0,('Tenant Charges'!$I14)) -> 987.01215 | K18: =IF(Rent!K18=0,0,('Tenant Charges'!$I14)) -> 987.01215 | L18: =IF(Rent!L18=0,0,('Tenant Charges'!$I14)) -> 987.01215 | ... P18: =IF(Rent!P18=0,0,('Tenant Charges'!$I14)) -> 987.01215 | Q18: =SUM(E18:P18) -> 7896.0972 | R18: =Q18/C18 -> 1.8666896
A24: TOTALS | C24: =SUM(C14:C23) -> 12474 | D24: =SUM(D14:D23) -> 1 | E24: =SUM(E14:E23) -> 0 | F24: =SUM(F14:F23) -> 0 | G24: =SUM(G14:G23) -> 0 | H24: =SUM(H14:H23) -> 0 | I24: =SUM(I14:I23) -> 1131.2139 | J24: =SUM(J14:J23) -> 1131.2139 | ... Q24: =SUM(Q14:Q23) -> 9049.7114
O26: TOTAL RE Tax | Q26: =Summary!O85 -> 34927.63
O27: RECAPTURE | Q27: =Q24/Q26 -> 0.25909893
D29: NMK Tie-out | E29: =E24-Summary!C19 -> 0 | F29: =F24-Summary!D19 -> 0 | G29: =G24-Summary!E19 -> 0 | H29: =H24-Summary!F19 -> 0 | I29: =I24-Summary!G19 -> 0 | J29: =J24-Summary!H19 -> 0 | K29: =K24-Summary!I19 -> 0 | L29: =L24-Summary!J19 -> 0 | ... Q29: =Q24-Summary!O19 -> 0

Sheet Ins.
P1: =Summary!T4 -> Date Revised: | Q1: =Summary!U4 -> 46235 | R1: =Summary!V4 -> 0
A2: =Summary!$A2 -> ATHENA PROPERTY MANAGEMENT
A3: =Summary!$A3 -> BELL MEDICAL
A4: =Summary!$A4 -> PROJECT NO. 802
A5: =Summary!$A5 -> 01/01/26-12/31/26
A6: =Summary!$A6 -> 2026 OPERATING BUDGET
A9: TENANT | B9: SUITE | C9: SQUARE | D9: PRORATA | E9: JAN | F9: FEB | G9: MARCH | H9: APRIL | I9: MAY | J9: JUNE | K9: JULY | L9: AUGUST | M9: SEPT | N9: OCT | O9: NOV | P9: DEC | Q9: TOTALS
B10: # | C10: FOOTAGE | D10: SHARE | R10: Cost PSF
A12: INSURANCE
A15: =Rent!A15 -> Occupational Medicine for Business & Industry | B15: =Rent!B15 -> 100A | C15: =Rent!C15 -> 5659 | D15: =C15/$C$25 -> 0.45366362 | E15: =IF(Rent!E15=0,0,('Tenant Charges'!$J11)) -> 0 | F15: =IF(Rent!F15=0,0,('Tenant Charges'!$J11)) -> 0 | G15: =IF(Rent!G15=0,0,('Tenant Charges'!$J11)) -> 0 | H15: =IF(Rent!H15=0,0,('Tenant Charges'!$J11)) -> 0 | I15: =IF(Rent!I15=0,0,('Tenant Charges'!$J11)) -> 0 | J15: =IF(Rent!J15=0,0,('Tenant Charges'!$J11)) -> 0 | K15: =IF(Rent!K15=0,0,('Tenant Charges'!$J11)) -> 0 | L15: =IF(Rent!L15=0,0,('Tenant Charges'!$J11)) -> 0 | ... P15: =IF(Rent!P15=0,0,('Tenant Charges'!$J11)) -> 0 | Q15: =SUM(E15:P15) -> 0 | R15: =Q15/C15 -> 0
A16: =Rent!A16 -> Arizona Sports & Spine Physicians | B16: =Rent!B16 -> 101A | C16: =Rent!C16 -> 1967 | D16: =C16/$C$25 -> 0.15768799 | E16: =IF(Rent!E16=0,0,('Tenant Charges'!$J12)) -> 0 | F16: =IF(Rent!F16=0,0,('Tenant Charges'!$J12)) -> 0 | G16: =IF(Rent!G16=0,0,('Tenant Charges'!$J12)) -> 0 | H16: =IF(Rent!H16=0,0,('Tenant Charges'!$J12)) -> 0 | I16: =IF(Rent!I16=0,0,('Tenant Charges'!$J12)) -> 0 | J16: =IF(Rent!J16=0,0,('Tenant Charges'!$J12)) -> 0 | K16: =IF(Rent!K16=0,0,('Tenant Charges'!$J12)) -> 0 | L16: =IF(Rent!L16=0,0,('Tenant Charges'!$J12)) -> 0 | ... P16: =IF(Rent!P16=0,0,('Tenant Charges'!$J12)) -> 0 | Q16: =SUM(E16:P16) -> 0 | R16: =Q16/C16 -> 0
A17: =Rent!A17 -> Vacant | B17: =Rent!B17 -> 100B | C17: =Rent!C17 -> 618 | D17: =C17/$C$25 -> 0.04954305 | E17: =IF(Rent!E17=0,0,('Tenant Charges'!$J13)) -> 0 | F17: =IF(Rent!F17=0,0,('Tenant Charges'!$J13)) -> 0 | G17: =IF(Rent!G17=0,0,('Tenant Charges'!$J13)) -> 0 | H17: =IF(Rent!H17=0,0,('Tenant Charges'!$J13)) -> 0 | I17: =IF(Rent!I17=0,0,('Tenant Charges'!$J13)) -> 23.202249 | J17: =IF(Rent!J17=0,0,('Tenant Charges'!$J13)) -> 23.202249 | K17: =IF(Rent!K17=0,0,('Tenant Charges'!$J13)) -> 23.202249 | L17: =IF(Rent!L17=0,0,('Tenant Charges'!$J13)) -> 23.202249 | ... P17: =IF(Rent!P17=0,0,('Tenant Charges'!$J13)) -> 23.202249 | Q17: =SUM(E17:P17) -> 185.61799 | R17: =Q17/C17 -> 0.30035273
A18: =Rent!A18 -> Vacant | B18: =Rent!B18 -> 101B/102B | C18: =Rent!C18 -> 4230 | D18: =C18/$C$25 -> 0.33910534 | E18: =IF(Rent!E18=0,0,('Tenant Charges'!$J14)) -> 0 | F18: =IF(Rent!F18=0,0,('Tenant Charges'!$J14)) -> 0 | G18: =IF(Rent!G18=0,0,('Tenant Charges'!$J14)) -> 0 | H18: =IF(Rent!H18=0,0,('Tenant Charges'!$J14)) -> 0 | I18: =IF(Rent!I18=0,0,('Tenant Charges'!$J14)) -> 158.81151 | J18: =IF(Rent!J18=0,0,('Tenant Charges'!$J14)) -> 158.81151 | K18: =IF(Rent!K18=0,0,('Tenant Charges'!$J14)) -> 158.81151 | L18: =IF(Rent!L18=0,0,('Tenant Charges'!$J14)) -> 158.81151 | ... P18: =IF(Rent!P18=0,0,('Tenant Charges'!$J14)) -> 158.81151 | Q18: =SUM(E18:P18) -> 1270.4921 | R18: =Q18/C18 -> 0.30035273
A25: TOTALS | C25: =SUM(C14:C24) -> 12474 | D25: =SUM(D14:D24) -> 1 | E25: =SUM(E14:E24) -> 0 | F25: =SUM(F14:F24) -> 0 | G25: =SUM(G14:G24) -> 0 | H25: =SUM(H14:H24) -> 0 | I25: =SUM(I14:I24) -> 182.01376 | J25: =SUM(J14:J24) -> 182.01376 | ... Q25: =SUM(Q14:Q24) -> 1456.1101
O27: TOTAL INS | Q27: =Summary!O80 -> 5619.9
O28: RECAPTURE | Q28: =Q25/Q27 -> 0.25909893
D30: NMK Tie-out | E30: =E25-Summary!C18 -> 0 | F30: =F25-Summary!D18 -> 0 | G30: =G25-Summary!E18 -> 0 | H30: =H25-Summary!F18 -> 0 | I30: =I25-Summary!G18 -> 0 | J30: =J25-Summary!H18 -> 0 | K30: =K25-Summary!I18 -> 0 | L30: =L25-Summary!J18 -> 0 | ... Q30: =Q25-Summary!O18 -> 0

Sheet Signage
P1: =Summary!T4 -> Date Revised: | Q1: =Summary!U4 -> 46235 | R1: =Summary!V4 -> 0
A2: =Summary!$A2 -> ATHENA PROPERTY MANAGEMENT
A3: =Summary!$A3 -> BELL MEDICAL
A4: =Summary!$A4 -> PROJECT NO. 802
A5: =Summary!$A5 -> 01/01/26-12/31/26
A6: =Summary!$A6 -> 2026 OPERATING BUDGET
A9: TENANT | B9: SUITE | C9: SQUARE | D9: PRORATA | E9: JAN | F9: FEB | G9: MARCH | H9: APRIL | I9: MAY | J9: JUNE | K9: JULY | L9: AUGUST | M9: SEPT | N9: OCT | O9: NOV | P9: DEC | Q9: TOTALS
B10: # | C10: FOOTAGE | D10: SHARE | R10: Cost PSF
A12: RE Tax
A15: =Rent!A15 -> Occupational Medicine for Business & Industry | B15: =Rent!B15 -> 100A | C15: =Rent!C15 -> 5659 | D15: =C15/$C$21 -> 0.45366362 | E15: 329.91 | F15: =E15 -> 329.91 | G15: =F15 -> 329.91 | H15: =G15 -> 329.91 | I15: =H15 -> 329.91 | J15: =I15 -> 329.91 | K15: =J15 -> 329.91 | L15: =K15 -> 329.91 | M15: =L15 -> 329.91 | ... P15: =O15 -> 329.91 | Q15: =SUM(E15:P15) -> 3958.92 | R15: =Q15/C15 -> 0.69957943
A16: =Rent!A16 -> Arizona Sports & Spine Physicians | B16: =Rent!B16 -> 101A | C16: =Rent!C16 -> 1967 | D16: =C16/$C$21 -> 0.15768799 | E16: 119.82 | F16: =E16 -> 119.82 | G16: =F16 -> 119.82 | H16: =G16 -> 119.82 | I16: =H16 -> 119.82 | J16: =I16 -> 119.82 | K16: =J16 -> 119.82 | L16: =K16 -> 119.82 | M16: =L16 -> 119.82 | ... P16: =O16 -> 119.82 | Q16: =SUM(E16:P16) -> 1437.84 | R16: =Q16/C16 -> 0.73098119
A17: =Rent!A17 -> Vacant | B17: =Rent!B17 -> 100B | C17: =Rent!C17 -> 618 | D17: =C17/$C$21 -> 0.04954305 | E17: 0 | F17: =E17 -> 0 | G17: =F17 -> 0 | H17: =G17 -> 0 | I17: =H17 -> 0 | J17: =I17 -> 0 | K17: =J17 -> 0 | L17: =K17 -> 0 | M17: =L17 -> 0 | ... P17: =O17 -> 0 | Q17: =SUM(E17:P17) -> 0 | R17: =Q17/C17 -> 0
A18: =Rent!A18 -> Vacant | B18: =Rent!B18 -> 101B/102B | C18: =Rent!C18 -> 4230 | D18: =C18/$C$21 -> 0.33910534 | E18: 0 | F18: =E18 -> 0 | G18: =F18 -> 0 | H18: =G18 -> 0 | I18: =H18 -> 0 | J18: =I18 -> 0 | K18: =J18 -> 0 | L18: =K18 -> 0 | M18: =L18 -> 0 | ... P18: =O18 -> 0 | Q18: =SUM(E18:P18) -> 0 | R18: =Q18/C18 -> 0
A21: TOTALS | C21: =SUM(C14:C20) -> 12474 | D21: =SUM(D14:D20) -> 1 | E21: =SUM(E14:E20) -> 449.73 | F21: =SUM(F14:F20) -> 449.73 | G21: =SUM(G14:G20) -> 449.73 | H21: =SUM(H14:H20) -> 449.73 | I21: =SUM(I14:I20) -> 449.73 | J21: =SUM(J14:J20) -> 449.73 | ... Q21: =SUM(Q14:Q20) -> 5396.76
O23: TOTAL RE Tax | Q23: =Summary!O85 -> 34927.63
O24: RECAPTURE | Q24: =Q21/Q23 -> 0.15451263
D26: NMK Tie-out | E26: =E21-Summary!C21 -> 0 | F26: =F21-Summary!D21 -> 0 | G26: =G21-Summary!E21 -> 0 | H26: =H21-Summary!F21 -> 0 | I26: =I21-Summary!G21 -> 0 | J26: =J21-Summary!H21 -> 0 | K26: =K21-Summary!I21 -> 0 | L26: =L21-Summary!J21 -> 0 | ... Q26: =Q21-Summary!O21 -> 0

Sheet Occup,
O1: =Summary!T4 -> Date Revised: | P1: =Summary!U4 -> 46235 | Q1: =Summary!V4 -> 0
A2: =Summary!$A2 -> ATHENA PROPERTY MANAGEMENT
A3: =Summary!$A3 -> BELL MEDICAL
A4: =Summary!$A4 -> PROJECT NO. 802
A5: =Summary!$A5 -> 01/01/26-12/31/26
A6: =Summary!$A6 -> 2026 OPERATING BUDGET
A9: TENANT | B9: SUITE | C9: SQUARE | D9: JAN | E9: FEB | F9: MARCH | G9: APRIL | H9: MAY | I9: JUNE | J9: JULY | K9: AUGUST | L9: SEPT | M9: OCT | N9: NOV | O9: DEC | P9: TOTALS
B10: # | C10: FOOTAGE
A12: ESTIMATED MONTHLY SQUARE FOOTAGE OCCUPIED
A15: =Rent!A15 -> Occupational Medicine for Business & Industry | B15: =Rent!B15 -> 100A | C15: =Rent!C15 -> 5659 | D15: =IF(Rent!E15=0,0,($C15)) -> 5659 | E15: =IF(Rent!F15=0,0,($C15)) -> 5659 | F15: =IF(Rent!G15=0,0,($C15)) -> 5659 | G15: =IF(Rent!H15=0,0,($C15)) -> 5659 | H15: =IF(Rent!I15=0,0,($C15)) -> 5659 | I15: =IF(Rent!J15=0,0,($C15)) -> 5659 | J15: =IF(Rent!K15=0,0,($C15)) -> 5659 | K15: =IF(Rent!L15=0,0,($C15)) -> 5659 | ... O15: =IF(Rent!P15=0,0,($C15)) -> 5659 | P15: =(SUM(D15:O15)/12)/C15 -> 1
A16: =Rent!A16 -> Arizona Sports & Spine Physicians | B16: =Rent!B16 -> 101A | C16: =Rent!C16 -> 1967 | D16: =IF(Rent!E16=0,0,($C16)) -> 1967 | E16: =IF(Rent!F16=0,0,($C16)) -> 1967 | F16: =IF(Rent!G16=0,0,($C16)) -> 1967 | G16: =IF(Rent!H16=0,0,($C16)) -> 1967 | H16: =IF(Rent!I16=0,0,($C16)) -> 1967 | I16: =IF(Rent!J16=0,0,($C16)) -> 1967 | J16: =IF(Rent!K16=0,0,($C16)) -> 1967 | K16: =IF(Rent!L16=0,0,($C16)) -> 1967 | ... O16: =IF(Rent!P16=0,0,($C16)) -> 1967 | P16: =(SUM(D16:O16)/12)/C16 -> 1
A17: =Rent!A17 -> Vacant | B17: =Rent!B17 -> 100B | C17: =Rent!C17 -> 618 | D17: =IF(Rent!E17=0,0,($C17)) -> 0 | E17: =IF(Rent!F17=0,0,($C17)) -> 0 | F17: =IF(Rent!G17=0,0,($C17)) -> 0 | G17: =IF(Rent!H17=0,0,($C17)) -> 0 | H17: =IF(Rent!I17=0,0,($C17)) -> 618 | I17: =IF(Rent!J17=0,0,($C17)) -> 618 | J17: =IF(Rent!K17=0,0,($C17)) -> 618 | K17: =IF(Rent!L17=0,0,($C17)) -> 618 | ... O17: =IF(Rent!P17=0,0,($C17)) -> 618 | P17: =(SUM(D17:O17)/12)/C17 -> 0.66666667
A18: =Rent!A18 -> Vacant | B18: =Rent!B18 -> 101B/102B | C18: =Rent!C18 -> 4230 | D18: =IF(Rent!E18=0,0,($C18)) -> 0 | E18: =IF(Rent!F18=0,0,($C18)) -> 0 | F18: =IF(Rent!G18=0,0,($C18)) -> 0 | G18: =IF(Rent!H18=0,0,($C18)) -> 0 | H18: =IF(Rent!I18=0,0,($C18)) -> 4230 | I18: =IF(Rent!J18=0,0,($C18)) -> 4230 | J18: =IF(Rent!K18=0,0,($C18)) -> 4230 | K18: =IF(Rent!L18=0,0,($C18)) -> 4230 | ... O18: =IF(Rent!P18=0,0,($C18)) -> 4230 | P18: =(SUM(D18:O18)/12)/C18 -> 0.66666667
A21: TOTALS | C21: =SUM(C14:C20) -> 12474 | D21: =SUM(D14:D20) -> 7626 | E21: =SUM(E14:E20) -> 7626 | F21: =SUM(F14:F20) -> 7626 | G21: =SUM(G14:G20) -> 7626 | H21: =SUM(H14:H20) -> 12474 | I21: =SUM(I14:I20) -> 12474 | J21: =SUM(J14:J20) -> 12474 | ... O21: =SUM(O14:O20) -> 12474
D22: =D21/$C$21 -> 0.61135161 | E22: =E21/$C$21 -> 0.61135161 | F22: =F21/$C$21 -> 0.61135161 | G22: =G21/$C$21 -> 0.61135161 | H22: =H21/$C$21 -> 1 | I22: =I21/$C$21 -> 1 | J22: =J21/$C$21 -> 1 | K22: =K21/$C$21 -> 1 | ... O22: =O21/$C$21 -> 1
A24: Occupied Square Footage | C24: =C15+C16 -> 7626
A26: Gross Up Percentage | C26: =C21/C24 -> 1.6357199
A28: 95% Occupancy | C28: =C26*0.95 -> 1.5539339

Sheet Sales Tax
A2: ATHENA PROPERTY MANAGEMENT
A3: =Summary!A3 -> BELL MEDICAL
A4: =Summary!A4 -> PROJECT NO. 802
A5: =Summary!A5 -> 01/01/26-12/31/26
A6: =Summary!A6 -> 2026 OPERATING BUDGET
Q8: YEARLY TOTAL
A9: TENANT | B9: SUITE | C9: SQUARE | D9: RATE | E9: JAN | F9: FEB | G9: MARCH | H9: APRIL | I9: MAY | J9: JUNE | K9: JULY | L9: AUGUST | M9: SEPT | N9: OCT | O9: NOV | P9: DEC | R9: ANN | S9: MON
B10: # | C10: FOOTAGE
A11: Rental Sales Tax | D11: =0.5%+2.5% -> 0.03
A14: =Rent!A15 -> Occupational Medicine for Business & Industry | B14: =Rent!B15 -> 100A | C14: =Rent!C15 -> 5659 | Q14: =SUM(E14:P14) -> 0
B15: Total Monthly Charges | E15: =IF(Rent!E15=0,0,(Rent!E15+(SUM('Tenant Charges'!$F11:$K11)))) -> 14210.384 | F15: =IF(Rent!F15=0,0,(Rent!F15+(SUM('Tenant Charges'!$F11:$K11)))) -> 14210.384 | G15: =IF(Rent!G15=0,0,(Rent!G15+(SUM('Tenant Charges'!$F11:$K11)))) -> 14210.384 | H15: =IF(Rent!H15=0,0,(Rent!H15+(SUM('Tenant Charges'!$F11:$K11)))) -> 14608.464 | I15: =IF(Rent!I15=0,0,(Rent!I15+(SUM('Tenant Charges'!$F11:$K11)))) -> 14608.464 | J15: =IF(Rent!J15=0,0,(Rent!J15+(SUM('Tenant Charges'!$F11:$K11)))) -> 14608.464 | K15: =IF(Rent!K15=0,0,(Rent!K15+(SUM('Tenant Charges'!$F11:$K11)))) -> 14608.464 | L15: =IF(Rent!L15=0,0,(Rent!L15+(SUM('Tenant Charges'!$F11:$K11)))) -> 14608.464 | ... P15: =IF(Rent!P15=0,0,(Rent!P15+(SUM('Tenant Charges'!$F11:$K11)))) -> 14608.464 | Q15: =SUM(E15:P15) -> 174107.33
