Workbook
Name _Builtin0: #N/A

Sheet Notes
B2: Greenfield Budget Notes
B3: Fire Inspections
B5: Parking Lot
B6: Roof
B7: Vendor Changes
B14: Notes to Owner
B15: Notes for 2025
B20: Misc | C20: Management Agreement Commenced June 1, 2025

Sheet 2026
BI1: YTD - 2026
B2: MONTHLY TENANT CHARGES | C2: Budget | D2: Cash | E2: Variance | F2: Comments | H2: Budget | I2: Cash | J2: Variance | K2: Comments | M2: Budget | N2: Cash | O2: Variance | P2: Comments | R2: Budget | S2: Cash | T2: Variance | U2: Comments | V2: Budget | W2: Cash | X2: Variance | Y2: Comments | Z2: Budget | AA2: Cash | AB2: Variance | AC2: Comments | AE2: Budget | AF2: Cash | AG2: Variance | AH2: Comments | AJ2: Budget | AK2: Cash | AL2: Variance | AM2: Comments | AO2: Budget | AP2: Cash | AQ2: Variance | AR2: Comments | AT2: Budget | AU2: Cash | AV2: Variance | AW2: Comments | AX2: Budget | AY2: Cash | AZ2: Variance | BA2: Comments | BC2: Budget | BD2: Cash | BE2: Variance | BF2: Comments | BH2: Budget | BI2: Cash | BJ2: Variance | BK2: Comments
B3: TENANT | C3: 46023 | D3: 46023 | E3: 46023 | F3: 46023 | H3: 46054 | I3: 46054 | J3: 46054 | K3: 46054 | M3: 46082 | N3: 46082 | O3: 46082 | P3: 46082 | R3: 46113 | S3: 46113 | T3: 46113 | U3: 46113 | V3: 46143 | W3: 46143 | X3: 46143 | Y3: 46143 | Z3: 46198 | AA3: 46198 | AB3: 46198 | AC3: 46198 | AE3: 46228 | AF3: 46228 | AG3: 46228 | AH3: 46228 | AJ3: 46259 | AK3: 46259 | AL3: 46259 | AM3: 46259 | AO3: 46290 | AP3: 46290 | AQ3: 46290 | AR3: 46290 | AT3: 46320 | AU3: 46320 | AV3: 46320 | AW3: 46320 | AX3: 46351 | AY3: 46351 | AZ3: 46351 | BA3: 46351 | BC3: 46381 | BD3: 46381 | BE3: 46381 | BF3: 46381
A4: =Rent!B14 -> Major A | B4: =Rent!A14 -> EOS Fitness | C4: =VLOOKUP(B4,'Final Data'!A3:B27,2,0) -> 66174.826 | D4: 66725.03 | E4: =D4-C4 -> 550.20436 | F4: CAM $550.19 Over Pmt | H4: =VLOOKUP(B4,'Final Data'!A:C,3,0) -> 66174.826 | I4: 66725.03 | J4: =I4-H4 -> 550.20436 | K4: CAM $550.19 Over Pmt | M4: =VLOOKUP(B4,'Final Data'!A:D,4,0) -> 66174.826 | N4: 81513.54 | O4: =N4-M4 -> 15338.714 | P4: Applied (1,100) CAM credit to charges PYC $16,038.14 received STX $401 Paid for prior balance. | R4: =VLOOKUP(B4,'Final Data'!A:E,5,0) -> 66174.826 | S4: 66174.83 | T4: =S4-R4 -> 0.0043562544 | V4: =VLOOKUP(B4,'Final Data'!A:G,6,0) -> 66174.826 | W4: 72994.79 | X4: =W4-V4 -> 6819.9644 | Y4: PYC $6,653.61 received STX $166.34 received | Z4: =VLOOKUP(B4,'Final Data'!A:G,7,0) -> 66174.826 | AA4: 66174.84 | AB4: =AA4-Z4 -> 0.014356254 | AE4: =VLOOKUP(B4,'Final Data'!A:H,8,0) -> 66174.826 | AF4: 66174.84 | AG4: =AF4-AE4 -> 0.014356254 | AJ4: =VLOOKUP(B4,'Final Data'!A:I,9,0) -> 66174.826 | AK4: 66174.84 | AL4: =AK4-AJ4 -> 0.014356254 | BH4: =+C4+H4+M4+R4+V4+Z4+AE4+AJ4+AO4+AT4+AX4+BC4 -> 529398.61 | BI4: =+D4+I4+N4+S4+W4+AA4+AF4+AK4+AP4+AU4+AY4+BD4 -> 552657.74 | BJ4: =+E4+J4+O4+T4+X4+AB4+AG4+AL4+AQ4+AV4+AZ4+BE4 -> 23259.135 | BK4: STX $401.00 Budget vs pmt. PYC $22,691.75 received in Mar'26 & May'26 STX $166.34 received in May'26
A5: =Rent!B15 -> B101 | B5: =Rent!A15 -> Third Pasrty MVS | C5: =VLOOKUP(B5,'Final Data'!A4:B28,2,0) -> 8225.115 | D5: 8225.14 | E5: =D5-C5 -> 0.024978176 | H5: =VLOOKUP(B5,'Final Data'!A:C,3,0) -> 8225.115 | I5: 8225.12 | J5: =I5-H5 -> 0.0049781756 | M5: =VLOOKUP(B5,'Final Data'!A:D,4,0) -> 8225.115 | N5: 8225.12 | O5: =N5-M5 -> 0.0049781756 | R5: =VLOOKUP(B5,'Final Data'!A:E,5,0) -> 8225.115 | S5: 8225.14 | T5: =S5-R5 -> 0.024978176 | V5: =VLOOKUP(B5,'Final Data'!A:G,6,0) -> 8225.115 | W5: 9380.92 | X5: =W5-V5 -> 1155.805 | Y5: PYC $1,100.74 received STX $27.52 received CAM $27.52 Over Pmt | Z5: =VLOOKUP(B5,'Final Data'!A:G,7,0) -> 8225.115 | AA5: 8197.62 | AB5: =AA5-Z5 -> -27.495022 | AC5: CAM ($27.52) Over pmt applied to current charges | AE5: =VLOOKUP(B5,'Final Data'!A:H,8,0) -> 8225.115 | AF5: 8225.14 | AG5: =AF5-AE5 -> 0.024978176 | AJ5: =VLOOKUP(B5,'Final Data'!A:I,9,0) -> 8225.115 | AK5: 8225.14 | AL5: =AK5-AJ5 -> 0.024978176 | BH5: =+C5+H5+M5+R5+V5+Z5+AE5+AJ5+AO5+AT5+AX5+BC5 -> 65800.92 | BI5: =+D5+I5+N5+S5+W5+AA5+AF5+AK5+AP5+AU5+AY5+BD5 -> 66929.34 | BJ5: =+E5+J5+O5+T5+X5+AB5+AG5+AL5+AQ5+AV5+AZ5+BE5 -> 1128.4198 | BK5: PYC $1,100.74 received in May'26 STX $27.52 received in May'26
A6: =Rent!B16 -> B103 | B6: =Rent!A16 -> Sally Beauty Supply | C6: =VLOOKUP(B6,'Final Data'!A5:B29,2,0) -> 3311.5729 | D6: 3371 | E6: =D6-C6 -> 59.4271 | F6: CAM $59.43 Over Pmt | H6: =VLOOKUP(B6,'Final Data'!A:C,3,0) -> 3311.5729 | I6: 3371 | J6: =I6-H6 -> 59.4271 | K6: CAM $59.43 Over Pmt | M6: =VLOOKUP(B6,'Final Data'!A:D,4,0) -> 3311.5729 | N6: 3371 | O6: =N6-M6 -> 59.4271 | P6: CAM $59.43 Over Pmt | R6: =VLOOKUP(B6,'Final Data'!A:E,5,0) -> 3311.5729 | S6: 3371 | T6: =S6-R6 -> 59.4271 | U6: CAM $59.43 Over Pmt | V6: =VLOOKUP(B6,'Final Data'!A:G,6,0) -> 3311.5729 | W6: 3371 | X6: =W6-V6 -> 59.4271 | Y6: CAM $59.43 Over Pmt | Z6: =VLOOKUP(B6,'Final Data'!A:G,7,0) -> 3311.5729 | AA6: 3371 | AB6: =AA6-Z6 -> 59.4271 | AC6: CAM $59.43 Over Pmt | AE6: =VLOOKUP(B6,'Final Data'!A:H,8,0) -> 3311.5729 | AF6: 3371 | AG6: =AF6-AE6 -> 59.4271 | AH6: CAM $59.43 Over Pmt | AJ6: =VLOOKUP(B6,'Final Data'!A:I,9,0) -> 3311.5729 | AK6: 2895.56 | AL6: =AK6-AJ6 -> -416.0129 | AM6: CAM credit ($416.01) being applied to BAS & NNN current charges | BH6: =+C6+H6+M6+R6+V6+Z6+AE6+AJ6+AO6+AT6+AX6+BC6 -> 26492.583 | BI6: =+D6+I6+N6+S6+W6+AA6+AF6+AK6+AP6+AU6+AY6+BD6 -> 26492.56 | BJ6: =+E6+J6+O6+T6+X6+AB6+AG6+AL6+AQ6+AV6+AZ6+BE6 -> -0.023198761
A7: =Rent!B17 -> B104 | B7: =Rent!A17 -> Wild Side Smoke Shop | C7: =VLOOKUP(B7,'Final Data'!A6:B30,2,0) -> 3363.2469 | D7: 3091.9 | E7: =D7-C7 -> -271.34687 | F7: CAM ($271.35) Short Pmt | H7: =VLOOKUP(B7,'Final Data'!A:C,3,0) -> 3363.2469 | I7: 3363.25 | J7: =I7-H7 -> 0.0031312417 | M7: =VLOOKUP(B7,'Final Data'!A:D,4,0) -> 3363.2469 | N7: 3363.25 | O7: =N7-M7 -> 0.0031312417 | R7: =VLOOKUP(B7,'Final Data'!A:E,5,0) -> 3363.2469 | S7: 3363.25 | T7: =S7-R7 -> 0.0031312417 | V7: =VLOOKUP(B7,'Final Data'!A:G,6,0) -> 3439.3634 | W7: 3363.25 | X7: =W7-V7 -> -76.113369 | Y7: BAS ($74.26) & STX ($1.85) Short Pmt | Z7: =VLOOKUP(B7,'Final Data'!A:G,7,0) -> 3439.3634 | AA7: 3363.25 | AB7: =AA7-Z7 -> -76.113369 | AC7: BAS ($74.26) & STX ($1.85) Short Pmt | AE7: =VLOOKUP(B7,'Final Data'!A:H,8,0) -> 3439.3634 | AF7: 3363.25 | AG7: =AF7-AE7 -> -76.113369 | AH7: BAS ($74.26) & STX ($1.85) Short Pmt | AJ7: =VLOOKUP(B7,'Final Data'!A:I,9,0) -> 3439.3634 | AK7: 3363.25 | AL7: =AK7-AJ7 -> -76.113369 | AM7: BAS ($74.26) & STX ($1.85) Short Pmt | BH7: =+C7+H7+M7+R7+V7+Z7+AE7+AJ7+AO7+AT7+AX7+BC7 -> 27210.441 | BI7: =+D7+I7+N7+S7+W7+AA7+AF7+AK7+AP7+AU7+AY7+BD7 -> 26634.65 | BJ7: =+E7+J7+O7+T7+X7+AB7+AG7+AL7+AQ7+AV7+AZ7+BE7 -> -575.79095 | BK7: CAM ($345.61) Short Pmt in Jan'26 & June'26 BAS ($222.78) & STX ($7.40) Short Pmt in May'26, June'26 & Aug'26
A8: =Rent!B18 -> B105 | B8: =Rent!A18 -> Green Spa, LLC | C8: =VLOOKUP(B8,'Final Data'!A7:B31,2,0) -> 2815.0955 | D8: 2698.17 | E8: =D8-C8 -> -116.92554 | F8: CAM ($116.92) Short Pmt | H8: =VLOOKUP(B8,'Final Data'!A:C,3,0) -> 2815.0955 | I8: 2937.03 | J8: =I8-H8 -> 121.93446 | K8: CAM $116.92 01/26 past due paid CAM $5.02 Over Pmt | M8: =VLOOKUP(B8,'Final Data'!A:D,4,0) -> 2815.0955 | N8: 2815.1 | O8: =N8-M8 -> 0.0044613863 | R8: =VLOOKUP(B8,'Final Data'!A:E,5,0) -> 2858.2788 | S8: 2815.1 | T8: =S8-R8 -> -43.178789 | U8: BAS ($42.13) Budget vs Pmt STX ($1.70) Short Pmt | V8: =VLOOKUP(B8,'Final Data'!A:G,6,0) -> 2858.2788 | W8: 2885.1 | X8: =W8-V8 -> 26.821211 | Y8: BAS ($42.13) Budget vs Pmt STX $1.70 received PYC $68.14 received | Z8: =VLOOKUP(B8,'Final Data'!A:G,7,0) -> 2858.2788 | AA8: 2885.1 | AB8: =AA8-Z8 -> 26.821211 | AC8: BAS ($42.13) Budget vs Pmt STX ($1.05) Budget vs Pmt CAM $70.01 Over Pmt | AE8: =VLOOKUP(B8,'Final Data'!A:H,8,0) -> 2858.2788 | AF8: 2815.1 | AG8: =AF8-AE8 -> -43.178789 | AH8: BAS ($42.13) Budget vs Pmt STX ($1.05) Budget vs Pmt | AJ8: =VLOOKUP(B8,'Final Data'!A:I,9,0) -> 2858.2788 | AK8: 2815.1 | AL8: =AK8-AJ8 -> -43.178789 | AM8: BAS ($42.13) Budget vs Pmt STX ($1.05) Budget vs Pmt | BH8: =+C8+H8+M8+R8+V8+Z8+AE8+AJ8+AO8+AT8+AX8+BC8 -> 22736.681 | BI8: =+D8+I8+N8+S8+W8+AA8+AF8+AK8+AP8+AU8+AY8+BD8 -> 22665.8 | BJ8: =+E8+J8+O8+T8+X8+AB8+AG8+AL8+AQ8+AV8+AZ8+BE8 -> -70.880559 | BK8: CAM $75.03 Over Pmt in Feb'26 & June'26 BAS ($210.65) Budget vs Pmt in Apr'26 to Aug'26 PYC $68.14 received in May'26 STX ($3.15) Budget vs Pmt in June'26 to Aug'26
B9: John F. Long Foundation | C9: 15.375 | D9: 60 | E9: =D9-C9 -> 44.625 | F9: ELEC $60.00 Past due paid SGN ($15.00) No pmt STX ($0.38) No Pmt | G9: =60-15 -> 45 | H9: =VLOOKUP(B9,'Final Data'!A:C,3,0) -> 15.375 | I9: 0 | J9: =I9-H9 -> -15.375 | K9: SGN ($15.00) No pmt STX ($0.38) No Pmt | M9: =VLOOKUP(B9,'Final Data'!A:D,4,0) -> 15.375 | N9: 0 | O9: =N9-M9 -> -15.375 | P9: SGN ($15.00) No pmt STX ($0.38) No Pmt | R9: =VLOOKUP(B9,'Final Data'!A:E,5,0) -> 15.375 | S9: 60 | T9: =S9-R9 -> 44.625 | U9: SGN $45.00 01/26 to 03/26 past due paid STX ($0.38) Short Pmt | V9: =VLOOKUP(B9,'Final Data'!A:G,6,0) -> 15.375 | W9: 0 | X9: =W9-V9 -> -15.375 | Y9: SGN ($15.00) & STX ($0.38) Short Pmt | Z9: =VLOOKUP(B9,'Final Data'!A:G,7,0) -> 15.375 | AA9: 0 | AB9: =AA9-Z9 -> -15.375 | AC9: SGN ($15.00) & STX ($0.38) Short Pmt | AE9: =VLOOKUP(B9,'Final Data'!A:H,8,0) -> 15.375 | AF9: 0 | AG9: =AF9-AE9 -> -15.375 | AH9: SGN ($15.00) & STX ($0.38) Short Pmt | AJ9: =VLOOKUP(B9,'Final Data'!A:I,9,0) -> 15.375 | AK9: 45 | AL9: =AK9-AJ9 -> 29.625 | AM9: SGN $45.00 past due paid SGN ($15.00) & STX ($0.38) Short Pmt | BH9: =+C9+H9+M9+R9+V9+Z9+AE9+AJ9+AO9+AT9+AX9+BC9 -> 123 | BI9: =+D9+I9+N9+S9+W9+AA9+AF9+AK9+AP9+AU9+AY9+BD9 -> 165 | BJ9: =+E9+J9+O9+T9+X9+AB9+AG9+AL9+AQ9+AV9+AZ9+BE9 -> 42 | BK9: ELEC $60.00 Past due paid in Jan'26 SGN ($15.00) Short Pmt in Aug'26 STX ($3.64) Short Pmt in from Jan'26 to Aug'26
A10: =Rent!B19 -> B106 | B10: =Rent!A19 -> AT&T Mobility | C10: 7038.9703 | D10: 7206.85 | E10: =D10-C10 -> 167.87974 | F10: CAM $167.88 Over Pmt | H10: =VLOOKUP(B10,'Final Data'!A:C,3,0) -> 7038.9703 | I10: 6871.07 | J10: =I10-H10 -> -167.90026 | K10: CAM $167.88 01/26 past due paid | M10: =VLOOKUP(B10,'Final Data'!A:D,4,0) -> 7038.9703 | N10: 7038.96 | O10: =N10-M10 -> -0.010264859 | R10: =VLOOKUP(B10,'Final Data'!A:E,5,0) -> 7038.9703 | S10: 7038.96 | T10: =S10-R10 -> -0.010264859 | V10: =VLOOKUP(B10,'Final Data'!A:G,6,0) -> 7038.9703 | W10: 4880.81 | X10: =W10-V10 -> -2158.1603 | Y10: PYC credit applied to BAS ($613.64) & NNN ($1,491.88) STX ($52.64) Credit applied to current charges | Z10: =VLOOKUP(B10,'Final Data'!A:G,7,0) -> 7038.9703 | AA10: 7038.96 | AB10: =AA10-Z10 -> -0.010264859 | AE10: =VLOOKUP(B10,'Final Data'!A:H,8,0) -> 7038.9703 | AF10: 7038.96 | AG10: =AF10-AE10 -> -0.010264859 | AJ10: =VLOOKUP(B10,'Final Data'!A:I,9,0) -> 7038.9703 | AK10: 0 | AL10: =AK10-AJ10 -> -7038.9703 | AM10: BAS ($5,375.40) & NNN ($1,663.57) Budget vs Pmt | BH10: =+C10+H10+M10+R10+V10+Z10+AE10+AJ10+AO10+AT10+AX10+BC10 -> 56311.762 | BI10: =+D10+I10+N10+S10+W10+AA10+AF10+AK10+AP10+AU10+AY10+BD10 -> 47114.57 | BJ10: =+E10+J10+O10+T10+X10+AB10+AG10+AL10+AQ10+AV10+AZ10+BE10 -> -9197.1921 | BK10: PYC credit applied to BAS ($613.64) & NNN ($1,491.88) in May'26 STX ($52.64) Credit applied to current charges in May'26 BAS ($5,375.40) & NNN ($1,663.57) Budget vs Pmt in Aug'26
A11: =Rent!B20 -> B108 | B11: =Rent!A20 -> Discount Nutrition | C11: =VLOOKUP(B11,'Final Data'!A9:B33,2,0) -> 3381.2829 | D11: 3207.94 | E11: =D11-C11 -> -173.34295 | F11: CAM ($173.34) Short Pmt | H11: =VLOOKUP(B11,'Final Data'!A:C,3,0) -> 3381.2829 | I11: 3207.94 | J11: =I11-H11 -> -173.34295 | K11: CAM ($173.34) Short Pmt | M11: =VLOOKUP(B11,'Final Data'!A:D,4,0) -> 3381.2829 | N11: 3207.94 | O11: =N11-M11 -> -173.34295 | P11: CAM ($173.34) Short Pmt | R11: =VLOOKUP(B11,'Final Data'!A:E,5,0) -> 3431.2107 | S11: 3207.94 | T11: =S11-R11 -> -223.2707 | U11: BAS ($48.71) Short Pmt CAM ($173.34) Short Pmt STX ($1.21) Short Pmt | V11: =VLOOKUP(B11,'Final Data'!A:G,6,0) -> 3431.2107 | W11: 0 | X11: =W11-V11 -> -3431.2107 | Y11: BAS ($2,484.18) & NNN ($947.02) No Pmt | Z11: =VLOOKUP(B11,'Final Data'!A:G,7,0) -> 3431.2107 | AA11: 3207.94 | AB11: =AA11-Z11 -> -223.2707 | AC11: BAS ($48.71) & NNN ($174.55) Short Pmt | AE11: =VLOOKUP(B11,'Final Data'!A:H,8,0) -> 3431.2107 | AF11: 3207.94 | AG11: =AF11-AE11 -> -223.2707 | AH11: BAS ($48.71) & NNN ($174.55) Short Pmt | AJ11: =VLOOKUP(B11,'Final Data'!A:I,9,0) -> 3431.2107 | AK11: 8422.82 | AL11: =AK11-AJ11 -> 4991.6093 | AM11: BAS $2,630.31 & NNN $2,321.77 Past due paid LAT $39.54 received | BH11: =+C11+H11+M11+R11+V11+Z11+AE11+AJ11+AO11+AT11+AX11+BC11 -> 27299.902 | BI11: =+D11+I11+N11+S11+W11+AA11+AF11+AK11+AP11+AU11+AY11+BD11 -> 27670.46 | BJ11: =+E11+J11+O11+T11+X11+AB11+AG11+AL11+AQ11+AV11+AZ11+BE11 -> 370.55766 | BK11: NNN $331.00 Budget vs Pmt LAT $39.54 received in Aug'26
A12: =Rent!B21 -> B109 | B12: =Rent!A21 -> Adapt Chiropractic | C12: 4285.8182 | D12: 4711.62 | E12: =D12-C12 -> 425.80178 | F12: CAM $425.79 Over Pmt | H12: =VLOOKUP(B12,'Final Data'!A:C,3,0) -> 4285.8182 | I12: 3860.04 | J12: =I12-H12 -> -425.77822 | K12: CAM (425.78) Pror month credit applied this month. | M12: =VLOOKUP(B12,'Final Data'!A:D,4,0) -> 4285.8182 | N12: 4285.83 | O12: =N12-M12 -> 0.011776869 | R12: =VLOOKUP(B12,'Final Data'!A:E,5,0) -> 4285.8182 | S12: 4285.83 | T12: =S12-R12 -> 0.011776869 | V12: =VLOOKUP(B12,'Final Data'!A:G,6,0) -> 4285.8182 | W12: 173.99 | X12: =W12-V12 -> -4111.8282 | Y12: PYC credit applied to BAS ($3,699.2) & NNN ($312.35) STX ($100.29) credit applied to current charges | Z12: =VLOOKUP(B12,'Final Data'!A:G,7,0) -> 4285.8182 | AA12: 4285.83 | AB12: =AA12-Z12 -> 0.011776869 | AE12: =VLOOKUP(B12,'Final Data'!A:H,8,0) -> 4285.8182 | AF12: 4285.83 | AG12: =AF12-AE12 -> 0.011776869 | AJ12: =VLOOKUP(B12,'Final Data'!A:I,9,0) -> 4285.8182 | AK12: 4285.83 | AL12: =AK12-AJ12 -> 0.011776869 | BH12: =+C12+H12+M12+R12+V12+Z12+AE12+AJ12+AO12+AT12+AX12+BC12 -> 34286.546 | BI12: =+D12+I12+N12+S12+W12+AA12+AF12+AK12+AP12+AU12+AY12+BD12 -> 30174.8 | BJ12: =+E12+J12+O12+T12+X12+AB12+AG12+AL12+AQ12+AV12+AZ12+BE12 -> -4111.7458 | BK12: PYC credit applied to BAS ($3,699.20) & NNN ($312.35) in May'26 STX ($100.29) credit applied to current charges in May'26
A13: =Rent!B22 -> B111 | B13: =Rent!A22 -> Speakeasy Suites | C13: =VLOOKUP(B13,'Final Data'!A11:B35,2,0) -> 8299.7744 | D13: 8299.78 | E13: =D13-C13 -> 0.0056334591 | H13: =VLOOKUP(B13,'Final Data'!A:C,3,0) -> 8299.7744 | I13: 8299.78 | J13: =I13-H13 -> 0.0056334591 | M13: =VLOOKUP(B13,'Final Data'!A:D,4,0) -> 8299.7744 | N13: 8299.78 | O13: =N13-M13 -> 0.0056334591 | R13: =VLOOKUP(B13,'Final Data'!A:E,5,0) -> 8299.7744 | S13: 8299.78 | T13: =S13-R13 -> 0.0056334591 | V13: =VLOOKUP(B13,'Final Data'!A:G,6,0) -> 8299.7744 | W13: 8299.78 | X13: =W13-V13 -> 0.0056334591 | Z13: =VLOOKUP(B13,'Final Data'!A:G,7,0) -> 8299.7744 | AA13: 8299.78 | AB13: =AA13-Z13 -> 0.0056334591 | AE13: =VLOOKUP(B13,'Final Data'!A:H,8,0) -> 8299.7744 | AF13: 9868.42 | AG13: =AF13-AE13 -> 1568.6456 | AH13: PYC $1,530.38 & STX $38.26 received | AJ13: =VLOOKUP(B13,'Final Data'!A:I,9,0) -> 8299.7744 | AK13: 8299.78 | AL13: =AK13-AJ13 -> 0.0056334591 | BH13: =+C13+H13+M13+R13+V13+Z13+AE13+AJ13+AO13+AT13+AX13+BC13 -> 66398.195 | BI13: =+D13+I13+N13+S13+W13+AA13+AF13+AK13+AP13+AU13+AY13+BD13 -> 67966.88 | BJ13: =+E13+J13+O13+T13+X13+AB13+AG13+AL13+AQ13+AV13+AZ13+BE13 -> 1568.6851 | BK13: PYC $1,530.38 & STX $38.26 received in July'26
B14: Sportsman's Warehouse | C14: 1537.5 | D14: 1537.5 | E14: =D14-C14 -> 0 | H14: =VLOOKUP(B14,'Final Data'!A:C,3,0) -> 1537.5 | I14: 1537.5 | J14: =I14-H14 -> 0 | M14: =VLOOKUP(B14,'Final Data'!A:D,4,0) -> 1537.5 | N14: 1537.5 | O14: =N14-M14 -> 0 | R14: =VLOOKUP(B14,'Final Data'!A:E,5,0) -> 1537.5 | S14: 1537.5 | T14: =S14-R14 -> 0 | V14: =VLOOKUP(B14,'Final Data'!A:G,6,0) -> 1537.5 | W14: 1537.5 | X14: =W14-V14 -> 0 | Z14: =VLOOKUP(B14,'Final Data'!A:G,7,0) -> 1537.5 | AA14: 1537.5 | AB14: =AA14-Z14 -> 0 | AE14: =VLOOKUP(B14,'Final Data'!A:H,8,0) -> 1537.5 | AF14: 1537.5 | AG14: =AF14-AE14 -> 0 | AJ14: =VLOOKUP(B14,'Final Data'!A:I,9,0) -> 1537.5 | AK14: 1537.5 | AL14: =AK14-AJ14 -> 0 | BH14: =+C14+H14+M14+R14+V14+Z14+AE14+AJ14+AO14+AT14+AX14+BC14 -> 12300 | BI14: =+D14+I14+N14+S14+W14+AA14+AF14+AK14+AP14+AU14+AY14+BD14 -> 12300 | BJ14: =+E14+J14+O14+T14+X14+AB14+AG14+AL14+AQ14+AV14+AZ14+BE14 -> 0
A15: =Rent!B23 -> 101 | B15: =Rent!A23 -> Kachina Stained Glass | C15: =VLOOKUP(B15,'Final Data'!A12:B36,2,0) -> 3290.9586 | D15: 3290.87 | E15: =D15-C15 -> -0.088595125 | H15: =VLOOKUP(B15,'Final Data'!A:C,3,0) -> 3290.9586 | I15: 3290.87 | J15: =I15-H15 -> -0.088595125 | M15: =VLOOKUP(B15,'Final Data'!A:D,4,0) -> 3290.9586 | N15: 3290.87 | O15: =N15-M15 -> -0.088595125 | R15: =VLOOKUP(B15,'Final Data'!A:E,5,0) -> 3290.9586 | S15: 3290.87 | T15: =S15-R15 -> -0.088595125 | V15: =VLOOKUP(B15,'Final Data'!A:G,6,0) -> 3290.9586 | W15: 3421.98 | X15: =W15-V15 -> 131.0214 | Y15: PYC $127.91 received STX $3.20 received | Z15: =VLOOKUP(B15,'Final Data'!A:G,7,0) -> 3290.9586 | AA15: 3290.87 | AB15: =AA15-Z15 -> -0.088595125 | AE15: =VLOOKUP(B15,'Final Data'!A:H,8,0) -> 3340.5891 | AF15: 3340.5 | AG15: =AF15-AE15 -> -0.089095125 | AJ15: =VLOOKUP(B15,'Final Data'!A:I,9,0) -> 3340.5891 | AK15: 0 | AL15: =AK15-AJ15 -> -3340.5891 | AM15: BAS ($2,447.45) & NNN ($893.05) Short Pmt | BH15: =+C15+H15+M15+R15+V15+Z15+AE15+AJ15+AO15+AT15+AX15+BC15 -> 26426.93 | BI15: =+D15+I15+N15+S15+W15+AA15+AF15+AK15+AP15+AU15+AY15+BD15 -> 23216.83 | BJ15: =+E15+J15+O15+T15+X15+AB15+AG15+AL15+AQ15+AV15+AZ15+BE15 -> -3210.0998 | BK15: PYC $127.91 received in May'26 STX $3.20 received in May'26 BAS ($2,447.45) & NNN ($893.05) Short Pmt in Aug'26
A16: =Rent!B24 -> 102 | B16: =Rent!A24 -> Zanders Creations | C16: =VLOOKUP(B16,'Final Data'!A13:B37,2,0) -> 3803.2513 | D16: 3803.17 | E16: =D16-C16 -> -0.081276413 | H16: =VLOOKUP(B16,'Final Data'!A:C,3,0) -> 3803.2513 | I16: 3803.17 | J16: =I16-H16 -> -0.081276413 | M16: =VLOOKUP(B16,'Final Data'!A:D,4,0) -> 3803.2513 | N16: 3803.17 | O16: =N16-M16 -> -0.081276413 | R16: =VLOOKUP(B16,'Final Data'!A:E,5,0) -> 3886.2713 | S16: 3803.17 | T16: =S16-R16 -> -83.101276 | U16: BAS ($83.02) Short Pmt | V16: =VLOOKUP(B16,'Final Data'!A:G,6,0) -> 3886.2713 | W16: 4380.69 | X16: =W16-V16 -> 494.41872 | Y16: PYC $397.40 received BAS $83.02 04/26 past due paid STX $12.01 received | Z16: =VLOOKUP(B16,'Final Data'!A:G,7,0) -> 3886.2713 | AA16: 3888.26 | AB16: =AA16-Z16 -> 1.9887236 | AC16: STX $2.00 received | AE16: =VLOOKUP(B16,'Final Data'!A:H,8,0) -> 3886.2713 | AF16: 3888.26 | AG16: =AF16-AE16 -> 1.9887236 | AH16: STX $2.00 received | AJ16: =VLOOKUP(B16,'Final Data'!A:I,9,0) -> 3886.2713 | AK16: 3888.26 | AL16: =AK16-AJ16 -> 1.9887236 | AM16: STX $2.00 received | BH16: =+C16+H16+M16+R16+V16+Z16+AE16+AJ16+AO16+AT16+AX16+BC16 -> 30841.11 | BI16: =+D16+I16+N16+S16+W16+AA16+AF16+AK16+AP16+AU16+AY16+BD16 -> 31258.15 | BJ16: =+E16+J16+O16+T16+X16+AB16+AG16+AL16+AQ16+AV16+AZ16+BE16 -> 417.03979 | BK16: PYC $397.40 received in May'26 STX $18.01 received in May'26 to Aug'26
A17: =Rent!B25 -> 103 | B17: =Rent!A25 -> Brightnow Dental | C17: 9511.6006 | D17: 0 | E17: =D17-C17 -> -9511.6006 | F17: BAS ($7,200.00) & NNN ($2,079.61) No Pmt STX ($231.99) No Budgeted | H17: =VLOOKUP(B17,'Final Data'!A:C,3,0) -> 9511.6006 | I17: 0 | J17: =I17-H17 -> -9511.6006 | K17: BAS ($7,200.00) & NNN ($2311.60) No Pmt | M17: =VLOOKUP(B17,'Final Data'!A:D,4,0) -> 9511.6006 | N17: 0 | O17: =N17-M17 -> -9511.6006 | P17: BAS ($7,200.00) & NNN ($2311.60) No Pmt | R17: =VLOOKUP(B17,'Final Data'!A:E,5,0) -> 9511.6006 | S17: 93000 | T17: =S17-R17 -> 83488.399 | U17: STM $93,000.00 received and not Budgeted BAS ($7,200.00) 04/26 NC Adjustment NNN ($2,311.60) 04/26 NC Adjustment | V17: =VLOOKUP(B17,'Final Data'!A:G,6,0) -> 9511.6006 | W17: 0 | X17: =W17-V17 -> -9511.6006 | Y17: BAS ($7,200.00) & NNN ($2311.60) No Pmt | Z17: =VLOOKUP(B17,'Final Data'!A:G,7,0) -> 9511.6006 | AA17: 0 | AB17: =AA17-Z17 -> -9511.6006 | AC17: BAS ($7,200.00) & NNN ($2311.60) No Pmt | AE17: =VLOOKUP(B17,'Final Data'!A:H,8,0) -> 9511.6006 | AF17: 0 | AG17: =AF17-AE17 -> -9511.6006 | AH17: BAS ($7,200.00) & NNN ($2311.60) No Pmt | AJ17: =VLOOKUP(B17,'Final Data'!A:I,9,0) -> 9511.6006 | AK17: 0 | AL17: =AK17-AJ17 -> -9511.6006 | AM17: BAS ($7,200.00) & NNN ($2,311.60) No Pmt | BH17: =+C17+H17+M17+R17+V17+Z17+AE17+AJ17+AO17+AT17+AX17+BC17 -> 76092.805 | BI17: =+D17+I17+N17+S17+W17+AA17+AF17+AK17+AP17+AU17+AY17+BD17 -> 93000 | BJ17: =+E17+J17+O17+T17+X17+AB17+AG17+AL17+AQ17+AV17+AZ17+BE17 -> 16907.195 | BK17: BAS ($50,400.00) & NNN ($15,949.21) No Pmt in Jan'26 to Mar'26 & May'26 to Aug'26 STX ($231.99) No Budgeted in Jan'26 STM $93,000.00 received and not Budgeted in April'26 BAS ($7,200.00) & NNN ($2,311.60) 04/26 NC Adjustment in Apr'26
A18: =Rent!B26 -> 106 | B18: =Rent!A26 -> Carr Animal Care | C18: 3540.8255 | D18: 3540.83 | E18: =D18-C18 -> 0.0044610389 | H18: =VLOOKUP(B18,'Final Data'!A:C,3,0) -> 3540.8255 | I18: 3540.83 | J18: =I18-H18 -> 0.0044610389 | M18: =VLOOKUP(B18,'Final Data'!A:D,4,0) -> 3540.8255 | N18: 3540.83 | O18: =N18-M18 -> 0.0044610389 | R18: =VLOOKUP(B18,'Final Data'!A:E,5,0) -> 3540.8255 | S18: 3540.83 | T18: =S18-R18 -> 0.0044610389 | V18: =VLOOKUP(B18,'Final Data'!A:G,6,0) -> 3540.8255 | W18: 2457.85 | X18: =W18-V18 -> -1082.9755 | Y18: PYC credit applied to ($511.61) & NNN ($544.96) STX (26.47) credit applied to current charges | Z18: =VLOOKUP(B18,'Final Data'!A:G,7,0) -> 3540.8255 | AA18: 3540.83 | AB18: =AA18-Z18 -> 0.0044610389 | AE18: =VLOOKUP(B18,'Final Data'!A:H,8,0) -> 3540.8255 | AF18: 3540.83 | AG18: =AF18-AE18 -> 0.0044610389 | AJ18: =VLOOKUP(B18,'Final Data'!A:I,9,0) -> 3540.8255 | AK18: 3540.83 | AL18: =AK18-AJ18 -> 0.0044610389 | BH18: =+C18+H18+M18+R18+V18+Z18+AE18+AJ18+AO18+AT18+AX18+BC18 -> 28326.604 | BI18: =+D18+I18+N18+S18+W18+AA18+AF18+AK18+AP18+AU18+AY18+BD18 -> 27243.66 | BJ18: =+E18+J18+O18+T18+X18+AB18+AG18+AL18+AQ18+AV18+AZ18+BE18 -> -1082.9443 | BK18: PYC credit applied to ($511.61) & NNN ($544.96) in May'26 STX (26.47) credit applied to current charges in May'26
A19: =Rent!B27 -> 107 | B19: =Rent!A27 -> Razors Barber Shop | C19: 2723.6704 | D19: 2629.68 | E19: =D19-C19 -> -93.990438 | F19: CAM ($94.00) Short Pmt | H19: =VLOOKUP(B19,'Final Data'!A:C,3,0) -> 2723.6704 | I19: 2629.78 | J19: =I19-H19 -> -93.890438 | K19: CAM ($94.00) Short Pmt | M19: =VLOOKUP(B19,'Final Data'!A:D,4,0) -> 2723.6704 | N19: 2629.78 | O19: =N19-M19 -> -93.890438 | P19: CAM ($94.00) Short Pmt | R19: =VLOOKUP(B19,'Final Data'!A:E,5,0) -> 2783.6637 | S19: 2629.78 | T19: =S19-R19 -> -153.88369 | U19: BAS ($58.53) & STX ($1.47) Short Pmt CAM ($93.90) Short Pmt | V19: =VLOOKUP(B19,'Final Data'!A:G,6,0) -> 2783.6637 | W19: 2629.78 | X19: =W19-V19 -> -153.88369 | Y19: BAS ($58.53) & NNN ($95.37) Short Pmt | Z19: =VLOOKUP(B19,'Final Data'!A:G,7,0) -> 2783.6637 | AA19: 2629.78 | AB19: =AA19-Z19 -> -153.88369 | AC19: BAS ($58.53) & NNN ($95.37) Short Pmt | AE19: =VLOOKUP(B19,'Final Data'!A:H,8,0) -> 2783.6637 | AF19: 3000.29 | AG19: =AF19-AE19 -> 216.62631 | AH19: BAS $216.63 Over Pmt | AJ19: =VLOOKUP(B19,'Final Data'!A:I,9,0) -> 2783.6637 | AK19: 2883.68 | AL19: =AK19-AJ19 -> 100.01631 | AM19: BAS $100.00 Over Pmt | BH19: =+C19+H19+M19+R19+V19+Z19+AE19+AJ19+AO19+AT19+AX19+BC19 -> 22089.33 | BI19: =+D19+I19+N19+S19+W19+AA19+AF19+AK19+AP19+AU19+AY19+BD19 -> 21662.55 | BJ19: =+E19+J19+O19+T19+X19+AB19+AG19+AL19+AQ19+AV19+AZ19+BE19 -> -426.77975 | BK19: BAS ($175.59) Short Pmt in Apr'26 to June'26 NNN ($568.11) Short Pmt from Jan'26 to Apr'26 & June'26 BAS $316.63 Over Pmt in July'26 & Aug'26
A20: =Rent!B28 -> 108 | B20: =Rent!A28 -> CrossFit New Strength | C20: 6899.642 | D20: 6499.12 | E20: =D20-C20 -> -400.52201 | F20: NCA ($400.54) Short Pmt | H20: =VLOOKUP(B20,'Final Data'!A:C,3,0) -> 6899.642 | I20: 6499.12 | J20: =I20-H20 -> -400.52201 | K20: NCA ($400.54) Short Pmt | M20: =VLOOKUP(B20,'Final Data'!A:D,4,0) -> 6899.642 | N20: 6499.12 | O20: =N20-M20 -> -400.52201 | P20: NCA ($400.54) Short Pmt | R20: =VLOOKUP(B20,'Final Data'!A:E,5,0) -> 6899.642 | S20: 12998.24 | T20: =S20-R20 -> 6098.598 | U20: NCA ($400.54) Short Pmt BAS $6,499.12 Over Pmt | V20: =VLOOKUP(B20,'Final Data'!A:G,6,0) -> 6899.642 | W20: 0 | X20: =W20-V20 -> -6899.642 | Y20: BAS ($4,639.93) & NNN ($2,259.73) No Pmt | Z20: =VLOOKUP(B20,'Final Data'!A:G,7,0) -> 6899.642 | AA20: 6499.12 | AB20: =AA20-Z20 -> -400.52201 | AC20: NCA ($400.54) Short Pmt | AE20: =VLOOKUP(B20,'Final Data'!A:H,8,0) -> 6899.642 | AF20: 6499.12 | AG20: =AF20-AE20 -> -400.52201 | AH20: NCA ($400.54) Short Pmt | AJ20: =VLOOKUP(B20,'Final Data'!A:I,9,0) -> 6899.642 | AK20: 0 | AL20: =AK20-AJ20 -> -6899.642 | AM20: BAS ($4,639.93) & NNN ($2,259.73) No Pmt | BH20: =+C20+H20+M20+R20+V20+Z20+AE20+AJ20+AO20+AT20+AX20+BC20 -> 55197.136 | BI20: =+D20+I20+N20+S20+W20+AA20+AF20+AK20+AP20+AU20+AY20+BD20 -> 45493.84 | BJ20: =+E20+J20+O20+T20+X20+AB20+AG20+AL20+AQ20+AV20+AZ20+BE20 -> -9703.2961 | BK20: BAS $6,499.12 Over Pmt in Apr'26 BAS ($9,279.86) No Pmt in May'26 & Aug'26 NNN ($6,922.70) Short Pmt from Jan'26 to Apr'26 & June'26 to Aug'26
A21: =Rent!B29 -> 111 | B21: =Rent!A29 -> Vacant (Time Out Bar) | C21: =VLOOKUP(B21,'Final Data'!A18:B42,2,0) -> 0 | D21: 0 | E21: =D21-C21 -> 0 | H21: =VLOOKUP(B21,'Final Data'!A:C,3,0) -> 0 | I21: 0 | J21: =I21-H21 -> 0 | M21: =VLOOKUP(B21,'Final Data'!A:D,4,0) -> 0 | N21: 0 | O21: =N21-M21 -> 0 | R21: =VLOOKUP(B21,'Final Data'!A:E,5,0) -> 0 | S21: 0 | T21: =S21-R21 -> 0 | V21: =VLOOKUP(B21,'Final Data'!A:G,6,0) -> 0 | W21: 0 | X21: =W21-V21 -> 0 | Z21: =VLOOKUP(B21,'Final Data'!A:G,7,0) -> 0 | AA21: 0 | AB21: =AA21-Z21 -> 0 | AE21: =VLOOKUP(B21,'Final Data'!A:H,8,0) -> 7969.7037 | AF21: 0 | AG21: =AF21-AE21 -> -7969.7037 | AH21: BAS ($6,190.30) & NNN ($1,779.00) No Pmt | AJ21: =VLOOKUP(B21,'Final Data'!A:I,9,0) -> 7969.7037 | AK21: 0 | AL21: =AK21-AJ21 -> -7969.7037 | AM21: BAS ($6,190.30) & NNN ($1,779.00) No Pmt | BH21: =+C21+H21+M21+R21+V21+Z21+AE21+AJ21+AO21+AT21+AX21+BC21 -> 15939.407 | BI21: =+D21+I21+N21+S21+W21+AA21+AF21+AK21+AP21+AU21+AY21+BD21 -> 0 | BJ21: =+E21+J21+O21+T21+X21+AB21+AG21+AL21+AQ21+AV21+AZ21+BE21 -> -15939.407 | BK21: BAS ($12,380.60) & NNN ($3,558.00) No Pmt in July'26 & Aug'26
B22: Walmart | C22: 2050 | D22: 2050 | E22: =D22-C22 -> 0 | H22: =VLOOKUP(B22,'Final Data'!A:C,3,0) -> 2050 | I22: 2050 | J22: =I22-H22 -> 0 | M22: =VLOOKUP(B22,'Final Data'!A:D,4,0) -> 2050 | N22: 2012.5 | O22: =N22-M22 -> -37.5 | P22: SGN ($37.50) Short Pmt | R22: =VLOOKUP(B22,'Final Data'!A:E,5,0) -> 2050 | S22: 2037.5 | T22: =S22-R22 -> -12.5 | U22: STX ($12.50) Short Pmt | V22: =VLOOKUP(B22,'Final Data'!A:G,6,0) -> 2050 | W22: 2037.5 | X22: =W22-V22 -> -12.5 | Y22: STX ($12.50) Short Pmt | Z22: =VLOOKUP(B22,'Final Data'!A:G,7,0) -> 2050 | AA22: 2037.5 | AB22: =AA22-Z22 -> -12.5 | AC22: STX ($12.50) Short Pmt | AE22: =VLOOKUP(B22,'Final Data'!A:H,8,0) -> 2050 | AF22: 2037.5 | AG22: =AF22-AE22 -> -12.5 | AH22: STX ($12.50) Short Pmt | AJ22: =VLOOKUP(B22,'Final Data'!A:I,9,0) -> 2050 | AK22: 2037.5 | AL22: =AK22-AJ22 -> -12.5 | AM22: STX ($12.50) Short Pmt | BH22: =+C22+H22+M22+R22+V22+Z22+AE22+AJ22+AO22+AT22+AX22+BC22 -> 16400 | BI22: =+D22+I22+N22+S22+W22+AA22+AF22+AK22+AP22+AU22+AY22+BD22 -> 16300 | BJ22: =+E22+J22+O22+T22+X22+AB22+AG22+AL22+AQ22+AV22+AZ22+BE22 -> -100 | BK22: SGN ($37.50) Short Pmt in Mar'26 STX ($62.50) Short Pmt in Apr'26 to Aug'26
B23: Tailgate Bar and Grill LLC | J23: =I23-H23 -> 0 | AJ23: 0 | AK23: 15383.27 | AL23: =AK23-AJ23 -> 15383.27 | AM23: BAS $15,516.12 & NNN $3,618.45 Not Budgeted MISC credit ($2,500.00) applied to BAS & NNN ABA ($1,251.30) | BH23: =+C23+H23+M23+R23+V23+Z23+AE23+AJ23+AO23+AT23+AX23+BC23 -> 0 | BI23: =+D23+I23+N23+S23+W23+AA23+AF23+AK23+AP23+AU23+AY23+BD23 -> 15383.27 | BJ23: =+E23+J23+O23+T23+X23+AB23+AG23+AL23+AQ23+AV23+AZ23+BE23 -> 15383.27 | BK23: BAS $15,516.12 & NNN $3,618.45 Not Budgeted in Aug'26 MISC credit ($2,500.00) applied to BAS & NNN in Aug'26 ABA ($1,251.30) in Aug'26
E24: =D24-C24 -> 0
E25: =D25-C25 -> 0
C26: =SUM(C4:C23) -> 140268.53 | D26: =SUM(D4:D23) -> 130948.6 | E26: =SUM(E4:E23) -> -9319.9253 | H26: =SUM(H4:H23) -> 140268.53 | I26: =SUM(I4:I23) -> 130211.53 | J26: =SUM(J4:J23) -> -10056.995 | M26: =SUM(M4:M25) -> 140268.53 | N26: =SUM(N4:N25) -> 145434.29 | O26: =SUM(O4:O25) -> 5165.7647 | R26: =SUM(R4:R25) -> 140504.65 | S26: =SUM(S4:S25) -> 229679.72 | T26: =SUM(T4:T25) -> 89175.07 | V26: =SUM(V4:V25) -> 140580.77 | W26: =SUM(W4:W25) -> 121814.94 | X26: =SUM(X4:X25) -> -18765.826 | Z26: =SUM(Z4:Z23) -> 140580.77 | AA26: =SUM(AA4:AA23) -> 130248.18 | AB26: =SUM(AB4:AB23) -> -10332.586 | AE26: =SUM(AE4:AE23) -> 148600.1 | AF26: =SUM(AF4:AF23) -> 132194.48 | AG26: =SUM(AG4:AG23) -> -16405.62 | AJ26: =SUM(AJ4:AJ23) -> 148600.1 | AK26: =SUM(AK4:AK23) -> 133798.36 | AL26: =SUM(AL4:AL23) -> -14801.74 | BH26: =SUM(BH4:BH23) -> 1139672 | BI26: =SUM(BI4:BI23) -> 1154330.1 | BJ26: =SUM(BJ4:BJ23) -> 14658.142
C27: 140268 | D27: 130948.6 | E27: -9319.4 | H27: 140268 | I27: 130211.53 | J27: -10056.47 | Z27: 140581 | AA27: 130248.18 | AB27: -10332.82 | AE27: 148599 | AF27: 132194.48 | AG27: -16404.52 | AJ27: 148599 | AK27: 133798.36 | AL27: -14800.64 | BH27: 1139669 | BI27: 1154330.1 | BJ27: 14661.1
C28: =C26-C27 -> 0.52527272 | D28: =D26-D27 -> 0 | E28: =E26-E27 -> -0.52527272 | H28: =H26-H27 -> 0.52527272 | I28: =I26-I27 -> 0 | J28: =J26-J27 -> -0.52527272 | M28: 140268 | N28: 145434.29 | O28: 5166.29 | R28: 140505 | S28: 229679.72 | T28: 89174.72 | V28: 140581 | W28: 121814.94 | X28: -18766.06 | Z28: =Z27-Z26 -> 0.23397728 | AA28: =AA27-AA26 -> 0 | AB28: =AB27-AB26 -> -0.23397728 | AE28: =AE27-AE26 -> -1.1002437 | AF28: =AF27-AF26 -> 0 | AG28: =AG27-AG26 -> 1.1002437 | AJ28: =AJ27-AJ26 -> -1.1002437 | AK28: =AK27-AK26 -> 0 | AL28: =AL27-AL26 -> 1.1002437 | BH28: =BH26-BH27 -> 2.9578736 | BI28: =BI26-BI27 -> 0 | BJ28: =BJ26-BJ27 -> -2.9578736
M29: =M28-M26 -> -0.52527272 | N29: =N28-N26 -> 0 | O29: =O28-O26 -> 0.52527272 | R29: =R26-R28 -> -0.35047728 | S29: =S26-S28 -> 0 | T29: =T26-T28 -> 0.35047728 | V29: =V26-V28 -> -0.23397728 | W29: =W26-W28 -> 0 | X29: =X26-X28 -> 0.23397728

Sheet Final Data
A3: Row Labels | B3: Sum of JAN | C3: Sum of FEB | D3: Sum of MARCH | E3: Sum of APRIL | F3: Sum of MAY | G3: Sum of JUNE | H3: Sum of JULY | I3: Sum of AUGUST | J3: Sum of SEPT | K3: Sum of OCT | L3: Sum of NOV | M3: Sum of DEC
A4: Adapt Chiropractic | B4: 4285.8182 | C4: 4285.8182 | D4: 4285.8182 | E4: 4285.8182 | F4: 4285.8182 | G4: 4285.8182 | H4: 4285.8182 | I4: 4285.8182 | J4: 4285.8182 | K4: 4285.8182 | L4: 4285.8182 | M4: 4285.8182
A5: AT&T Mobility | B5: 7038.9703 | C5: 7038.9703 | D5: 7038.9703 | E5: 7038.9703 | F5: 7038.9703 | G5: 7038.9703 | H5: 7038.9703 | I5: 7038.9703 | J5: 7038.9703 | K5: 7038.9703 | L5: 7038.9703 | M5: 7038.9703
A6: Brightnow Dental | B6: 9511.6006 | C6: 9511.6006 | D6: 9511.6006 | E6: 9511.6006 | F6: 9511.6006 | G6: 9511.6006 | H6: 9511.6006 | I6: 9511.6006 | J6: 9511.6006 | K6: 9511.6006 | L6: 9511.6006 | M6: 9511.6006
A7: Carr Animal Care | B7: 3540.8255 | C7: 3540.8255 | D7: 3540.8255 | E7: 3540.8255 | F7: 3540.8255 | G7: 3540.8255 | H7: 3540.8255 | I7: 3540.8255 | J7: 3540.8255 | K7: 3839.0493 | L7: 3839.0493 | M7: 3839.0493
A8: CrossFit New Strength | B8: 6899.642 | C8: 6899.642 | D8: 6899.642 | E8: 6899.642 | F8: 6899.642 | G8: 6899.642 | H8: 6899.642 | I8: 6899.642 | J8: 6899.642 | K8: 6899.642 | L8: 6899.642 | M8: 6899.642
A9: Discount Nutrition | B9: 3381.2829 | C9: 3381.2829 | D9: 3381.2829 | E9: 3431.2107 | F9: 3431.2107 | G9: 3431.2107 | H9: 3431.2107 | I9: 3431.2107 | J9: 3431.2107 | K9: 3431.2107 | L9: 3431.2107 | M9: 3431.2107
A10: EOS Fitness | B10: 66174.826 | C10: 66174.826 | D10: 66174.826 | E10: 66174.826 | F10: 66174.826 | G10: 66174.826 | H10: 66174.826 | I10: 66174.826 | J10: 66174.826 | K10: 66174.826 | L10: 66174.826 | M10: 66174.826
A11: Green Spa, LLC | B11: 2815.0955 | C11: 2815.0955 | D11: 2815.0955 | E11: 2858.2788 | F11: 2858.2788 | G11: 2858.2788 | H11: 2858.2788 | I11: 2858.2788 | J11: 2858.2788 | K11: 2858.2788 | L11: 2858.2788 | M11: 2858.2788
A12: John F. Long Foundation | B12: 15.375 | C12: 15.375 | D12: 15.375 | E12: 15.375 | F12: 15.375 | G12: 15.375 | H12: 15.375 | I12: 15.375 | J12: 15.375 | K12: 15.375 | L12: 15.375 | M12: 129.64575
A13: Kachina Stained Glass | B13: 3290.9586 | C13: 3290.9586 | D13: 3290.9586 | E13: 3290.9586 | F13: 3290.9586 | G13: 3290.9586 | H13: 3340.5891 | I13: 3340.5891 | J13: 3340.5891 | K13: 3340.5891 | L13: 3340.5891 | M13: 3340.5891
A14: Razors Barber Shop | B14: 2723.6704 | C14: 2723.6704 | D14: 2723.6704 | E14: 2783.6637 | F14: 2783.6637 | G14: 2783.6637 | H14: 2783.6637 | I14: 2783.6637 | J14: 2783.6637 | K14: 2783.6637 | L14: 2783.6637 | M14: 2783.6637
A15: Sally Beauty Supply | B15: 3311.5729 | C15: 3311.5729 | D15: 3311.5729 | E15: 3311.5729 | F15: 3311.5729 | G15: 3311.5729 | H15: 3311.5729 | I15: 3311.5729 | J15: 3311.5729 | K15: 3311.5729 | L15: 3311.5729 | M15: 3311.5729
... A29: Difference | B29: 0 | C29: 0 | D29: 0 | E29: 0 | F29: 0 | G29: 0 | H29: 0 | I29: 0 | J29: 0 | K29: 0 | L29: 0 | M29: 0

Sheet Pivot
A3: Row Labels | B3: Sum of JAN | C3: Sum of FEB | D3: Sum of MARCH | E3: Sum of APRIL | F3: Sum of MAY | G3: Sum of JUNE | H3: Sum of JULY | I3: Sum of AUGUST | J3: Sum of SEPT | K3: Sum of OCT | L3: Sum of NOV | M3: Sum of DEC
A4: Adapt Chiropractic | B4: 4285.8182 | C4: 4285.8182 | D4: 4285.8182 | E4: 4285.8182 | F4: 4285.8182 | G4: 4285.8182 | H4: 4285.8182 | I4: 4285.8182 | J4: 4285.8182 | K4: 4285.8182 | L4: 4285.8182 | M4: 4285.8182
A5: AT&T Mobility | B5: 7038.9703 | C5: 7038.9703 | D5: 7038.9703 | E5: 7038.9703 | F5: 7038.9703 | G5: 7038.9703 | H5: 7038.9703 | I5: 7038.9703 | J5: 7038.9703 | K5: 7038.9703 | L5: 7038.9703 | M5: 7038.9703
A6: Brightnow Dental | B6: 9511.6006 | C6: 9511.6006 | D6: 9511.6006 | E6: 9511.6006 | F6: 9511.6006 | G6: 9511.6006 | H6: 9511.6006 | I6: 9511.6006 | J6: 9511.6006 | K6: 9511.6006 | L6: 9511.6006 | M6: 9511.6006
A7: Carr Animal Care | B7: 3540.8255 | C7: 3540.8255 | D7: 3540.8255 | E7: 3540.8255 | F7: 3540.8255 | G7: 3540.8255 | H7: 3540.8255 | I7: 3540.8255 | J7: 3540.8255 | K7: 3839.0493 | L7: 3839.0493 | M7: 3839.0493
A8: CrossFit New Strength | B8: 6899.642 | C8: 6899.642 | D8: 6899.642 | E8: 6899.642 | F8: 6899.642 | G8: 6899.642 | H8: 6899.642 | I8: 6899.642 | J8: 6899.642 | K8: 6899.642 | L8: 6899.642 | M8: 6899.642
A9: Discount Nutrition | B9: 3381.2829 | C9: 3381.2829 | D9: 3381.2829 | E9: 3431.2107 | F9: 3431.2107 | G9: 3431.2107 | H9: 3431.2107 | I9: 3431.2107 | J9: 3431.2107 | K9: 3431.2107 | L9: 3431.2107 | M9: 3431.2107
A10: EOS Fitness | B10: 66174.826 | C10: 66174.826 | D10: 66174.826 | E10: 66174.826 | F10: 66174.826 | G10: 66174.826 | H10: 66174.826 | I10: 66174.826 | J10: 66174.826 | K10: 66174.826 | L10: 66174.826 | M10: 66174.826
A11: Green Spa, LLC | B11: 2815.0955 | C11: 2815.0955 | D11: 2815.0955 | E11: 2858.2788 | F11: 2858.2788 | G11: 2858.2788 | H11: 2858.2788 | I11: 2858.2788 | J11: 2858.2788 | K11: 2858.2788 | L11: 2858.2788 | M11: 2858.2788
A12: John F. Long Foundation | B12: 15.375 | C12: 15.375 | D12: 15.375 | E12: 15.375 | F12: 15.375 | G12: 15.375 | H12: 15.375 | I12: 15.375 | J12: 15.375 | K12: 15.375 | L12: 15.375 | M12: 129.64575
A13: Kachina Stained Glass | B13: 3290.9586 | C13: 3290.9586 | D13: 3290.9586 | E13: 3290.9586 | F13: 3290.9586 | G13: 3290.9586 | H13: 3340.5891 | I13: 3340.5891 | J13: 3340.5891 | K13: 3340.5891 | L13: 3340.5891 | M13: 3340.5891
A14: Razors Barber Shop | B14: 2723.6704 | C14: 2723.6704 | D14: 2723.6704 | E14: 2783.6637 | F14: 2783.6637 | G14: 2783.6637 | H14: 2783.6637 | I14: 2783.6637 | J14: 2783.6637 | K14: 2783.6637 | L14: 2783.6637 | M14: 2783.6637
A15: Sally Beauty Supply | B15: 3311.5729 | C15: 3311.5729 | D15: 3311.5729 | E15: 3311.5729 | F15: 3311.5729 | G15: 3311.5729 | H15: 3311.5729 | I15: 3311.5729 | J15: 3311.5729 | K15: 3311.5729 | L15: 3311.5729 | M15: 3311.5729
... A23: Grand Total | B23: 140268.53 | C23: 140268.53 | D23: 140268.53 | E23: 140504.65 | F23: 140580.77 | G23: 140580.77 | H23: 148600.1 | I23: 148600.1 | J23: 148600.1 | K23: 149088.68 | L23: 149268.65 | M23: 149382.92

Sheet Data
A1: Tenant Name | B1: Particulars | C1: JAN | D1: FEB | E1: MARCH | F1: APRIL | G1: MAY | H1: JUNE | I1: JULY | J1: AUGUST | K1: SEPT | L1: OCT | M1: NOV | N1: DEC
A2: EOS Fitness | B2: Rent | C2: 52938 | D2: 52938 | E2: 52938 | F2: 52938 | G2: 52938 | H2: 52938 | I2: 52938 | J2: 52938 | K2: 52938 | L2: 52938 | M2: 52938 | N2: 52938
A3: Third Pasrty MVS | B3: Rent | C3: 6190.3 | D3: 6190.3 | E3: 6190.3 | F3: 6190.3 | G3: 6190.3 | H3: 6190.3 | I3: 6190.3 | J3: 6190.3 | K3: 6190.3 | L3: 6376.01 | M3: 6376.01 | N3: 6376.01
A4: Sally Beauty Supply | B4: Rent | C4: 2539.06 | D4: 2539.06 | E4: 2539.06 | F4: 2539.06 | G4: 2539.06 | H4: 2539.06 | I4: 2539.06 | J4: 2539.06 | K4: 2539.06 | L4: 2539.06 | M4: 2539.06 | N4: 2539.06
A5: Wild Side Smoke Shop | B5: Rent | C5: 2475.43 | D5: 2475.43 | E5: 2475.43 | F5: 2475.43 | G5: 2549.69 | H5: 2549.69 | I5: 2549.69 | J5: 2549.69 | K5: 2549.69 | L5: 2549.69 | M5: 2549.69 | N5: 2549.69
A6: Green Spa, LLC | B6: Rent | C6: 2106.41 | D6: 2106.41 | E6: 2106.41 | F6: 2148.54 | G6: 2148.54 | H6: 2148.54 | I6: 2148.54 | J6: 2148.54 | K6: 2148.54 | L6: 2148.54 | M6: 2148.54 | N6: 2148.54
A7: AT&T Mobility | B7: Rent | C7: 5375.4 | D7: 5375.4 | E7: 5375.4 | F7: 5375.4 | G7: 5375.4 | H7: 5375.4 | I7: 5375.4 | J7: 5375.4 | K7: 5375.4 | L7: 5375.4 | M7: 5375.4 | N7: 5375.4
A8: Discount Nutrition | B8: Rent | C8: 2435.47 | D8: 2435.47 | E8: 2435.47 | F8: 2484.18 | G8: 2484.18 | H8: 2484.18 | I8: 2484.18 | J8: 2484.18 | K8: 2484.18 | L8: 2484.18 | M8: 2484.18 | N8: 2484.18
A9: Adapt Chiropractic | B9: Rent | C9: 3699.2 | D9: 3699.2 | E9: 3699.2 | F9: 3699.2 | G9: 3699.2 | H9: 3699.2 | I9: 3699.2 | J9: 3699.2 | K9: 3699.2 | L9: 3699.2 | M9: 3699.2 | N9: 3699.2
A10: Speakeasy Suites | B10: Rent | C10: 5852.65 | D10: 5852.65 | E10: 5852.65 | F10: 5852.65 | G10: 5852.65 | H10: 5852.65 | I10: 5852.65 | J10: 5852.65 | K10: 5852.65 | L10: 5852.65 | M10: 6028.23 | N10: 6028.23
A11: Kachina Stained Glass | B11: Rent | C11: 2399.03 | D11: 2399.03 | E11: 2399.03 | F11: 2399.03 | G11: 2399.03 | H11: 2399.03 | I11: 2447.45 | J11: 2447.45 | K11: 2447.45 | L11: 2447.45 | M11: 2447.45 | N11: 2447.45
A12: Zanders Creations | B12: Rent | C12: 2767.06 | D12: 2767.06 | E12: 2767.06 | F12: 2850.08 | G12: 2850.08 | H12: 2850.08 | I12: 2850.08 | J12: 2850.08 | K12: 2850.08 | L12: 2850.08 | M12: 2850.08 | N12: 2850.08
A13: Brightnow Dental | B13: Rent | C13: 7200 | D13: 7200 | E13: 7200 | F13: 7200 | G13: 7200 | H13: 7200 | I13: 7200 | J13: 7200 | K13: 7200 | L13: 7200 | M13: 7200 | N13: 7200
... A16: CrossFit New Strength | B16: Rent | C16: 4639.93 | D16: 4639.93 | E16: 4639.93 | F16: 4639.93 | G16: 4639.93 | H16: 4639.93 | I16: 4639.93 | J16: 4639.93 | K16: 4639.93 | L16: 4639.93 | M16: 4639.93 | N16: 4639.93
A17: Vacant (Time Out Bar) | B17: Rent | I17: 6190.3 | J17: 6190.3 | K17: 6190.3 | L17: 6190.3 | M17: 6190.3 | N17: 6190.3
A18: EOS Fitness | B18: CAM | C18: 4021.8169 | D18: 4021.8169 | E18: 4021.8169 | F18: 4021.8169 | G18: 4021.8169 | H18: 4021.8169 | I18: 4021.8169 | J18: 4021.8169 | K18: 4021.8169 | L18: 4021.8169 | M18: 4021.8169 | N18: 4021.8169
A19: Third Pasrty MVS | B19: CAM | C19: 583.52592 | D19: 583.52592 | E19: 583.52592 | F19: 583.52592 | G19: 583.52592 | H19: 583.52592 | I19: 583.52592 | J19: 583.52592 | K19: 583.52592 | L19: 583.52592 | M19: 583.52592 | N19: 583.52592
A20: Sally Beauty Supply | B20: CAM | C20: 338.83978 | D20: 338.83978 | E20: 338.83978 | F20: 338.83978 | G20: 338.83978 | H20: 338.83978 | I20: 338.83978 | J20: 338.83978 | K20: 338.83978 | L20: 338.83978 | M20: 338.83978 | N20: 338.83978
A21: Wild Side Smoke Shop | B21: CAM | C21: 272.31209 | D21: 272.31209 | E21: 272.31209 | F21: 272.31209 | G21: 272.31209 | H21: 272.31209 | I21: 272.31209 | J21: 272.31209 | K21: 272.31209 | L21: 272.31209 | M21: 272.31209 | N21: 272.31209
A22: Green Spa, LLC | B22: CAM | C22: 216.29361 | D22: 216.29361 | E22: 216.29361 | F22: 216.29361 | G22: 216.29361 | H22: 216.29361 | I22: 216.29361 | J22: 216.29361 | K22: 216.29361 | L22: 216.29361 | M22: 216.29361 | N22: 216.29361
A23: AT&T Mobility | B23: CAM | C23: 450.26332 | D23: 450.26332 | E23: 450.26332 | F23: 450.26332 | G23: 450.26332 | H23: 450.26332 | I23: 450.26332 | J23: 450.26332 | K23: 450.26332 | L23: 450.26332 | M23: 450.26332 | N23: 450.26332
A24: Discount Nutrition | B24: CAM | C24: 291.76296 | D24: 291.76296 | E24: 291.76296 | F24: 291.76296 | G24: 291.76296 | H24: 291.76296 | I24: 291.76296 | J24: 291.76296 | K24: 291.76296 | L24: 291.76296 | M24: 291.76296 | N24: 291.76296
A25: Adapt Chiropractic | B25: CAM | C25: 105.51137 | D25: 105.51137 | E25: 105.51137 | F25: 105.51137 | G25: 105.51137 | H25: 105.51137 | I25: 105.51137 | J25: 105.51137 | K25: 105.51137 | L25: 105.51137 | M25: 105.51137 | N25: 105.51137
A26: Speakeasy Suites | B26: CAM | C26: 758.58369 | D26: 758.58369 | E26: 758.58369 | F26: 758.58369 | G26: 758.58369 | H26: 758.58369 | I26: 758.58369 | J26: 758.58369 | K26: 758.58369 | L26: 758.58369 | M26: 758.58369 | N26: 758.58369
A27: Kachina Stained Glass | B27: CAM | C27: 250.33262 | D27: 250.33262 | E27: 250.33262 | F27: 250.33262 | G27: 250.33262 | H27: 250.33262 | I27: 250.33262 | J27: 250.33262 | K27: 250.33262 | L27: 250.33262 | M27: 250.33262 | N27: 250.33262
A28: Zanders Creations | B28: CAM | C28: 318.79966 | D28: 318.79966 | E28: 318.79966 | F28: 318.79966 | G28: 318.79966 | H28: 318.79966 | I28: 318.79966 | J28: 318.79966 | K28: 318.79966 | L28: 318.79966 | M28: 318.79966 | N28: 318.79966
A29: Brightnow Dental | B29: CAM | C29: 797.7944 | D29: 797.7944 | E29: 797.7944 | F29: 797.7944 | G29: 797.7944 | H29: 797.7944 | I29: 797.7944 | J29: 797.7944 | K29: 797.7944 | L29: 797.7944 | M29: 797.7944 | N29: 797.7944
... A98: EOS Fitness | B98: Signage | C98: 0 | D98: 0 | E98: 0 | F98: 0 | G98: 0 | H98: 0 | I98: 0 | J98: 0 | K98: 0 | L98: 0 | M98: 0 | N98: 0
A99: Third Pasrty MVS | B99: Signage
A100: Sally Beauty Supply | B100: Signage
A101: Wild Side Smoke Shop | B101: Signage
A102: Green Spa, LLC | B102: Signage
A103: AT&T Mobility | B103: Signage | C103: 500 | D103: 500 | E103: 500 | F103: 500 | G103: 500 | H103: 500 | I103: 500 | J103: 500 | K103: 500 | L103: 500 | M103: 500 | N103: 500
A104: Discount Nutrition | B104: Signage
A105: Adapt Chiropractic | B105: Signage
A106: Speakeasy Suites | B106: Signage
A107: Kachina Stained Glass | B107: Signage | C107: 70.83 | D107: 70.83 | E107: 70.83 | F107: 70.83 | G107: 70.83 | H107: 70.83 | I107: 70.83 | J107: 70.83 | K107: 70.83 | L107: 70.83 | M107: 70.83 | N107: 70.83
A108: Zanders Creations | B108: Signage
A109: Brightnow Dental | B109: Signage | C109: 500 | D109: 500 | E109: 500 | F109: 500 | G109: 500 | H109: 500 | I109: 500 | J109: 500 | K109: 500 | L109: 500 | M109: 500 | N109: 500
A110: Carr Animal Care | B110: Signage
...

Sheet Summary
A2: ATHENA PROPERTY MANAGEMENT
A3: GREENFIELD GATEWAY MESA, ARIZONA
A4: PROJECT NO. 801 | T4: Date Revised: | U4: =TODAY() -> 46269
A5: 01/01/26-12/31/26
A6: 2026 OPERATING BUDGET
A8: GENERAL | O8: 2026 | P8: 2025 | Q8: 2025 | R8: BUDGET | S8: VARIANCE | T8: DENOM. | U8: COST
A9: LEDGER | B9: DESCRIPTION | C9: JAN | D9: FEB | E9: MARCH | F9: APRIL | G9: MAY | H9: JUNE | I9: JULY | J9: AUGUST | K9: SEPT | L9: OCT | M9: NOV | N9: DEC | O9: BUDGET | P9: FORECAST | Q9: BUDGET | R9: $ PSF | S9: 2026 BUDGET vs. | T9: SQUARE | U9: PER | V9: % Change
A10: CODE | O10: TOTALS | P10: TOTALS | Q10: TOTALS | S10: 2025 FORECAST | T10: FOOTG. | U10: SQ. FT. | AF10: As of 9/13
B12: INCOME
A13: 40100 | B13: Rental Income | C13: =Rent!E34 -> 105478.32 | D13: =Rent!F34 -> 105478.32 | E13: =Rent!G34 -> 105478.32 | F13: =Rent!H34 -> 105710.71 | G13: =Rent!I34 -> 105784.97 | H13: =Rent!J34 -> 105784.97 | I13: =Rent!K34 -> 112023.69 | J13: =Rent!L34 -> 112023.69 | ... N13: =Rent!P34 -> 112675.93 | O13: =SUM(C13:N13) -> 1307638.9 | P13: 1272840 | Q13: 1350412 | R13: =SUM((O13)/(Rent!#REF!+Rent!#REF!+Rent!$C$15+Rent!$C$17+Rent!$C$18+Rent!$C$19+Rent!$C$20+Rent!$C$21+Rent!$C$22)) -> #REF! | S13: =O13-P13 -> 34798.89 | T13: =Rent!$C$34 -> 67709 | U13: =O13/T13 -> 19.31263
A14: 40140 | B14: Common Area | C14: =CAM!E35 -> 9715.6352 | D14: =CAM!F35 -> 9715.6352 | E14: =CAM!G35 -> 9715.6352 | F14: =CAM!H35 -> 9715.6352 | G14: =CAM!I35 -> 9715.6352 | H14: =CAM!J35 -> 9715.6352 | I14: =CAM!K35 -> 10110.449 | J14: =CAM!L35 -> 10110.449 | ... N14: =CAM!P35 -> 10110.449 | O14: =SUM(C14:N14) -> 118956.5 | P14: 99472 | Q14: 106692 | R14: =SUM((O14)/(Rent!#REF!+Rent!#REF!+Rent!$C$15+Rent!$C$17+Rent!$C$18+Rent!$C$19+Rent!$C$20+Rent!$C$21+Rent!$C$22)) -> #REF! | S14: =P14-O14 -> -19484.504 | T14: =Rent!$C$34 -> 67709 | U14: =O14/T14 -> 1.7568788
A15: 41300 | B15: State and County Rental Tax 3% | C15: ='Sales Tax'!E109 -> 3421.1835 | D15: ='Sales Tax'!F109 -> 3421.1835 | E15: ='Sales Tax'!G109 -> 3421.1835 | F15: ='Sales Tax'!H109 -> 3424.9178 | G15: ='Sales Tax'!I109 -> 3426.7743 | H15: ='Sales Tax'!J109 -> 3426.7743 | I15: ='Sales Tax'!K109 -> 3622.3678 | J15: ='Sales Tax'!L109 -> 3622.3678 | ... N15: ='Sales Tax'!P109 -> 3752.9446 | O15: =SUM(C15:N15) -> 42435.023 | P15: 40624 | Q15: 43176 | R15: =SUM((O15)/(Rent!#REF!+Rent!#REF!+Rent!$C$15+Rent!$C$17+Rent!$C$18+Rent!$C$19+Rent!$C$20+Rent!$C$21+Rent!$C$22)) -> #REF! | S15: =P15-O15 -> -1811.0232 | T15: =Rent!$C$34 -> 67709
A16: 40150 | B16: Prior Year CAM | C16: 0 | D16: 0 | E16: 0 | F16: 0 | G16: 0 | H16: 0 | I16: 0 | J16: 0 | K16: 0 | L16: 0 | M16: 0 | N16: 0 | O16: =SUM(C16:N16) -> 0 | R16: =SUM((O16)/(Rent!#REF!+Rent!#REF!+Rent!$C$15+Rent!$C$17+Rent!$C$18+Rent!$C$19+Rent!$C$20+Rent!$C$21+Rent!$C$22)) -> #REF! | S16: =P16-O16 -> 0 | U16: 0
A17: 40170 | B17: Building CAM | C17: ='Building Expenses'!E35 -> 2845.3195 | D17: ='Building Expenses'!F35 -> 2845.3195 | E17: ='Building Expenses'!G35 -> 2845.3195 | F17: ='Building Expenses'!H35 -> 2845.3195 | G17: ='Building Expenses'!I35 -> 2845.3195 | H17: ='Building Expenses'!J35 -> 2845.3195 | I17: ='Building Expenses'!K35 -> 3338.1127 | J17: ='Building Expenses'!L35 -> 3338.1127 | ... N17: ='Building Expenses'!P35 -> 3338.1127 | O17: =SUM(C17:N17) -> 37100.593 | R17: =SUM(O17)/(Rent!#REF!+Rent!#REF!+Rent!C16+Rent!C17+Rent!C18+Rent!C19+Rent!C20+Rent!C21) -> #REF! | S17: =P17-O17 -> -37100.593 | T17: =Rent!$C$34 -> 67709 | U17: =O17/T17 -> 0.54794182
A18: 40230 | B18: Insurance Income | C18: =Ins.!E35 -> 2545.0928 | D18: =Ins.!F35 -> 2545.0928 | E18: =Ins.!G35 -> 2545.0928 | F18: =Ins.!H35 -> 2545.0928 | G18: =Ins.!I35 -> 2545.0928 | H18: =Ins.!J35 -> 2545.0928 | I18: =Ins.!K35 -> 2663.375 | J18: =Ins.!L35 -> 2663.375 | ... N18: =Ins.!P35 -> 2663.375 | O18: =SUM(C18:N18) -> 31250.807 | P18: 17496 | Q18: 18516 | R18: =SUM(O18)/(Rent!#REF!+Rent!C15+Rent!C17+Rent!C18+Rent!C19+Rent!C20+Rent!C21+Rent!C22) -> #REF! | S18: =P18-O18 -> -13754.807 | T18: =Rent!$C$34 -> 67709 | U18: =O18/T18 -> 0.46154583
A19: 40240 | B19: Property Tax Income | C19: ='RE Tax'!E37 -> 11506.312 | D19: ='RE Tax'!F37 -> 11506.312 | E19: ='RE Tax'!G37 -> 11506.312 | F19: ='RE Tax'!H37 -> 11506.312 | G19: ='RE Tax'!I37 -> 11506.312 | H19: ='RE Tax'!J37 -> 11506.312 | I19: ='RE Tax'!K37 -> 12041.063 | J19: ='RE Tax'!L37 -> 12041.063 | ... N19: ='RE Tax'!P37 -> 12041.063 | O19: =SUM(C19:N19) -> 141284.25 | P19: 157244 | Q19: 165792 | R19: =SUM(O19)/(Rent!#REF!+Rent!C16+Rent!C18+Rent!C19+Rent!C20+Rent!C21+Rent!C22+Rent!C23) -> #REF! | S19: =P19-O19 -> 15959.747 | T19: =Rent!$C$34 -> 67709 | U19: =O19/T19 -> 2.0866392
A20: 40250 | B20: Miscellaneous Income | C20: 0 | D20: 0 | E20: 0 | F20: 0 | G20: 0 | H20: 0 | I20: 0 | J20: 0 | K20: 0 | L20: 0 | M20: 0 | N20: 0 | O20: =SUM(C20:N20) -> 0 | P20: 7280 | Q20: 0 | S20: =P20-O20 -> 7280 | T20: =Rent!$C$34 -> 67709
A21: 40390 | B21: Administrative Fee Income | C21: ='Admin Fee'!E34 -> 170.83229 | D21: ='Admin Fee'!F34 -> 170.83229 | E21: ='Admin Fee'!G34 -> 170.83229 | F21: ='Admin Fee'!H34 -> 170.83229 | G21: ='Admin Fee'!I34 -> 170.83229 | H21: ='Admin Fee'!J34 -> 170.83229 | I21: ='Admin Fee'!K34 -> 215.21264 | J21: ='Admin Fee'!L34 -> 215.21264 | ... N21: ='Admin Fee'!P34 -> 215.21264 | O21: =SUM(C21:N21) -> 2316.2696 | P21: 35017 | Q21: 38976 | R21: =SUM(O21)/(Rent!#REF!+Rent!C17+Rent!C19+Rent!C20+Rent!C21+Rent!C22+Rent!C23+Rent!C24) -> #REF! | S21: =P21-O21 -> 32700.73 | T21: =Rent!$C$34 -> 67709 | U21: =O21/T21 -> 0.034209183
B22: Sign Income | C22: =Signage!E37 -> 4585.83 | D22: =Signage!F37 -> 4585.83 | E22: =Signage!G37 -> 4585.83 | F22: =Signage!H37 -> 4585.83 | G22: =Signage!I37 -> 4585.83 | H22: =Signage!J37 -> 4585.83 | I22: =Signage!K37 -> 4585.83 | J22: =Signage!L37 -> 4585.83 | ... N22: =Signage!P37 -> 4585.83 | O22: =SUM(C22:N22) -> 55029.96 | P22: 50500 | Q22: 54000 | R22: =SUM(O22)/(Rent!#REF!+Rent!C18+Rent!C20+Rent!C21+Rent!C22+Rent!C23+Rent!C24+Rent!C25) -> #REF! | S22: =P22-O22 -> -4529.96 | T22: =Rent!$C$34 -> 67709 | U22: =O22/T22 -> 0.81274218
A23: 40143 | B23: Deferred CAM Recovery | C23: ='Rent Deferral Recovery'!D30 -> 0 | D23: ='Rent Deferral Recovery'!E30 -> 0 | E23: ='Rent Deferral Recovery'!F30 -> 0 | F23: ='Rent Deferral Recovery'!G30 -> 0 | G23: ='Rent Deferral Recovery'!H30 -> 0 | H23: ='Rent Deferral Recovery'!I30 -> 0 | I23: ='Rent Deferral Recovery'!J30 -> 0 | J23: ='Rent Deferral Recovery'!K30 -> 0 | ... N23: ='Rent Deferral Recovery'!O30 -> 0 | O23: =SUM(C23:N23) -> 0 | R23: =SUM(O23)/(Rent!#REF!+Rent!C19+Rent!C21+Rent!C22+Rent!C23+Rent!C24+Rent!C25+Rent!C26) -> #REF! | S23: =P23-O23 -> 0 | T23: =Rent!$C$34 -> 67709 | U23: =O23/T23 -> 0
A24: 40600 | B24: Late Charge Income | C24: 0 | D24: 0 | E24: 0 | F24: 0 | G24: 0 | H24: 0 | I24: 0 | J24: 0 | K24: 0 | L24: 0 | M24: 0 | N24: 0 | O24: =SUM(C24:N24) -> 0 | S24: =P24-O24 -> 0 | T24: =Rent!$C$34 -> 67709 | U24: =O24/T24 -> 0
A25: 40220 | B25: Rent Abatement | C25: 0 | D25: 0 | E25: 0 | F25: 0 | G25: 0 | H25: 0 | I25: 0 | J25: 0 | K25: 0 | L25: 0 | M25: 0 | N25: 0 | O25: =SUM(C25:N25) -> 0 | S25: =P25-O25 -> 0 | T25: =Rent!$C$34 -> 67709
A26: 45000 | B26: Investment Interest | C26: 0 | D26: 0 | E26: 0 | F26: 0 | G26: 0 | H26: 0 | I26: 0 | J26: 0 | K26: 0 | L26: 0 | M26: 0 | N26: 0 | O26: =SUM(C26:N26) -> 0 | P26: 185 | Q26: 0 | S26: =P26-O26 -> 185 | T26: =Rent!$C$34 -> 67709
B27: TOTAL INCOME | C27: =SUM(C13:C25) -> 140268.53 | D27: =SUM(D13:D25) -> 140268.53 | E27: =SUM(E13:E25) -> 140268.53 | F27: =SUM(F13:F25) -> 140504.65 | G27: =SUM(G13:G25) -> 140580.77 | H27: =SUM(H13:H25) -> 140580.77 | I27: =SUM(I13:I25) -> 148600.1 | J27: =SUM(J13:J25) -> 148600.1 | ... O27: =SUM(O13:O25) -> 1736012.3 | P27: =SUM(P13:P26) -> 1680658 | Q27: =SUM(Q13:Q26) -> 1777564 | R27: =SUM(R13:R24) -> #REF! | S27: =SUM(S13:S24) -> 14058.48 | U27: =SUM(U13:U24) -> 25.012587 | V27: =S27/O27 -> 0.0080981455
B29: COMMON AREA EXPENSES
A31: 50150 | B31: Landscape- Tree Trimming | C31: 0 | D31: 0 | E31: 0 | F31: 0 | G31: 0 | H31: 0 | I31: 0 | J31: 0 | K31: 0 | L31: 17000 | M31: 0 | N31: 0 | O31: =SUM(C31:N31) -> 17000 | P31: 17000 | Q31: 17000 | R31: =O31/T31 -> 0.25107445 | S31: =P31-O31 -> 0 | T31: =CAM!C$35 -> 67709 | U31: =O31/T31 -> 0.25107445
A32: 50160 | B32: Landscape Consumables | C32: 0 | D32: 0 | E32: 0 | F32: 0 | G32: 1500 | H32: 0 | I32: 0 | J32: 0 | K32: 0 | L32: 1500 | M32: 0 | N32: 0 | O32: =SUM(C32:N32) -> 3000 | P32: 2599 | Q32: 0 | R32: 0 | S32: =P32-O32 -> -401 | T32: =CAM!C$35 -> 67709 | U32: 0
A33: 50190 | B33: Sprinkler Repairs | E33: 300 | H33: 300 | K33: 300 | N33: 300 | O33: =SUM(C33:N33) -> 1200 | P33: 1400 | Q33: 2400 | R33: =O33/T33 -> 0.017722902 | S33: =P33-O33 -> 200 | T33: =CAM!C$35 -> 67709 | U33: =O33/T33 -> 0.017722902
A34: 50170 | B34: Landscape Maintenance | C34: 1560 | D34: =C34 -> 1560 | E34: =D34 -> 1560 | F34: =E34 -> 1560 | G34: =F34 -> 1560 | H34: =G34 -> 1560 | I34: =H34 -> 1560 | J34: =I34 -> 1560 | K34: =J34 -> 1560 | ... N34: =M34 -> 1560 | O34: =SUM(C34:N34) -> 18720 | P34: 16170 | Q34: 17640 | R34: =O34/T34 -> 0.27647728 | S34: =P34-O34 -> -2550 | T34: =CAM!C$35 -> 67709 | U34: =O34/T34 -> 0.27647728
A35: 50510 | B35: Parking Lot Light Maintenance | C35: 125 | D35: 125 | E35: 125 | F35: 125 | G35: 125 | H35: 125 | I35: 125 | J35: 125 | K35: 125 | L35: 125 | M35: 125 | N35: 125 | O35: =SUM(C35:N35) -> 1500 | P35: 1375 | Q35: 1500 | R35: =O35/T35 -> 0.022153628 | S35: =P35-O35 -> -125 | T35: =CAM!C$35 -> 67709 | U35: =O35/T35 -> 0.022153628
A36: 50520 | B36: Parking Lot Repairs | C36: 0 | D36: 0 | E36: 0 | F36: 0 | G36: 5000 | H36: 0 | I36: 0 | J36: 0 | K36: 0 | L36: 0 | M36: 0 | N36: 0 | O36: =SUM(C36:N36) -> 5000 | P36: 0 | Q36: 5000 | R36: =O36/T36 -> 0.073845427 | S36: =P36-O36 -> -5000 | T36: =CAM!C$35 -> 67709 | U36: =O36/T36 -> 0.073845427
A37: 50530 | B37: Parking Lot Light Repairs | C37: 300 | D37: =C37 -> 300 | E37: =D37 -> 300 | F37: =E37 -> 300 | G37: =F37 -> 300 | H37: =G37 -> 300 | I37: =H37 -> 300 | J37: =I37 -> 300 | K37: =J37 -> 300 | ... N37: =M37 -> 300 | O37: =SUM(C37:N37) -> 3600 | P37: 4000 | Q37: 1200 | R37: =O37/T37 -> 0.053168707 | S37: =P37-O37 -> 400 | T37: =CAM!C$35 -> 67709 | U37: =O37/T37 -> 0.053168707
A38: 51020 | B38: General Maintenance | C38: 300 | D38: =C38 -> 300 | E38: =D38 -> 300 | F38: =E38 -> 300 | G38: =F38 -> 300 | H38: =G38 -> 300 | I38: =H38 -> 300 | J38: =I38 -> 300 | K38: =J38 -> 300 | ... N38: =M38 -> 300 | O38: =SUM(C38:N38) -> 3600 | P38: 3801 | Q38: 3600 | R38: =O38/T38 -> 0.053168707 | S38: =P38-O38 -> 201 | T38: =CAM!C$35 -> 67709 | U38: =O38/T38 -> 0.053168707
A39: 51030 | B39: Miscellaneous Maintenance | C39: 0 | D39: 0 | E39: 0 | F39: 0 | G39: 0 | H39: 0 | I39: 0 | J39: 0 | K39: 0 | L39: 0 | M39: 0 | N39: 0 | O39: =SUM(C39:N39) -> 0 | P39: 1630 | Q39: 0 | S39: =P39-O39 -> 1630 | T39: =CAM!C$35 -> 67709
A40: 51040 | B40: Day Porter | C40: 875 | D40: =C40 -> 875 | E40: =D40 -> 875 | F40: =E40 -> 875 | G40: =F40 -> 875 | H40: =G40 -> 875 | I40: =H40 -> 875 | J40: =I40 -> 875 | K40: =J40 -> 875 | ... N40: =M40 -> 875 | O40: =SUM(C40:N40) -> 10500 | P40: 8668 | Q40: 9456 | R40: =O40/T40 -> 0.1550754 | S40: =P40-O40 -> -1832 | T40: =CAM!C$35 -> 67709 | U40: =O40/T40 -> 0.1550754
A41: 52010 | B41: Janitorial Supplies | D41: =C41 -> 0 | E41: 50 | G41: =F41 -> 0 | H41: 50 | J41: =I41 -> 0 | K41: 50 | M41: =L41 -> 0 | N41: 50 | O41: =SUM(C41:N41) -> 200 | P41: 1045 | Q41: 1140 | R41: =O41/T41 -> 0.0029538171 | S41: =P41-O41 -> 845 | T41: =CAM!C$35 -> 67709 | U41: =O41/T41 -> 0.0029538171
A42: 51050 | B42: Pest Control | C42: 99 | D42: =C42 -> 99 | E42: =D42 -> 99 | F42: =E42 -> 99 | G42: =F42 -> 99 | H42: =G42 -> 99 | I42: =H42 -> 99 | J42: =I42 -> 99 | K42: =J42 -> 99 | ... N42: =M42 -> 99 | O42: =SUM(C42:N42) -> 1188 | P42: 990 | Q42: 1188 | R42: =O42/T42 -> 0.017545673 | S42: =P42-O42 -> -198 | T42: =CAM!C$35 -> 67709 | U42: =O42/T42 -> 0.017545673
A43: 5116 | B43: Security | C43: 0 | D43: 0 | E43: 0 | F43: 0 | G43: 0 | H43: 0 | I43: 0 | J43: 0 | K43: 0 | L43: 0 | M43: 0 | N43: 0 | O43: =SUM(C43:N43) -> 0 | R43: =O43/T43 -> 0 | S43: =P43-O43 -> 0 | T43: =CAM!C$35 -> 67709 | U43: =O43/T43 -> 0
A44: 51080 | B44: Management Fee | C44: 4267 | D44: 4267 | E44: 4267 | F44: 4274 | G44: 4277 | H44: 4277 | I44: 4278 | J44: 4278 | K44: 4278 | L44: 4296 | M44: 4298 | N44: 4302 | O44: =SUM(C44:N44) -> 51359 | P44: 56656 | Q44: 55075 | R44: =O44/T44 -> 0.75852545 | S44: =P44-O44 -> 5297 | T44: =CAM!C$35 -> 67709 | U44: =O44/T44 -> 0.75852545
A45: 51100 | B45: Sidewalk Maintenance | C45: 0 | D45: 0 | E45: 0 | F45: 0 | G45: 0 | H45: 0 | I45: 0 | J45: 0 | K45: 0 | L45: 0 | M45: 0 | N45: 0 | O45: =SUM(C45:N45) -> 0 | R45: =O45/T45 -> 0 | S45: =P45-O45 -> 0 | T45: =CAM!C$35 -> 67709 | U45: =O45/T45 -> 0
...

Sheet Cap-EX
B3: AMORTIZED PROJECTS
B5: DESCRIPTION | C5: GL CODE | D5: TOTAL PROJECT COST | F5: COST PER YR | G5: # OF YEARS | H5: DATES | K5: NOTES
B6: Roof | C6: =Summary!A53 -> 51070 | D6: 113849 | F6: =(D6-18500)/8 -> 11918.625 | G6: 9 | H6: 2020-2028 | K6: $18,500 billed in 2020;
B7: Cameras | C7: N/A | D7: 35000 | F7: =IFERROR(D7/G7,0) -> 7000 | G7: 5 | H7: 2020-2024 | K7: Project completed
F8: =IFERROR(D8/G8,0) -> 0
B13: CAP-EX
C15: ACTUAL | D15: ACTUAL | E15: FORECAST | F15: BUDGET | G15: PROJECTED | H15: PROJECTED | I15: PROJECTED | J15: PROJECTED | M15: past / project future projects
B16: DESCRIPTION | C16: 2022 | D16: 2023 | E16: 2024 | F16: 2025 | G16: 2026 | H16: 2027 | I16: 2028 | J16: 2029 | K16: NOTES
B17: Monument Sign upgrade
B18: Electrical/Lighting
B19: Roof
B20: Paint
B21: Landscape
B22: HVAC
B23: Plumbing
B24: Parking lot Slurry
B28: MAINTENANCE TRACKING
B30: DESCRIPTION | D30: COMPLETED | E30: DUE | G30: VENDOR | I30: NOTES
B31: 5-Year Fire Inspection | F31: TBD
B32: Slurry Seal | F32: TBD
B33: Roof | F33: TBD
B34: Paint | F34: TBD
B35: LED | F35: TBD

Sheet Rent
P1: =Summary!T4 -> Date Revised: | Q1: =Summary!U4 -> 46269 | R1: =Summary!W4 -> 0
A2: =Summary!$A2 -> ATHENA PROPERTY MANAGEMENT
A3: =Summary!$A3 -> GREENFIELD GATEWAY MESA, ARIZONA
A4: =Summary!$A4 -> PROJECT NO. 801
A5: =Summary!$A5 -> 01/01/26-12/31/26
A6: =Summary!$A6 -> 2026 OPERATING BUDGET
A9: TENANT | B9: SUITE | C9: SQUARE | D9: RATE | E9: JAN | F9: FEB | G9: MARCH | H9: APRIL | I9: MAY | J9: JUNE | K9: JULY | L9: AUGUST | M9: SEPT | N9: OCT | O9: NOV | P9: DEC | Q9: TOTALS | R9: NOTES
B10: # | C10: FOOTAGE
A12: BASE RENT
A14: EOS Fitness | B14: Major A | C14: 35000 | D14: =P14*12/C14 -> 18.150171 | E14: 52938 | F14: =E14 -> 52938 | G14: =F14 -> 52938 | H14: =G14 -> 52938 | I14: =H14 -> 52938 | J14: =I14 -> 52938 | K14: =J14 -> 52938 | L14: =K14 -> 52938 | M14: =L14 -> 52938 | ... P14: =O14 -> 52938 | Q14: =SUM(E14:P14) -> 635256 | R14: Next increase 5/1/2029 for $58,231.00 or 1.66 Psf
A15: Third Pasrty MVS | B15: B101 | C15: 3000 | D15: =P15*12/C15 -> 25.50404 | E15: 6190.3 | F15: =E15 -> 6190.3 | G15: =F15 -> 6190.3 | H15: =G15 -> 6190.3 | I15: =H15 -> 6190.3 | J15: =I15 -> 6190.3 | K15: =J15 -> 6190.3 | L15: =K15 -> 6190.3 | M15: =L15 -> 6190.3 | N15: 6376.01 | O15: =N15 -> 6376.01 | P15: =O15 -> 6376.01 | Q15: =SUM(E15:P15) -> 74840.73 | R15: Rent increase 10/1/2026 $6,376.01 or 2.13 Psf
A16: Sally Beauty Supply | B16: B103 | C16: 1625 | D16: =P16*12/C16 -> 18.749982 | E16: 2539.06 | F16: =E16 -> 2539.06 | G16: =F16 -> 2539.06 | H16: =G16 -> 2539.06 | I16: =H16 -> 2539.06 | J16: =I16 -> 2539.06 | K16: =J16 -> 2539.06 | L16: =K16 -> 2539.06 | M16: =L16 -> 2539.06 | ... O16: =N16 -> 2539.06 | P16: 2539.06 | Q16: =SUM(E16:P16) -> 30468.72 | R16: Next increase 12/1/2027 (fixed for 2 years)
A17: Wild Side Smoke Shop | B17: B104 | C17: 1400 | D17: =P17*12/C17 -> 21.854486 | E17: 2475.43 | F17: =E17 -> 2475.43 | G17: =F17 -> 2475.43 | H17: =G17 -> 2475.43 | I17: 2549.69 | J17: =I17 -> 2549.69 | K17: =J17 -> 2549.69 | L17: =K17 -> 2549.69 | M17: =L17 -> 2549.69 | N17: =M17 -> 2549.69 | O17: =N17 -> 2549.69 | P17: =O17 -> 2549.69 | Q17: =SUM(E17:P17) -> 30299.24 | R17: Rent increase 5/1/2026 $2,549.69 or 1.82 Psf
A18: Green Spa, LLC | B18: B105 | C18: 1112 | D18: =P18*12/C18 -> 23.185683 | E18: 2106.41 | F18: =E18 -> 2106.41 | G18: =F18 -> 2106.41 | H18: 2148.54 | I18: =H18 -> 2148.54 | J18: =I18 -> 2148.54 | K18: =J18 -> 2148.54 | L18: =K18 -> 2148.54 | M18: =L18 -> 2148.54 | N18: =M18 -> 2148.54 | O18: =N18 -> 2148.54 | P18: =O18 -> 2148.54 | Q18: =SUM(E18:P18) -> 25656.09 | R18: Lease expires 3/31/2026 OPT 4/1/2026 for $2,148.54 or 1.93 Psf
A19: AT&T Mobility | B19: B106 | C19: 2494 | D19: =P19*12/C19 -> 25.863994 | E19: 5375.4 | F19: =E19 -> 5375.4 | G19: =F19 -> 5375.4 | H19: =G19 -> 5375.4 | I19: =H19 -> 5375.4 | J19: =I19 -> 5375.4 | K19: =J19 -> 5375.4 | L19: =K19 -> 5375.4 | M19: =L19 -> 5375.4 | ... P19: =O19 -> 5375.4 | Q19: =SUM(E19:P19) -> 64504.8 | R19: Lease Expires 3/31/2026 OPT 4/1/2026 FMV
