Workbook
Name _Builtin0: #N/A

Sheet 2026
B1: 165
B2: VARIANCE REPORT
B3: 2026
C4: JAN | H4: FEB | M4: MARCH | R4: APRIL | W4: MAY | AB4: JUNE | AG4: JULY | AL4: AUGUST | AQ4: SEPTEMBER | AV4: OCTOBER | BA4: NOVEMBER | BF4: DECEMBER | BK4: YTD
B6: Tenant | C6: Budget | D6: Cash Receipts | E6: Variance | F6: Comments | H6: Budget | I6: Cash Receipts | J6: Variance | K6: Comments | M6: Budget | N6: Cash Receipts | O6: Variance | P6: Comments | R6: Budget | S6: Cash Receipts | T6: Variance | U6: Comments | W6: Budget | X6: Cash Receipts | Y6: Variance | Z6: Comments | AB6: Budget | AC6: Cash Receipts | AD6: Variance | AE6: Comments | AG6: Budget | AH6: Cash Receipts | AI6: Variance | AJ6: Comments | AL6: Budget | AM6: Cash Receipts | AN6: Variance | AO6: Comments | AQ6: Budget | AR6: Cash Receipts | AS6: Variance | AT6: Comments | AV6: Budget | AW6: Cash Receipts | AX6: Variance | AY6: Comments | BA6: Budget | BB6: Cash Receipts | BC6: Variance | BD6: Comments | BF6: Budget | BG6: Cash Receipts | BH6: Variance | BI6: Comments | BL6: Budget | BM6: Cash Receipts | BN6: Variance
A7: =Rent!B14 -> A 1-4 | B7: =Rent!A14 -> ISLAND LAVA JAVA | C7: =VLOOKUP(B7,'Final Data'!A:B,2,0)+942 -> 49863.183 | D7: 45483.44 | E7: =D7-C7 -> -4379.743 | F7: GET ($196.7) Budget vs Pmt PCR ($4,183.04) Budget vs Pmt | H7: =VLOOKUP(B7,'Final Data'!$A$3:$C$35,3,0)+942 -> 49863.183 | I7: 47223.98 | J7: =I7-H7 -> -2639.203 | K7: GET ($118.38) Short Pmt PCR ($2,520.82) Budget vs Pmt | M7: =VLOOKUP(B7,'Final Data'!$A$3:$D$31,4,0)+942 -> 49863.183 | N7: =44637.21-15376.01 -> 29261.2 | O7: =N7-M7 -> -20601.983 | P7: GET ($926.7) Budget Vs Pmt. PCR ($20,000) Budget vs Pmt PRO $824.72 Over Pmt MKT ($500.00) Budget vs Pmt | R7: =VLOOKUP(B7,'Final Data'!$A$3:$E$29,5,0)+942 -> 49863.183 | S7: =46931.45+15376.01 -> 62307.46 | T7: =S7-R7 -> 12444.277 | U7: GET $560.35 Budget Vs Pmt IFC $1,579.92 Budget Vs Pmt PCR $10,304.00 Budget Vs Pmt | W7: =VLOOKUP(B7,'Final Data'!$A$3:$F$37,6,0)+942 -> 49863.183 | X7: 42915.52 | Y7: =X7-W7 -> -6947.663 | Z7: GET ($312.26) Budget Vs Pmt PCR (6,635.40) Budget Vs Pmt | AB7: =VLOOKUP(B7,'Final Data'!$A$3:$G$37,7,0)+942 -> 49863.183 | AC7: 31044.65 | AD7: =AC7-AB7 -> -18818.533 | AE7: PCR ($7,699.03) Budget vs Pmt NNN ($10,273.05) SHORTPAID DUE TO PYC CREDIT APPLIED GET ($846.45) Budget Vs Pmt | AG7: =VLOOKUP(B7,'Final Data'!$A$3:$H$37,8,0)+942 -> 49863.183 | AH7: 40624.76 | AI7: =AH7-AG7 -> -9238.423 | AJ7: PCR ($8,823.08) Budget vs Pmt GET ($415.34) Budget Vs Pmt | AL7: =VLOOKUP(B7,'Final Data'!$A$3:$I$36,9,0)+942 -> 49863.183 | AM7: =41690.24-226.54 -> 41463.7 | AN7: =AM7-AL7 -> -8399.483 | AO7: PCR ($8,021.89) Budget vs Pmt GET ($377.59) Budget Vs Pmt | BK7: =B7 -> ISLAND LAVA JAVA | BL7: =C7+H7+M7+R7+W7+AB7+AG7+AL7+AQ7+AV7+BA7+BF7 -> 398905.46 | BM7: =D7+I7+N7+S7+X7+AC7+AH7+AM7+AR7+AW7+BB7+BG7 -> 340324.71 | BN7: =BM7-BL7 -> -58580.754 | BO7: PCR ($47,579.26) Budget vs Pmt Jan'26 to July'26 GET ($2,633.07) Budget Vs Pmt in Feb'26 to July'26 MKT ($500.00) Budget vs Pmt in Mar'26 PRO $824.72 Over Pmt in Mar'26 IFC $1,579.92 Budget Vs Pmt in Apr'26 NNN ($10,273.05) SHORTPAID DUE TO PYC CREDIT APPLIED in June'26
A8: =Rent!B15 -> B-5 | B8: =Rent!A15 -> TAKA SUSHI | C8: =VLOOKUP(B8,'Final Data'!A:B,2,0)+1.18+19.94 -> 7297.6182 | D8: 7271.44 | E8: =D8-C8 -> -26.178202 | F8: GET ($1.18) Budget vs Pmt PCR ($25.00) Budget vs Pmt | H8: =VLOOKUP(B8,'Final Data'!$A$3:$C$35,3,0)+1.18+19.94 -> 7297.6182 | I8: 7271.44 | J8: =I8-H8 -> -26.178202 | K8: GET ($1.18) Budget vs Pmt PCR ($25.00) Budget vs Pmt | M8: =VLOOKUP(B8,'Final Data'!$A$3:$D$31,4,0)+1.18+19.94 -> 7297.6182 | N8: 7271.44 | O8: =N8-M8 -> -26.178202 | P8: GET ($1.18) Budget vs Pmt PCR ($25.00) Budget vs Pmt | R8: =VLOOKUP(B8,'Final Data'!$A$3:$E$29,5,0)+1.18+19.94 -> 7297.6182 | S8: 7271.44 | T8: =S8-R8 -> -26.178202 | U8: GET ($1.18) Budget vs Pmt PCR ($25.00) Budget vs Pmt | W8: =VLOOKUP(B8,'Final Data'!$A$3:$F$37,6,0)+1.18+19.94 -> 7297.6182 | X8: 7271.44 | Y8: =X8-W8 -> -26.178202 | Z8: GET ($1.18) Budget vs Pmt PCR ($25.00) Budget vs Pmt | AB8: =VLOOKUP(B8,'Final Data'!$A$3:$G$37,7,0)+1.18+19.94 -> 7297.6182 | AC8: 4288.55 | AD8: =AC8-AB8 -> -3009.0682 | AE8: GET ($135.40) Budget vs Pmt PCR ($25.00) Budget vs Pmt NNN ($2,848.66) SHORTPAID DUE TO PYC CREDIT APPLIED | AG8: =VLOOKUP(B8,'Final Data'!$A$3:$H$37,8,0)+1.18+19.94 -> 7297.6182 | AH8: 7271.44 | AI8: =AH8-AG8 -> -26.178202 | AJ8: GET ($1.18) Budget vs Pmt PCR ($25.00) Budget vs Pmt | AL8: =VLOOKUP(B8,'Final Data'!$A$3:$I$36,9,0)+1.18+19.94 -> 7297.6182 | AM8: 7271.44 | AN8: =AM8-AL8 -> -26.178202 | AO8: GET ($1.18) Budget vs Pmt PCR ($25.00) Budget vs Pmt | BK8: =B8 -> TAKA SUSHI | BL8: =C8+H8+M8+R8+W8+AB8+AG8+AL8+AQ8+AV8+BA8+BF8 -> 58380.946 | BM8: =D8+I8+N8+S8+X8+AC8+AH8+AM8+AR8+AW8+BB8+BG8 -> 55188.63 | BN8: =BM8-BL8 -> -3192.3156 | BO8: GET ($143.65 ) Budget vs Pmt in Jan'26 to Aug'26 PCR ($200.00) Budget vs Pmt in Jan'26 to Aug'26 NNN ($2,848.66) SHORTPAID DUE TO PYC CREDIT APPLIED in June'26
A9: =Rent!B16 -> B-6 | B9: =Rent!A16 -> KANAKA KAVA | C9: =VLOOKUP(B9,'Final Data'!A:B,2,0)+9.42 -> 3208.7524 | D9: 2999.33 | E9: =D9-C9 -> -209.4224 | F9: GET ($9.42) Budget vs Pmt PCR ($200) Budget vs Pmt | H9: =VLOOKUP(B9,'Final Data'!$A$3:$C$35,3,0)+9.42 -> 3208.7524 | I9: 3520.14 | J9: =I9-H9 -> 311.3876 | K9: GET $14.01 Budget vs Pmt PCR $297.37 Budget vs Pmt | M9: =VLOOKUP(B9,'Final Data'!$A$3:$D$31,4,0)+9.42 -> 3208.7524 | N9: 2999.33 | O9: =N9-M9 -> -209.4224 | P9: GET ($9.42) Budget vs Pmt PCR ($200) Budget vs Pmt | R9: =VLOOKUP(B9,'Final Data'!$A$3:$E$29,5,0)+9.42 -> 3270.5524 | S9: 3764.64 | T9: =S9-R9 -> 494.0876 | U9: GET $25.01 Budget vs Pmt PCR $469.07 Budget vs Pmt | W9: =VLOOKUP(B9,'Final Data'!$A$3:$F$37,6,0)+9.42 -> 3270.5524 | X9: 3348.47 | Y9: =X9-W9 -> 77.917605 | Z9: GET $6.28 Budget vs Pmt PCR $71.63 Budget vs Pmt | AB9: =VLOOKUP(B9,'Final Data'!$A$3:$G$37,7,0)+9.42 -> 3270.5524 | AC9: 2604.11 | AD9: =AC9-AB9 -> -666.4424 | AE9: GET ($27.21) Budget vs Pmt PCR ($108.80) Budget vs Pmt NNN ($530.44) SHORTPAID DUE TO PYC CREDIT APPLIED | AG9: =VLOOKUP(B9,'Final Data'!$A$3:$H$37,8,0)+9.42 -> 3270.5524 | AH9: 3064.04 | AI9: =AH9-AG9 -> -206.5124 | AJ9: GET ($6.52) Budget vs Pmt PCR ($80.56) Budget vs Pmt PCR ($119.44) Short Pmt | AL9: =VLOOKUP(B9,'Final Data'!$A$3:$I$36,9,0)+9.42 -> 3270.5524 | AM9: 3189.11 | AN9: =AM9-AL9 -> -81.442395 | AO9: GET ($0.89) Budget vs Pmt PCR ($80.56) Budget vs Pmt | BK9: =B9 -> KANAKA KAVA | BL9: =C9+H9+M9+R9+W9+AB9+AG9+AL9+AQ9+AV9+BA9+BF9 -> 25979.019 | BM9: =D9+I9+N9+S9+X9+AC9+AH9+AM9+AR9+AW9+BB9+BG9 -> 25489.17 | BN9: =BM9-BL9 -> -489.84916 | BO9: GET ($8.16) Budget vs Pmt in Jan'26 to Aug'26 PCR $168.15 Budget vs Pmt in Jan'26 to Aug'26 PCR ($119.44) Short Pmt in July'26 NNN ($530.44) SHORTPAID DUE TO PYC CREDIT APPLIED in June'26
A10: =Rent!B17 -> C-7 | B10: =Rent!A17 -> GECKO GIRLZ SHAVE ICE SHACK | C10: =VLOOKUP(B10,'Final Data'!A:B,2,0)+42.39 -> 5174.1597 | D10: 4630.02 | E10: =D10-C10 -> -544.1397 | F10: GET ($55.64) Short Pmt GET $31.17 Budget vs Pmt PCR ($1,180.82) Short Pmt PCR $661.15 Budget vs Pmt | H10: =VLOOKUP(B10,'Final Data'!$A$3:$C$35,3,0)+42.39 -> 5174.1597 | I10: 5468.23 | J10: =I10-H10 -> 294.0703 | K10: GET $13.25 Over Pmt PCR $280.82 Over Pmt | M10: =VLOOKUP(B10,'Final Data'!$A$3:$D$31,4,0)+42.39 -> 5174.1597 | N10: 5679.04 | O10: =N10-M10 -> 504.8803 | P10: GET $22.74 Past due paid for Feb'26 PCR $1,382.14 past due paid for Feb'26 PCR ($900) Short Pmt Mar'26 | R10: =VLOOKUP(B10,'Final Data'!$A$3:$E$29,5,0)+42.39 -> 5174.1597 | S10: 5308.46 | T10: =S10-R10 -> 134.3003 | U10: GET $6.06 Past due paid for Mar'26 PCR $128.24 Budget vs Pmt | W10: =VLOOKUP(B10,'Final Data'!$A$3:$F$37,6,0)+42.39 -> 5174.1597 | X10: 6482.98 | Y10: =X10-W10 -> 1308.8203 | Z10: GET $ $58.91 Past due paid for Apr'26 PCR $1,249.91 Budget vs Pmt | AB10: =VLOOKUP(B10,'Final Data'!$A$3:$G$37,7,0)+42.39 -> 5249.9997 | AC10: 5718.71 | AD10: =AC10-AB10 -> 468.7103 | AE10: GET $ $24.52 Budget vs Pmt BAS ($45.51) Budget vs Pmt PCR $1,863.72 Budget vs Pmt NNN ($1,374.02) SHORTPAID DUE TO PYC CREDIT APPLIED | AG10: =VLOOKUP(B10,'Final Data'!$A$3:$H$37,8,0)+42.39 -> 5176.5997 | AH10: 4311.19 | AI10: =AH10-AG10 -> -865.4097 | AJ10: GET ($38.81) Budget vs Pmt BAS $73.40 Budget vs Pmt PCR ($900) Budget vs Pmt | AL10: =VLOOKUP(B10,'Final Data'!$A$3:$I$36,9,0)+42.39 -> 5176.5997 | AM10: 7305.67 | AN10: =AM10-AL10 -> 2129.0703 | AO10: GET $95.94 Budget vs Pmt BAS $73.40 Budget vs Pmt PCR $1,959.73 Budget vs Pmt | BK10: =B10 -> GECKO GIRLZ SHAVE ICE SHACK | BL10: =C10+H10+M10+R10+W10+AB10+AG10+AL10+AQ10+AV10+BA10+BF10 -> 41473.998 | BM10: =D10+I10+N10+S10+X10+AC10+AH10+AM10+AR10+AW10+BB10+BG10 -> 44904.3 | BN10: =BM10-BL10 -> 3430.3024 | BO10: GET $157.85 Budget Vs Pmt Mar'26 to Aug'26 PCR $4,545.89 Budget Vs Pmt Mar'26 to Aug'26 NNN ($1,374.02) SHORTPAID DUE TO PYC CREDIT APPLIED in June'26 BAS $101.29 Budget vs Pmt in June'26 to Aug'26
A11: =Rent!B18 -> C-8 | B11: =Rent!A18 -> BIG ISLAND RUNNING CO. | C11: =VLOOKUP(B11,'Final Data'!A:B,2,0)+44.75 -> 5382.4026 | D11: 6371.65 | E11: =D11-C11 -> 989.24741 | F11: GET $44.52 Budget vs Pmt PCR $944.73 Budget vs Pmt | H11: =VLOOKUP(B11,'Final Data'!$A$3:$C$35,3,0)+44.75 -> 5382.4026 | I11: 6272.23 | J11: =I11-H11 -> 889.82741 | K11: GET $40.05 Budget vs Pmt PCR $849.78 Budget vs Pmt | M11: =VLOOKUP(B11,'Final Data'!$A$3:$D$31,4,0)+44.75 -> 5382.4026 | N11: 5451.14 | O11: =N11-M11 -> 68.737405 | P11: GET $3.10 Budget vs Pmt PCR $65.64 Budget vs Pmt | R11: =VLOOKUP(B11,'Final Data'!$A$3:$E$29,5,0)+44.75 -> 5382.4026 | S11: 5606.61 | T11: =S11-R11 -> 224.20741 | U11: GET $10.09 Budget vs Pmt PCR $214.12 Budget vs Pmt | W11: =VLOOKUP(B11,'Final Data'!$A$3:$F$37,6,0)+44.75 -> 5382.4026 | X11: 5101.23 | Y11: =X11-W11 -> -281.17259 | Z11: GET ($12.65) Budget vs Pmt PCR ($268.52) Budget vs Pmt | AB11: =VLOOKUP(B11,'Final Data'!$A$3:$G$37,7,0)+44.75 -> 5382.4026 | AC11: 3932.12 | AD11: =AC11-AB11 -> -1450.2826 | AE11: GET ($65.26) Budget vs Pmt PCR ($92.13) Budget vs Pmt NNN ($1,292.89) SHORTPAID DUE TO PYC CREDIT APPLIED | AG11: =VLOOKUP(B11,'Final Data'!$A$3:$H$37,8,0)+44.75 -> 5382.4026 | AH11: 4976.7 | AI11: =AH11-AG11 -> -405.70259 | AJ11: GET ($18.25) Budget vs Pmt PCR ($387.45) Budget vs Pmt | AL11: =VLOOKUP(B11,'Final Data'!$A$3:$I$36,9,0)+44.75 -> 5382.4026 | AM11: 5783.98 | AN11: =AM11-AL11 -> 401.57741 | AO11: GET $18.07 Budget vs Pmt PCR $383.51 Budget vs Pmt | BK11: =B11 -> BIG ISLAND RUNNING CO. | BL11: =C11+H11+M11+R11+W11+AB11+AG11+AL11+AQ11+AV11+BA11+BF11 -> 43059.221 | BM11: =D11+I11+N11+S11+X11+AC11+AH11+AM11+AR11+AW11+BB11+BG11 -> 43495.66 | BN11: =BM11-BL11 -> 436.43924 | BO11: GET $19.66 Budget vs Pmt in Jan'26 to Aug'26 PCR $1,709.68 Budget vs Pmt in Jan'26 to Aug'26 NNN ($1,292.89) SHORTPAID DUE TO PYC CREDIT APPLIED in June'26
A12: =Rent!B19 -> D11-12 | B12: =Rent!A19 -> CAFE KONA | C12: =VLOOKUP(B12,'Final Data'!A:B,2,0) -> 7048.3605 | D12: 7650.79 | E12: =D12-C12 -> 602.42946 | F12: CAM $301.22 Over Pmt GET $13.55 Budget vs Pmt PCR $287.67 Budget vs Pmt | H12: =VLOOKUP(B12,'Final Data'!$A$3:$C$35,3,0) -> 7048.3605 | I12: =7425.16-340.02 -> 7085.14 | J12: =I12-H12 -> 36.77946 | K12: CAM ($301.22) PAST DUE PAID 01/26 GET $15.21 Budget vs Pmt PRO $322.80 Budget vs Pmt | M12: =VLOOKUP(B12,'Final Data'!$A$3:$D$31,4,0) -> 7048.3605 | N12: 7358.56 | O12: =N12-M12 -> 310.19946 | P12: GET $13.96 Budget vs Pmt PRO $296.25 Budget vs Pmt | R12: =VLOOKUP(B12,'Final Data'!$A$3:$E$29,5,0) -> 7048.3605 | S12: 7384.37 | T12: =S12-R12 -> 336.00946 | U12: GET $15.12 Budget vs Pmt PRO $320.90 Budget vs Pmt | W12: =VLOOKUP(B12,'Final Data'!$A$3:$F$37,6,0) -> 7048.3605 | X12: 7338.71 | Y12: =X12-W12 -> 290.34946 | Z12: GET $13.07 Budget vs Pmt PRO $277.29 Budget vs Pmt | AB12: =VLOOKUP(B12,'Final Data'!$A$3:$G$37,7,0) -> 7048.3605 | AC12: 7369.28 | AD12: =AC12-AB12 -> 320.91946 | AE12: GET $14.44 Budget vs Pmt PRO $306.49 Budget vs Pmt | AG12: =VLOOKUP(B12,'Final Data'!$A$3:$H$37,8,0) -> 7048.3605 | AH12: 7374.28 | AI12: =AH12-AG12 -> 325.91946 | AJ12: GET $14.67 Budget vs Pmt PRO $311.26 Budget vs Pmt | AL12: =VLOOKUP(B12,'Final Data'!$A$3:$I$36,9,0) -> 7048.3605 | AM12: 7048.35 | AN12: =AM12-AL12 -> -0.010540113 | BK12: =B12 -> CAFE KONA | BL12: =C12+H12+M12+R12+W12+AB12+AG12+AL12+AQ12+AV12+BA12+BF12 -> 56386.884 | BM12: =D12+I12+N12+S12+X12+AC12+AH12+AM12+AR12+AW12+BB12+BG12 -> 58609.48 | BN12: =BM12-BL12 -> 2222.5957 | BO12: GET $100.02 Budget vs Pmt in Jan'26 to July'26 PCR $287.67 Budget vs Pmt in Jan'26 & Feb'26 PRO $1,834.99 Budget vs Pmt in Feb'26 & July'26
A13: =Rent!B20 -> D9-D10 | B13: =Rent!A20 -> LUCASIE LTD | C13: =VLOOKUP(B13,'Final Data'!A:B,2,0) -> 10696.314 | D13: 8979.69 | E13: =D13-C13 -> -1716.6245 | F13: CAM ($1,639.41) Short Pmt GET ($77.25) Short Pmt | H13: =VLOOKUP(B13,'Final Data'!$A$3:$C$35,3,0) -> 10696.314 | I13: 10696.35 | J13: =I13-H13 -> 0.03552504 | M13: =VLOOKUP(B13,'Final Data'!$A$3:$D$31,4,0) -> 10998.824 | N13: 11013.08 | O13: =N13-M13 -> 14.255525 | P13: GET $14.26 Over Pmt | R13: =VLOOKUP(B13,'Final Data'!$A$3:$E$29,5,0) -> 10998.824 | S13: 0 | T13: =S13-R13 -> -10998.824 | U13: BAS ($7,895.51) No Pmt NNN ($3,103.31) No Pmt | W13: =VLOOKUP(B13,'Final Data'!$A$3:$F$37,6,0) -> 10998.824 | X13: 22163.96 | Y13: =X13-W13 -> 11165.136 | Z13: BAS $7,895.51 Past due paid NNN $3,269.63 Past due paid | AB13: =VLOOKUP(B13,'Final Data'!$A$3:$G$37,7,0) -> 10998.824 | AC13: 0 | AD13: =AC13-AB13 -> -10998.824 | AE13: BAS ($7,895.51) No Pmt NNN ($3,103.31) No Pmt | AG13: =VLOOKUP(B13,'Final Data'!$A$3:$H$37,8,0) -> 10998.824 | AH13: 22026.16 | AI13: =AH13-AG13 -> 11027.336 | AJ13: BAS $7,895.51 past due paid NNN $ $3,131.83 past due paid | AL13: =VLOOKUP(B13,'Final Data'!$A$3:$I$36,9,0) -> 10998.824 | AM13: 11013.08 | AN13: =AM13-AL13 -> 14.255525 | AO13: GET $14.26 Budget vs Pmt | BK13: =B13 -> LUCASIE LTD | BL13: =C13+H13+M13+R13+W13+AB13+AG13+AL13+AQ13+AV13+BA13+BF13 -> 87385.576 | BM13: =D13+I13+N13+S13+X13+AC13+AH13+AM13+AR13+AW13+BB13+BG13 -> 85892.32 | BN13: =BM13-BL13 -> -1493.2558 | BO13: CAM ($1,639.41) Short Pmt in Jan'26 GET ($34.42) Short Pmt in Jan'26 & Julyr'26 NNN $166.32 Budget Vs Pmt in May'26 GET $14.26 Budget vs Pmt in Aug'26
A14: =Rent!B21 -> DU-1 | B14: =Rent!A21 -> FOSTERS KITCHEN | C14: =VLOOKUP(B14,'Final Data'!A:B,2,0) -> 23777.974 | D14: 0 | E14: =D14-C14 -> -23777.974 | F14: BAS (11,905.63) No Pmt NNN ($11,372.34) No Pmt MKT ($500.00) No Pmt | H14: =VLOOKUP(B14,'Final Data'!$A$3:$C$35,3,0) -> 23777.974 | I14: 0 | J14: =I14-H14 -> -23777.974 | K14: BAS ($11,905.63) No Pmt NNN ($11,872.34) No Pmt | M14: =VLOOKUP(B14,'Final Data'!$A$3:$D$31,4,0) -> 23777.974 | N14: =190223.76-118889.85 -> 71333.91 | O14: =N14-M14 -> 47555.936 | P14: BAS $23,811.26 Past Due Paid for Jan'25 & Feb'26 NNN $23,744.68 Past Due Paid for Jan'25 & Feb'26 | R14: =VLOOKUP(B14,'Final Data'!$A$3:$E$29,5,0) -> 23777.974 | S14: 23777.97 | T14: =S14-R14 -> -0.0043720919 | W14: =VLOOKUP(B14,'Final Data'!$A$3:$F$37,6,0) -> 23777.974 | X14: 23777.97 | Y14: =X14-W14 -> -0.0043720919 | AB14: =VLOOKUP(B14,'Final Data'!$A$3:$G$37,7,0) -> 23777.974 | AC14: 23777.97 | AD14: =AC14-AB14 -> -0.0043720919 | AG14: =VLOOKUP(B14,'Final Data'!$A$3:$H$37,8,0) -> 24135.144 | AH14: 0 | AI14: =AH14-AG14 -> -24135.144 | AJ14: BAS ($12,262.80) No Pmt NNN ($11,872.34) No Pmt | AL14: =VLOOKUP(B14,'Final Data'!$A$3:$I$36,9,0)+211.95 -> 28847.094 | AM14: 47555.94 | AN14: =AM14-AL14 -> 18708.846 | AO14: BAS $12,262.80 Past due paid NNN $7,194.05 Past due paid CAM ($748.00) Short Pmt | BK14: =B14 -> FOSTERS KITCHEN | BL14: =C14+H14+M14+R14+W14+AB14+AG14+AL14+AQ14+AV14+BA14+BF14 -> 195650.08 | BM14: =D14+I14+N14+S14+X14+AC14+AH14+AM14+AR14+AW14+BB14+BG14 -> 190223.76 | BN14: =BM14-BL14 -> -5426.325 | BO14: NNN ($11,872.34) No Pmt in July'26 NNN $7,194.05 Past due paid in Aug'26 CAM ($748.00) Short Pmt in Aug'26
A15: =Rent!B22 -> E | B15: =Rent!A22 -> HUMPYS BIG ISLAND ALEHOUSE | C15: =VLOOKUP(B15,'Final Data'!A:B,2,0) -> 27656.092 | D15: 26178 | E15: =D15-C15 -> -1478.0923 | F15: GET ($1,478.09) Short Pmt | H15: =VLOOKUP(B15,'Final Data'!$A$3:$C$35,3,0) -> 27656.092 | I15: 26178 | J15: =I15-H15 -> -1478.0923 | K15: GET ($1,478.09) Budget vs Pmt | M15: =VLOOKUP(B15,'Final Data'!$A$3:$D$31,4,0) -> 27656.092 | N15: 26178 | O15: =N15-M15 -> -1478.0923 | P15: GET ($1,478.09) Budget vs Pmt | R15: =VLOOKUP(B15,'Final Data'!$A$3:$E$29,5,0) -> 27656.092 | S15: 26178 | T15: =S15-R15 -> -1478.0923 | U15: GET ($1,478.09) Budget vs Pmt | W15: =VLOOKUP(B15,'Final Data'!$A$3:$F$37,6,0) -> 27656.092 | X15: 26178 | Y15: =X15-W15 -> -1478.0923 | Z15: GET ($1,478.09) Budget vs Pmt | AB15: =VLOOKUP(B15,'Final Data'!$A$3:$G$37,7,0) -> 27656.092 | AC15: =91657.31-65479.31 -> 26178 | AD15: =AC15-AB15 -> -1478.0923 | AE15: GET $1,468.45 Budget vs Pmt RDR $62,532.77 SHORTPAID DUE TO PYC CREDIT APPLIED RDR ($62,532.77) 2025 CAM REC DEFERRAL RDR ($2,946.54) 2025 CAM GET DEFERRAL | AG15: =VLOOKUP(B15,'Final Data'!$A$3:$H$37,8,0) -> 27656.092 | AH15: 0 | AI15: =AH15-AG15 -> -27656.092 | AJ15: BAS ($25,000.00) No Pmt NNN ($2,656.09) No Pmt | AL15: =VLOOKUP(B15,'Final Data'!$A$3:$I$36,9,0) -> 27656.092 | AM15: =-13123.31+65479.31 -> 52356 | AN15: =AM15-AL15 -> 24699.908 | AO15: BAS $25,000.00 Past due paid GET ($300.09) Budget vs Pmt | BK15: =B15 -> HUMPYS BIG ISLAND ALEHOUSE | BL15: =C15+H15+M15+R15+W15+AB15+AG15+AL15+AQ15+AV15+BA15+BF15 -> 221248.74 | BM15: =D15+I15+N15+S15+X15+AC15+AH15+AM15+AR15+AW15+BB15+BG15 -> 209424 | BN15: =BM15-BL15 -> -11824.738 | BO15: GET ($6,222.10) Budget vs Pmt in Jan'26 to Aug'26 RDR ($2,946.54) 2025 CAM GET DEFERRAL in June'26 NNN ($2,656.09) No Pmt in July'26
A16: =Rent!B23 -> F15,17&A8 | B16: =Rent!A23 -> ABC STORE #75 | C16: =VLOOKUP(B16,'Final Data'!A:B,2,0)+2500+847.8-1000 -> 53899.272 | D16: =61535.66-991.58 -> 60544.08 | E16: =D16-C16 -> 6644.8075 | F16: GET $366.87 Budget vs Pmt PCR $5,277.93 Budget vs Pmt MIS $1,000 Budget vs MRI | H16: =VLOOKUP(B16,'Final Data'!$A$3:$C$35,3,0)+2500+847.8-1000 -> 53899.272 | I16: =54363.95+991.58 -> 55355.53 | J16: =I16-H16 -> 1456.2575 | K16: GET $133.38 Budget vs Pmt PCR $322.88 Budget vs Pmt MIS $1,000 Budget vs MRI | M16: =VLOOKUP(B16,'Final Data'!$A$3:$D$31,4,0)+2500+847.8-1000 -> 53899.272 | N16: 54567.28 | O16: =N16-M16 -> 668.00751 | P16: GET $97.91 Budget vs Pmt PCR $570.10 Budget vs Pmt | R16: =VLOOKUP(B16,'Final Data'!$A$3:$E$29,5,0)+2500+847.8-1000 -> 53899.272 | S16: 61312.36 | T16: =S16-R16 -> 7413.0875 | U16: GET ($1,098.56) Budget vs Pmt PCR $7,011.64 Budget vs Pmt MIS $1,500.00 Budget vs Pmt | W16: =VLOOKUP(B16,'Final Data'!$A$3:$F$37,6,0)+2500+847.8-1000 -> 53899.272 | X16: 54937.13 | Y16: =X16-W16 -> 1037.8575 | Z16: GET ($1,385.44) Budget vs Pmt PCR $923.29 Budget vs Pmt MIS $1,500.00 Budget vs Pmt | AB16: =VLOOKUP(B16,'Final Data'!$A$3:$G$37,7,0)+2500+847.8-1000 -> 53899.272 | AC16: 57039.44 | AD16: =AC16-AB16 -> 3140.1675 | AE16: GET ($1,290.84) Budget vs Pmt PCR $2,931.00 Budget vs Pmt MIS $1,500.00 Budget vs Pmt | AG16: =VLOOKUP(B16,'Final Data'!$A$3:$H$37,8,0)+2500+847.8-1000 -> 53899.272 | AH16: 27793.2 | AI16: =AH16-AG16 -> -26106.072 | AJ16: GET ($2,606.91) Budget vs Pmt PCR $2,936.94 Budget vs Pmt MIS $1,500.00 Budget vs Pmt NNN ($27,936.11) short pmt due to applied PYC | AL16: =VLOOKUP(B16,'Final Data'!$A$3:$I$36,9,0)+2500+847.8-1000 -> 53899.272 | AM16: 62473.27 | AN16: =AM16-AL16 -> 8573.9975 | AO16: GET ($1,046.32) Budget vs Pmt PCR $8,120.31 Budget vs Pmt MIS $1,500.00 Budget vs Pmt | BK16: =B16 -> ABC STORE #75 | BL16: =C16+H16+M16+R16+W16+AB16+AG16+AL16+AQ16+AV16+BA16+BF16 -> 431194.18 | BM16: =D16+I16+N16+S16+X16+AC16+AH16+AM16+AR16+AW16+BB16+BG16 -> 434022.29 | BN16: =BM16-BL16 -> 2828.11 | BO16: GET ($6,829.91) Budget vs Pmt in Jan'26 to Aug'26 PCR $28,094.09 Budget vs Pmt in Jan'26 to Aug'26 MIS $9,500 Budget vs MRI for Jan'26 to Aug'26 NNN ($27,936.11) short pmt due to applied PYC in July'26
A17: =Rent!B24 -> F-16 | B17: =Rent!A24 -> GYPSEA GALATO | C17: =VLOOKUP(B17,'Final Data'!A:B,2,0)+38.62 -> 5248.9125 | D17: 5260.52 | E17: =D17-C17 -> 11.60748 | F17: PCR ($80.89) Short Pmt PCR $91.97 Budget vs Pmt | H17: =VLOOKUP(B17,'Final Data'!$A$3:$C$35,3,0)+38.62 -> 5248.9125 | I17: 5962.06 | J17: =I17-H17 -> 713.14748 | K17: GET $32.10 Budget vs Pmt PCR $681.05 Budget vs Pmt | M17: =VLOOKUP(B17,'Final Data'!$A$3:$D$31,4,0)+38.62 -> 5248.9125 | N17: =6142.56-301.92 -> 5840.64 | O17: =N17-M17 -> 591.72748 | P17: GET $30.27 Budget vs Pmt PCR $642.34 Budget vs Pmt PCR ($80.89) Short Pmt | R17: =VLOOKUP(B17,'Final Data'!$A$3:$E$29,5,0)+38.62 -> 5248.9125 | S17: 5493.06 | T17: =S17-R17 -> 244.14748 | U17: CAM ($390.28) Short Pmt GET $32.20 Budget vs Pmt PCR $602.23 Budget vs Pmt | W17: =VLOOKUP(B17,'Final Data'!$A$3:$F$37,6,0)+38.62 -> 5248.9125 | X17: =5506.75-409.72 -> 5097.03 | Y17: =X17-W17 -> -151.88252 | Z17: GET ($38.63) Budget vs Pmt PCR ($113.25) Budget vs Pmt | AB17: =VLOOKUP(B17,'Final Data'!$A$3:$G$37,7,0)+38.62 -> 5330.8625 | AC17: 473.98 | AD17: =AC17-AB17 -> -4856.8825 | AE17: GET ($214.85) Budget vs Pmt PCR ($367.35) Budget vs Pmt NNN ($4,274.68) SHORTPAID DUE TO PYC CREDIT APPLIED | AG17: =VLOOKUP(B17,'Final Data'!$A$3:$H$37,8,0)+38.62 -> 5330.8625 | AH17: 5690.28 | AI17: =AH17-AG17 -> 359.41748 | AJ17: GET $19.87 Budget vs Pmt PCR $339.54 Budget vs Pmt | AL17: =VLOOKUP(B17,'Final Data'!$A$3:$I$36,9,0)+38.62 -> 5330.8625 | AM17: =4678.77+711.64 -> 5390.41 | AN17: =AM17-AL17 -> 59.54748 | AO17: GET ($8.14) Budget vs Pmt CAM $390.28 past due paid PCR $70.47 Budget vs Pmt NNN ($393.06) Short Paid due to PYC credit applied in Aug'26 | AP17: =-8.14+390.28+70.47-393.06 -> 59.55 | BK17: =B17 -> GYPSEA GALATO | BL17: =C17+H17+M17+R17+W17+AB17+AG17+AL17+AQ17+AV17+BA17+BF17 -> 42237.15 | BM17: =D17+I17+N17+S17+X17+AC17+AH17+AM17+AR17+AW17+BB17+BG17 -> 39207.98 | BN17: =BM17-BL17 -> -3029.1702 | BO17: GET ($147.18) Budget vs Pmt in Jan'26 to Aug'26 PCR $1,785.75 Budget vs Pmt in Jan'26 to Aug'26 NNN ($4,667.74) SHORTPAID DUE TO PYC CREDIT APPLIED in June'26 & Aug'26 | BS17: 139.04
A18: =Rent!B25 -> G | B18: =Rent!A25 -> OCEANS SPORTS BAR AND GRILL | C18: =VLOOKUP(B18,'Final Data'!A:B,2,0) -> 16707.224 | D18: 16707.22 | E18: =D18-C18 -> -0.0040942424 | H18: =VLOOKUP(B18,'Final Data'!$A$3:$C$35,3,0) -> 16707.224 | I18: 16707.22 | J18: =I18-H18 -> -0.0040942424 | M18: =VLOOKUP(B18,'Final Data'!$A$3:$D$31,4,0) -> 16707.224 | N18: 16707.22 | O18: =N18-M18 -> -0.0040942424 | R18: =VLOOKUP(B18,'Final Data'!$A$3:$E$29,5,0) -> 16707.224 | S18: 16707.22 | T18: =S18-R18 -> -0.0040942424 | W18: =VLOOKUP(B18,'Final Data'!$A$3:$F$37,6,0) -> 16707.224 | X18: 16707.22 | Y18: =X18-W18 -> -0.0040942424 | AB18: =VLOOKUP(B18,'Final Data'!$A$3:$G$37,7,0) -> 16707.224 | AC18: 16707.22 | AD18: =AC18-AB18 -> -0.0040942424 | AG18: =VLOOKUP(B18,'Final Data'!$A$3:$H$37,8,0) -> 16707.224 | AH18: 16707.22 | AI18: =AH18-AG18 -> -0.0040942424 | AL18: =VLOOKUP(B18,'Final Data'!$A$3:$I$36,9,0) -> 16707.224 | AM18: 16707.22 | AN18: =AM18-AL18 -> -0.0040942424 | BK18: =B18 -> OCEANS SPORTS BAR AND GRILL | BL18: =C18+H18+M18+R18+W18+AB18+AG18+AL18+AQ18+AV18+BA18+BF18 -> 133657.79 | BM18: =D18+I18+N18+S18+X18+AC18+AH18+AM18+AR18+AW18+BB18+BG18 -> 133657.76 | BN18: =BM18-BL18 -> -0.032753939 | BS18: 8.14
A19: =Rent!B26 -> H | B19: =Rent!A26 -> JACKS DIVE LOCKER | C19: =VLOOKUP(B19,'Final Data'!A:B,2,0) -> 35662.42 | D19: 35662.42 | E19: =D19-C19 -> 0.00032877734 | H19: =VLOOKUP(B19,'Final Data'!$A$3:$C$35,3,0) -> 35662.42 | I19: 35662.42 | J19: =I19-H19 -> 0.00032877734 | M19: =VLOOKUP(B19,'Final Data'!$A$3:$D$31,4,0) -> 35662.42 | N19: 35662.42 | O19: =N19-M19 -> 0.00032877734 | R19: =VLOOKUP(B19,'Final Data'!$A$3:$E$29,5,0) -> 35662.42 | S19: 35662.42 | T19: =S19-R19 -> 0.00032877734 | W19: =VLOOKUP(B19,'Final Data'!$A$3:$F$37,6,0) -> 35662.42 | X19: 35662.42 | Y19: =X19-W19 -> 0.00032877734 | AB19: =VLOOKUP(B19,'Final Data'!$A$3:$G$37,7,0) -> 35662.42 | AC19: 35662.42 | AD19: =AC19-AB19 -> 0.00032877734 | AG19: =VLOOKUP(B19,'Final Data'!$A$3:$H$37,8,0) -> 35662.42 | AH19: 17133.72 | AI19: =AH19-AG19 -> -18528.7 | AJ19: GET ($833.79) Budget vs Pmt NNN ($17,694.92) short pmt due to applied PYC | AL19: =VLOOKUP(B19,'Final Data'!$A$3:$I$36,9,0) -> 35662.42 | AM19: 35662.42 | AN19: =AM19-AL19 -> 0.00032877734 | BK19: =B19 -> JACKS DIVE LOCKER | BL19: =C19+H19+M19+R19+W19+AB19+AG19+AL19+AQ19+AV19+BA19+BF19 -> 285299.36 | BM19: =D19+I19+N19+S19+X19+AC19+AH19+AM19+AR19+AW19+BB19+BG19 -> 266770.66 | BN19: =BM19-BL19 -> -18528.697 | BO19: GET ($833.79) Budget vs Pmt in July'26 NNN ($17,694.92) short pmt due to applied PYC in July'26
A20: =Rent!B27 -> I | B20: =Rent!A27 -> QPOT | C20: =VLOOKUP(B20,'Final Data'!A:B,2,0) -> 0 | D20: 0 | E20: =D20-C20 -> 0 | H20: =VLOOKUP(B20,'Final Data'!$A$3:$C$35,3,0) -> 0 | I20: 0 | J20: =I20-H20 -> 0 | M20: =VLOOKUP(B20,'Final Data'!$A$3:$D$31,4,0) -> 0 | N20: 0 | O20: =N20-M20 -> 0 | R20: =VLOOKUP(B20,'Final Data'!$A$3:$E$29,5,0) -> 0 | S20: 0 | T20: =S20-R20 -> 0 | W20: =VLOOKUP(B20,'Final Data'!$A$3:$F$37,6,0) -> 0 | X20: 0 | Y20: =X20-W20 -> 0 | AB20: 0 | AC20: 0 | AD20: =AC20-AB20 -> 0 | AG20: =VLOOKUP(B20,'Final Data'!$A$3:$H$37,8,0) -> 27672.534 | AH20: 0 | AI20: =AH20-AG20 -> -27672.534 | AJ20: BAS ($13,000) No Pmt NNN ($14,672.53) No Pmt | AL20: =VLOOKUP(B20,'Final Data'!$A$3:$I$36,9,0) -> 27672.534 | AM20: 0 | AN20: =AM20-AL20 -> -27672.534 | AO20: BAS ($13,000) No Pmt NNN ($14,672.53) No Pmt | BK20: =B20 -> QPOT | BL20: =C20+H20+M20+R20+W20+AB20+AG20+AL20+AQ20+AV20+BA20+BF20 -> 55345.069 | BM20: =D20+I20+N20+S20+X20+AC20+AH20+AM20+AR20+AW20+BB20+BG20 -> 0 | BN20: =BM20-BL20 -> -55345.069 | BO20: BAS ($26,000) No Pmt in July'26 & Aug'26 NNN ($29,345.07) No Pmt in July'26 & Aug'26
A21: =Rent!B28 -> PC-1&2 | B21: =Rent!A28 -> BOWLS SUPERFOODS & ORALE TACOS | C21: =VLOOKUP(B21,'Final Data'!A:B,2,0) -> 0 | D21: 0 | E21: =D21-C21 -> 0 | H21: =VLOOKUP(B21,'Final Data'!$A$3:$C$35,3,0) -> 0 | I21: 0 | J21: =I21-H21 -> 0 | M21: =VLOOKUP(B21,'Final Data'!$A$3:$D$31,4,0) -> 0 | N21: 0 | O21: =N21-M21 -> 0 | R21: =VLOOKUP(B21,'Final Data'!$A$3:$E$29,5,0) -> 0 | S21: 0 | T21: =S21-R21 -> 0 | W21: =VLOOKUP(B21,'Final Data'!$A$3:$F$37,6,0) -> 0 | X21: 0 | Y21: =X21-W21 -> 0 | AB21: 0 | AC21: 0 | AD21: =AC21-AB21 -> 0 | AG21: =VLOOKUP(B21,'Final Data'!$A$3:$H$37,8,0) -> 0 | AH21: 0 | AI21: =AH21-AG21 -> 0 | AL21: =VLOOKUP(B21,'Final Data'!$A$3:$I$36,9,0) -> 0 | BK21: =B21 -> BOWLS SUPERFOODS & ORALE TACOS | BL21: =C21+H21+M21+R21+W21+AB21+AG21+AL21+AQ21+AV21+BA21+BF21 -> 0 | BM21: =D21+I21+N21+S21+X21+AC21+AH21+AM21+AR21+AW21+BB21+BG21 -> 0 | BN21: =BM21-BL21 -> 0
A22: =Rent!B29 -> PC 3&4 | B22: =Rent!A29 -> KONA GEAR INC. | C22: =VLOOKUP(B22,'Final Data'!A:B,2,0)+141.3 -> 12251.462 | D22: =11275.74-2165.57 -> 9110.17 | E22: =D22-C22 -> -3141.2918 | F22: GET ($141.3) Budget vs Pmt PCR ($3,000) Budget vs Pmt | H22: =VLOOKUP(B22,'Final Data'!$A$3:$C$35,3,0)+141.3 -> 12251.462 | I22: =14213.8-2938.06 -> 11275.74 | J22: =I22-H22 -> -975.72178 | K22: GET ($43.84) Budget vs Pmt PCR ($931.88) Budget vs Pmt | M22: =VLOOKUP(B22,'Final Data'!$A$3:$D$31,4,0)+141.3 -> 12251.462 | N22: =12863.85+5103.63+340.02 -> 18307.5 | O22: =N22-M22 -> 6056.0382 | P22: GET $272.58 Budget vs Pmt PCR $3,518.74 Budget vs Pmt PRO $2,264.72 Budget vs Pmt | R22: =VLOOKUP(B22,'Final Data'!$A$3:$E$29,5,0)+141.3 -> 12255.872 | S22: 16026.55 | T22: =S22-R22 -> 3770.6782 | U22: GET ($120.10) Budget vs Pmt PCR $2,678.47 Budget vs Pmt PRO $1,211.91 Budget vs Pmt | W22: =VLOOKUP(B22,'Final Data'!$A$3:$F$37,6,0)+141.3 -> 12255.872 | X22: 12950.67 | Y22: =X22-W22 -> 694.79822 | Z22: GET ($258.51) Budget vs Pmt PCR $8.05 Budget vs Pmt PRO $944.86 Budget vs Pmt | AB22: =VLOOKUP(B22,'Final Data'!$A$3:$G$37,7,0)+141.3 -> 12255.872 | AC22: 7915.58 | AD22: =AC22-AB22 -> -4340.2918 | AE22: GET ($485.09) Budget vs Pmt PCR $309.97 Budget vs Pmt PRO $975.06 Budget vs Pmt NNN ($5,140.63) SHORTPAID DUE TO PYC CREDIT APPLIED | AG22: =VLOOKUP(B22,'Final Data'!$A$3:$H$37,8,0)+141.3 -> 12255.872 | AH22: 13601.76 | AI22: =AH22-AG22 -> 1345.8882 | AJ22: GET ($229.24) Budget vs Pmt PCR $573.34 Budget vs Pmt PRO $1001.39 Budget vs Pmt | AL22: =VLOOKUP(B22,'Final Data'!$A$3:$I$36,9,0)+141.3 -> 12255.872 | AM22: 12875.45 | AN22: =AM22-AL22 -> 619.57822 | AO22: GET ($261.90)Budget vs Pmt PCR ($57.25) Budget vs Pmt PRO $938.33 Budget vs Pmt | BK22: =B22 -> KONA GEAR INC. | BL22: =C22+H22+M22+R22+W22+AB22+AG22+AL22+AQ22+AV22+BA22+BF22 -> 98033.744 | BM22: =D22+I22+N22+S22+X22+AC22+AH22+AM22+AR22+AW22+BB22+BG22 -> 102063.42 | BN22: =BM22-BL22 -> 4029.6758 | BO22: GET ($1,267.40) Budget vs Pmt in Jan'26 to Aug'26 PCR $3,099.44 Budget vs Pmt in Jan'26 to Aug'26 PRO $7,336.27 Budget vs Pmt in Apr'26 to Aug'26 NNN ($5,140.63) SHORTPAID DUE TO PYC CREDIT APPLIED in June'26
A23: =Rent!B30 -> PC/U1 | B23: =Rent!A30 -> LAVERNES | C23: =VLOOKUP(B23,'Final Data'!A:B,2,0) -> 18449.433 | D23: 18449.43 | E23: =D23-C23 -> -0.0028573606 | H23: =VLOOKUP(B23,'Final Data'!$A$3:$C$35,3,0) -> 18449.433 | I23: 18449.43 | J23: =I23-H23 -> -0.0028573606 | M23: =VLOOKUP(B23,'Final Data'!$A$3:$D$31,4,0) -> 18449.433 | N23: 18449.43 | O23: =N23-M23 -> -0.0028573606 | R23: =VLOOKUP(B23,'Final Data'!$A$3:$E$29,5,0) -> 18449.433 | S23: 18449.43 | T23: =S23-R23 -> -0.0028573606 | W23: =VLOOKUP(B23,'Final Data'!$A$3:$F$37,6,0) -> 18449.433 | X23: 18449.43 | Y23: =X23-W23 -> -0.0028573606 | AB23: =VLOOKUP(B23,'Final Data'!$A$3:$G$37,7,0) -> 18449.433 | AC23: 16726.85 | AD23: =AC23-AB23 -> -1722.5829 | AE23: GET ($77.53) Budget vs Pmt NNN ($1,645.06) SHORTPAID DUE TO PYC CREDIT APPLIED | AG23: =VLOOKUP(B23,'Final Data'!$A$3:$H$37,8,0) -> 18449.433 | AH23: 0 | AI23: =AH23-AG23 -> -18449.433 | AJ23: BAS ($7,408) No Pmt NNN ($11,041) No Pmt | AL23: =VLOOKUP(B23,'Final Data'!$A$3:$I$36,9,0) -> 18449.433 | AM23: 36898.86 | AN23: =AM23-AL23 -> 18449.427 | AO23: BAS $7,408 Past due paid for 07/26 in Aug'26 NNN $11,041 Past due paid for 07/26 in Aug'26 | BK23: =B23 -> LAVERNES | BL23: =C23+H23+M23+R23+W23+AB23+AG23+AL23+AQ23+AV23+BA23+BF23 -> 147595.46 | BM23: =D23+I23+N23+S23+X23+AC23+AH23+AM23+AR23+AW23+BB23+BG23 -> 145872.86 | BN23: =BM23-BL23 -> -1722.6029 | BO23: GET ($77.53) Budget vs Pmt in June'26 NNN ($1,645.06) SHORTPAID DUE TO PYC CREDIT APPLIED in June'26
B24: Parking Income | C24: 30000 | D24: 35803.84 | E24: =D24-C24 -> 5803.84 | F24: PARKLINQ RESERVA PAYOUT | H24: 30000 | I24: 42482.1 | J24: =I24-H24 -> 12482.1 | K24: PARKLINQ RESERVA PAYOUT | M24: 30000 | N24: 36409.48 | O24: =N24-M24 -> 6409.48 | P24: PARKING Budget Vs Pmt | R24: 30000 | S24: 37497.87 | T24: =S24-R24 -> 7497.87 | U24: PARKLINQ RESERVA PAYOUT | W24: ='Final Data'!F26 -> 30000 | X24: 32117.71 | Y24: =X24-W24 -> 2117.71 | Z24: PARKLINQ RESERVA PAYOUT | AB24: ='Final Data'!G26 -> 30000 | AC24: 35429.5 | AD24: =AC24-AB24 -> 5429.5 | AE24: PARKLINQ RESERVA PAYOUT | AG24: ='Final Data'!H26 -> 30000 | AH24: 42007.06 | AI24: =AH24-AG24 -> 12007.06 | AJ24: PARKLINQ RESERVA PAYOUT | AL24: ='Final Data'!I26 -> 30000 | AM24: 44202.54 | AN24: =AM24-AL24 -> 14202.54 | AO24: PARKLINQ RESERVA PAYOUT | BK24: =B24 -> Parking Income | BL24: =C24+H24+M24+R24+W24+AB24+AG24+AL24+AQ24+AV24+BA24+BF24 -> 240000 | BM24: =D24+I24+N24+S24+X24+AC24+AH24+AM24+AR24+AW24+BB24+BG24 -> 305950.1 | BN24: =BM24-BL24 -> 65950.1 | BO24: PARKLINQ RESERVA PAYOUT in Jan'26 to Aug'26 PARKING Budget Vs Pmt in Mar'26
AB25: 0 | AG25: 0 | AI25: =AH25-AG25 -> 0
E26: =D26-C26 -> 0 | BK26: BUDGET VS MRI | BL26: =C26+H26+M26+R26+W26+AB26+AG26+AL26+AQ26+AV26+BA26+BF26 -> 0 | BM26: =D26+I26+N26+S26+X26+AC26+AH26+AM26+AR26+AW26+BB26+BG26 -> 0 | BN26: =BM26-BL26 -> 0
B27: Totals | C27: =SUM(C7:C26) -> 312323.58 | D27: =SUM(D7:D26) -> 291102.04 | E27: =SUM(E7:E26) -> -21221.541 | H27: =SUM(H7:H26) -> 312323.58 | I27: =SUM(I7:I26) -> 299610.01 | J27: =SUM(J7:J26) -> -12713.571 | M27: =SUM(M7:M26) -> 312626.09 | N27: =SUM(N7:N26) -> 352489.67 | O27: =SUM(O7:O26) -> 39863.579 | R27: =SUM(R7:R26) -> 312692.3 | S27: =SUM(S7:S26) -> 332747.86 | T27: =SUM(T7:T26) -> 20055.559 | W27: =SUM(W7:W26) -> 312692.3 | X27: =SUM(X7:X26) -> 320499.89 | Y27: =SUM(Y7:Y26) -> 7807.589 | AB27: =SUM(AB7:AB26) -> 312850.09 | AC27: =SUM(AC7:AC26) -> 274868.38 | AD27: =SUM(AD7:AD26) -> -37981.711 | AG27: =SUM(AG7:AG26) -> 340806.4 | AH27: =SUM(AH7:AH26) -> 212581.81 | AI27: =SUM(AI7:AI26) -> -128224.59 | AL27: =SUM(AL7:AL26) -> 345518.35 | AM27: =SUM(AM7:AM26) -> 397197.44 | AN27: =SUM(AN7:AN26) -> 51679.095 | AQ27: =SUM(AQ7:AQ26) -> 0 | AR27: =SUM(AR7:AR26) -> 0 | AS27: =SUM(AS7:AS26) -> 0 | AV27: =SUM(AV7:AV26) -> 0 | AW27: =SUM(AW7:AW26) -> 0 | AX27: =SUM(AX7:AX26) -> 0 | BA27: =SUM(BA7:BA26) -> 0 | BB27: =SUM(BB7:BB26) -> 0 | BC27: =SUM(BC7:BC26) -> 0 | BF27: =SUM(BF7:BF26) -> 0 | BG27: =SUM(BG7:BG26) -> 0 | BH27: =SUM(BH7:BH26) -> 0 | BL27: =SUM(BL7:BL26) -> 2561832.7 | BM27: =SUM(BM7:BM26) -> 2481097.1 | BN27: =SUM(BN7:BN26) -> -80735.586
C29: 312325 | D29: 291102.04 | E29: -21222.96 | H29: 312325 | I29: 299610.01 | J29: -12714.99 | M29: 312627 | N29: 312627 | O29: 312627 | R29: 312693 | S29: 332747.86 | T29: 20054.86 | W29: 312693 | X29: 320499.89 | Y29: 7806.89 | AB29: 312851 | AC29: 274868.38 | AD29: -37982.62 | AG29: 340807 | AH29: 212581.81 | AI29: -128225.19 | AL29: 345519 | AM29: 397197.44 | AN29: 51678.44 | BL29: 2561840 | BM29: 2481097.1 | BN29: -80742.9
AB30: =AB29-AB27 -> 0.90904947 | AC30: =AC29-AC27 -> 0 | AD30: =AD29-AD27 -> -0.90904947 | AG30: =AG29-AG27 -> 0.60479938 | AH30: =AH29-AH27 -> 0 | AI30: =AI29-AI27 -> -0.60479938 | AL30: =AL29-AL27 -> 0.65479938 | AM30: =AM29-AM27 -> 0 | AN30: =AN29-AN27 -> -0.65479938
C31: =C29-C27 -> 1.4190495 | D31: =D29-D27 -> 0 | E31: =E29-E27 -> -1.4190495 | H31: =H29-H27 -> 1.4190495 | I31: =I29-I27 -> 0 | J31: =J29-J27 -> -1.4190495 | M31: =M29-M27 -> 0.90904947 | N31: =N29-N27 -> -39862.67 | O31: =O29-O27 -> 272763.42 | R31: =R29-R27 -> 0.69904947 | S31: =S29-S27 -> 0 | T31: =T29-T27 -> -0.69904947 | W31: =W29-W27 -> 0.69904947 | X31: =X29-X27 -> 0 | Y31: =Y29-Y27 -> -0.69904947 | BL31: =BL29-BL27 -> 7.3138956 | BM31: =BM29-BM27 -> 0 | BN31: =BN29-BN27 -> -7.3138956

Sheet Final Data
A3: Row Labels | B3: Sum of JAN | C3: Sum of FEB | D3: Sum of MARCH | E3: Sum of APRIL | F3: Sum of MAY | G3: Sum of JUNE | H3: Sum of JULY | I3: Sum of AUGUST | J3: Sum of SEPT | K3: Sum of OCT | L3: Sum of NOV | M3: Sum of DEC
A4: ABC STORE #75 | B4: 51551.472 | C4: 51551.472 | D4: 51551.472 | E4: 51551.472 | F4: 51551.472 | G4: 51551.472 | H4: 51551.472 | I4: 51551.472 | J4: 51551.472 | K4: 51551.472 | L4: 51551.472 | M4: 51551.472
A5: BIG ISLAND RUNNING CO. | B5: 5337.6526 | C5: 5337.6526 | D5: 5337.6526 | E5: 5337.6526 | F5: 5337.6526 | G5: 5337.6526 | H5: 5337.6526 | I5: 5337.6526 | J5: 5337.6526 | K5: 5337.6526 | L5: 5418.7626 | M5: 5418.7626
A6: BOWLS SUPERFOODS & ORALE TACOS | B6: 0 | C6: 0 | D6: 0 | E6: 0 | F6: 0 | G6: 0 | H6: 0 | I6: 0 | J6: 0 | K6: 0 | L6: 0 | M6: 19500
A7: CAFE KONA | B7: 7048.3605 | C7: 7048.3605 | D7: 7048.3605 | E7: 7048.3605 | F7: 7048.3605 | G7: 7048.3605 | H7: 7048.3605 | I7: 7048.3605 | J7: 7048.3605 | K7: 7048.3605 | L7: 7048.3605 | M7: 7048.3605
A8: FOSTERS KITCHEN | B8: 23777.974 | C8: 23777.974 | D8: 23777.974 | E8: 23777.974 | F8: 23777.974 | G8: 23777.974 | H8: 24135.144 | I8: 28635.144 | J8: 28635.144 | K8: 28635.144 | L8: 28635.144 | M8: 28635.144
A9: GECKO GIRLZ SHAVE ICE SHACK | B9: 5131.7697 | C9: 5131.7697 | D9: 5131.7697 | E9: 5131.7697 | F9: 5131.7697 | G9: 5207.6097 | H9: 5134.2097 | I9: 5134.2097 | J9: 5134.2097 | K9: 5134.2097 | L9: 5134.2097 | M9: 5134.2097
A10: GYPSEA GALATO | B10: 5210.2925 | C10: 5210.2925 | D10: 5210.2925 | E10: 5210.2925 | F10: 5210.2925 | G10: 5292.2425 | H10: 5292.2425 | I10: 5292.2425 | J10: 5292.2425 | K10: 5292.2425 | L10: 5292.2425 | M10: 5292.2425
A11: HUMPYS BIG ISLAND ALEHOUSE | B11: 27656.092 | C11: 27656.092 | D11: 27656.092 | E11: 27656.092 | F11: 27656.092 | G11: 27656.092 | H11: 27656.092 | I11: 27656.092 | J11: 57691.574 | K11: 57691.574 | L11: 57691.574 | M11: 57691.574
A12: ISLAND LAVA JAVA | B12: 48921.183 | C12: 48921.183 | D12: 48921.183 | E12: 48921.183 | F12: 48921.183 | G12: 48921.183 | H12: 48921.183 | I12: 48921.183 | J12: 48921.183 | K12: 48921.183 | L12: 48921.183 | M12: 48921.183
A13: JACKS DIVE LOCKER | B13: 35662.42 | C13: 35662.42 | D13: 35662.42 | E13: 35662.42 | F13: 35662.42 | G13: 35662.42 | H13: 35662.42 | I13: 35662.42 | J13: 35662.42 | K13: 35662.42 | L13: 36539.44 | M13: 36539.44
A14: KANAKA KAVA | B14: 3199.3324 | C14: 3199.3324 | D14: 3199.3324 | E14: 3261.1324 | F14: 3261.1324 | G14: 3261.1324 | H14: 3261.1324 | I14: 3261.1324 | J14: 3261.1324 | K14: 3261.1324 | L14: 3261.1324 | M14: 3261.1324
A15: KONA GEAR INC. | B15: 12110.162 | C15: 12110.162 | D15: 12110.162 | E15: 12114.572 | F15: 12114.572 | G15: 12114.572 | H15: 12114.572 | I15: 12114.572 | J15: 12114.572 | K15: 12114.572 | L15: 12114.572 | M15: 12114.572
... A20: TAKA SUSHI | B20: 7276.4982 | C20: 7276.4982 | D20: 7276.4982 | E20: 7276.4982 | F20: 7276.4982 | G20: 7276.4982 | H20: 7276.4982 | I20: 7276.4982 | J20: 7276.4982 | K20: 7276.4982 | L20: 7276.4982 | M20: 7276.4982
A21: (blank)
A22: Grand Total | B22: 278736.18 | C22: 278736.18 | D22: 279038.69 | E22: 279104.9 | F22: 279104.9 | G22: 279262.69 | H22: 307219 | I22: 311719 | J22: 341754.48 | K22: 341754.48 | L22: 342712.61 | M22: 362212.61
B24: 278736.18 | C24: 278736.18 | D24: 279038.69 | E24: 279104.9 | F24: 279104.9 | G24: 279262.69 | H24: 307219 | I24: 311719 | J24: 341754.48 | K24: 341754.48 | L24: 342712.61 | M24: 362212.61
A26: =Summ.!B16 -> Parking Income (PKG) | B26: =Summ.!C16 -> 30000 | C26: =Summ.!D16 -> 30000 | D26: =Summ.!E16 -> 30000 | E26: =Summ.!F16 -> 30000 | F26: =Summ.!G16 -> 30000 | G26: =Summ.!H16 -> 30000 | H26: =Summ.!I16 -> 30000 | ... M26: =Summ.!N16 -> 50000
A27: ='Excise Tax'!A32 -> Percentage Rent Excise Tax | B27: ='Excise Tax'!E32 -> 2067.4545 | C27: ='Excise Tax'!F32 -> 2067.4545 | D27: ='Excise Tax'!G32 -> 2067.4545 | E27: ='Excise Tax'!H32 -> 2067.4545 | F27: ='Excise Tax'!I32 -> 2067.4545 | G27: ='Excise Tax'!J32 -> 2067.4545 | H27: ='Excise Tax'!K32 -> 2067.4545 | I27: ='Excise Tax'!L32 -> 2279.4045 | ... M27: ='Excise Tax'!P32 -> 2420.7045
A28: =Summ.!B24 -> Miscellaneous Income | B28: =Summ.!C24 -> 2500 | C28: =Summ.!D24 -> 2500 | D28: =Summ.!E24 -> 2500 | E28: =Summ.!F24 -> 2500 | F28: =Summ.!G24 -> 2500 | G28: =Summ.!H24 -> 2500 | H28: =Summ.!I24 -> 2500 | ... M28: =Summ.!N24 -> 2500
A29: ='Rent Recovery'!A45 -> Excise Tax | B29: ='Rent Recovery'!E45 -> 19.936001 | C29: ='Rent Recovery'!F45 -> 19.936001 | D29: ='Rent Recovery'!G45 -> 19.936001 | E29: ='Rent Recovery'!H45 -> 19.936001 | F29: ='Rent Recovery'!I45 -> 19.936001 | G29: ='Rent Recovery'!J45 -> 19.936001 | H29: ='Rent Recovery'!K45 -> 19.936001 | I29: ='Rent Recovery'!L45 -> 19.936001 | ... M29: ='Rent Recovery'!P45 -> 19.936001
A31: Final Total | B31: =SUM(B24:B29) -> 313323.57 | C31: =SUM(C24:C29) -> 313323.57 | D31: =SUM(D24:D29) -> 313626.08 | E31: =SUM(E24:E29) -> 313692.29 | F31: =SUM(F24:F29) -> 313692.29 | G31: =SUM(G24:G29) -> 313850.08 | H31: =SUM(H24:H29) -> 341806.39 | I31: =SUM(I24:I29) -> 346518.34 | ... M31: =SUM(M24:M29) -> 417153.25
A33: Summary | B33: =Summ.!C30 -> 313323.57 | C33: =Summ.!D30 -> 313323.57 | D33: =Summ.!E30 -> 313626.08 | E33: =Summ.!F30 -> 313692.29 | F33: =Summ.!G30 -> 313692.29 | G33: =Summ.!H30 -> 313850.08 | H33: =Summ.!I30 -> 341806.39 | I33: =Summ.!J30 -> 346518.34 | ... M33: =Summ.!N30 -> 417153.25
A35: Difference | B35: =B33-B31 -> 0 | C35: =C33-C31 -> 0 | D35: =D33-D31 -> 0 | E35: =E33-E31 -> 0 | F35: =F33-F31 -> 0 | G35: =G33-G31 -> 0 | H35: =H33-H31 -> 0 | I35: =I33-I31 -> 0 | ... M35: =M33-M31 -> 0
I38: =I31-H31 -> 4711.95
I39: -4500

Sheet Pivot
A3: Row Labels | B3: Sum of JAN | C3: Sum of FEB | D3: Sum of MARCH | E3: Sum of APRIL | F3: Sum of MAY | G3: Sum of JUNE | H3: Sum of JULY | I3: Sum of AUGUST | J3: Sum of SEPT | K3: Sum of OCT | L3: Sum of NOV | M3: Sum of DEC
A4: ABC STORE #75 | B4: 51551.472 | C4: 51551.472 | D4: 51551.472 | E4: 51551.472 | F4: 51551.472 | G4: 51551.472 | H4: 51551.472 | I4: 51551.472 | J4: 51551.472 | K4: 51551.472 | L4: 51551.472 | M4: 51551.472
A5: BIG ISLAND RUNNING CO. | B5: 5337.6526 | C5: 5337.6526 | D5: 5337.6526 | E5: 5337.6526 | F5: 5337.6526 | G5: 5337.6526 | H5: 5337.6526 | I5: 5337.6526 | J5: 5337.6526 | K5: 5337.6526 | L5: 5418.7626 | M5: 5418.7626
A6: BOWLS SUPERFOODS & ORALE TACOS | B6: 0 | C6: 0 | D6: 0 | E6: 0 | F6: 0 | G6: 0 | H6: 0 | I6: 0 | J6: 0 | K6: 0 | L6: 0 | M6: 19500
A7: CAFE KONA | B7: 7048.3605 | C7: 7048.3605 | D7: 7048.3605 | E7: 7048.3605 | F7: 7048.3605 | G7: 7048.3605 | H7: 7048.3605 | I7: 7048.3605 | J7: 7048.3605 | K7: 7048.3605 | L7: 7048.3605 | M7: 7048.3605
A8: FOSTERS KITCHEN | B8: 23777.974 | C8: 23777.974 | D8: 23777.974 | E8: 23777.974 | F8: 23777.974 | G8: 23777.974 | H8: 24135.144 | I8: 28635.144 | J8: 28635.144 | K8: 28635.144 | L8: 28635.144 | M8: 28635.144
A9: GECKO GIRLZ SHAVE ICE SHACK | B9: 5131.7697 | C9: 5131.7697 | D9: 5131.7697 | E9: 5131.7697 | F9: 5131.7697 | G9: 5207.6097 | H9: 5134.2097 | I9: 5134.2097 | J9: 5134.2097 | K9: 5134.2097 | L9: 5134.2097 | M9: 5134.2097
A10: GYPSEA GALATO | B10: 5210.2925 | C10: 5210.2925 | D10: 5210.2925 | E10: 5210.2925 | F10: 5210.2925 | G10: 5292.2425 | H10: 5292.2425 | I10: 5292.2425 | J10: 5292.2425 | K10: 5292.2425 | L10: 5292.2425 | M10: 5292.2425
A11: HUMPYS BIG ISLAND ALEHOUSE | B11: 27656.092 | C11: 27656.092 | D11: 27656.092 | E11: 27656.092 | F11: 27656.092 | G11: 27656.092 | H11: 27656.092 | I11: 27656.092 | J11: 57691.574 | K11: 57691.574 | L11: 57691.574 | M11: 57691.574
A12: ISLAND LAVA JAVA | B12: 48921.183 | C12: 48921.183 | D12: 48921.183 | E12: 48921.183 | F12: 48921.183 | G12: 48921.183 | H12: 48921.183 | I12: 48921.183 | J12: 48921.183 | K12: 48921.183 | L12: 48921.183 | M12: 48921.183
A13: JACKS DIVE LOCKER | B13: 35662.42 | C13: 35662.42 | D13: 35662.42 | E13: 35662.42 | F13: 35662.42 | G13: 35662.42 | H13: 35662.42 | I13: 35662.42 | J13: 35662.42 | K13: 35662.42 | L13: 36539.44 | M13: 36539.44
A14: KANAKA KAVA | B14: 3199.3324 | C14: 3199.3324 | D14: 3199.3324 | E14: 3261.1324 | F14: 3261.1324 | G14: 3261.1324 | H14: 3261.1324 | I14: 3261.1324 | J14: 3261.1324 | K14: 3261.1324 | L14: 3261.1324 | M14: 3261.1324
A15: KONA GEAR INC. | B15: 12110.162 | C15: 12110.162 | D15: 12110.162 | E15: 12114.572 | F15: 12114.572 | G15: 12114.572 | H15: 12114.572 | I15: 12114.572 | J15: 12114.572 | K15: 12114.572 | L15: 12114.572 | M15: 12114.572
... A20: TAKA SUSHI | B20: 7276.4982 | C20: 7276.4982 | D20: 7276.4982 | E20: 7276.4982 | F20: 7276.4982 | G20: 7276.4982 | H20: 7276.4982 | I20: 7276.4982 | J20: 7276.4982 | K20: 7276.4982 | L20: 7276.4982 | M20: 7276.4982
A21: (blank)
A22: Grand Total | B22: 278736.18 | C22: 278736.18 | D22: 279038.69 | E22: 279104.9 | F22: 279104.9 | G22: 279262.69 | H22: 307219 | I22: 311719 | J22: 341754.48 | K22: 341754.48 | L22: 342712.61 | M22: 362212.61

Sheet DATA
A1: TENANT | B1: Particular | C1: JAN | D1: FEB | E1: MARCH | F1: APRIL | G1: ` | H1: JUNE | I1: JULY | J1: AUGUST | K1: SEPT | L1: OCT | M1: NOV | N1: DEC
A2: ISLAND LAVA JAVA | B2: ESTIMATED BASE RENT | C2: 15803.54 | D2: 15803.54 | E2: 15803.54 | F2: 15803.54 | G2: 15803.54 | H2: 15803.54 | I2: 15803.54 | J2: 15803.54 | K2: 15803.54 | L2: 15803.54 | M2: 15803.54 | N2: 15803.54
A3: TAKA SUSHI | B3: ESTIMATED BASE RENT | C3: 3383.1 | D3: 3383.1 | E3: 3383.1 | F3: 3383.1 | G3: 3383.1 | H3: 3383.1 | I3: 3383.1 | J3: 3383.1 | K3: 3383.1 | L3: 3383.1 | M3: 3383.1 | N3: 3383.1
A4: KANAKA KAVA | B4: ESTIMATED BASE RENT | C4: 2060 | D4: 2060 | E4: 2060 | F4: 2121.8 | G4: 2121.8 | H4: 2121.8 | I4: 2121.8 | J4: 2121.8 | K4: 2121.8 | L4: 2121.8 | M4: 2121.8 | N4: 2121.8
A5: GECKO GIRLZ SHAVE ICE SHACK | B5: ESTIMATED BASE RENT | C5: 2527.84 | D5: 2527.84 | E5: 2527.84 | F5: 2527.84 | G5: 2527.84 | H5: 2603.68 | I5: 2530.28 | J5: 2530.28 | K5: 2530.28 | L5: 2530.28 | M5: 2530.28 | N5: 2530.28
A6: BIG ISLAND RUNNING CO. | B6: ESTIMATED BASE RENT | C6: 2703.75 | D6: 2703.75 | E6: 2703.75 | F6: 2703.75 | G6: 2703.75 | H6: 2703.75 | I6: 2703.75 | J6: 2703.75 | K6: 2703.75 | L6: 2703.75 | M6: 2784.86 | N6: 2784.86
A7: CAFE KONA | B7: ESTIMATED BASE RENT | C7: 3826.9 | D7: 3826.9 | E7: 3826.9 | F7: 3826.9 | G7: 3826.9 | H7: 3826.9 | I7: 3826.9 | J7: 3826.9 | K7: 3826.9 | L7: 3826.9 | M7: 3826.9 | N7: 3826.9
A8: LUCASIE LTD | B8: ESTIMATED BASE RENT | C8: 7593 | D8: 7593 | E8: 7895.51 | F8: 7895.51 | G8: 7895.51 | H8: 7895.51 | I8: 7895.51 | J8: 7895.51 | K8: 7895.51 | L8: 7895.51 | M8: 7895.51 | N8: 7895.51
A9: FOSTERS KITCHEN | B9: ESTIMATED BASE RENT | C9: 11905.63 | D9: 11905.63 | E9: 11905.63 | F9: 11905.63 | G9: 11905.63 | H9: 11905.63 | I9: 12262.8 | J9: 12262.8 | K9: 12262.8 | L9: 12262.8 | M9: 12262.8 | N9: 12262.8
A10: HUMPYS BIG ISLAND ALEHOUSE | B10: ESTIMATED BASE RENT | C10: 25000 | D10: 25000 | E10: 25000 | F10: 25000 | G10: 25000 | H10: 25000 | I10: 25000 | J10: 25000 | K10: 20666.8 | L10: 20666.8 | M10: 20666.8 | N10: 20666.8
A11: ABC STORE #75 | B11: ESTIMATED BASE RENT | C11: 24000 | D11: 24000 | E11: 24000 | F11: 24000 | G11: 24000 | H11: 24000 | I11: 24000 | J11: 24000 | K11: 24000 | L11: 24000 | M11: 24000 | N11: 24000
A12: GYPSEA GALATO | B12: ESTIMATED BASE RENT | C12: 2731.82 | D12: 2731.82 | E12: 2731.82 | F12: 2731.82 | G12: 2731.82 | H12: 2813.77 | I12: 2813.77 | J12: 2813.77 | K12: 2813.77 | L12: 2813.77 | M12: 2813.77 | N12: 2813.77
A13: OCEANS SPORTS BAR AND GRILL | B13: ESTIMATED BASE RENT | C13: 10049.12 | D13: 10049.12 | E13: 10049.12 | F13: 10049.12 | G13: 10049.12 | H13: 10049.12 | I13: 10049.12 | J13: 10049.12 | K13: 10049.12 | L13: 10049.12 | M13: 10049.12 | N13: 10049.12
... A15: QPOT | B15: ESTIMATED BASE RENT | C15: 0 | D15: 0 | E15: 0 | F15: 0 | G15: 0 | H15: 0 | I15: 13000 | J15: 13000 | K15: 13000 | L15: 13000 | M15: 13000 | N15: 13000
A16: BOWLS SUPERFOODS & ORALE TACOS | B16: ESTIMATED BASE RENT | D16: 0 | E16: 0 | F16: 0 | G16: 0 | H16: 0 | J16: 0 | K16: 0 | L16: 0 | M16: 0 | N16: 19500
A17: KONA GEAR INC. | B17: ESTIMATED BASE RENT | C17: 6440.59 | D17: 6440.59 | E17: 6440.59 | F17: 6445 | G17: 6445 | H17: 6445 | I17: 6445 | J17: 6445 | K17: 6445 | L17: 6445 | M17: 6445 | N17: 6445
A18: LAVERNES | B18: ESTIMATED BASE RENT | C18: 7408 | D18: 7408 | E18: 7408 | F18: 7408 | G18: 7408 | H18: 7408 | I18: 7408 | J18: 7408 | K18: 7408 | L18: 7408 | M18: 7408 | N18: 7408
A19: TAKA SUSHI | B19: Rent Recovery | C19: 423.09 | D19: 423.09 | E19: 423.09 | F19: 423.09 | G19: 423.09 | H19: 423.09 | I19: 423.09 | J19: 423.09 | K19: 423.09 | L19: 423.09 | M19: 423.09 | N19: 423.09
A20: ISLAND LAVA JAVA | B20: COMMON AREA MAINTENANCE | C20: 6087.6782 | D20: 6087.6782 | E20: 6087.6782 | F20: 6087.6782 | G20: 6087.6782 | H20: 6087.6782 | I20: 6087.6782 | J20: 6087.6782 | K20: 6087.6782 | L20: 6087.6782 | M20: 6087.6782 | N20: 6087.6782
A21: TAKA SUSHI | B21: COMMON AREA MAINTENANCE | C21: 1688.1401 | D21: 1688.1401 | E21: 1688.1401 | F21: 1688.1401 | G21: 1688.1401 | H21: 1688.1401 | I21: 1688.1401 | J21: 1688.1401 | K21: 1688.1401 | L21: 1688.1401 | M21: 1688.1401 | N21: 1688.1401
A22: KANAKA KAVA | B22: COMMON AREA MAINTENANCE | C22: 314.365 | D22: 314.365 | E22: 314.365 | F22: 314.365 | G22: 314.365 | H22: 314.365 | I22: 314.365 | J22: 314.365 | K22: 314.365 | L22: 314.365 | M22: 314.365 | N22: 314.365
A23: GECKO GIRLZ SHAVE ICE SHACK | B23: COMMON AREA MAINTENANCE | C23: 814.20535 | D23: 814.20535 | E23: 814.20535 | F23: 814.20535 | G23: 814.20535 | H23: 814.20535 | I23: 814.20535 | J23: 814.20535 | K23: 814.20535 | L23: 814.20535 | M23: 814.20535 | N23: 814.20535
A24: BIG ISLAND RUNNING CO. | B24: COMMON AREA MAINTENANCE | C24: 825.20813 | D24: 825.20813 | E24: 825.20813 | F24: 825.20813 | G24: 825.20813 | H24: 825.20813 | I24: 825.20813 | J24: 825.20813 | K24: 825.20813 | L24: 825.20813 | M24: 825.20813 | N24: 825.20813
A25: CAFE KONA | B25: COMMON AREA MAINTENANCE | C25: 1562.3941 | D25: 1562.3941 | E25: 1562.3941 | F25: 1562.3941 | G25: 1562.3941 | H25: 1562.3941 | I25: 1562.3941 | J25: 1562.3941 | K25: 1562.3941 | L25: 1562.3941 | M25: 1562.3941 | N25: 1562.3941
A26: LUCASIE LTD | B26: COMMON AREA MAINTENANCE | C26: 1639.4135 | D26: 1639.4135 | E26: 1639.4135 | F26: 1639.4135 | G26: 1639.4135 | H26: 1639.4135 | I26: 1639.4135 | J26: 1639.4135 | K26: 1639.4135 | L26: 1639.4135 | M26: 1639.4135 | N26: 1639.4135
A27: FOSTERS KITCHEN | B27: COMMON AREA MAINTENANCE | C27: 5542.255 | D27: 5542.255 | E27: 5542.255 | F27: 5542.255 | G27: 5542.255 | H27: 5542.255 | I27: 5542.255 | J27: 5542.255 | K27: 5542.255 | L27: 5542.255 | M27: 5542.255 | N27: 5542.255
A28: HUMPYS BIG ISLAND ALEHOUSE | B28: COMMON AREA MAINTENANCE | C28: 0 | D28: 0 | E28: 0 | F28: 0 | G28: 0 | H28: 0 | I28: 0 | J28: 0 | K28: 16875.113 | L28: 16875.113 | M28: 16875.113 | N28: 16875.113
... A145: LUCASIE LTD | B145: ESTIMATED PERCENTAGE RENT | C145: 0 | D145: 0 | E145: 0 | F145: 0 | G145: 0 | H145: 0 | I145: 0 | J145: 0 | K145: 0 | L145: 0 | M145: 0 | N145: 0
A146: FOSTERS KITCHEN | B146: ESTIMATED PERCENTAGE RENT | D146: 0 | E146: 0 | F146: 0 | G146: 0 | H146: 0 | J146: 4500 | K146: 4500 | L146: 4500 | M146: 4500 | N146: 4500
A147: HUMPYS BIG ISLAND ALEHOUSE | B147: ESTIMATED PERCENTAGE RENT | C147: 0 | D147: 0 | E147: 0 | F147: 0 | G147: 0 | H147: 0 | I147: 0 | K147: 3000 | L147: 3000 | M147: 3000 | N147: 3000
A148: ABC STORE #75 | B148: ESTIMATED PERCENTAGE RENT | C148: 18000 | D148: 18000 | E148: 18000 | F148: 18000 | G148: 18000 | H148: 18000 | I148: 18000 | J148: 18000 | K148: 18000 | L148: 18000 | M148: 18000 | N148: 18000
A149: GYPSEA GALATO | B149: ESTIMATED PERCENTAGE RENT | C149: 820 | D149: 820 | E149: 820 | F149: 820 | G149: 820 | H149: 820 | I149: 820 | J149: 820 | K149: 820 | L149: 820 | M149: 820 | N149: 820
A150: OCEANS SPORTS BAR AND GRILL | B150: ESTIMATED PERCENTAGE RENT | C150: 0 | D150: 0 | E150: 0 | F150: 0 | G150: 0 | H150: 0 | I150: 0 | J150: 0 | K150: 0 | L150: 0 | M150: 0 | N150: 0
A151: JACKS DIVE LOCKER | B151: ESTIMATED PERCENTAGE RENT | C151: 0 | D151: 0 | E151: 0 | F151: 0 | G151: 0 | H151: 0 | I151: 0 | J151: 0 | K151: 0 | L151: 0 | M151: 0 | N151: 0
A152: QPOT | B152: ESTIMATED PERCENTAGE RENT | E152: 0 | H152: 0 | K152: 0 | N152: 0
A153: BOWLS SUPERFOODS & ORALE TACOS | B153: ESTIMATED PERCENTAGE RENT | C153: 0 | D153: 0 | E153: 0 | F153: 0 | G153: 0 | H153: 0 | I153: 0 | J153: 0 | K153: 0 | L153: 0 | M153: 0 | N153: 0
A154: KONA GEAR INC. | B154: ESTIMATED PERCENTAGE RENT | C154: 3000 | D154: 3000 | E154: 3000 | F154: 3000 | G154: 3000 | H154: 3000 | I154: 3000 | J154: 3000 | K154: 3000 | L154: 3000 | M154: 3000 | N154: 3000
A155: LAVERNES | B155: ESTIMATED PERCENTAGE RENT | C155: 0 | D155: 0 | E155: 0 | F155: 0 | G155: 0 | H155: 0 | I155: 0 | J155: 0 | K155: 0 | L155: 0 | M155: 0 | N155: 0

Sheet Summ.
R1: Date Revised:
A2: ATHENA PROPERTY MANAGEMENT
A3: Coconut Grove - Kona Hawaii
A4: PROJECT NO. 165
A5: 01/01/26- 12/31/26
A6: 2026 OPERATING BUDGET
A8: GL | O8: 2026 TOTALS | P8: 2025 | Q8: 2025 | S8: % +/- from 2025
A9: CODE | B9: DESCRIPTION | C9: JAN | D9: FEB | E9: MARCH | F9: APRIL | G9: MAY | H9: JUNE | I9: JULY | J9: AUGUST | K9: SEPT | L9: OCT | M9: NOV | N9: DEC | P9: Forecast | Q9: Budget | R9: Variance | T9: NOTES
P10: Totals | Q10: Totals
B12: INCOME
A13: 40100 | B13: Base Rent | C13: =Rent!F33 -> 148820.58 | D13: =Rent!G33 -> 148820.58 | E13: =Rent!H33 -> 149123.09 | F13: =Rent!I33 -> 149189.3 | G13: =Rent!J33 -> 149189.3 | H13: =Rent!K33 -> 149347.09 | I13: =Rent!L33 -> 162630.86 | J13: =Rent!M33 -> 162630.86 | ... N13: =Rent!Q33 -> 178755.79 | O13: =SUM(C13:N13) -> 1874358.6 | P13: 1722677 | Q13: 1782656 | R13: =+O13-P13 -> 151681.56 | S13: =(O13-Q13)/Q13 -> 0.051441534
A14: 40106 | B14: Rent Recovery | C14: ='Rent Recovery'!E38 -> 423.09 | D14: ='Rent Recovery'!F38 -> 423.09 | E14: ='Rent Recovery'!G38 -> 423.09 | F14: ='Rent Recovery'!H38 -> 423.09 | G14: ='Rent Recovery'!I38 -> 423.09 | H14: ='Rent Recovery'!J38 -> 423.09 | I14: ='Rent Recovery'!K38 -> 423.09 | J14: ='Rent Recovery'!L38 -> 423.09 | ... N14: ='Rent Recovery'!P38 -> 423.09 | O14: =SUM(C14:N14) -> 5077.08 | P14: 5077 | Q14: 5076 | S14: =(O14-Q14)/Q14 -> 0.00021276596
A15: 40110 | B15: Percentage Rent | C15: ='% Rent'!E36 -> 43895 | D15: ='% Rent'!F36 -> 43895 | E15: ='% Rent'!G36 -> 43895 | F15: ='% Rent'!H36 -> 43895 | G15: ='% Rent'!I36 -> 43895 | H15: ='% Rent'!J36 -> 43895 | I15: ='% Rent'!K36 -> 43895 | J15: ='% Rent'!L36 -> 48395 | ... N15: ='% Rent'!P36 -> 51395 | O15: =SUM(C15:N15) -> 561240 | P15: 609190 | Q15: 673152 | R15: =+O15-P15 -> -47950 | S15: =(O15-Q15)/Q15 -> -0.16625071 | T15: Need percentage
A16: 40129 | B16: Parking Income (PKG) | C16: 30000 | D16: =C16 -> 30000 | E16: =D16 -> 30000 | F16: =E16 -> 30000 | G16: =F16 -> 30000 | H16: =G16 -> 30000 | I16: =H16 -> 30000 | J16: =I16 -> 30000 | K16: 50000 | L16: =K16 -> 50000 | M16: =L16 -> 50000 | N16: =M16 -> 50000 | O16: =SUM(C16:N16) -> 440000 | P16: 344359 | Q16: 549996 | R16: =+O16-P16 -> 95641 | S16: =(O16-Q16)/Q16 -> -0.19999418 | T16: Based off of 2025 actuals
A17: 40143 | B17: CAM Recovery | C17: ='CAM Recovery'!E17 -> 0 | D17: ='CAM Recovery'!F17 -> 0 | E17: ='CAM Recovery'!G17 -> 0 | F17: ='CAM Recovery'!H17 -> 0 | G17: ='CAM Recovery'!I17 -> 0 | H17: ='CAM Recovery'!J17 -> 0 | I17: ='CAM Recovery'!K17 -> 0 | J17: ='CAM Recovery'!L17 -> 0 | ... N17: ='CAM Recovery'!P17 -> 0 | O17: =SUM(C17:N17) -> 0 | S17: =(O17-Q17)/Q17 -> #DIV/0!
A18: 40140 | B18: Common Area Collections (CAMS) | C18: =CAM!E33 -> 42081.776 | D18: =CAM!F33 -> 42081.776 | E18: =CAM!G33 -> 42081.776 | F18: =CAM!H33 -> 42081.776 | G18: =CAM!I33 -> 42081.776 | H18: =CAM!J33 -> 42081.776 | I18: =CAM!K33 -> 48580.862 | J18: =CAM!L33 -> 48580.862 | ... N18: =CAM!P33 -> 65455.975 | O18: =SUM(C18:N18) -> 611476.28 | P18: 768194 | Q18: 980252 | R18: =+O18-P18 -> -156717.72 | S18: =(O18-Q18)/Q18 -> -0.37620502
A19: 40150 | B19: Prior Year CAMS | C19: 0 | D19: 0 | E19: 0 | F19: 0 | G19: 0 | H19: 0 | I19: 0 | J19: 0 | K19: 0 | L19: 0 | M19: 0 | N19: 0 | O19: =SUM(C19:N19) -> 0 | P19: 41626 | R19: =+O19-P19 -> -41626 | S19: =(O19-Q19)/Q19 -> #DIV/0! | T19: as of 09/22 OPX over budget by $160k. Estimate for management fee discount as done in 2021 PYC.
A20: 40170 | B20: Building Recoveries | C20: ='Building Exp.'!E33 -> 4016.0574 | D20: ='Building Exp.'!F33 -> 4016.0574 | E20: ='Building Exp.'!G33 -> 4016.0574 | F20: ='Building Exp.'!H33 -> 4016.0574 | G20: ='Building Exp.'!I33 -> 4016.0574 | H20: ='Building Exp.'!J33 -> 4016.0574 | I20: ='Building Exp.'!K33 -> 4016.0574 | J20: ='Building Exp.'!L33 -> 4016.0574 | ... N20: ='Building Exp.'!P33 -> 6595.6558 | O20: =SUM(C20:N20) -> 58511.083 | P20: 91042 | Q20: 118234 | R20: =+O20-P20 -> -32530.917 | S20: =(O20-Q20)/Q20 -> -0.50512473
A21: 40180 | B21: Food Court | C21: ='Food Court'!E33 -> 7051.1113 | D21: ='Food Court'!F33 -> 7051.1113 | E21: ='Food Court'!G33 -> 7051.1113 | F21: ='Food Court'!H33 -> 7051.1113 | G21: ='Food Court'!I33 -> 7051.1113 | H21: ='Food Court'!J33 -> 7051.1113 | I21: ='Food Court'!K33 -> 9702.6718 | J21: ='Food Court'!L33 -> 9702.6718 | ... N21: ='Food Court'!P33 -> 14082.234 | O21: =SUM(C21:N21) -> 118040.95 | P21: 101411 | Q21: 135136 | R21: =+O21-P21 -> 16629.946 | S21: =(O21-Q21)/Q21 -> -0.12650259
A22: 40230 | B22: Insurance Income | C22: =Ins.!F33 -> 8139.0591 | D22: =Ins.!G33 -> 8139.0591 | E22: =Ins.!H33 -> 8139.0591 | F22: =Ins.!I33 -> 8139.0591 | G22: =Ins.!J33 -> 8139.0591 | H22: =Ins.!K33 -> 8139.0591 | I22: =Ins.!L33 -> 10677.984 | J22: =Ins.!M33 -> 10677.984 | ... N22: =Ins.!Q33 -> 14871.506 | O22: =SUM(C22:N22) -> 129676.35 | P22: 168681 | Q22: 213510 | R22: =+O22-P22 -> -39004.653 | S22: =(O22-Q22)/Q22 -> -0.39264509
A23: 40240 | B23: Property Tax Income | C23: ='RE Tax'!E33 -> 9593.5322 | D23: ='RE Tax'!F33 -> 9593.5322 | E23: ='RE Tax'!G33 -> 9593.5322 | F23: ='RE Tax'!H33 -> 9593.5322 | G23: ='RE Tax'!I33 -> 9593.5322 | H23: ='RE Tax'!J33 -> 9593.5322 | I23: ='RE Tax'!K33 -> 11616.237 | J23: ='RE Tax'!L33 -> 11616.237 | ... N23: ='RE Tax'!P33 -> 14957.122 | O23: =SUM(C23:N23) -> 140622.16 | P23: 152409 | Q23: 185396 | R23: =+O23-P23 -> -11786.844 | S23: =(O23-Q23)/Q23 -> -0.24150383
A24: 40250 | B24: Miscellaneous Income | C24: =Rent!D37 -> 2500 | D24: =Rent!E37 -> 2500 | E24: =Rent!F37 -> 2500 | F24: =Rent!G37 -> 2500 | G24: =Rent!H37 -> 2500 | H24: =Rent!I37 -> 2500 | I24: =Rent!J37 -> 2500 | J24: =Rent!K37 -> 2500 | ... N24: =Rent!O37 -> 2500 | O24: =SUM(C24:N24) -> 30000 | P24: 500 | R24: =+O24-P24 -> 29500 | S24: =(O24-Q24)/Q24 -> #DIV/0! | T24: ABC STORAGE UNIT
A25: 40600 | B25: Late Charge Income | C25: 0 | D25: 0 | E25: 0 | F25: 0 | G25: 0 | H25: 0 | I25: 0 | J25: 0 | K25: 0 | L25: 0 | M25: 0 | N25: 0 | O25: =SUM(C25:N25) -> 0 | R25: =+O25-P25 -> 0 | S25: =(O25-Q25)/Q25 -> #DIV/0!
A26: 40300 | B26: Promo Fee (Marketing Income) | C26: =Marketing!E33 -> 2755.67 | D26: =Marketing!F33 -> 2755.67 | E26: =Marketing!G33 -> 2755.67 | F26: =Marketing!H33 -> 2755.67 | G26: =Marketing!I33 -> 2755.67 | H26: =Marketing!J33 -> 2755.67 | I26: =Marketing!K33 -> 3055.67 | J26: =Marketing!L33 -> 3055.67 | ... N26: =Marketing!P33 -> 3055.67 | O26: =SUM(C26:N26) -> 34868.04 | P26: 48514 | Q26: 36672 | R26: =+O26-P26 -> -13645.96 | S26: =(O26-Q26)/Q26 -> -0.049191754 | T26: Pulls from "Marketing" tab (not marketing budget)
A27: 41100 | B27: Other Income/ Excise Tax | C27: ='Excise Tax'!E35+'Rent Recovery'!E45+'CAM Recovery'!E45 -> 14047.696 | D27: ='Excise Tax'!F35+'Rent Recovery'!F45+'CAM Recovery'!F45 -> 14047.696 | E27: ='Excise Tax'!G35+'Rent Recovery'!G45+'CAM Recovery'!G45 -> 14047.696 | F27: ='Excise Tax'!H35+'Rent Recovery'!H45+'CAM Recovery'!H45 -> 14047.696 | G27: ='Excise Tax'!I35+'Rent Recovery'!I45+'CAM Recovery'!I45 -> 14047.696 | H27: ='Excise Tax'!J35+'Rent Recovery'!J45+'CAM Recovery'!J45 -> 14047.696 | I27: ='Excise Tax'!K35+'Rent Recovery'!K45+'CAM Recovery'!K45 -> 14707.954 | J27: ='Excise Tax'!L35+'Rent Recovery'!L45+'CAM Recovery'!L45 -> 14919.904 | ... N27: ='Excise Tax'!P35+'Rent Recovery'!P45+'CAM Recovery'!P45 -> 15061.204 | O27: =SUM(C$27:N$27) -> 174158.85 | P27: 184054 | Q27: 197272 | R27: =+O27-P27 -> -9895.1529 | S27: =(O27-Q27)/Q27 -> -0.11716388 | T27: 4.71% of all income
O28: =SUM(C$28:N$28) -> 0 | R28: =+O28-P28 -> 0
B30: TOTAL INCOME | C30: =SUM(C13:C28) -> 313323.57 | D30: =SUM(D13:D28) -> 313323.57 | E30: =SUM(E13:E28) -> 313626.08 | F30: =SUM(F13:F28) -> 313692.29 | G30: =SUM(G13:G28) -> 313692.29 | H30: =SUM(H13:H28) -> 313850.08 | I30: =SUM(I13:I28) -> 341806.39 | J30: =SUM(J13:J28) -> 346518.34 | ... R30: =SUM(R13:R28) -> -59704.74 | S30: =(O30-Q30)/Q30 -> -0.14338163
B32: EXPENSES
A33: 50160 | B33: Landscape Consumables | D33: =(6835.6*3%)+6835.6 -> 7040.668 | E33: =(8654.458*3%)+8654 -> 8913.6337 | F33: 0 | G33: =(10000*3%)+10000 -> 10300 | H33: 0 | I33: 0 | J33: 0 | L33: 0 | M33: 0 | O33: =SUM(C33:N33) -> 26254.302 | P33: 12542 | Q33: 26255 | R33: =+O33-P33 -> 13712.302 | S33: =(O33-Q33)/Q33 -> -2.6595315e-05
A34: 50190 | B34: Landscape Sprinkler Repairs | C34: 250 | F34: 250 | I34: 250 | L34: 250 | O34: =SUM(C34:N34) -> 1000 | P34: 2472 | Q34: 8748 | R34: =+O34-P34 -> -1472 | S34: =(O34-Q34)/Q34 -> -0.88568816 | T34: Contingency for irrigation repairs based on PY actuals.
A35: 50170 | B35: Landscape Maintenance | C35: =(7506.4*1.03)+300 -> 8031.592 | D35: =C35 -> 8031.592 | E35: =D35 -> 8031.592 | F35: =E35 -> 8031.592 | G35: =F35 -> 8031.592 | H35: =G35 -> 8031.592 | I35: =H35 -> 8031.592 | J35: =I35 -> 8031.592 | K35: =J35 -> 8031.592 | ... N35: =M35 -> 8031.592 | O35: =SUM(C35:N35) -> 96379.104 | P35: 91884 | Q35: 92784 | R35: =+O35-P35 -> 4495.104 | S35: =(O35-Q35)/Q35 -> 0.038747025 | T35: Service with Hawaii Island Lawns budget assumes 3% increase over PY. + $300/mo Outback | U35: add Outback landscaping
