Workbook
Name _Builtin0: #N/A

Sheet Variance
A1: 731
A2: VARIANCE REPORT
A3: 2026
B4: JANUARY | G4: FEBRUARY | L4: MARCH | Q4: APRIL | V4: MAY | AA4: JUNE | AF4: JULY | AK4: AUGUST | AP4: SEPTEMBER | AU4: OCTOBER | AZ4: NOVEMBER | BE4: DECEMBER | BJ4: YTD
BL5: 2026
B6: Budget | C6: Cash Receipts | D6: Variance | E6: Comments | G6: Budget | H6: Cash Receipts | I6: Variance | J6: Comments | L6: Budget | M6: Cash Receipts | N6: Variance | O6: Comments | Q6: Budget | R6: Cash Receipts | S6: Variance | T6: Comments | V6: Budget | W6: Cash Receipts | X6: Variance | Y6: Comments | AA6: Budget | AB6: Cash Receipts | AC6: Variance | AD6: Comments | AF6: Budget | AG6: Cash Receipts | AH6: Variance | AI6: Comments | AK6: Budget | AL6: Cash Receipts | AM6: Variance | AN6: Comments | AP6: Budget | AQ6: Cash Receipts | AR6: Variance | AS6: Comments | AU6: Budget | AV6: Cash Receipts | AW6: Variance | AX6: Comments | AZ6: Budget | BA6: Cash Receipts | BB6: Variance | BC6: Comments | BE6: Budget | BF6: Cash Receipts | BG6: Variance | BH6: Comments | BK6: Budget | BL6: Cash Receipts | BM6: Variance
A7: VACANT (old Big Lots) | B7: =+Rent!E13+CAM!E13+Ins.!E13+'RE Tax'!E13+'Admin. Fee'!E13+'Sales Tax'!E19 -> 0 | D7: =C7-B7 -> 0 | G7: =+Rent!F13+CAM!F13+Ins.!F13+'RE Tax'!F13+'Admin. Fee'!F13+'Sales Tax'!F19 -> 0 | I7: =H7-G7 -> 0 | N7: =M7-L7 -> 0 | S7: =R7-Q7 -> 0 | X7: =W7-V7 -> 0 | AC7: =AB7-AA7 -> 0 | AH7: =AG7-AF7 -> 0 | AM7: =AL7-AK7 -> 0 | AR7: =AQ7-AP7 -> 0 | AW7: =AV7-AU7 -> 0 | BB7: =BA7-AZ7 -> 0 | BG7: =BF7-BE7 -> 0 | BJ7: =A7 -> VACANT (old Big Lots) | BK7: =B7+G7+L7+Q7+V7+AA7+AF7+AK7+AP7+AU7+AZ7+BE7 -> 0 | BL7: =C7+H7+M7+R7+W7+AB7+AG7+AL7+AQ7+AV7+BA7+BF7 -> 0 | BM7: =BL7-BK7 -> 0
A8: Planet Fitness | B8: =++Rent!E14+CAM!E14+Ins.!E14+'RE Tax'!E14+'Admin. Fee'!E14+'Sales Tax'!E27 -> 28917.105 | C8: 28918.07 | D8: =C8-B8 -> 0.96510989 | G8: =++Rent!F14+CAM!F14+Ins.!F14+'RE Tax'!F14+'Admin. Fee'!F14+'Sales Tax'!F27 -> 28917.105 | H8: 28916.1 | I8: =H8-G8 -> -1.0048901 | L8: =++Rent!G14+CAM!G14+Ins.!G14+'RE Tax'!G14+'Admin. Fee'!G14+'Sales Tax'!G27 -> 28917.105 | M8: 28917.09 | N8: =M8-L8 -> -0.014890114 | Q8: =Rent!H14+CAM!H14+Ins.!H14+'RE Tax'!H14+'Admin. Fee'!H13+'Sales Tax'!H27 -> 28917.105 | R8: 28917.09 | S8: =R8-Q8 -> -0.014890114 | V8: =Rent!I14+CAM!I14+Ins.!I14+'RE Tax'!I14+'Admin. Fee'!I13+'Sales Tax'!I27 -> 28917.105 | W8: 28917.09 | X8: =W8-V8 -> -0.014890114 | AA8: =Rent!J14+CAM!J14+Ins.!J14+'RE Tax'!J14+'Admin. Fee'!J13+'Sales Tax'!J27 -> 28917.105 | AB8: 28917.09 | AC8: =AB8-AA8 -> -0.014890114 | AF8: =Rent!K14+CAM!K14+Ins.!K14+'RE Tax'!K14+'Admin. Fee'!K13+'Sales Tax'!K27 -> 28917.105 | AG8: 28917.09 | AH8: =AG8-AF8 -> -0.014890114 | AM8: =AL8-AK8 -> 0 | AR8: =AQ8-AP8 -> 0 | AW8: =AV8-AU8 -> 0 | BB8: =BA8-AZ8 -> 0 | BG8: =BF8-BE8 -> 0 | BJ8: =A8 -> Planet Fitness | BK8: =B8+G8+L8+Q8+V8+AA8+AF8+AK8+AP8+AU8+AZ8+BE8 -> 202419.73 | BL8: =C8+H8+M8+R8+W8+AB8+AG8+AL8+AQ8+AV8+BA8+BF8 -> 202419.62 | BM8: =BL8-BK8 -> -0.1142308
A9: EV Charging Station | B9: =+Rent!E15+CAM!E15+Ins.!E15+'RE Tax'!E15+'Admin. Fee'!E15+'Sales Tax'!E35 -> 1800.8108 | C9: 1800.81 | D9: =C9-B9 -> -0.0008 | G9: =+Rent!F15+CAM!F15+Ins.!F15+'RE Tax'!F15+'Admin. Fee'!F15+'Sales Tax'!F35 -> 1800.8108 | H9: 1854.83 | I9: =H9-G9 -> 54.0192 | J9: BAS $54.02 Over Pmt | L9: =++Rent!G15+CAM!G15+Ins.!G15+'RE Tax'!G15+'Admin. Fee'!G15+'Sales Tax'!G28+'Sales Tax'!G30 -> 1854.8343 | M9: 1854.83 | N9: =M9-L9 -> -0.0043 | Q9: =Rent!H15+CAM!H15+Ins.!H15+'RE Tax'!H15+'Admin. Fee'!H14+'Sales Tax'!H30 -> 1854.8343 | R9: 1854.83 | S9: =R9-Q9 -> -0.0043 | V9: =Rent!I15+CAM!I15+Ins.!I15+'RE Tax'!I15+'Admin. Fee'!I14+'Sales Tax'!I30 -> 1854.8343 | W9: 1854.83 | X9: =W9-V9 -> -0.0043 | AA9: 1854.83 | AB9: 1854.83 | AC9: =AB9-AA9 -> 0 | AF9: 1854.83 | AG9: 1800.81 | AH9: =AG9-AF9 -> -54.02 | AI9: The BAS($54.02) Credit applied | AM9: =AL9-AK9 -> 0 | AR9: =AQ9-AP9 -> 0 | AW9: =AV9-AU9 -> 0 | BB9: =BA9-AZ9 -> 0 | BG9: =BF9-BE9 -> 0 | BJ9: =A9 -> EV Charging Station | BK9: =B9+G9+L9+Q9+V9+AA9+AF9+AK9+AP9+AU9+AZ9+BE9 -> 12875.784 | BL9: =C9+H9+M9+R9+W9+AB9+AG9+AL9+AQ9+AV9+BA9+BF9 -> 12875.77 | BM9: =BL9-BK9 -> -0.0145
A10: SIRIT HALLOWEEN | B10: 0 | C10: 19524.11 | D10: =C10-B10 -> 19524.11 | E10: Utilities charged and received during short trm rent | G10: 0 | I10: =H10-G10 -> 0 | L10: =++Rent!G16+CAM!G16+Ins.!G16+'RE Tax'!G16+'Admin. Fee'!G16+'Sales Tax'!G29 -> 0 | N10: =M10-L10 -> 0 | Q10: 0 | R10: 1562.18 | S10: =R10-Q10 -> 1562.18 | V10: =Rent!I16+CAM!I16+Ins.!I16+'RE Tax'!I16+'Admin. Fee'!I15+'Sales Tax'!I29 -> 0 | X10: =W10-V10 -> 0 | AA10: =Rent!J16+CAM!J16+Ins.!J16+'RE Tax'!J16+'Admin. Fee'!J15+'Sales Tax'!J29 -> 0 | AB10: 0 | AC10: =AB10-AA10 -> 0 | AH10: =AG10-AF10 -> 0 | AM10: =AL10-AK10 -> 0 | AR10: =AQ10-AP10 -> 0 | AW10: =AV10-AU10 -> 0 | BB10: =BA10-AZ10 -> 0 | BG10: =BF10-BE10 -> 0 | BJ10: =A10 -> SIRIT HALLOWEEN | BK10: =B10+G10+L10+Q10+V10+AA10+AF10+AK10+AP10+AU10+AZ10+BE10 -> 0 | BL10: =C10+H10+M10+R10+W10+AB10+AG10+AL10+AQ10+AV10+BA10+BF10 -> 21086.29 | BM10: =BL10-BK10 -> 21086.29 | BN10: $21,086.29 Utilities charged and received during short trm rent in Jan'26 & Apr'26
A11: UTILITIES INCOME | B11: 0 | C11: 349.71 | D11: =C11-B11 -> 349.71 | E11: Budget vs pmt for regular utilities | G11: 0 | H11: 400 | I11: =H11-G11 -> 400 | J11: Budget vs pmt for regular utilities | L11: =++Rent!G17+CAM!G17+Ins.!G17+'RE Tax'!G17+'Admin. Fee'!G17 -> 0 | M11: 364.58 | N11: =M11-L11 -> 364.58 | O11: Budget vs pmt for regular utilities | R11: 0 | S11: =R11-Q11 -> 0 | V11: 0 | W11: 390.64 | X11: =W11-V11 -> 390.64 | Y11: Budget vs pmt for regular utilities | AA11: =Rent!J17+CAM!J17+Ins.!J17+'RE Tax'!J17+'Admin. Fee'!J16 -> 0 | AB11: 0 | AC11: =AB11-AA11 -> 0 | AH11: =AG11-AF11 -> 0 | AM11: =AL11-AK11 -> 0 | AR11: =AQ11-AP11 -> 0 | AW11: =AV11-AU11 -> 0 | BB11: =BA11-AZ11 -> 0 | BG11: =BF11-BE11 -> 0 | BJ11: =A11 -> UTILITIES INCOME | BK11: =B11+G11+L11+Q11+V11+AA11+AF11+AK11+AP11+AU11+AZ11+BE11 -> 0 | BL11: =C11+H11+M11+R11+W11+AB11+AG11+AL11+AQ11+AV11+BA11+BF11 -> 1504.93 | BM11: =BL11-BK11 -> 1504.93 | BN11: $1,504.93 Budget vs pmt for regular utilities in Jan'26 - May'26
A12: CAM UTILITY REIMBURSEMENT | L12: =++Rent!G18+CAM!G18+Ins.!G18+'RE Tax'!G18+'Admin. Fee'!G18+'Sales Tax'!G31 -> 0 | N12: =M12-L12 -> 0 | X12: =W12-V12 -> 0 | AA12: =Rent!J18+CAM!J18+Ins.!J18+'RE Tax'!J18+'Admin. Fee'!J17+'Sales Tax'!J31 -> 0 | AB12: 290.04 | AC12: =AB12-AA12 -> 290.04 | AD12: Budget vs Pmt for CAM utilities | AG12: 286.67 | AH12: =AG12-AF12 -> 286.67 | AI12: Budget vs Pmt for CAM utilities | AM12: =AL12-AK12 -> 0 | AR12: =AQ12-AP12 -> 0 | AW12: =AV12-AU12 -> 0 | BB12: =BA12-AZ12 -> 0 | BG12: =BF12-BE12 -> 0 | BK12: 0 | BL12: =C12+H12+M12+R12+W12+AB12+AG12+AL12+AQ12+AV12+BA12+BF12 -> 576.71 | BM12: =BL12-BK12 -> 576.71 | BN12: Budget vs Pmt for CAM utilities Jun'26 & Jul'26
L13: =++Rent!G19+CAM!G19+Ins.!G19+'RE Tax'!G19+'Admin. Fee'!G19+'Sales Tax'!G32 -> 0 | N13: =M13-L13 -> 0 | S13: =R13-Q13 -> 0 | X13: =W13-V13 -> 0 | AA13: =Rent!J19+CAM!J19+Ins.!J19+'RE Tax'!J19+'Admin. Fee'!J18+'Sales Tax'!J32 -> 0 | AC13: =AB13-AA13 -> 0 | AH13: =AG13-AF13 -> 0 | AM13: =AL13-AK13 -> 0 | AR13: =AQ13-AP13 -> 0 | AW13: =AV13-AU13 -> 0 | BB13: =BA13-AZ13 -> 0 | BG13: =BF13-BE13 -> 0
S14: =R14-Q12 -> 0 | X14: =W14-V14 -> 0 | AC14: =AB14-AA14 -> 0 | AH14: =AG14-AF14 -> 0 | AM14: =AL14-AK14 -> 0 | AR14: =AQ14-AP14 -> 0 | AW14: =AV14-AU14 -> 0 | BB14: =BA14-AZ14 -> 0 | BG14: =BF14-BE14 -> 0
A15: Totals | B15: =SUM(B7:B14) -> 30717.916 | C15: =SUM(C7:C14) -> 50592.7 | D15: =SUM(D7:D14) -> 19874.784 | G15: =SUM(G7:G14) -> 30717.916 | H15: =SUM(H7:H14) -> 31170.93 | I15: =SUM(I7:I14) -> 453.01431 | L15: =SUM(L7:L14) -> 30771.939 | M15: =SUM(M7:M14) -> 31136.5 | N15: =SUM(N7:N14) -> 364.56081 | Q15: =SUM(Q7:Q14) -> 30771.939 | R15: =SUM(R7:R14) -> 32334.1 | S15: =SUM(S7:S14) -> 1562.1608 | V15: =SUM(V7:V14) -> 30771.939 | W15: =SUM(W7:W14) -> 31162.56 | X15: =SUM(X7:X14) -> 390.62081 | AA15: =SUM(AA7:AA14) -> 30771.935 | AB15: =SUM(AB7:AB14) -> 31061.96 | AC15: =SUM(AC7:AC14) -> 290.02511 | AF15: =SUM(AF7:AF14) -> 30771.935 | AG15: =SUM(AG7:AG14) -> 31004.57 | AH15: =SUM(AH7:AH14) -> 232.63511 | AK15: =SUM(AK7:AK14) -> 0 | AL15: =SUM(AL7:AL14) -> 0 | AM15: =SUM(AM7:AM14) -> 0 | AP15: =SUM(AP7:AP14) -> 0 | AQ15: =SUM(AQ7:AQ14) -> 0 | AR15: =SUM(AR7:AR14) -> 0 | AU15: =SUM(AU7:AU14) -> 0 | AV15: =SUM(AV7:AV14) -> 0 | AW15: =SUM(AW7:AW14) -> 0 | AZ15: =SUM(AZ7:AZ14) -> 0 | BA15: =SUM(BA7:BA14) -> 0 | BB15: =SUM(BB7:BB14) -> 0 | BE15: =SUM(BE7:BE14) -> 0 | BF15: =SUM(BF7:BF14) -> 0 | BG15: =SUM(BG7:BG14) -> 0 | BK15: =SUM(BK7:BK14) -> 215295.52 | BL15: =SUM(BL7:BL14) -> 238463.32 | BM15: =SUM(BM7:BM14) -> 23167.801
G16: 30717 | H16: 31170.93 | I16: 453.93 | L16: 30771 | M16: 31136.5 | N16: 365.5 | Q16: 30771 | R16: 32334.1 | S16: 1563.1 | V16: 30771 | W16: 31162.56 | X16: 391.56 | AA16: 30771 | AB16: 31061.96 | AC16: 290.96 | AF16: 30771 | AG16: 31004.57 | AH16: 233.57 | BK16: 215289 | BL16: 238463.32 | BM16: 23174.32 | BN16: i/s
G17: =G15-G16 -> 0.91569011 | H17: =H15-H16 -> 0 | I17: =I15-I16 -> -0.91569011 | L17: =L15-L16 -> 0.93919011 | M17: =M15-M16 -> 0 | N17: =N15-N16 -> -0.93919011 | Q17: =Q15-Q16 -> 0.93919011 | R17: =R15-R16 -> 0 | S17: =S15-S16 -> -0.93919011 | V17: =V15-V16 -> 0.93919011 | W17: =W15-W16 -> 0 | X17: =X15-X16 -> -0.93919011 | AA17: =AA16-AA15 -> -0.93489011 | AB17: =AB16-AB15 -> 0 | AC17: =AC16-AC15 -> 0.93489011 | AF17: =AF16-AF15 -> -0.93489011 | AG17: =AG16-AG15 -> 0 | AH17: =AH16-AH15 -> 0.93489011 | BK17: =BK15-BK16 -> 6.5187308 | BL17: =BL15-BL16 -> 0 | BM17: =BM15-BM16 -> -6.5187308

Sheet Summary
N1: Date Revised | O1: =TODAY() -> 46234
A2: ATHENA PROPERTY MANAGEMENT
A3: Goodyear Arizona Big Lots
A4: Property Number: 731
A5: 01/01/2026 TO 12/31/2026
A6: 2026 OPERATING BUDGET
A8: CODE | B8: DESCRIPTION | C8: JAN | D8: FEB | E8: MARCH | F8: APRIL | G8: MAY | H8: JUNE | I8: JULY | J8: AUGUST | K8: SEPT | L8: OCT | M8: NOV | N8: DEC | O8: 2026 TOTALS | P8: 2025 FORECAST | Q8: 2025 Budget | R8: Variance | S8: SF
B12: INCOME
A13: 40100 | B13: Base Income | C13: =Rent!E20 -> 22130.44 | D13: =Rent!F20 -> 22130.44 | E13: =Rent!G20 -> 22182.89 | F13: =Rent!H20 -> 22182.89 | G13: =Rent!I20 -> 22182.89 | H13: =Rent!J20 -> 22182.89 | I13: =Rent!K20 -> 22182.89 | J13: =Rent!L20 -> 22182.89 | ... N13: =Rent!P20 -> 22182.89 | O13: =SUM(C13:N13) -> 266089.78 | P13: 311153 | Q13: 265460 | R13: =O13-P13 -> -45063.22
A14: 40140 | B14: Common Area Income | C14: =CAM!E24 -> 4548.4942 | D14: =CAM!F24 -> 4548.4942 | E14: =CAM!G24 -> 4548.4942 | F14: =CAM!H24 -> 4548.4942 | G14: =CAM!I24 -> 4548.4942 | H14: =CAM!J24 -> 4548.4942 | I14: =CAM!K24 -> 4548.4942 | J14: =CAM!L24 -> 4548.4942 | ... N14: =CAM!P24 -> 4548.4942 | O14: =SUM(C14:N14) -> 54581.93 | P14: 57545 | Q14: 55380 | R14: =O14-P14 -> -2963.0699 | T14: Per Planet Fitness, Admin fee added in CAM
A15: 41300 | B15: State and County Rental Tax | C15: ='Sales Tax'!E40 -> 894.69657 | D15: ='Sales Tax'!F40 -> 894.69657 | E15: ='Sales Tax'!G40 -> 896.27007 | F15: ='Sales Tax'!H40 -> 896.27007 | G15: ='Sales Tax'!I40 -> 896.27007 | H15: ='Sales Tax'!J40 -> 896.27007 | I15: ='Sales Tax'!K40 -> 896.27007 | J15: ='Sales Tax'!L40 -> 896.27007 | ... N15: ='Sales Tax'!P40 -> 896.27007 | O15: =SUM(C15:N15) -> 10752.094 | P15: 12024 | Q15: 10737 | R15: =O15-P15 -> -1271.9061 | T15: County 0.5% + State 2.5% - See Sales Tax Tab
A16: 40150 | B16: Prior Year CAMS | C16: 0 | D16: 0 | E16: 0 | F16: 0 | G16: 0 | H16: 0 | I16: 0 | J16: 0 | K16: 0 | L16: 0 | M16: 0 | N16: 0 | O16: =SUM(C16:N16) -> 0 | P16: 0 | Q16: 0 | R16: =O16-P16 -> 0
A17: 40220 | B17: Rent Concessions | C17: 0 | D17: 0 | E17: 0 | F17: 0 | G17: 0 | H17: 0 | I17: 0 | J17: 0 | K17: 0 | L17: 0 | M17: 0 | N17: 0 | O17: =SUM(C17:N17) -> 0 | P17: 0 | Q17: 0 | R17: =O17-P17 -> 0 | T17: Planet Fitness Free Rent 4 months of term
A18: 40230 | B18: Insurance Income | C18: =Ins.!E26 -> 582.25279 | D18: =Ins.!F26 -> 582.25279 | E18: =Ins.!G26 -> 582.25279 | F18: =Ins.!H26 -> 582.25279 | G18: =Ins.!I26 -> 582.25279 | H18: =Ins.!J26 -> 582.25279 | I18: =Ins.!K26 -> 582.25279 | J18: =Ins.!L26 -> 582.25279 | ... N18: =Ins.!P26 -> 582.25279 | O18: =SUM(C18:N18) -> 6987.0335 | P18: 7486 | Q18: 7488 | R18: =O18-P18 -> -498.9665 | T18: Big Lots pays on actuals
A19: 40240 | B19: Property Tax Income | C19: ='RE Tax'!E32 -> 2562.0321 | D19: ='RE Tax'!F32 -> 2562.0321 | E19: ='RE Tax'!G32 -> 2562.0321 | F19: ='RE Tax'!H32 -> 2562.0321 | G19: ='RE Tax'!I32 -> 2562.0321 | H19: ='RE Tax'!J32 -> 2562.0321 | I19: ='RE Tax'!K32 -> 2562.0321 | J19: ='RE Tax'!L32 -> 2562.0321 | ... N19: ='RE Tax'!P32 -> 2562.0321 | O19: =SUM(C19:N19) -> 30744.386 | P19: 29484 | Q19: 29484 | R19: =O19-P19 -> 1260.3858
A20: 40400 | B20: Administrative Fees | C20: ='Admin. Fee'!E27 -> 0 | D20: ='Admin. Fee'!F27 -> 0 | E20: ='Admin. Fee'!G27 -> 0 | F20: ='Admin. Fee'!H27 -> 0 | G20: ='Admin. Fee'!I27 -> 0 | H20: ='Admin. Fee'!J27 -> 0 | I20: ='Admin. Fee'!K27 -> 0 | J20: ='Admin. Fee'!L27 -> 0 | ... N20: ='Admin. Fee'!P27 -> 0 | O20: =SUM(C20:N20) -> 0 | P20: 0 | Q20: 0 | R20: =O20-P20 -> 0
A21: 40250 | B21: Miscellaneous Income | C21: =C81 -> 0 | D21: =D81 -> 0 | E21: =E81 -> 0 | F21: =F81 -> 0 | G21: =G81 -> 0 | H21: =H81 -> 0 | I21: =I81 -> 0 | J21: =J81 -> 0 | ... N21: =N81 -> 0 | O21: =SUM(C21:N21) -> 0 | P21: 0 | Q21: 0 | R21: =O21-P21 -> 0 | T21: Offsets water owner's expense
A22: 40600 | B22: Late Charge Income | C22: 0 | D22: 0 | E22: 0 | F22: 0 | G22: 0 | H22: 0 | I22: 0 | J22: 0 | K22: 0 | L22: 0 | M22: 0 | N22: 0 | O22: =SUM(C22:N22) -> 0 | P22: 0 | Q22: 0 | R22: =O22-P22 -> 0
B25: TOTAL INCOME | C25: =SUM(C13:C24) -> 30717.916 | D25: =SUM(D13:D24) -> 30717.916 | E25: =SUM(E13:E24) -> 30771.939 | F25: =SUM(F13:F24) -> 30771.939 | G25: =SUM(G13:G24) -> 30771.939 | H25: =SUM(H13:H24) -> 30771.939 | I25: =SUM(I13:I24) -> 30771.939 | J25: =SUM(J13:J24) -> 30771.939 | ... Q25: =SUM(Q13:Q24) -> 368549 | R25: =O25-P25 -> -48536.777
B27: COMMON AREA EXPENSES
A28: 50105 | B28: Common Area Association | C28: =102419/12 -> 8534.9167 | D28: =C28 -> 8534.9167 | E28: =D28 -> 8534.9167 | F28: =E28 -> 8534.9167 | G28: =F28 -> 8534.9167 | H28: =G28 -> 8534.9167 | I28: =H28 -> 8534.9167 | J28: =I28 -> 8534.9167 | K28: =J28 -> 8534.9167 | ... N28: =M28 -> 8534.9167 | O28: =SUM(C28:N28) -> 102419 | P28: 118828 | Q28: 92556 | R28: =O28-P28 -> -16409 | S28: 239262 | T28: Assume Association costs increase by 10% over 2025 year (less asphalt & hydrants)…. Pending receipt from Eloni's 2026 Budget
A29: 50160 | B29: Landscape Consumables | C29: 0 | D29: 0 | E29: 0 | F29: 0 | G29: 0 | H29: 0 | I29: 0 | J29: 0 | K29: 0 | L29: 0 | M29: 0 | N29: 0 | O29: =SUM(C29:N29) -> 0 | P29: 0 | Q29: 0 | R29: =O29-P29 -> 0 | S29: =Rent!C20 -> 50394
A30: 50190 | B30: Sprinkler Repairs | C30: 0 | D30: 0 | E30: 0 | F30: 0 | G30: 0 | H30: 0 | I30: 0 | J30: 0 | K30: 0 | L30: 0 | M30: 0 | N30: 0 | O30: =SUM(C30:N30) -> 0 | P30: 0 | Q30: 0 | R30: =O30-P30 -> 0 | S30: =Rent!C20 -> 50394
A31: 50170 | B31: Landscape Maintenance | C31: 0 | D31: 0 | E31: 0 | F31: 0 | G31: 0 | H31: 0 | I31: 0 | J31: 0 | K31: 0 | L31: 0 | M31: 0 | N31: 0 | O31: =SUM(C31:N31) -> 0 | P31: 0 | Q31: 300 | R31: =O31-P31 -> 0 | S31: =Rent!C20 -> 50394
A32: 50510 | B32: Parking Lot Lights Maintenance | C32: 0 | D32: 0 | E32: 150 | F32: 0 | G32: 0 | H32: 0 | I32: 0 | J32: 0 | K32: 150 | L32: 0 | M32: 0 | N32: 0 | O32: =SUM(C32:N32) -> 300 | P32: 0 | Q32: 0 | R32: =O32-P32 -> 300 | S32: =Rent!C20 -> 50394 | T32: Contingency for building exterior lighting repairs
A33: 50520 | B33: Parking Lot Maintenance | C33: 0 | D33: 0 | E33: =D33 -> 0 | F33: 0 | G33: 0 | H33: 0 | I33: 0 | K33: 0 | L33: 0 | M33: 0 | N33: 0 | O33: =SUM(C33:N33) -> 0 | P33: 0 | Q33: 19358 | R33: =O33-P33 -> 0 | S33: =Rent!C20 -> 50394
A34: 50530 | B34: Parking Lot Lights Repairs | C34: 0 | D34: 0 | E34: 0 | F34: 0 | G34: 0 | H34: 0 | I34: 0 | J34: 0 | K34: 0 | L34: 0 | M34: 0 | N34: 0 | O34: =SUM(C34:N34) -> 0 | P34: 0 | Q34: 0 | R34: =O34-P34 -> 0 | S34: =Rent!C20 -> 50394
A35: 51020 | B35: General Maintenance | C35: 0 | D35: 0 | E35: 0 | F35: 0 | G35: 0 | H35: 4000 | I35: 0 | J35: 0 | K35: 0 | L35: 0 | M35: 0 | N35: 2000 | O35: =SUM(C35:N35) -> 6000 | P35: 520 | Q35: 750 | R35: =O35-P35 -> 5480 | S35: =Rent!C20 -> 50394 | T35: Contingency $500 (backflow repairs included in this)
A36: 51040 | B36: Janitorial | C36: 0 | D36: 0 | E36: 0 | F36: 0 | G36: 0 | H36: 0 | I36: 0 | J36: 0 | K36: 0 | L36: 0 | M36: 0 | N36: 0 | O36: =SUM(C36:N36) -> 0 | P36: 0 | Q36: 0 | R36: =O36-P36 -> 0 | S36: =Rent!C20 -> 50394
A37: 52020 | B37: Backflow Maintenance | C37: 0 | D37: 0 | E37: 0 | F37: 0 | G37: 350 | H37: 0 | I37: 0 | J37: 0 | K37: 0 | L37: 0 | M37: 0 | N37: 0 | O37: =SUM(C37:N37) -> 350 | P37: 0 | Q37: 350 | R37: =O37-P37 -> 350 | S37: =Rent!C20 -> 50394
A38: 52030 | B38: Backflow Repairs | C38: 0 | D38: 0 | E38: 0 | F38: 0 | G38: 0 | H38: 0 | I38: 0 | J38: 0 | K38: 0 | L38: 0 | M38: 0 | N38: 0 | O38: =SUM(C38:N38) -> 0 | P38: 0 | Q38: 0 | R38: =O38-P38 -> 0
A39: 51060 | B39: Roof Maintenance | C39: 0 | D39: 0 | E39: 0 | F39: 0 | G39: 0 | H39: 0 | I39: 0 | J39: 0 | K39: 0 | L39: 0 | M39: 0 | N39: 0 | O39: =SUM(C39:N39) -> 0 | P39: 0 | Q39: 0 | R39: =O39-P39 -> 0 | S39: =Rent!C20 -> 50394
A40: 51070 | B40: Roof Repairs | C40: 0 | D40: 0 | E40: 0 | F40: 0 | G40: 0 | H40: 0 | I40: 0 | J40: 0 | K40: 0 | L40: 0 | M40: 0 | N40: 0 | O40: =SUM(C40:N40) -> 0 | P40: 5450 | Q40: 1800 | R40: =O40-P40 -> -5450 | S40: =Rent!C20 -> 50394 | T40: Contingency $450 for roof repairs
A41: 51080 | B41: Onsite Management | C41: 0 | D41: 0 | E41: 0 | F41: 0 | G41: 0 | H41: 0 | I41: 0 | J41: 0 | K41: 0 | L41: 0 | M41: 0 | N41: 0 | O41: =SUM(C41:N41) -> 0 | P41: 0 | Q41: 0 | R41: =O41-P41 -> 0 | S41: =Rent!C20 -> 50394 | T41: Management Fee 3% of Sales - See Other Professional Fees GL Below in Owner's Expense
A42: 51100 | B42: Sidewalk Maintenance | C42: 0 | D42: 0 | E42: 0 | F42: 0 | G42: 0 | H42: 0 | I42: 0 | J42: 0 | K42: 0 | L42: 0 | M42: 0 | N42: 0 | O42: =SUM(C42:N42) -> 0 | P42: 0 | Q42: 0 | R42: =O42-P42 -> 0 | S42: =Rent!C20 -> 50394
A43: 51110 | B43: Monitor Fire Sprinklers | C43: 0 | D43: 0 | E43: 250 | F43: 0 | G43: 0 | H43: 250 | I43: 0 | J43: 0 | K43: 250 | L43: 0 | M43: 0 | N43: 250 | O43: =SUM(C43:N43) -> 1000 | P43: 1053 | Q43: 612 | R43: =O43-P43 -> -53 | S43: =Rent!C20 -> 50394
A44: 51120 | B44: Fire Protection Repairs | C44: 0 | D44: 0 | E44: 0 | F44: 1000 | G44: 0 | H44: 0 | I44: 0 | J44: 0 | K44: 0 | L44: 0 | M44: 0 | N44: 0 | O44: =SUM(C44:N44) -> 1000 | P44: 1692 | Q44: 200 | R44: =O44-P44 -> -692 | S44: =Rent!C20 -> 50394
A45: 56130 | B45: Misc Expense | C45: 0 | D45: 0 | E45: 0 | F45: 0 | G45: 0 | H45: 0 | I45: 0 | J45: 0 | K45: 0 | L45: 0 | M45: 0 | N45: 0 | O45: =SUM(C45:N45) -> 0 | P45: 0 | Q45: 0 | R45: =O45-P45 -> 0 | S45: =Rent!C20 -> 50394
A46: 51150 | B46: Sweeping | C46: 0 | D46: 0 | E46: 0 | F46: 0 | G46: 0 | H46: 0 | I46: 0 | J46: 0 | K46: 0 | L46: 0 | M46: 0 | N46: 0 | O46: =SUM(C46:N46) -> 0 | P46: 0 | Q46: 0 | R46: =O46-P46 -> 0 | S46: =Rent!C20 -> 50394
A47: 51160 | B47: Security | C47: 0 | D47: 0 | E47: 0 | F47: 0 | G47: 0 | H47: 0 | I47: 0 | J47: 0 | K47: 0 | L47: 0 | M47: 0 | N47: 0 | O47: =SUM(C47:N47) -> 0 | P47: 0 | Q47: 0 | R47: =O47-P47 -> 0 | S47: =Rent!C20 -> 50394
...

Sheet Rent
A2: =Summary!$A2 -> ATHENA PROPERTY MANAGEMENT
A3: =Summary!$A3 -> Goodyear Arizona Big Lots
A5: =Summary!$A5 -> 01/01/2026 TO 12/31/2026
A6: =Summary!$A6 -> 2026 OPERATING BUDGET
A9: TENANT | B9: SUITE | C9: SQUARE | D9: RATE | E9: JAN | F9: FEB | G9: MARCH | H9: APRIL | I9: MAY | J9: JUNE | K9: JULY | L9: AUGUST | M9: SEPT | N9: OCT | O9: NOV | P9: DEC | Q9: TOTALS | R9: ANN | S9: MON
B10: # | C10: FOOTAGE
A12: BASE RENT
A13: VACANT (old Big Lots) | B13: 409-117 | C13: =27500+659 -> 28159 | D13: =E13*12/C13 -> 0 | E13: 0 | F13: 0 | G13: 0 | H13: 0 | I13: 0 | J13: 0 | K13: 0 | L13: 0 | M13: 0 | N13: 0 | O13: 0 | P13: 0 | Q13: =SUM(E13:P13) -> 0 | R13: =Q13/C13 -> 0 | S13: =R13/12 -> 0
A14: Planet Fitness | B14: 409-112 | C14: 22235 | D14: =E14*12/C14 -> 10.999998 | E14: 20382.08 | F14: 20382.08 | G14: 20382.08 | H14: 20382.08 | I14: 20382.08 | J14: 20382.08 | K14: 20382.08 | L14: 20382.08 | M14: 20382.08 | N14: 20382.08 | O14: 20382.08 | P14: 20382.08 | Q14: =SUM(E14:P14) -> 244584.96 | R14: =Q14/C14 -> 10.999998 | S14: =R14/12 -> 0.91666652 | T14: Next Base Rent increase is 2028
A15: EV Charging Station | B15: PKG | C15: 0 | D15: 0 | E15: 1748.36 | F15: =E15 -> 1748.36 | G15: 1800.81 | H15: =G15 -> 1800.81 | I15: =H15 -> 1800.81 | J15: =I15 -> 1800.81 | K15: =J15 -> 1800.81 | L15: =K15 -> 1800.81 | M15: =L15 -> 1800.81 | N15: =M15 -> 1800.81 | O15: =N15 -> 1800.81 | P15: =O15 -> 1800.81 | Q15: =SUM(E15:P15) -> 21504.82 | T15: Base Rent Increase effective 2/1/2025 at $1,748.36 - TT confirmed increase as effective 2/1
Q16: =SUM(E16:P16) -> 0
A20: TOTAL BASE RENT | C20: =SUM(C13:C19) -> 50394 | E20: =SUM(E13:E19) -> 22130.44 | F20: =SUM(F13:F19) -> 22130.44 | G20: =SUM(G13:G19) -> 22182.89 | H20: =SUM(H13:H19) -> 22182.89 | I20: =SUM(I13:I19) -> 22182.89 | J20: =SUM(J13:J19) -> 22182.89 | K20: =SUM(K13:K19) -> 22182.89 | L20: =SUM(L13:L19) -> 22182.89 | ... P20: =SUM(P13:P19) -> 22182.89 | Q20: =SUM(E20:P20) -> 266089.78

Sheet CAM
A2: =Summary!$A2 -> ATHENA PROPERTY MANAGEMENT
A3: =Summary!$A3 -> Goodyear Arizona Big Lots
A5: =Summary!$A5 -> 01/01/2026 TO 12/31/2026
A6: =Summary!$A6 -> 2026 OPERATING BUDGET
D8: SQ FT
A9: TENANT | B9: SUITE | C9: SQUARE | D9: % OF | E9: JAN | F9: FEB | G9: MARCH | H9: APRIL | I9: MAY | J9: JUNE | K9: JULY | L9: AUGUST | M9: SEPT | N9: OCT | O9: NOV | P9: DEC | Q9: TOTALS
B10: # | C10: FOOTAGE | D10: TOTAL
A12: COMMON AREA MAINTENANCE
A13: =Rent!A13 -> VACANT (old Big Lots) | B13: =Rent!B13 -> 409-117 | C13: =Rent!C13 -> 28159 | D13: =C13/$C$24 -> 0.55877684 | E13: =IF(Rent!E13=0,0,'TENANT CHARGES'!$E$11) -> 0 | F13: =IF(Rent!F13=0,0,'TENANT CHARGES'!$E$11) -> 0 | G13: =IF(Rent!G13=0,0,'TENANT CHARGES'!$E$11) -> 0 | H13: =IF(Rent!H13=0,0,'TENANT CHARGES'!$E$11) -> 0 | I13: =IF(Rent!I13=0,0,'TENANT CHARGES'!$E$11) -> 0 | J13: =IF(Rent!J13=0,0,'TENANT CHARGES'!$E$11) -> 0 | K13: =IF(Rent!K13=0,0,'TENANT CHARGES'!$E$11) -> 0 | L13: =IF(Rent!L13=0,0,'TENANT CHARGES'!$E$11) -> 0 | ... P13: =IF(Rent!P13=0,0,'TENANT CHARGES'!$E$11) -> 0 | Q13: =SUM(E13:P13) -> 0 | R13: =+P13/C13 -> 0
A14: =Rent!A14 -> Planet Fitness | B14: =Rent!B14 -> 409-112 | C14: =Rent!C14 -> 22235 | D14: =C14/$C$24 -> 0.44122316 | E14: =IF(Rent!E14=0,0,'TENANT CHARGES'!$E$12) -> 4548.4942 | F14: =IF(Rent!F14=0,0,'TENANT CHARGES'!$E$12) -> 4548.4942 | G14: =IF(Rent!G14=0,0,'TENANT CHARGES'!$E$12) -> 4548.4942 | H14: =IF(Rent!H14=0,0,'TENANT CHARGES'!$E$12) -> 4548.4942 | I14: =IF(Rent!I14=0,0,'TENANT CHARGES'!$E$12) -> 4548.4942 | J14: =IF(Rent!J14=0,0,'TENANT CHARGES'!$E$12) -> 4548.4942 | K14: =IF(Rent!K14=0,0,'TENANT CHARGES'!$E$12) -> 4548.4942 | L14: =IF(Rent!L14=0,0,'TENANT CHARGES'!$E$12) -> 4548.4942 | ... P14: =IF(Rent!P14=0,0,'TENANT CHARGES'!$E$12) -> 4548.4942 | Q14: =SUM(E14:P14) -> 54581.93 | R14: =+P14/C14 -> 0.20456461
A15: =Rent!A15 -> EV Charging Station | B15: =Rent!B15 -> PKG | C15: 0 | D15: 0 | E15: 0 | F15: 0 | G15: 0 | H15: 0 | I15: 0 | J15: 0 | K15: 0 | L15: 0 | M15: 0 | N15: 0 | O15: 0 | P15: 0 | Q15: =SUM(E15:P15) -> 0
A24: TOTAL CAM | C24: =SUM(C13:C23) -> 50394 | D24: =SUM(D13:D23) -> 1 | E24: =SUM(E13:E16) -> 4548.4942 | F24: =SUM(F13:F16) -> 4548.4942 | G24: =SUM(G13:G16) -> 4548.4942 | H24: =SUM(H13:H16) -> 4548.4942 | I24: =SUM(I13:I16) -> 4548.4942 | J24: =SUM(J13:J16) -> 4548.4942 | K24: =SUM(K13:K16) -> 4548.4942 | L24: =SUM(L13:L16) -> 4548.4942 | ... Q24: =SUM(Q13:Q16) -> 54581.93
O26: TOTAL CAM | Q26: =Summary!O55 -> 114069
O27: RECAPTURE | Q27: =Q24/Q26 -> 0.47849924

Sheet Ins.
A2: =Summary!$A2 -> ATHENA PROPERTY MANAGEMENT
A3: =Summary!$A3 -> Goodyear Arizona Big Lots
A5: =Summary!$A5 -> 01/01/2026 TO 12/31/2026
A6: =Summary!$A6 -> 2026 OPERATING BUDGET
A8: TENANT | B8: SUITE # | C8: SQUARE FOOTAGE | D8: PRO-RATA SHARE | E8: JAN | F8: FEB | G8: MARCH | H8: APRIL | I8: MAY | J8: JUNE | K8: JULY | L8: AUGUST | M8: SEPT | N8: OCT | O8: NOV | P8: DEC | Q8: TOTALS
A12: INSURANCE
A13: =Rent!A13 -> VACANT (old Big Lots) | B13: =Rent!B13 -> 409-117 | C13: =Rent!C13 -> 28159 | D13: =C13/$C$26 -> 0.55877684 | E13: 0 | F13: 0 | G13: 0 | H13: 0 | I13: 0 | J13: 0 | K13: 0 | L13: 0 | M13: 0 | N13: 0 | O13: 0 | P13: 0 | Q13: =SUM(E13:P13) -> 0 | R13: =Q13/C13 -> 0
A14: =Rent!A14 -> Planet Fitness | B14: =Rent!B14 -> 409-112 | C14: =Rent!C14 -> 22235 | D14: =C14/$C$26 -> 0.44122316 | E14: =IF(Rent!E14=0,0,'TENANT CHARGES'!$F$12) -> 582.25279 | F14: =IF(Rent!F14=0,0,'TENANT CHARGES'!$F$12) -> 582.25279 | G14: =IF(Rent!G14=0,0,'TENANT CHARGES'!$F$12) -> 582.25279 | H14: =IF(Rent!H14=0,0,'TENANT CHARGES'!$F$12) -> 582.25279 | I14: =IF(Rent!I14=0,0,'TENANT CHARGES'!$F$12) -> 582.25279 | J14: =IF(Rent!J14=0,0,'TENANT CHARGES'!$F$12) -> 582.25279 | K14: =IF(Rent!K14=0,0,'TENANT CHARGES'!$F$12) -> 582.25279 | L14: =IF(Rent!L14=0,0,'TENANT CHARGES'!$F$12) -> 582.25279 | ... P14: =IF(Rent!P14=0,0,'TENANT CHARGES'!$F$12) -> 582.25279 | Q14: =SUM(E14:P14) -> 6987.0335 | R14: =Q14/C14 -> 0.31423582
A15: =Rent!A15 -> EV Charging Station | B15: =Rent!B15 -> PKG | C15: =Rent!C15 -> 0 | D15: 0 | E15: 0 | F15: 0 | G15: 0 | H15: 0 | I15: 0 | J15: 0 | K15: 0 | L15: 0 | M15: 0 | N15: 0 | O15: 0 | P15: 0 | Q15: =SUM(E15:P15) -> 0
A26: TOTAL INSURANCE | C26: =SUM(C13:C25) -> 50394 | D26: =SUM(D13:D25) -> 1 | E26: =SUM(E13:E24) -> 582.25279 | F26: =SUM(F13:F24) -> 582.25279 | G26: =SUM(G13:G24) -> 582.25279 | H26: =SUM(H13:H24) -> 582.25279 | I26: =SUM(I13:I24) -> 582.25279 | J26: =SUM(J13:J24) -> 582.25279 | K26: =SUM(K13:K24) -> 582.25279 | L26: =SUM(L13:L24) -> 582.25279 | ... Q26: =SUM(Q13:Q24) -> 6987.0335
O28: TOTAL INS | Q28: =Summary!O64 -> 15835.6
O29: RECAPTURE | Q29: =Q26/Q28 -> 0.44122316

Sheet RE Tax
A2: =Summary!$A2 -> ATHENA PROPERTY MANAGEMENT
A3: =Summary!$A3 -> Goodyear Arizona Big Lots
A5: =Summary!$A5 -> 01/01/2026 TO 12/31/2026
A6: =Summary!$A6 -> 2026 OPERATING BUDGET
A9: TENANT | B9: SUITE | C9: SQUARE | D9: PRO-RATA | E9: JAN | F9: FEB | G9: MARCH | H9: APRIL | I9: MAY | J9: JUNE | K9: JULY | L9: AUGUST | M9: SEPT | N9: OCT | O9: NOV | P9: DEC | Q9: TOTALS | R9: PSF
B10: # | C10: FOOTAGE | D10: SHARE
A12: PROPERTY TAX
A13: =Rent!A13 -> VACANT (old Big Lots) | B13: =Rent!B13 -> 409-117 | C13: =Rent!C13 -> 28159 | D13: 0.5588 | E13: 0 | F13: =+E13 -> 0 | G13: =+F13 -> 0 | H13: 0 | I13: 0 | J13: 0 | K13: =+J13 -> 0 | L13: =+K13 -> 0 | M13: =+L13 -> 0 | N13: =+M13 -> 0 | O13: =H13 -> 0 | P13: 0 | Q13: =SUM(E13:O13) -> 0 | R13: =+Q13/C13 -> 0
A14: =Rent!A14 -> Planet Fitness | B14: =Rent!B14 -> 409-112 | C14: =Rent!C14 -> 22235 | D14: 0.4412 | E14: =IF(Rent!E14=0,0,'TENANT CHARGES'!$H$12) -> 2562.0321 | F14: =IF(Rent!F14=0,0,'TENANT CHARGES'!$H$12) -> 2562.0321 | G14: =IF(Rent!G14=0,0,'TENANT CHARGES'!$H$12) -> 2562.0321 | H14: =IF(Rent!H14=0,0,'TENANT CHARGES'!$H$12) -> 2562.0321 | I14: =IF(Rent!I14=0,0,'TENANT CHARGES'!$H$12) -> 2562.0321 | J14: =IF(Rent!J14=0,0,'TENANT CHARGES'!$H$12) -> 2562.0321 | K14: =IF(Rent!K14=0,0,'TENANT CHARGES'!$H$12) -> 2562.0321 | L14: =IF(Rent!L14=0,0,'TENANT CHARGES'!$H$12) -> 2562.0321 | ... Q14: =IF(Rent!Q14=0,0,'TENANT CHARGES'!$H$12) -> 2562.0321 | R14: =+Q14/C14 -> 0.11522519
A15: =Rent!A15 -> EV Charging Station | B15: =Rent!B15 -> PKG | C15: =Rent!C15 -> 0 | D15: 0 | E15: 0 | F15: 0 | G15: 0 | H15: 0 | I15: 0 | J15: 0 | K15: 0 | L15: 0 | M15: 0 | N15: 0 | O15: 0 | P15: 0 | Q15: =SUM(E15:P15) -> 0
A32: TOTALS | C32: =SUM(C13:C31) -> 50394 | D32: =SUM(D13:D31) -> 1 | E32: =SUM(E13:E31) -> 2562.0321 | F32: =SUM(F13:F31) -> 2562.0321 | G32: =SUM(G13:G31) -> 2562.0321 | H32: =SUM(H13:H31) -> 2562.0321 | I32: =SUM(I13:I31) -> 2562.0321 | J32: =SUM(J13:J31) -> 2562.0321 | ... Q32: =SUM(Q13:Q31) -> 2562.0321
O34: TOTAL TAX | Q34: =Summary!O69 -> 69679.9
O35: RECAPTURE | Q35: =Q32/Q34 -> 0.036768597

Sheet Admin. Fee
A2: =Summary!$A2 -> ATHENA PROPERTY MANAGEMENT
A3: =Summary!$A3 -> Goodyear Arizona Big Lots
A5: =Summary!$A5 -> 01/01/2026 TO 12/31/2026
A6: =Summary!$A6 -> 2026 OPERATING BUDGET
A9: TENANT | B9: SUITE | C9: SQUARE | D9: RATE | E9: JAN | F9: FEB | G9: MARCH | H9: APRIL | I9: MAY | J9: JUNE | K9: JULY | L9: AUGUST | M9: SEPT | N9: OCT | O9: NOV | P9: DEC | Q9: TOTALS
B10: # | C10: FOOTAGE
A12: ADMIN. FEES
A13: =Rent!A13 -> VACANT (old Big Lots) | B13: =Rent!B13 -> 409-117 | C13: =Rent!C13 -> 28159 | D13: 0.5588 | E13: 0 | F13: 0 | G13: 0 | H13: 0 | I13: 0 | J13: 0 | K13: 0 | L13: 0 | M13: 0 | N13: 0 | O13: 0 | P13: 0 | Q13: =SUM(E13:P13) -> 0 | R13: =+Q13/C13 -> 0
A14: =Rent!A14 -> Planet Fitness | B14: =Rent!B14 -> 409-112 | C14: =Rent!C14 -> 22235 | D14: 0.4422 | E14: ='TENANT CHARGES'!$G$12 -> 0 | F14: ='TENANT CHARGES'!$G$12 -> 0 | G14: ='TENANT CHARGES'!$G$12 -> 0 | H14: ='TENANT CHARGES'!$G$12 -> 0 | I14: ='TENANT CHARGES'!$G$12 -> 0 | J14: ='TENANT CHARGES'!$G$12 -> 0 | K14: ='TENANT CHARGES'!$G$12 -> 0 | L14: ='TENANT CHARGES'!$G$12 -> 0 | ... P14: ='TENANT CHARGES'!$G$12 -> 0 | Q14: =SUM(E14:P14) -> 0 | R14: =+Q14/C14 -> 0 | S14: Admin Fee included as CAM per TT lease
A15: =Rent!A15 -> EV Charging Station | B15: =Rent!B15 -> PKG | C15: 0 | D15: 0 | E15: 0 | F15: 0 | G15: 0 | H15: 0 | I15: 0 | J15: 0 | K15: 0 | L15: 0 | M15: 0 | N15: 0 | O15: 0 | P15: 0 | Q15: =SUM(E15:P15) -> 0
A27: TOTALS | C27: =SUM(C13:C26) -> 50394 | D27: =D13+D14 -> 1.001 | E27: =SUM(E13:E26) -> 0 | F27: =SUM(F13:F26) -> 0 | G27: =SUM(G13:G26) -> 0 | H27: =SUM(H13:H26) -> 0 | I27: =SUM(I13:I26) -> 0 | J27: =SUM(J13:J26) -> 0 | K27: =SUM(K13:K26) -> 0 | L27: =SUM(L13:L26) -> 0 | ... Q27: =SUM(Q13:Q26) -> 0
O29: TOTAL MGMT | Q29: =Summary!O41 -> 0
O30: RECAPTURE | Q30: =Q27/Q29 -> #DIV/0!

Sheet Occup.
A2: =+Summary!A2 -> ATHENA PROPERTY MANAGEMENT
A3: =Summary!$A3 -> Goodyear Arizona Big Lots
A5: =Summary!$A5 -> 01/01/2026 TO 12/31/2026
A6: =Summary!$A6 -> 2026 OPERATING BUDGET
A9: TENANT | B9: SUITE | C9: SQUARE | D9: JAN | E9: FEB | F9: MARCH | G9: APRIL | H9: MAY | I9: JUNE | J9: JULY | K9: AUGUST | L9: SEPT | M9: OCT | N9: NOV | O9: DEC | P9: TOTALS
B10: # | C10: FOOTAGE
A12: ESTIMATED MONTHLY SQUARE FOOTAGE OCCUPIED
A13: =Rent!A13 -> VACANT (old Big Lots) | B13: =Rent!B13 -> 409-117 | C13: =Rent!C13 -> 28159 | D13: =IF(Rent!E13=0,0,($C13)) -> 0 | E13: =IF(Rent!F13=0,0,($C13)) -> 0 | F13: =IF(Rent!G13=0,0,($C13)) -> 0 | G13: =IF(Rent!H13=0,0,($C13)) -> 0 | H13: =IF(Rent!I13=0,0,($C13)) -> 0 | I13: =IF(Rent!J13=0,0,($C13)) -> 0 | J13: =IF(Rent!K13=0,0,($C13)) -> 0 | K13: =IF(Rent!L13=0,0,($C13)) -> 0 | ... O13: =IF(Rent!P13=0,0,($C13)) -> 0 | P13: =(SUM(D13:O13))/12 -> 0
A14: =Rent!A14 -> Planet Fitness | B14: =Rent!B14 -> 409-112 | C14: 22235 | D14: =IF(Rent!E14=0,0,($C14)) -> 22235 | E14: =IF(Rent!F14=0,0,($C14)) -> 22235 | F14: =IF(Rent!G14=0,0,($C14)) -> 22235 | G14: =IF(Rent!H14=0,0,($C14)) -> 22235 | H14: =IF(Rent!I14=0,0,($C14)) -> 22235 | I14: =IF(Rent!J14=0,0,($C14)) -> 22235 | J14: =IF(Rent!K14=0,0,($C14)) -> 22235 | K14: =IF(Rent!L14=0,0,($C14)) -> 22235 | ... O14: =IF(Rent!P14=0,0,($C14)) -> 22235 | P14: =(SUM(D14:O14))/12 -> 22235
A15: =Rent!A15 -> EV Charging Station | B15: =Rent!B15 -> PKG | C15: 0 | D15: =IF(Rent!E15=0,0,($C15)) -> 0 | E15: =IF(Rent!F15=0,0,($C15)) -> 0 | F15: =IF(Rent!G15=0,0,($C15)) -> 0 | G15: =IF(Rent!H15=0,0,($C15)) -> 0 | H15: =IF(Rent!I15=0,0,($C15)) -> 0 | I15: =IF(Rent!J15=0,0,($C15)) -> 0 | J15: =IF(Rent!K15=0,0,($C15)) -> 0 | K15: =IF(Rent!L15=0,0,($C15)) -> 0 | ... O15: =IF(Rent!P15=0,0,($C15)) -> 0 | P15: =(SUM(D15:O15))/12 -> 0
A24: TOTALS | C24: =SUM(C13:C22) -> 50394 | D24: =SUM(D13:D22) -> 22235 | E24: =SUM(E13:E22) -> 22235 | F24: =SUM(F13:F22) -> 22235 | G24: =SUM(G13:G22) -> 22235 | H24: =SUM(H13:H22) -> 22235 | I24: =SUM(I13:I22) -> 22235 | J24: =SUM(J13:J22) -> 22235 | ... O24: =SUM(O13:O22) -> 22235 | P24: 0
D25: =D24/$C$24 -> 0.44122316 | E25: =E24/$C$24 -> 0.44122316 | F25: =F24/$C$24 -> 0.44122316 | G25: =G24/$C$24 -> 0.44122316 | H25: =H24/$C$24 -> 0.44122316 | I25: =I24/$C$24 -> 0.44122316 | J25: =J24/$C$24 -> 0.44122316 | K25: =K24/$C$24 -> 0.44122316 | ... O25: =O24/$C$24 -> 0.44122316

Sheet Sales Tax
A2: =Summary!$A2 -> ATHENA PROPERTY MANAGEMENT
A3: =Summary!$A3 -> Goodyear Arizona Big Lots
A5: =Summary!$A5 -> 01/01/2026 TO 12/31/2026
A6: =Summary!$A6 -> 2026 OPERATING BUDGET
Q8: YEARLY TOTAL
A9: TENANT | B9: SUITE | C9: SQUARE | D9: RATE | E9: JAN | F9: FEB | G9: MARCH | H9: APRIL | I9: MAY | J9: JUNE | K9: JULY | L9: AUGUST | M9: SEPT | N9: OCT | O9: NOV | P9: DEC | R9: ANN | S9: MON
B10: # | C10: FOOTAGE
A11: Rental Sales Tax | D11: =0.5%+2.5% -> 0.03
A13: Big Lots | C13: 28159 | Q13: =SUM(E13:P13) -> 0
B14: Rent | D14: 0.03 | E14: =Rent!E13*3% -> 0 | F14: =Rent!F13*3% -> 0 | G14: =Rent!H13*3% -> 0 | H14: =Rent!I13*3% -> 0 | I14: =Rent!J13*3% -> 0 | J14: =Rent!K13*3% -> 0 | K14: =Rent!L13*3% -> 0 | L14: =Rent!M13*3% -> 0 | M14: =Rent!N13*3% -> 0 | N14: =Rent!O13*3% -> 0 | O14: =Rent!P13*3% -> 0 | P14: =Rent!P13*3% -> 0 | Q14: =SUM(E14:P14) -> 0
B15: CAM | D15: 0.03 | E15: =CAM!E13*3% -> 0 | F15: =CAM!F13*3% -> 0 | G15: =CAM!G13*3% -> 0 | H15: =CAM!H13*3% -> 0 | I15: =CAM!I13*3% -> 0 | J15: =CAM!J13*3% -> 0 | K15: =CAM!K13*3% -> 0 | L15: =CAM!L13*3% -> 0 | ... P15: =CAM!P13*3% -> 0 | Q15: =SUM(E15:P15) -> 0
B16: INS | D16: 0.03 | E16: =Ins.!E13 -> 0 | F16: =Ins.!F13 -> 0 | G16: =Ins.!G13 -> 0 | H16: =Ins.!H13 -> 0 | I16: =Ins.!I13 -> 0 | J16: =Ins.!J13 -> 0 | K16: =Ins.!K13 -> 0 | L16: =Ins.!L13 -> 0 | M16: =Ins.!M13 -> 0 | N16: =Ins.!N13*3% -> 0 | O16: =Ins.!O13 -> 0 | P16: =Ins.!P13 -> 0 | Q16: =SUM(E16:P16) -> 0
B17: RET | D17: 0.03 | E17: ='RE Tax'!E13*3% -> 0 | F17: ='RE Tax'!F13*3% -> 0 | G17: ='RE Tax'!G13*3% -> 0 | H17: ='RE Tax'!H13*3% -> 0 | I17: ='RE Tax'!I13*3% -> 0 | J17: ='RE Tax'!J13*3% -> 0 | K17: ='RE Tax'!K13*3% -> 0 | L17: ='RE Tax'!L13*3% -> 0 | ... P17: ='RE Tax'!P13*3% -> 0 | Q17: =SUM(E17:P17) -> 0
B18: ADMIN | D18: 0.03 | E18: ='Admin. Fee'!E13*3% -> 0 | F18: ='Admin. Fee'!F13*3% -> 0 | G18: ='Admin. Fee'!G13*3% -> 0 | H18: ='Admin. Fee'!H13*3% -> 0 | I18: ='Admin. Fee'!I13*3% -> 0 | J18: ='Admin. Fee'!J13*3% -> 0 | K18: ='Admin. Fee'!K13*3% -> 0 | L18: ='Admin. Fee'!L13*3% -> 0 | ... P18: ='Admin. Fee'!P13*3% -> 0
C19: Total | E19: =SUM(E14:E18) -> 0 | F19: =SUM(F14:F18) -> 0 | G19: =SUM(G14:G18) -> 0 | H19: =SUM(H14:H18) -> 0 | I19: =SUM(I14:I18) -> 0 | J19: =SUM(J14:J18) -> 0 | K19: =SUM(K14:K18) -> 0 | L19: =SUM(L14:L18) -> 0 | ... P19: =SUM(P14:P18) -> 0 | Q19: =SUM(E19:P19) -> 0
A21: Planet Fitness | C21: 22235 | Q21: =SUM(E21:P21) -> 0
B22: Rent | D22: 0.03 | E22: =Rent!E14*3% -> 611.4624 | F22: =Rent!F14*3% -> 611.4624 | G22: =Rent!G14*3% -> 611.4624 | H22: =Rent!H14*3% -> 611.4624 | I22: =Rent!I14*3% -> 611.4624 | J22: =Rent!J14*3% -> 611.4624 | K22: =Rent!K14*3% -> 611.4624 | L22: =Rent!L14*3% -> 611.4624 | ... P22: =Rent!P14*3% -> 611.4624 | Q22: =SUM(E22:P22) -> 7337.5488
B23: CAM | D23: 0.03 | E23: =CAM!E14*3% -> 136.45483 | F23: =CAM!F14*3% -> 136.45483 | G23: =CAM!G14*3% -> 136.45483 | H23: =CAM!H14*3% -> 136.45483 | I23: =CAM!I14*3% -> 136.45483 | J23: =CAM!J14*3% -> 136.45483 | K23: =CAM!K14*3% -> 136.45483 | L23: =CAM!L14*3% -> 136.45483 | ... P23: =CAM!P14*3% -> 136.45483 | Q23: =SUM(E23:P23) -> 1637.4579
B24: INS | D24: 0.03 | E24: =Ins.!E14*3% -> 17.467584 | F24: =Ins.!F14*3% -> 17.467584 | G24: =Ins.!G14*3% -> 17.467584 | H24: =Ins.!H14*3% -> 17.467584 | I24: =Ins.!I14*3% -> 17.467584 | J24: =Ins.!J14*3% -> 17.467584 | K24: =Ins.!K14*3% -> 17.467584 | L24: =Ins.!L14*3% -> 17.467584 | ... P24: =Ins.!P14*3% -> 17.467584 | Q24: =SUM(E24:P24) -> 209.611
B25: RET | D25: 0.03 | E25: ='RE Tax'!E14*3% -> 76.860964 | F25: ='RE Tax'!F14*3% -> 76.860964 | G25: ='RE Tax'!G14*3% -> 76.860964 | H25: ='RE Tax'!H14*3% -> 76.860964 | I25: ='RE Tax'!I14*3% -> 76.860964 | J25: ='RE Tax'!J14*3% -> 76.860964 | K25: ='RE Tax'!K14*3% -> 76.860964 | L25: ='RE Tax'!L14*3% -> 76.860964 | ... P25: ='RE Tax'!P14*3% -> 76.860964 | Q25: =SUM(E25:P25) -> 922.33157
B26: ADMIN | D26: 0.03 | E26: ='Admin. Fee'!E14*3% -> 0 | F26: ='Admin. Fee'!F14*3% -> 0 | G26: ='Admin. Fee'!G14*3% -> 0 | H26: ='Admin. Fee'!H14*3% -> 0 | I26: ='Admin. Fee'!I14*3% -> 0 | J26: ='Admin. Fee'!J14*3% -> 0 | K26: ='Admin. Fee'!K14*3% -> 0 | L26: ='Admin. Fee'!L14*3% -> 0 | ... P26: ='Admin. Fee'!P14*3% -> 0 | Q26: =SUM(E26:P26) -> 0
C27: Total | E27: =SUM(E22:E26) -> 842.24577 | F27: =SUM(F22:F26) -> 842.24577 | G27: =SUM(G22:G26) -> 842.24577 | H27: =SUM(H22:H26) -> 842.24577 | I27: =SUM(I22:I26) -> 842.24577 | J27: =SUM(J22:J26) -> 842.24577 | K27: =SUM(K22:K26) -> 842.24577 | L27: =SUM(L22:L26) -> 842.24577 | ... Q27: =SUM(Q22:Q26) -> 10106.949
A29: EV Charging Station | C29: 0 | Q29: =SUM(E29:P29) -> 0
B30: Rent | D30: 0.03 | E30: =Rent!E15*3% -> 52.4508 | F30: =Rent!F15*3% -> 52.4508 | G30: =Rent!G15*3% -> 54.0243 | H30: =Rent!H15*3% -> 54.0243 | I30: =Rent!I15*3% -> 54.0243 | J30: =Rent!J15*3% -> 54.0243 | K30: =Rent!K15*3% -> 54.0243 | L30: =Rent!L15*3% -> 54.0243 | ... P30: =Rent!P15*3% -> 54.0243 | Q30: =SUM(E30:P30) -> 645.1446
B31: CAM | D31: 0.03 | E31: =CAM!E15*3% -> 0 | F31: =CAM!F15*3% -> 0 | G31: =CAM!G15*3% -> 0 | H31: =CAM!H15*3% -> 0 | I31: =CAM!I15*3% -> 0 | J31: =CAM!J15*3% -> 0 | K31: =CAM!K15*3% -> 0 | L31: =CAM!L15*3% -> 0 | ... P31: =CAM!P15*3% -> 0 | Q31: =SUM(E31:P31) -> 0
B32: INS | D32: 0.03 | E32: =Ins.!E15*3% -> 0 | F32: =Ins.!F15*3% -> 0 | G32: =Ins.!G15*3% -> 0 | H32: =Ins.!H15*3% -> 0 | I32: =Ins.!I15*3% -> 0 | J32: =Ins.!J15*3% -> 0 | K32: =Ins.!K15*3% -> 0 | L32: =Ins.!L15*3% -> 0 | ... P32: =Ins.!P15*3% -> 0 | Q32: =SUM(E32:P32) -> 0
B33: RET | D33: 0.03 | E33: ='RE Tax'!E15*3% -> 0 | F33: ='RE Tax'!F15*3% -> 0 | G33: ='RE Tax'!G15*3% -> 0 | H33: ='RE Tax'!H15*3% -> 0 | I33: ='RE Tax'!I15*3% -> 0 | J33: ='RE Tax'!J15*3% -> 0 | K33: ='RE Tax'!K15*3% -> 0 | L33: ='RE Tax'!L15*3% -> 0 | ... P33: ='RE Tax'!P15*3% -> 0 | Q33: =SUM(E33:P33) -> 0
B34: ADMIN | D34: 0.03 | E34: ='Admin. Fee'!E15*3% -> 0 | F34: ='Admin. Fee'!F15*3% -> 0 | G34: ='Admin. Fee'!G15*3% -> 0 | H34: ='Admin. Fee'!H15*3% -> 0 | I34: ='Admin. Fee'!I15*3% -> 0 | J34: ='Admin. Fee'!J15*3% -> 0 | K34: ='Admin. Fee'!K15*3% -> 0 | L34: ='Admin. Fee'!L15*3% -> 0 | ... P34: ='Admin. Fee'!P15*3% -> 0 | Q34: =SUM(E34:P34) -> 0
C35: Total | E35: =SUM(E30:E34) -> 52.4508 | F35: =SUM(F30:F34) -> 52.4508 | G35: =SUM(G30:G34) -> 54.0243 | H35: =SUM(H30:H34) -> 54.0243 | I35: =SUM(I30:I34) -> 54.0243 | J35: =SUM(J30:J34) -> 54.0243 | K35: =SUM(K30:K34) -> 54.0243 | L35: =SUM(L30:L34) -> 54.0243 | ... P35: =SUM(P30:P34) -> 54.0243 | Q35: =SUM(E35:P35) -> 645.1446
A37: Totals | E37: =E19+E27+E35 -> 894.69657 | F37: =F19+F27+F35 -> 894.69657 | G37: =G19+G27+G35 -> 896.27007 | H37: =H19+H27+H35 -> 896.27007 | I37: =I19+I27+I35 -> 896.27007 | J37: =J19+J27+J35 -> 896.27007 | K37: =K19+K27+K35 -> 896.27007 | L37: =L19+L27+L35 -> 896.27007 | ... P37: =P19+P27+P35 -> 896.27007 | Q37: =SUM(E37:P37) -> 10752.094 | T37: MH
A40: Grand Total | E40: =E37 -> 894.69657 | F40: =F37 -> 894.69657 | G40: =G37 -> 896.27007 | H40: =H37 -> 896.27007 | I40: =I37 -> 896.27007 | J40: =J37 -> 896.27007 | K40: =K37 -> 896.27007 | L40: =L37 -> 896.27007 | ... Q40: =Q37 -> 10752.094

Sheet CAM Majors
B3: =Summary!A2 -> ATHENA PROPERTY MANAGEMENT | J3: =Summary!A6 -> 2026 OPERATING BUDGET | U3: =$J$3 -> 2026 OPERATING BUDGET
B4: =Summary!A3 -> Goodyear Arizona Big Lots | J4: =Summary!A3 -> Goodyear Arizona Big Lots | U4: =$J$4 -> Goodyear Arizona Big Lots
B5: =Summary!A5 -> 01/01/2026 TO 12/31/2026 | J5: =Summary!A5 -> 01/01/2026 TO 12/31/2026 | U5: =J5 -> 01/01/2026 TO 12/31/2026
B6: =Summary!A6 -> 2026 OPERATING BUDGET
K8: Tenant: | L8: =Rent!A13 -> VACANT (old Big Lots) | U8: Tenant: | V8: =Rent!A14 -> Planet Fitness
K9: Unit Number: | L9: =Rent!B13 -> 409-117 | U9: Unit Number: | V9: =Rent!B14 -> 409-112 | Y9: CAM CAP 3%
K10: Square Footage: | L10: =Rent!C13 -> 28159 | U10: Square Footage: | V10: =Rent!C14 -> 22235
AE11: CAM CAP Contollable expenses are not allowed to increase by more than 3% over previous calculated on a cumulative basis. Controllable expenses shall mean utilities, trash, security, snow and ice removal, etc.)
B12: G.L. Code | C12: Expense Category | F12: Annual Expense | H12: Demoninator | Q12: Admin | AA12: Admin
J13: G.L. | L13: Center Total | M13: Less | N13: Billable | O13: Tenant | P13: Billable | Q13: Fee | R13: Total | T13: G.L. | V13: Center Total | W13: Less | X13: Billable | Y13: Tenant | Z13: Billable | AA13: Fee | AB13: Total
J14: Code | K14: Description | L14: Total | M14: Exclusions | N14: Amount | O14: Share | P14: Amount | Q14: 0.1 | R14: Due | T14: Code | U14: Description | V14: Total | W14: Exclusions | X14: Amount | Y14: Share | Z14: Amount | AA14: 0.05 | AB14: Due
C16: INSURANCE | K16: =Summary!B57 -> INSURANCE | U16: =$K16 -> INSURANCE
B17: =Summary!A58 -> 50112 | C17: =Summary!B58 -> Insurance - Liability | G17: =Summary!O58 -> 0 | H17: 50394 | J17: =Summary!A58 -> 50112 | K17: =Summary!B58 -> Insurance - Liability | L17: =Summary!O58 -> 0 | M17: =-L17 -> 0 | N17: =L17+M17 -> 0 | O17: =L10/Rent!C20 -> 0.55877684 | P17: =O17*N17 -> 0 | Q17: =P17*$Q$14 -> 0 | R17: =Q17+P17 -> 0 | T17: =$J17 -> 50112 | U17: =$K17 -> Insurance - Liability | V17: =$L17 -> 0 | W17: 0 | X17: =V17+W17 -> 0 | Y17: =V10/Rent!C20 -> 0.44122316 | Z17: =Y17*X17 -> 0 | AA17: =Z17*$AA$14 -> 0 | AB17: =AA17+Z17 -> 0
B18: =Summary!A59 -> 50120 | C18: =Summary!B59 -> Insurance - Property/General | G18: =Summary!O59 -> 15835.6 | H18: 50394 | J18: =Summary!A59 -> 50120 | K18: =Summary!B59 -> Insurance - Property/General | L18: =Summary!O59 -> 15835.6 | M18: =-L18 -> -15835.6 | N18: =L18+M18 -> 0 | O18: =O$17 -> 0.55877684 | P18: =O18*N18 -> 0 | Q18: =P18*$Q$14 -> 0 | R18: =Q18+P18 -> 0 | T18: =$J18 -> 50120 | U18: =$K18 -> Insurance - Property/General | V18: =$L18 -> 15835.6 | X18: =V18+W18 -> 15835.6 | Y18: =Y$17 -> 0.44122316 | Z18: =Y18*X18 -> 6987.0335 | AA18: 0 | AB18: =AA18+Z18 -> 6987.0335 | AE18: 2024 | AF18: 32711.5
B19: =Summary!A60 -> 51043 | C19: =Summary!B60 -> Insurance - Business Owners Policy | G19: =Summary!O60 -> 0 | H19: 50394 | J19: =Summary!A60 -> 51043 | K19: =Summary!B60 -> Insurance - Business Owners Policy | L19: =Summary!O60 -> 0 | M19: =-L19 -> 0 | N19: =L19+M19 -> 0 | O19: =O$17 -> 0.55877684 | P19: =O19*N19 -> 0 | Q19: =P19*$Q$14 -> 0 | R19: =Q19+P19 -> 0 | T19: =$J19 -> 51043 | U19: =$K19 -> Insurance - Business Owners Policy | V19: =$L19 -> 0 | W19: 0 | X19: =V19+W19 -> 0 | Y19: =Y$17 -> 0.44122316 | Z19: =Y19*X19 -> 0 | AA19: =Z19*Y19 -> 0 | AB19: =AA19+Z19 -> 0 | AE19: 2025 | AF19: =AF18*103% -> 33692.845
B20: =Summary!A61 -> 50140 | C20: =Summary!B61 -> Insurance - Flood & Earthquake | G20: =Summary!O61 -> 0 | H20: 50394 | J20: =Summary!A61 -> 50140 | K20: =Summary!B61 -> Insurance - Flood & Earthquake | L20: =Summary!O61 -> 0 | M20: =-L20 -> 0 | N20: =L20+M20 -> 0 | O20: =O$17 -> 0.55877684 | P20: =O20*N20 -> 0 | Q20: =P20*$Q$14 -> 0 | R20: =Q20+P20 -> 0 | T20: =$J20 -> 50140 | U20: =$K20 -> Insurance - Flood & Earthquake | V20: =$L20 -> 0 | W20: =-V20 -> 0 | X20: =V20+W20 -> 0 | Y20: =Y$17 -> 0.44122316 | Z20: =Y20*X20 -> 0 | AA20: =Z20*Y20 -> 0 | AB20: =AA20+Z20 -> 0 | AE20: 2026 | AF20: =AF19*103% -> 34703.63
B21: =Summary!A62 -> 50130 | C21: =Summary!B62 -> Umbrella - Insurance | G21: =Summary!O62 -> 0 | H21: 50394 | J21: =Summary!A62 -> 50130 | K21: =Summary!B62 -> Umbrella - Insurance | L21: =Summary!O62 -> 0 | M21: =-L21 -> 0 | N21: =L21+M21 -> 0 | O21: =O$17 -> 0.55877684 | P21: =O21*N21 -> 0 | Q21: =P21*$Q$14 -> 0 | R21: =Q21+P21 -> 0 | T21: =$J21 -> 50130 | U21: =$K21 -> Umbrella - Insurance | V21: =$L21 -> 0 | X21: =V21+W21 -> 0 | Y21: =Y$17 -> 0.44122316 | Z21: =Y21*X21 -> 0 | AA21: =Z21*Y21 -> 0 | AB21: =AA21+Z21 -> 0
C23: SUBTOTAL INSURANCE | G23: =SUM(G17:G22) -> 15835.6 | K23: SUBTOTAL INSURANCE | L23: =SUM(L17:L21) -> 15835.6 | M23: =SUM(M17:M21) -> -15835.6 | N23: =SUM(N17:N21) -> 0 | P23: =SUM(P17:P21) -> 0 | Q23: =SUM(Q17:Q21) -> 0 | R23: =SUM(R17:R22) -> 0 | S23: =R23/L10 -> 0 | U23: SUBTOTAL INSURANCE | V23: =SUM(V17:V21) -> 15835.6 | W23: =SUM(W17:W21) -> 0 | X23: =SUM(X17:X21) -> 15835.6 | Z23: =SUM(Z17:Z21) -> 6987.0335 | AA23: =SUM(AA17:AA21) -> 0 | AB23: =SUM(AB17:AB21) -> 6987.0335 | AC23: =AB23/V10 -> 0.31423582
C25: COMMON AREA EXPENSES | K25: =Summary!B27 -> COMMON AREA EXPENSES | U25: =$K25 -> COMMON AREA EXPENSES
B26: =Summary!A28 -> 50105 | C26: =Summary!B28 -> Common Area Association | E26: numbers split between GLs | G26: =Summary!O28-G27-G28-G29-G31-G32-G34-G38-G39-G42-G43-G46-G47-G50 -> -17113.3 | H26: 50394 | J26: =Summary!A28 -> 50105 | K26: =C26 -> Common Area Association | L26: =G26 -> -17113.3 | M26: =-L26 -> 17113.3 | N26: =L26+M26 -> 0 | O26: =O19 -> 0.55877684 | P26: =O26*N26 -> 0 | Q26: =P26*$Q$14 -> 0 | R26: =Q26+P26 -> 0 | T26: =$J26 -> 50105 | U26: =C26 -> Common Area Association | V26: =$L26 -> -17113.3 | W26: 0 | Y26: =Y19 -> 0.44122316 | Z26: =Y26*X26 -> 0 | AA26: =Z26*$AA$14 -> 0 | AB26: =AA26+Z26 -> 0
B27: =Summary!A29 -> 50160 | C27: =Summary!B29 -> Landscape Consumables | E27: grass & trees | G27: =1475+737.5 -> 2212.5 | H27: 50394 | J27: =Summary!A29 -> 50160 | K27: =C27 -> Landscape Consumables | L27: =G27 -> 2212.5 | M27: =-L27 -> -2212.5 | N27: =L27+M27 -> 0 | O27: =O20 -> 0.55877684 | P27: =O27*N27 -> 0 | Q27: =P27*$Q$14 -> 0 | R27: =Q27+P27 -> 0 | T27: =$J27 -> 50160 | U27: =C27 -> Landscape Consumables | V27: =$L27 -> 2212.5 | W27: 0 | X27: =V27+W27 -> 2212.5 | Y27: =Y20 -> 0.44122316 | Z27: =Y27*X27 -> 976.20624 | AA27: =Z27*$AA$14 -> 48.810312 | AB27: =AA27+Z27 -> 1025.0166
B28: =Summary!A30 -> 50190 | C28: =Summary!B30 -> Sprinkler Repairs | G28: 2212.5 | H28: 50394 | J28: =Summary!A30 -> 50190 | K28: =C28 -> Sprinkler Repairs | L28: =G28 -> 2212.5 | M28: =-L28 -> -2212.5 | N28: =L28+M28 -> 0 | O28: =O$27 -> 0.55877684 | P28: =O28*N28 -> 0 | Q28: =P28*$Q$14 -> 0 | R28: =Q28+P28 -> 0 | T28: =$J28 -> 50190 | U28: =C28 -> Sprinkler Repairs | V28: =$L28 -> 2212.5 | W28: 0 | X28: =V28+W28 -> 2212.5 | Y28: =Y$27 -> 0.44122316 | Z28: =Y28*X28 -> 976.20624 | AA28: =Z28*$AA$14 -> 48.810312 | AB28: =AA28+Z28 -> 1025.0166
B29: =Summary!A31 -> 50170 | C29: =Summary!B31 -> Landscape Maintenance | G29: 10325 | H29: 50394 | J29: =Summary!A31 -> 50170 | K29: =C29 -> Landscape Maintenance | L29: =G29 -> 10325 | M29: =-L29 -> -10325 | N29: =L29+M29 -> 0 | O29: =O$27 -> 0.55877684 | P29: =O29*N29 -> 0 | Q29: =P29*$Q$14 -> 0 | R29: =Q29+P29 -> 0 | T29: =$J29 -> 50170 | U29: =C29 -> Landscape Maintenance | V29: =$L29 -> 10325 | W29: 0 | X29: =V29+W29 -> 10325 | Y29: =Y$27 -> 0.44122316 | Z29: =Y29*X29 -> 4555.6291 | AA29: =Z29*$AA$14 -> 227.78146 | AB29: =AA29+Z29 -> 4783.4106
B30: =Summary!A32 -> 50510 | C30: =Summary!B32 -> Parking Lot Lights Maintenance | G30: =Summary!O32 -> 300 | H30: 50394 | J30: =Summary!A32 -> 50510 | K30: =C30 -> Parking Lot Lights Maintenance | L30: =G30 -> 300 | M30: =-L30 -> -300 | N30: =L30+M30 -> 0 | O30: =O$27 -> 0.55877684 | P30: =O30*N30 -> 0 | Q30: =P30*$Q$14 -> 0 | R30: =Q30+P30 -> 0 | T30: =$J30 -> 50510 | U30: =C30 -> Parking Lot Lights Maintenance | V30: =$L30 -> 300 | W30: 0 | X30: =V30+W30 -> 300 | Y30: =Y$27 -> 0.44122316 | Z30: =Y30*X30 -> 132.36695 | AA30: =Z30*$AA$14 -> 6.6183474 | AB30: =AA30+Z30 -> 138.9853
B31: =Summary!A33 -> 50520 | C31: =Summary!B33 -> Parking Lot Maintenance | E31: asphalt & hydrants | G31: =15866.98+9130.25 -> 24997.23 | H31: 50394 | J31: =Summary!A33 -> 50520 | K31: =C31 -> Parking Lot Maintenance | L31: =G31 -> 24997.23 | M31: =-L31 -> -24997.23 | N31: =L31+M31 -> 0 | O31: =O$27 -> 0.55877684 | P31: =O31*N31 -> 0 | Q31: =P31*$Q$14 -> 0 | R31: =Q31+P31 -> 0 | T31: =$J31 -> 50520 | U31: =C31 -> Parking Lot Maintenance | V31: =$L31 -> 24997.23 | W31: 0 | X31: =V31+W31 -> 24997.23 | Y31: =Y$27 -> 0.44122316 | Z31: =Y31*X31 -> 11029.357 | AA31: =Z31*$AA$14 -> 551.46784 | AB31: =AA31+Z31 -> 11580.825
B32: =Summary!A34 -> 50530 | C32: =Summary!B34 -> Parking Lot Lights Repairs | G32: 2890.16 | H32: 50394 | J32: =Summary!A34 -> 50530 | K32: =C32 -> Parking Lot Lights Repairs | L32: =G32 -> 2890.16 | M32: =-L32 -> -2890.16 | N32: =L32+M32 -> 0 | O32: =O$27 -> 0.55877684 | P32: =O32*N32 -> 0 | Q32: =P32*$Q$14 -> 0 | R32: =Q32+P32 -> 0 | T32: =$J32 -> 50530 | U32: =C32 -> Parking Lot Lights Repairs | V32: =$L32 -> 2890.16 | W32: 0 | X32: =V32+W32 -> 2890.16 | Y32: =Y$27 -> 0.44122316 | Z32: =Y32*X32 -> 1275.2055 | AA32: =Z32*$AA$14 -> 63.760277 | AB32: =AA32+Z32 -> 1338.9658
B33: =Summary!A35 -> 51020 | C33: =Summary!B35 -> General Maintenance | G33: =Summary!O35 -> 6000 | H33: 50394 | J33: =Summary!A35 -> 51020 | K33: =C33 -> General Maintenance | L33: =G33 -> 6000 | M33: =-L33 -> -6000 | N33: =L33+M33 -> 0 | O33: =O$27 -> 0.55877684 | P33: =O33*N33 -> 0 | Q33: =P33*$Q$14 -> 0 | R33: =Q33+P33 -> 0 | T33: =$J33 -> 51020 | U33: =C33 -> General Maintenance | V33: =$L33 -> 6000 | W33: 0 | X33: =V33+W33 -> 6000 | Y33: =Y$27 -> 0.44122316 | Z33: =Y33*X33 -> 2647.339 | AA33: =Z33*$AA$14 -> 132.36695 | AB33: =AA33+Z33 -> 2779.7059
B34: =Summary!A36 -> 51040 | C34: =Summary!B36 -> Janitorial | G34: 16962.5 | H34: 50394 | J34: =Summary!A36 -> 51040 | K34: =C34 -> Janitorial | L34: =G34 -> 16962.5 | M34: =-L34 -> -16962.5 | N34: =L34+M34 -> 0 | O34: =O$27 -> 0.55877684 | P34: =O34*N34 -> 0 | Q34: =P34*$Q$14 -> 0 | R34: =Q34+P34 -> 0 | T34: =$J34 -> 51040 | U34: =C34 -> Janitorial | V34: =$L34 -> 16962.5 | W34: 0 | X34: =V34+W34 -> 16962.5 | Y34: =Y$27 -> 0.44122316 | Z34: =Y34*X34 -> 7484.2479 | AA34: =Z34*$AA$14 -> 374.21239 | AB34: =AA34+Z34 -> 7858.4603
B35: =Summary!A37 -> 52020 | C35: =Summary!B37 -> Backflow Maintenance | G35: =Summary!O37 -> 350 | H35: =H26 -> 50394 | J35: =Summary!A37 -> 52020 | K35: =C35 -> Backflow Maintenance | L35: =G35 -> 350 | M35: =-L35 -> -350 | N35: =L35+M35 -> 0 | O35: =O$27 -> 0.55877684 | P35: =O35*N35 -> 0 | Q35: =P35*$Q$14 -> 0 | R35: =Q35+P35 -> 0 | T35: =$J35 -> 52020 | U35: =C35 -> Backflow Maintenance | V35: =$L35 -> 350 | W35: 0 | X35: =V35+W35 -> 350 | Y35: =Y$27 -> 0.44122316 | Z35: =Y35*X35 -> 154.42811 | AA35: =Z35*$AA$14 -> 7.7214053 | AB35: =AA35+Z35 -> 162.14951
B36: =Summary!A39 -> 51060 | C36: =Summary!B39 -> Roof Maintenance | G36: =Summary!O39 -> 0 | H36: =H27 -> 50394 | J36: =Summary!A39 -> 51060 | K36: =C36 -> Roof Maintenance | L36: =G36 -> 0 | M36: =-L36 -> 0 | N36: =L36+M36 -> 0 | O36: =O$27 -> 0.55877684 | P36: =O36*N36 -> 0 | Q36: =P36*$Q$14 -> 0 | R36: =Q36+P36 -> 0 | T36: =$J36 -> 51060 | U36: =C36 -> Roof Maintenance | V36: =$L36 -> 0 | W36: 0 | X36: =V36+W36 -> 0 | Y36: =Y$27 -> 0.44122316 | Z36: =Y36*X36 -> 0 | AA36: =Z36*$AA$14 -> 0 | AB36: =AA36+Z36 -> 0
B37: =Summary!A40 -> 51070 | C37: =Summary!B40 -> Roof Repairs | G37: =Summary!O40 -> 0 | H37: =H28 -> 50394 | J37: =Summary!A40 -> 51070 | K37: =C37 -> Roof Repairs | L37: =G37 -> 0 | M37: =-L37 -> 0 | N37: =L37+M37 -> 0 | O37: =+O36 -> 0.55877684 | P37: =O37*N37 -> 0 | Q37: =P37*$Q$14 -> 0 | R37: =Q37+P37 -> 0 | T37: =$J37 -> 51070 | U37: =C37 -> Roof Repairs | V37: =$L37 -> 0 | W37: 0 | X37: =V37+W37 -> 0 | Y37: =+Y36 -> 0.44122316 | Z37: =Y37*X37 -> 0 | AA37: =Z37*$AA$14 -> 0 | AB37: =AA37+Z37 -> 0
B38: =Summary!A41 -> 51080 | C38: =Summary!B41 -> Onsite Management | G38: 9310.86 | H38: =H29 -> 50394 | J38: =Summary!A41 -> 51080 | K38: =C38 -> Onsite Management | L38: =G38 -> 9310.86 | M38: =-L38 -> -9310.86 | N38: =L38+M38 -> 0 | O38: =O$27 -> 0.55877684 | P38: =O38*N38 -> 0 | Q38: =P38*$Q$14 -> 0 | R38: =Q38+P38 -> 0 | T38: =$J38 -> 51080 | U38: =C38 -> Onsite Management | V38: =$L38 -> 9310.86 | W38: =-V38 -> -9310.86 | X38: =V38+W38 -> 0 | Y38: =Y$27 -> 0.44122316 | Z38: =Y38*X38 -> 0 | AA38: =Z38*$AA$14 -> 0 | AB38: =AA38+Z38 -> 0
B39: =Summary!A42 -> 51100 | C39: =Summary!B42 -> Sidewalk Maintenance | G39: 1032.5 | H39: =H30 -> 50394 | J39: =Summary!A42 -> 51100 | K39: =C39 -> Sidewalk Maintenance | L39: =G39 -> 1032.5 | M39: =-L39 -> -1032.5 | N39: =L39+M39 -> 0 | O39: =O$27 -> 0.55877684 | P39: =O39*N39 -> 0 | Q39: =P39*$Q$14 -> 0 | R39: =Q39+P39 -> 0 | T39: =$J39 -> 51100 | U39: =C39 -> Sidewalk Maintenance | V39: =$L39 -> 1032.5 | W39: 0 | X39: =V39+W39 -> 1032.5 | Y39: =Y$27 -> 0.44122316 | Z39: =Y39*X39 -> 455.56291 | AA39: =Z39*$AA$14 -> 22.778146 | AB39: =AA39+Z39 -> 478.34106
B40: =Summary!A43 -> 51110 | C40: =Summary!B43 -> Monitor Fire Sprinklers | G40: =Summary!O43 -> 1000 | H40: =H31 -> 50394 | J40: =Summary!A43 -> 51110 | K40: =C40 -> Monitor Fire Sprinklers | L40: =G40 -> 1000 | M40: =-L40 -> -1000 | N40: =L40+M40 -> 0 | O40: =+O39 -> 0.55877684 | P40: =O40*N40 -> 0 | Q40: =P40*$Q$14 -> 0 | R40: =Q40+P40 -> 0 | T40: =$J40 -> 51110 | U40: =C40 -> Monitor Fire Sprinklers | V40: =$L40 -> 1000 | W40: 0 | X40: =V40+W40 -> 1000 | Y40: =+Y39 -> 0.44122316 | Z40: =Y40*X40 -> 441.22316 | AA40: =Z40*$AA$14 -> 22.061158 | AB40: =AA40+Z40 -> 463.28432
B41: =Summary!A44 -> 51120 | C41: =Summary!B44 -> Fire Protection Repairs | G41: =Summary!O44 -> 1000 | H41: =H32 -> 50394 | J41: =Summary!A44 -> 51120 | K41: =C41 -> Fire Protection Repairs | L41: =G41 -> 1000 | M41: =-L41 -> -1000 | N41: =L41+M41 -> 0 | O41: =O57 -> 0.55877684 | P41: =O41*N41 -> 0 | Q41: =P41*$Q$14 -> 0 | R41: =Q41+P41 -> 0 | T41: =$J41 -> 51120 | U41: =C41 -> Fire Protection Repairs | V41: =$L41 -> 1000 | W41: 0 | X41: =V41+W41 -> 1000 | Y41: =Y57 -> 0.44122316 | Z41: =Y41*X41 -> 441.22316 | AA41: =Z41*$AA$14 -> 22.061158 | AB41: =AA41+Z41 -> 463.28432
B42: =Summary!A45 -> 56130 | C42: =Summary!B45 -> Misc Expense | E42: paint & gen maint | G42: =737.5+3318.75 -> 4056.25 | H42: =H33 -> 50394 | J42: =Summary!A45 -> 56130 | K42: =C42 -> Misc Expense | L42: =G42 -> 4056.25 | M42: =-L42 -> -4056.25 | N42: =L42+M42 -> 0 | O42: =+O41 -> 0.55877684 | P42: =O42*N42 -> 0 | Q42: =P42*$Q$14 -> 0 | R42: =Q42+P42 -> 0 | T42: =$J42 -> 56130 | U42: =C42 -> Misc Expense | V42: =$L42 -> 4056.25 | W42: =-V42 -> -4056.25 | X42: =V42+W42 -> 0 | Y42: =+Y41 -> 0.44122316 | Z42: =Y42*X42 -> 0 | AA42: =Z42*$AA$14 -> 0 | AB42: =AA42+Z42 -> 0
B43: =Summary!A46 -> 51150 | C43: =Summary!B46 -> Sweeping | G43: 3835 | H43: =H34 -> 50394 | J43: =Summary!A46 -> 51150 | K43: =C43 -> Sweeping | L43: =G43 -> 3835 | M43: =-L43 -> -3835 | N43: =L43+M43 -> 0 | O43: =O$27 -> 0.55877684 | P43: =O43*N43 -> 0 | Q43: =P43*$Q$14 -> 0 | R43: =Q43+P43 -> 0 | T43: =$J43 -> 51150 | U43: =C43 -> Sweeping | V43: =$L43 -> 3835 | W43: 0 | X43: =V43+W43 -> 3835 | Y43: =Y$27 -> 0.44122316 | Z43: =Y43*X43 -> 1692.0908 | AA43: =Z43*$AA$14 -> 84.604541 | AB43: =AA43+Z43 -> 1776.6954
B44: =Summary!A47 -> 51160 | C44: =Summary!B47 -> Security | G44: =Summary!O47 -> 0 | H44: =H35 -> 50394 | J44: =Summary!A47 -> 51160 | K44: =C44 -> Security | L44: =G44 -> 0 | M44: =-L44 -> 0 | N44: =L44+M44 -> 0 | O44: =O$27 -> 0.55877684 | P44: =O44*N44 -> 0 | Q44: =P44*$Q$14 -> 0 | R44: =Q44+P44 -> 0 | T44: =$J44 -> 51160 | U44: =C44 -> Security | V44: =$L44 -> 0 | W44: 0 | X44: =V44+W44 -> 0 | Y44: =Y$27 -> 0.44122316 | Z44: =Y44*X44 -> 0 | AA44: =Z44*$AA$14 -> 0 | AB44: =AA44+Z44 -> 0
B45: =Summary!A48 -> 55110 | C45: =Summary!B48 -> Electric/Common Area | G45: =Summary!O48 -> 3000 | H45: =H36 -> 50394 | J45: =Summary!A48 -> 55110 | K45: =C45 -> Electric/Common Area | L45: =G45 -> 3000 | M45: =-L45 -> -3000 | N45: =L45+M45 -> 0 | O45: =O$27 -> 0.55877684 | P45: =O45*N45 -> 0 | Q45: =P45*$Q$14 -> 0 | R45: =Q45+P45 -> 0 | T45: =$J45 -> 55110 | U45: =C45 -> Electric/Common Area | V45: =$L45 -> 3000 | W45: 0 | X45: =V45+W45 -> 3000 | Y45: =Y$27 -> 0.44122316 | Z45: =Y45*X45 -> 1323.6695 | AA45: =Z45*$AA$14 -> 66.183474 | AB45: =AA45+Z45 -> 1389.853
B46: =Summary!A49 -> 55110 | C46: =Summary!B49 -> Electric/Association | G46: 21000 | H46: =H37 -> 50394 | J46: =Summary!A49 -> 55110 | K46: =C46 -> Electric/Association | L46: =G46 -> 21000 | M46: =-L46 -> -21000 | N46: =L46+M46 -> 0 | O46: =O$27 -> 0.55877684 | P46: =O46*N46 -> 0 | Q46: =P46*$Q$14 -> 0 | R46: =Q46+P46 -> 0 | T46: =$J46 -> 55110 | U46: =C46 -> Electric/Association | V46: =$L46 -> 21000 | W46: 0 | X46: =V46+W46 -> 21000 | Y46: =Y$27 -> 0.44122316 | Z46: =Y46*X46 -> 9265.6864 | AA46: =Z46*$AA$14 -> 463.28432 | AB46: =AA46+Z46 -> 9728.9707
...

Sheet TENANT CHARGES
A2: =Summary!A2 -> ATHENA PROPERTY MANAGEMENT
A3: =Summary!A3 -> Goodyear Arizona Big Lots
A4: =Summary!A4 -> Property Number: 731
A5: =Summary!A5 -> 01/01/2026 TO 12/31/2026
A6: =Summary!A6 -> 2026 OPERATING BUDGET
A8: 2025 MONTHLY TENANT CHARGES
B9: TENANT | C9: TENANT SF | D9: BASE RENT (BAS) | E9: COMMON AREA - MONTHLY (CAM) | F9: INSURANCE (INS) | G9: ADMIN FEE | H9: REAL ESTATE TAX (RET) | I9: SALES TAX | J9: TOTAL CHARGES 2026 | K9: TOTAL CAM CHARGES 2026 | L9: TOTAL CAM CHARGES 2025 | M9: DIFFERENCE | N9: % Increase/Decrease | O9: CURRENT CHARGES | P9: VARIANCE | Q9: Percentage Change | R9: Tenant cost per SF | V9: COMMENTS
A10: Lease ID | T10: without trash
A11: 008859 | B11: =Rent!A13 -> VACANT (old Big Lots) | C11: =Rent!C13 -> 28159 | D11: =Rent!E13 -> 0 | E11: 0 | F11: 0 | G11: 0 | H11: 0 | I11: 0 | J11: =SUM(D11:I11) -> 0 | K11: =E11+I11 -> 0 | M11: =+K11-L11 -> 0 | N11: =SUM((1)-(L11/K11)) -> #DIV/0! | O11: =4020.58+494.79+93.1+933.64+7615.76 -> 13157.87 | P11: =+K11-O11 -> -13157.87 | Q11: =P11/K11 -> #DIV/0! | R11: =(K11*12)/C11 -> 0 | S11: =SUM(1)-(O11/K11) -> #DIV/0! | T11: 472.33 | U11: 0.0923
A12: 011232 | B12: =Rent!A14 -> Planet Fitness | C12: =Rent!C14 -> 22235 | D12: =Rent!E14 -> 20382.08 | E12: =('CAM Majors'!AB66-'CAM Majors'!AB59-'CAM Majors'!AB23)/12 -> 4548.4942 | F12: ='CAM Majors'!AB23/12 -> 582.25279 | G12: 0 | H12: ='CAM Majors'!AB59/12 -> 2562.0321 | I12: ='Sales Tax'!E27 -> 842.24577 | J12: =SUM(D12:H12) -> 28074.859 | K12: =E12+F12+G12+H12 -> 7692.7791 | L12: 7695.51 | M12: =+K12-L12 -> -2.7308834 | N12: =SUM((1)-(L12/K12)) -> -0.00035499308 | O12: =11816.48+1604.24+1198.26+166.15+24692.1 -> 39477.23 | P12: =+K12-O12 -> -31784.451 | Q12: =P12/K12 -> -4.1317254 | R12: =(K12*12)/C12 -> 4.1517135 | S12: =SUM(1)-(O12/K12) -> -4.1317254 | T12: 633.3 | U12: 0.0923
A13: 011169 | B13: =Rent!A15 -> EV Charging Station | C13: PKG | D13: =Rent!E15 -> 1748.36 | E13: 0 | F13: 0 | G13: 0 | H13: 0 | I13: ='Sales Tax'!E35 -> 52.4508 | J13: =SUM(D13:I13) -> 1800.8108 | K13: 0 | L13: 0 | M13: =+K13-L13 -> 0
C14: 0
C15: 0
B19: TOTAL CHARGES | D19: =SUM(D11:D18) -> 22130.44 | E19: =SUM(E11:E18) -> 4548.4942 | F19: =SUM(F11:F18) -> 582.25279 | G19: =SUM(G11:G14) -> 0 | H19: =SUM(H13:H18) -> 0 | I19: =SUM(I11:I18) -> 894.69657 | J19: =SUM(J11:J18) -> 29875.67 | K19: =SUM(K11:K18) -> 7692.7791 | L19: =SUM(L11:L18) -> 7695.51 | M19: =K19-L19 -> -2.7308834 | N19: =SUM(N11:N18) -> #DIV/0! | O19: =SUM(O11:O18) -> 52635.1 | P19: =SUM(P11:P18) -> -44942.321
B21: BILL AT 2025 CHARGES
B25: Operations Manager
D26: Danielle Cebrero
B28: President/Sr. Vice President
D29: Jeff Lochner
C107: =-(C47+C44) -> 0 | D107: =-(D47+D44) -> 0 | E107: =-(E47+E44) -> 0 | H107: =-(H47+H44) -> 0 | J107: =-(J47+J44) -> 0 | K107: =-(K47+K44) -> 0 | L107: =-(L47+L44) -> 0

Sheet CAM CAPS
A2: VACANCY
A18: PLANET FITNESS
A20: Per Section 5 (page 7)

Sheet Slippage
B1: =Summary!A3 -> Goodyear Arizona Big Lots
B2: =Summary!A5 -> 01/01/2026 TO 12/31/2026
A3: EXPENSES | B3: ANNUAL TOTAL | D3: =Rent!$A13 -> VACANT (old Big Lots) | E3: Planet Fitness | F3: TOTAL RECOVERY | G3: VARIANCE | H3: % DIFFERENCE
A5: =Summary!B27 -> COMMON AREA EXPENSES
A7: =Summary!B28 -> Common Area Association | B7: =Summary!O28 -> 102419 | D7: ='CAM Majors'!R26 -> 0 | E7: ='CAM Majors'!AB26 -> 0 | F7: =SUM(D7:E7) -> 0 | G7: =B7-F7 -> 102419 | H7: =IF(G7=0,0,G7/B7) -> 1 | I7: Slippage due to Big Lot's CAM CAP
