Workbook
Name __dat1: #REF!
Name _1: #REF!
Name _1: #REF!
Name _1: #REF!
Name _1: '[1]Square (The)'!$D$18:$D$22
Name _1: '[1]Square (The)'!$D$18:$D$22
Name _1_245118304: #REF!
Name _10: #REF!
Name _10: #REF!
Name _2: #REF!
Name _2: #REF!
Name _2: [2]data!$J$22:$BR$22
Name _2: '[1]Square (The)'!$J$22:$BR$22
Name _2: '[1]Square (The)'!$J$22:$BR$22
Name _2_245118304: #REF!
Name _245118304: #REF!
Name _245118304BDR: #REF!
Name _265329000: #REF!
Name _3_245118304BDR: #REF!
Name _4_245118304BDR: #REF!
Name _5_265329000: #REF!
Name _6_265329000: #REF!
Name _dat1: [3]data!$A$2:$Q$1000
Name _dat1: [4]data!$A$2:$Q$1000
Name account_data: [7]Menu!$U$36
Name account_data: [8]Menu!$U$36
Name account_data: [9]Menu!$U$36
Name Actual_Rent: 'MR-Stat Data Sheet Bud'!$U$8:$AF$1326
Name Actual_Sqft: #REF!
Name Actual_Sqft: '[10]MR-Stat Data Sheet Bud'!$I$8:$T$402
Name Actual_Sqft: 'MR-Stat Data Sheet Bud'!$I$8:$T$402
Name ActualMonth: '[11]Min Rent Bud '!$V$8:$AG$10
Name ActualMonth: 'MR-Stat Data Sheet Bud'!$AG$8:$AR$9
Name ActualMonth: 'Min Rent Bud'!$V$8:$AG$10
Name amt_class_type_data: [7]Menu!$U$33
Name amt_class_type_data: [8]Menu!$U$33
Name amt_class_type_data: [9]Menu!$U$33
Name amy: '[6]Newport Hills'!$A$2:$J$477
Name amy: [12]variance!$A$2:$J$476
Name amy: [6]data!$A$2:$J$476
Name amy: [13]variance!$A$2:$J$476
Name annual_data: [7]Menu!$U$23
Name annual_data: [8]Menu!$U$23
Name annual_data: [9]Menu!$U$23
Name Bay: [14]Bluffs!$A$2:$J$1340
Name Bay: [15]Bluffs!$A$2:$J$1340
Name Bay: [16]Bluffs!$A$2:$J$1340
Name Bayside: #REF!
Name BS: #REF!
Name BS: #REF!
Name Budget_Type: [7]Menu!$N$13
Name Budget_Type: [8]Menu!$N$13
Name Budget_Type: [9]Menu!$N$13
Name CC_Name: [7]Menu!$N$15
Name CC_Name: [8]Menu!$N$15
Name CC_Name: [9]Menu!$N$15
Name cdm: '[6]Newport Hills'!$A$2:$J$1341
Name cdm: [17]variance!$A$2:$J$1340
Name cdm: [6]data!$A$2:$J$1340
Name cdm: [18]variance!$A$2:$J$1340

Sheet XXXX

Sheet Review Comments
B8: Monthly Financial Analysis
B9: Review Comments
A11: Property: | B11: ABI PROPERTIES
A13: Month: | B13: FOR THE MONTH ENDED 08/31/26
A16: 1.
A22: 2.
A28: 3.
A34: 4.
A40: 5.
A46: 6.
A52: 7.
A58: 8.
A64: 9.
A70: 10.

Sheet Min Rent Plan
N1: =+$M$10 -> 1 | O1: =+$M$10+0.1 -> 1.1 | Q1: =+$M$10+0.2 -> 1.2 | R1: =+$M$10+0.3 -> 1.3 | W1: =+$V$10 -> 2 | X1: =+$V$10+0.1 -> 2.1 | Z1: =+$V$10+0.2 -> 2.2 | AA1: =+$V$10+0.3 -> 2.3 | AF1: =+$AE$10 -> 3 | AG1: =+$AE$10+0.1 -> 3.1 | AI1: =+$AE$10+0.2 -> 3.2 | AJ1: =+$AE$10+0.3 -> 3.3 | AO1: =+$AN$10 -> 4 | AP1: =+$AN$10+0.1 -> 4.1 | AR1: =+$AN$10+0.2 -> 4.2 | AS1: =+$AN$10+0.3 -> 4.3 | AX1: =+$AW$10 -> 5 | AY1: =+$AW$10+0.1 -> 5.1 | BA1: =+$AW$10+0.2 -> 5.2 | BB1: =+$AW$10+0.3 -> 5.3 | BG1: =+$BF$10 -> 6 | BH1: =+$BF$10+0.1 -> 6.1 | BJ1: =+$BF$10+0.2 -> 6.2 | BK1: =+$BF$10+0.3 -> 6.3 | BP1: =+$BO$10 -> 7 | BQ1: =+$BO$10+0.1 -> 7.1 | BS1: =+$BO$10+0.2 -> 7.2 | BT1: =+$BO$10+0.3 -> 7.3 | BY1: =+$BX$10 -> 8 | BZ1: =+$BX$10+0.1 -> 8.1 | CB1: =+$BX$10+0.2 -> 8.2 | CC1: =+$BX$10+0.3 -> 8.3 | CH1: =+$CG$10 -> 9 | CI1: =+$CG$10+0.1 -> 9.1 | CK1: =+$CG$10+0.2 -> 9.2 | CL1: =+$CG$10+0.3 -> 9.3 | CQ1: =+$CP$10 -> 10 | CR1: =+CQ1+0.1 -> 10.1 | CT1: =+CQ1+0.2 -> 10.2 | CU1: =+CQ1+0.3 -> 10.3 | CZ1: 11 | DA1: 11.1 | DC1: 11.2 | DD1: 11.3 | DI1: 12 | DJ1: 12.1 | DL1: 12.2 | DM1: 12.3
C2: =+'Review Comments'!B11 -> ABI PROPERTIES | N2: Month to Date | Q2: Weighted Average | W2: Month to Date | Z2: Weighted Average | AF2: Month to Date | AI2: Weighted Average | AO2: Month to Date | AR2: Weighted Average | AX2: Month to Date | BA2: Weighted Average | BG2: Month to Date | BJ2: Weighted Average | BP2: Month to Date | BS2: Weighted Average | BY2: Month to Date | CB2: Weighted Average | CH2: Month to Date | CK2: Weighted Average | CQ2: Month to Date | CT2: Weighted Average | CZ2: Month to Date | DC2: Weighted Average | DI2: Month to Date | DL2: Weighted Average
C3: MINIMUM RENT VARIANCE REPORT 2009/2010 | N3: Inline | O3: Overall | Q3: Inline | R3: Overall | W3: Inline | X3: Overall | Z3: Inline | AA3: Overall | AF3: Inline | AG3: Overall | AI3: Inline | AJ3: Overall | AO3: Inline | AP3: Overall | AR3: Inline | AS3: Overall | AX3: Inline | AY3: Overall | BA3: Inline | BB3: Overall | BG3: Inline | BH3: Overall | BJ3: Inline | BK3: Overall | BP3: Inline | BQ3: Overall | BS3: Inline | BT3: Overall | BY3: Inline | BZ3: Overall | CB3: Inline | CC3: Overall | CH3: Inline | CI3: Overall | CK3: Inline | CL3: Overall | CQ3: Inline | CR3: Overall | CT3: Inline | CU3: Overall | CZ3: Inline | DA3: Overall | DC3: Inline | DD3: Overall | DI3: Inline | DJ3: Overall | DL3: Inline | DM3: Overall
C4: ACTUAL VS. PLAN | J4: Occupied Sq Ft | N4: ='Inline Rates'!J3 -> 12056 | O4: =+'Inline Rates'!J14 -> 63153 | Q4: ='Inline Rates'!K3 -> 12056 | R4: =+O4 -> 63153 | W4: =+'Inline Rates'!P3 -> 12056 | X4: =+'Inline Rates'!P14 -> 63153 | Z4: =+'Inline Rates'!Q3/2 -> 12056 | AA4: =('Inline Rates'!P18)/2 -> 63153 | AF4: =+'Inline Rates'!V3 -> 12056 | AG4: =+'Inline Rates'!V14 -> 63153 | AI4: =+'Inline Rates'!W3/3 -> 12056 | AJ4: =('Inline Rates'!V18)/3 -> 63153 | AO4: =+'Inline Rates'!AB3 -> 12056 | AP4: =+'Inline Rates'!AB14 -> 63153 | AR4: =+'Inline Rates'!AC3/4 -> 12056 | AS4: =('Inline Rates'!AB18)/4 -> 63153 | AX4: =+'Inline Rates'!AH3 -> 12056 | AY4: =+'Inline Rates'!AH14 -> 63153 | BA4: =+'Inline Rates'!AI3/5 -> 12056 | BB4: =('Inline Rates'!AH18)/5 -> 63153 | BG4: =+'Inline Rates'!AN3 -> 12056 | BH4: =+'Inline Rates'!AN14 -> 63153 | BJ4: =+'Inline Rates'!AO3/6 -> 12056 | BK4: =('Inline Rates'!AN18)/6 -> 63153 | BP4: =+'Inline Rates'!AT3 -> 12056 | BQ4: =+'Inline Rates'!AT14 -> 63153 | BS4: =+'Inline Rates'!AU3/7 -> 12056 | BT4: =('Inline Rates'!AT18)/7 -> 63153 | BY4: =+'Inline Rates'!AZ3 -> 12056 | BZ4: =+'Inline Rates'!AZ14 -> 63153 | CB4: =+'Inline Rates'!BA3/8 -> 12056 | CC4: =('Inline Rates'!AZ18)/8 -> 63153 | CH4: =+'Inline Rates'!BF3 -> 12056 | CI4: =+'Inline Rates'!BF14 -> 63153 | CK4: =+'Inline Rates'!BG3/9 -> 12056 | CL4: =('Inline Rates'!BF18)/9 -> 63153 | CQ4: =+'Inline Rates'!BL3 -> 12056 | CR4: =+'Inline Rates'!BL14 -> 63153 | CT4: =+'Inline Rates'!BM3/10 -> 12056 | CU4: =('Inline Rates'!BL18)/10 -> 63153 | CZ4: =+'Inline Rates'!BR3 -> 12056 | DA4: =+'Inline Rates'!BR14 -> 63153 | DC4: =+'Inline Rates'!BS3/11 -> 12056 | DD4: =('Inline Rates'!BR18)/11 -> 63153 | DI4: =+'Inline Rates'!BX3 -> 12056 | DJ4: =+'Inline Rates'!BX14 -> 63153 | DL4: =+'Inline Rates'!BY3/12 -> 12056 | DM4: =('Inline Rates'!BX18)/12 -> 63153
J5: Vacant Sq Ft | N5: ='Inline Rates'!J4-N4 -> 1200 | O5: =+'Inline Rates'!K14-O4 -> 1200 | Q5: ='Inline Rates'!K4-Q4 -> 1200 | R5: =+O5 -> 1200 | W5: ='Inline Rates'!P4-W4 -> 1200 | X5: =+'Inline Rates'!Q14-'Min Rent Plan'!X4 -> 1200 | Z5: =+'Inline Rates'!Q4/2-Z4 -> 1200 | AA5: =(('Inline Rates'!Q18)/2)-AA4 -> 1200 | AF5: ='Inline Rates'!V4-AF4 -> 1200 | AG5: =+'Inline Rates'!W14-AG4 -> 1200 | AI5: =+'Inline Rates'!W4/3-AI4 -> 1200 | AJ5: =(('Inline Rates'!W18)/3)-AJ4 -> 1200 | AO5: =+'Inline Rates'!AB4-AO4 -> 1200 | AP5: =+'Inline Rates'!AC14-AP4 -> 1200 | AR5: =+'Inline Rates'!AC4/4-AR4 -> 1200 | AS5: =(('Inline Rates'!AC18)/4)-AS4 -> 1200 | AX5: =+'Inline Rates'!AH4-AX4 -> 1200 | AY5: =+'Inline Rates'!AI14-AY4 -> 1200 | BA5: =+'Inline Rates'!AI4/5-BA4 -> 1200 | BB5: =(('Inline Rates'!AI18)/5)-BB4 -> 1200 | BG5: =+'Inline Rates'!AN4-BG4 -> 1200 | BH5: =+'Inline Rates'!AO14-BH4 -> 1200 | BJ5: =+'Inline Rates'!AO4/6-BJ4 -> 1200 | BK5: =(('Inline Rates'!AO18)/6)-BK4 -> 1200 | BP5: =+'Inline Rates'!AT4-BP4 -> 1200 | BQ5: =+'Inline Rates'!AU14-BQ4 -> 1200 | BS5: =+'Inline Rates'!AU4/7-BS4 -> 1200 | BT5: =(('Inline Rates'!AU18)/7)-BT4 -> 1200 | BY5: =+'Inline Rates'!AZ4-BY4 -> 1200 | BZ5: =+'Inline Rates'!BA14-BZ4 -> 1200 | CB5: =+'Inline Rates'!BA4/8-CB4 -> 1200 | CC5: =(('Inline Rates'!BA18)/8)-CC4 -> 1200 | CH5: =+'Inline Rates'!BF4-CH4 -> 1200 | CI5: =+'Inline Rates'!BG14-CI4 -> 1200 | CK5: =+'Inline Rates'!BG4/9-CK4 -> 1200 | CL5: =(('Inline Rates'!BG18)/9)-CL4 -> 1200 | CQ5: =+'Inline Rates'!BL4-CQ4 -> 1200 | CR5: =+'Inline Rates'!BM14-CR4 -> 1200 | CT5: =+'Inline Rates'!BM4/10-'Min Rent Plan'!CT4 -> 1200 | CU5: =(('Inline Rates'!BM18)/10)-CU4 -> 1200 | CZ5: =+'Inline Rates'!BR4-CZ4 -> 1200 | DA5: =+'Inline Rates'!BS14-DA4 -> 1200 | DC5: =+'Inline Rates'!BS4/11-DC4 -> 1200 | DD5: =(('Inline Rates'!BS18)/11)-DD4 -> 1200 | DI5: =+'Inline Rates'!BX4-DI4 -> 1200 | DJ5: =+'Inline Rates'!BY14-DJ4 -> 1200 | DL5: =+'Inline Rates'!BY4/12-DL4 -> 1200 | DM5: =(('Inline Rates'!BY18)/12)-DM4 -> 1200
J6: Total Sq Ft | N6: =SUM(N4:N5) -> 13256 | O6: =SUM(O4:O5) -> 64353 | Q6: =SUM(Q4:Q5) -> 13256 | R6: =SUM(R4:R5) -> 64353 | W6: =SUM(W4:W5) -> 13256 | X6: =SUM(X4:X5) -> 64353 | Z6: =SUM(Z4:Z5) -> 13256 | AA6: =SUM(AA4:AA5) -> 64353 | AF6: =SUM(AF4:AF5) -> 13256 | AG6: =SUM(AG4:AG5) -> 64353 | AI6: =SUM(AI4:AI5) -> 13256 | AJ6: =SUM(AJ4:AJ5) -> 64353 | AO6: =SUM(AO4:AO5) -> 13256 | AP6: =SUM(AP4:AP5) -> 64353 | AR6: =SUM(AR4:AR5) -> 13256 | AS6: =SUM(AS4:AS5) -> 64353 | AX6: =SUM(AX4:AX5) -> 13256 | AY6: =SUM(AY4:AY5) -> 64353 | BA6: =SUM(BA4:BA5) -> 13256 | BB6: =SUM(BB4:BB5) -> 64353 | BG6: =SUM(BG4:BG5) -> 13256 | BH6: =SUM(BH4:BH5) -> 64353 | BJ6: =SUM(BJ4:BJ5) -> 13256 | BK6: =SUM(BK4:BK5) -> 64353 | BP6: =SUM(BP4:BP5) -> 13256 | BQ6: =SUM(BQ4:BQ5) -> 64353 | BS6: =SUM(BS4:BS5) -> 13256 | BT6: =SUM(BT4:BT5) -> 64353 | BY6: =SUM(BY4:BY5) -> 13256 | BZ6: =SUM(BZ4:BZ5) -> 64353 | CB6: =SUM(CB4:CB5) -> 13256 | CC6: =SUM(CC4:CC5) -> 64353 | CH6: =SUM(CH4:CH5) -> 13256 | CI6: =SUM(CI4:CI5) -> 64353 | CK6: =SUM(CK4:CK5) -> 13256 | CL6: =SUM(CL4:CL5) -> 64353 | CQ6: =SUM(CQ4:CQ5) -> 13256 | CR6: =SUM(CR4:CR5) -> 64353 | CT6: =SUM(CT4:CT5) -> 13256 | CU6: =SUM(CU4:CU5) -> 64353 | CZ6: =SUM(CZ4:CZ5) -> 13256 | DA6: =SUM(DA4:DA5) -> 64353 | DC6: =SUM(DC4:DC5) -> 13256 | DD6: =SUM(DD4:DD5) -> 64353 | DI6: =SUM(DI4:DI5) -> 13256 | DJ6: =SUM(DJ4:DJ5) -> 64353 | DL6: =SUM(DL4:DL5) -> 13256 | DM6: =SUM(DM4:DM5) -> 64353
I7: Percentage Occupied | J7: Pct Occupied | N7: =+N4/N6 -> 0.90947495 | O7: =+O4/O6 -> 0.98135285 | Q7: =+Q4/Q6 -> 0.90947495 | R7: =+R4/R6 -> 0.98135285 | W7: =+W4/W6 -> 0.90947495 | X7: =+X4/X6 -> 0.98135285 | Z7: =+Z4/Z6 -> 0.90947495 | AA7: =+AA4/AA6 -> 0.98135285 | AF7: =+AF4/AF6 -> 0.90947495 | AG7: =+AG4/AG6 -> 0.98135285 | AI7: =+AI4/AI6 -> 0.90947495 | AJ7: =+AJ4/AJ6 -> 0.98135285 | AO7: =+AO4/AO6 -> 0.90947495 | AP7: =+AP4/AP6 -> 0.98135285 | AR7: =+AR4/AR6 -> 0.90947495 | AS7: =+AS4/AS6 -> 0.98135285 | AX7: =+AX4/AX6 -> 0.90947495 | AY7: =+AY4/AY6 -> 0.98135285 | BA7: =+BA4/BA6 -> 0.90947495 | BB7: =+BB4/BB6 -> 0.98135285 | BG7: =+BG4/BG6 -> 0.90947495 | BH7: =+BH4/BH6 -> 0.98135285 | BJ7: =+BJ4/BJ6 -> 0.90947495 | BK7: =+BK4/BK6 -> 0.98135285 | BP7: =+BP4/BP6 -> 0.90947495 | BQ7: =+BQ4/BQ6 -> 0.98135285 | BS7: =+BS4/BS6 -> 0.90947495 | BT7: =+BT4/BT6 -> 0.98135285 | BY7: =+BY4/BY6 -> 0.90947495 | BZ7: =+BZ4/BZ6 -> 0.98135285 | CB7: =+CB4/CB6 -> 0.90947495 | CC7: =+CC4/CC6 -> 0.98135285 | CH7: =+CH4/CH6 -> 0.90947495 | CI7: =+CI4/CI6 -> 0.98135285 | CK7: =+CK4/CK6 -> 0.90947495 | CL7: =+CL4/CL6 -> 0.98135285 | CQ7: =+CQ4/CQ6 -> 0.90947495 | CR7: =+CR4/CR6 -> 0.98135285 | CT7: =+CT4/CT6 -> 0.90947495 | CU7: =+CU4/CU6 -> 0.98135285 | CZ7: =+CZ4/CZ6 -> 0.90947495 | DA7: =+DA4/DA6 -> 0.98135285 | DC7: =+DC4/DC6 -> 0.90947495 | DD7: =+DD4/DD6 -> 0.98135285 | DI7: =+DI4/DI6 -> 0.90947495 | DJ7: =+DJ4/DJ6 -> 0.98135285 | DL7: =+DL4/DL6 -> 0.90947495 | DM7: =+DM4/DM6 -> 0.98135285
J8: Inline Rate | N8: ='Inline Rates'!J8 -> 52.953932 | O8: N/A | Q8: ='Inline Rates'!K8 -> 52.953932 | R8: N/A | W8: =+'Inline Rates'!P8 -> 52.953932 | X8: N/A | Z8: =+'Inline Rates'!Q8 -> 52.953932 | AA8: N/A | AF8: =+'Inline Rates'!V8 -> 53.171666 | AG8: N/A | AI8: =+'Inline Rates'!W8 -> 53.02651 | AJ8: N/A | AO8: =+'Inline Rates'!AB8 -> 53.171666 | AP8: N/A | AR8: =+'Inline Rates'!AC8 -> 53.062799 | AS8: N/A | AX8: =+'Inline Rates'!AH8 -> 49.305956 | AY8: N/A | BA8: =+'Inline Rates'!AI8 -> 49.667419 | BB8: N/A | BG8: =+'Inline Rates'!AN8 -> 48.775352 | BH8: N/A | BJ8: =+'Inline Rates'!AO8 -> 51.943864 | BK8: N/A | BP8: =+'Inline Rates'!AT8 -> 54.436812 | BQ8: N/A | BS8: =+'Inline Rates'!AU8 -> 52.694099 | BT8: N/A | BY8: =+'Inline Rates'!AZ8 -> 54.436812 | BZ8: N/A | CB8: =+'Inline Rates'!BA8 -> 52.911938 | CC8: N/A | CH8: =+'Inline Rates'!BF8 -> 54.436812 | CI8: N/A | CK8: =+'Inline Rates'!BG8 -> 53.081368 | CL8: N/A | CQ8: =+'Inline Rates'!BL8 -> 53.227455 | CR8: N/A | CT8: =+'Inline Rates'!BM8 -> 52.926259 | CU8: N/A | CZ8: =+'Inline Rates'!BR8 -> 53.227455 | DA8: N/A | DC8: =+'Inline Rates'!BS8 -> 52.946736 | DD8: N/A | DI8: =+'Inline Rates'!BX8 -> 51.29149 | DJ8: N/A | DL8: =+'Inline Rates'!BY8 -> 52.256344 | DM8: N/A
I10: 12 | M10: 1 | V10: 2 | AE10: 3 | AN10: 4 | AW10: 5 | BF10: 6 | BO10: 7 | BX10: 8 | CG10: 9 | CP10: 10 | CY10: 11 | DH10: 12
C11: Tenant | F11: Suite | K11: July | L11: July | M11: JULY | Q11: Year to Date | T11: Aug | U11: Aug | V11: AUGUST | Z11: Year to Date | AC11: Sep | AD11: Sep | AE11: SEPT | AI11: Year to Date | AL11: Oct | AM11: Oct | AN11: OCT | AR11: Year to Date | AU11: Nov | AV11: Nov | AW11: NOV | BA11: Year to Date | BD11: Dec | BE11: Dec | BF11: DEC | BJ11: Year to Date | BM11: Jan | BN11: Jan | BO11: JAN | BS11: Year to Date | BV11: Feb | BW11: Feb | BX11: FEB | CB11: Year to Date | CE11: Mar | CF11: Mar | CG11: MAR | CK11: Year to Date | CN11: Apr | CO11: Apr | CP11: APR | CT11: Year to Date | CW11: May | CX11: May | CY11: MAY | DC11: Year to Date | DF11: June | DG11: June | DH11: JUNE | DL11: Year to Date | DO11: Year to Date | DQ11: Annual
C12: Name | D12: Lse Start | E12: Lse Exp. | F12: Status | G12: No. | H12: Sq Ft | I12: Month | K12: MRI | L12: Adjustment | M12: Actual | N12: Plan | O12: Variance | Q12: Actual | R12: Plan | S12: Variance | T12: MRI | U12: Adjustment | V12: Actual | W12: Plan | X12: Variance | Z12: Actual | AA12: Plan | AB12: Variance | AC12: MRI | AD12: Adjustment | AE12: Actual | AF12: Plan | AG12: Variance | AI12: Actual | AJ12: Plan | AK12: Variance | AL12: MRI | AM12: Adjustment | AN12: Actual | AO12: Plan | AP12: Variance | AR12: Actual | AS12: Plan | AT12: Variance | AU12: MRI | AV12: Adjustment | AW12: Actual | AX12: Plan | AY12: Variance | BA12: Actual | BB12: Plan | BC12: Variance | BD12: MRI | BE12: Adjustment | BF12: Actual | BG12: Plan | BH12: Variance | BJ12: Actual | BK12: Plan | BL12: Variance | BM12: MRI | BN12: Adjustment | BO12: Actual | BP12: Plan | BQ12: Variance | BS12: Actual | BT12: Plan | BU12: Variance | BV12: MRI | BW12: Adjustment | BX12: Actual | BY12: Plan | BZ12: Variance | CB12: Actual | CC12: Plan | CD12: Variance | CE12: MRI | CF12: Adjustment | CG12: Actual | CH12: Plan | CI12: Variance | CK12: Actual | CL12: Plan | CM12: Variance | CN12: MRI | CO12: Adjustment | CP12: Actual | CQ12: Plan | CR12: Variance | CT12: Actual | CU12: Plan | CV12: Variance | CW12: MRI | CX12: Adjustment | CY12: Actual | CZ12: Plan | DA12: Variance | DC12: Actual | DD12: Plan | DE12: Variance | DF12: MRI | DG12: Adjustment | DH12: Actual | DI12: Plan | DJ12: Variance | DL12: Actual | DM12: Plan | DN12: Variance | DO12: Explanation | DQ12: Plan | DR12: Var. to Plan | DS12: Explanation
C13: Inline
A14: 1 | B14: 621201-000001 | C14: Bayside Cleaners | D14: 32295 | E14: 40694 | F14: Occupied | G14: 1056 | H14: 1500 | I14: =HLOOKUP(I$10,M$10:DI$53,ROW()-9,FALSE) -> 11843.75 | K14: =IF(ISERROR(VLOOKUP($B14,'MRI Data'!$A:$P,M$10+3,FALSE)),0,VLOOKUP($B14,'MRI Data'!$A:$P,M$10+3,FALSE)) -> 11388.75 | M14: =SUM(K14:L14) -> 11388.75 | N14: 11389 | O14: =+M14-N14 -> -0.25 | Q14: =+M14 -> 11388.75 | R14: =+N14 -> 11389 | S14: =O14 -> -0.25 | T14: =IF(ISERROR(VLOOKUP($B14,'MRI Data'!$A:$P,V$10+3,FALSE)),0,VLOOKUP($B14,'MRI Data'!$A:$P,V$10+3,FALSE)) -> 11388.75 | V14: =SUM(T14:U14) -> 11388.75 | W14: 11389 | X14: =+V14-W14 -> -0.25 | Z14: =+Q14+V14 -> 22777.5 | AA14: =+R14+W14 -> 22778 | AB14: =+Z14-AA14 -> -0.5 | AC14: =IF(ISERROR(VLOOKUP($B14,'MRI Data'!$A:$P,AE$10+3,FALSE)),0,VLOOKUP($B14,'MRI Data'!$A:$P,AE$10+3,FALSE)) -> 11388.75 | AE14: =SUM(AC14:AD14) -> 11388.75 | AF14: 11389 | AG14: =+AE14-AF14 -> -0.25 | AI14: =+Z14+AE14 -> 34166.25 | AJ14: =+AA14+AF14 -> 34167 | AK14: =+AI14-AJ14 -> -0.75 | AL14: =IF(ISERROR(VLOOKUP($B14,'MRI Data'!$A:$P,AN$10+3,FALSE)),0,VLOOKUP($B14,'MRI Data'!$A:$P,AN$10+3,FALSE)) -> 11388.75 | AN14: =SUM(AL14:AM14) -> 11388.75 | AO14: 11389 | AP14: =+AN14-AO14 -> -0.25 | AR14: =+AI14+AN14 -> 45555 | AS14: =+AJ14+AO14 -> 45556 | AT14: =+AR14-AS14 -> -1 | AU14: =IF(ISERROR(VLOOKUP($B14,'MRI Data'!$A:$P,AW$10+3,FALSE)),0,VLOOKUP($B14,'MRI Data'!$A:$P,AW$10+3,FALSE)) -> 11388.75 | AW14: =SUM(AU14:AV14) -> 11388.75 | AX14: 11389 | AY14: =+AW14-AX14 -> -0.25 | BA14: =+AR14+AW14 -> 56943.75 | BB14: =+AS14+AX14 -> 56945 | BC14: =+BA14-BB14 -> -1.25 | BD14: =IF(ISERROR(VLOOKUP($B14,'MRI Data'!$A:$P,BF$10+3,FALSE)),0,VLOOKUP($B14,'MRI Data'!$A:$P,BF$10+3,FALSE)) -> 11388.75 | BF14: =SUM(BD14:BE14) -> 11388.75 | BG14: 11389 | BH14: =+BF14-BG14 -> -0.25 | BJ14: =+BA14+BF14 -> 68332.5 | BK14: =+BB14+BG14 -> 68334 | BL14: =+BJ14-BK14 -> -1.5 | BM14: =IF(ISERROR(VLOOKUP($B14,'MRI Data'!$A:$P,BO$10+3,FALSE)),0,VLOOKUP($B14,'MRI Data'!$A:$P,BO$10+3,FALSE)) -> 11388.75 | BO14: =SUM(BM14:BN14) -> 11388.75 | BP14: 11389 | BQ14: =+BO14-BP14 -> -0.25 | BS14: =+BJ14+BO14 -> 79721.25 | BT14: =+BK14+BP14 -> 79723 | BU14: =+BS14-BT14 -> -1.75 | BV14: =IF(ISERROR(VLOOKUP($B14,'MRI Data'!$A:$P,BX$10+3,FALSE)),0,VLOOKUP($B14,'MRI Data'!$A:$P,BX$10+3,FALSE)) -> 11388.75 | BX14: =SUM(BV14:BW14) -> 11388.75 | BY14: 11389 | BZ14: =+BX14-BY14 -> -0.25 | CB14: =+BS14+BX14 -> 91110 | CC14: =+BT14+BY14 -> 91112 | CD14: =+CB14-CC14 -> -2 | CE14: =IF(ISERROR(VLOOKUP($B14,'MRI Data'!$A:$P,CG$10+3,FALSE)),0,VLOOKUP($B14,'MRI Data'!$A:$P,CG$10+3,FALSE)) -> 11388.75 | CG14: =SUM(CE14:CF14) -> 11388.75 | CH14: 11389 | CI14: =+CG14-CH14 -> -0.25 | CK14: =+CB14+CG14 -> 102498.75 | CL14: =+CC14+CH14 -> 102501 | CM14: =+CK14-CL14 -> -2.25 | CN14: =IF(ISERROR(VLOOKUP($B14,'MRI Data'!$A:$P,CP$10+3,FALSE)),0,VLOOKUP($B14,'MRI Data'!$A:$P,CP$10+3,FALSE)) -> 11388.75 | CP14: =SUM(CN14:CO14) -> 11388.75 | CQ14: 11389 | CR14: =+CP14-CQ14 -> -0.25 | CT14: =+CK14+CP14 -> 113887.5 | CU14: =+CL14+CQ14 -> 113890 | CV14: =+CT14-CU14 -> -2.5 | CW14: =IF(ISERROR(VLOOKUP($B14,'MRI Data'!$A:$P,CY$10+3,FALSE)),0,VLOOKUP($B14,'MRI Data'!$A:$P,CY$10+3,FALSE)) -> 11388.75 | CY14: =SUM(CW14:CX14) -> 11388.75 | CZ14: 11389 | DA14: =+CY14-CZ14 -> -0.25 | DC14: =+CT14+CY14 -> 125276.25 | DD14: =+CU14+CZ14 -> 125279 | DE14: =+DC14-DD14 -> -2.75 | DF14: =IF(ISERROR(VLOOKUP($B14,'MRI Data'!$A:$P,DH$10+3,FALSE)),0,VLOOKUP($B14,'MRI Data'!$A:$P,DH$10+3,FALSE)) -> 11843.75 | DH14: =SUM(DF14:DG14) -> 11843.75 | DI14: 11844 | DJ14: =+DH14-DI14 -> -0.25 | DL14: =+DC14+DH14 -> 137120 | DM14: =+DD14+DI14 -> 137123 | DN14: =+DL14-DM14 -> -3 | DQ14: =+DM14 -> 137123 | DR14: 0
A15: 2 | B15: 621201-000013 | C15: Carol Klein Fine Jewelry 1028 | D15: 35223 | E15: 40724 | F15: Occupied | G15: 1028 | H15: 1055 | I15: =HLOOKUP(I$10,M$10:DI$53,ROW()-9,FALSE) -> 5417.43 | K15: =IF(ISERROR(VLOOKUP($B15,'MRI Data'!$A:$P,M$10+3,FALSE)),0,VLOOKUP($B15,'MRI Data'!$A:$P,M$10+3,FALSE)) -> 5417.43 | M15: =SUM(K15:L15) -> 5417.43 | N15: 5417 | O15: =+M15-N15 -> 0.43 | Q15: =+M15 -> 5417.43 | R15: =+N15 -> 5417 | S15: =O15 -> 0.43 | T15: =IF(ISERROR(VLOOKUP($B15,'MRI Data'!$A:$P,V$10+3,FALSE)),0,VLOOKUP($B15,'MRI Data'!$A:$P,V$10+3,FALSE)) -> 5417.43 | V15: =SUM(T15:U15) -> 5417.43 | W15: 5417 | X15: =+V15-W15 -> 0.43 | Z15: =+Q15+V15 -> 10834.86 | AA15: =+R15+W15 -> 10834 | AB15: =+Z15-AA15 -> 0.86 | AC15: =IF(ISERROR(VLOOKUP($B15,'MRI Data'!$A:$P,AE$10+3,FALSE)),0,VLOOKUP($B15,'MRI Data'!$A:$P,AE$10+3,FALSE)) -> 5417.43 | AE15: =SUM(AC15:AD15) -> 5417.43 | AF15: 5417 | AG15: =+AE15-AF15 -> 0.43 | AI15: =+Z15+AE15 -> 16252.29 | AJ15: =+AA15+AF15 -> 16251 | AK15: =+AI15-AJ15 -> 1.29 | AL15: =IF(ISERROR(VLOOKUP($B15,'MRI Data'!$A:$P,AN$10+3,FALSE)),0,VLOOKUP($B15,'MRI Data'!$A:$P,AN$10+3,FALSE)) -> 5417.43 | AN15: =SUM(AL15:AM15) -> 5417.43 | AO15: 5417 | AP15: =+AN15-AO15 -> 0.43 | AR15: =+AI15+AN15 -> 21669.72 | AS15: =+AJ15+AO15 -> 21668 | AT15: =+AR15-AS15 -> 1.72 | AU15: =IF(ISERROR(VLOOKUP($B15,'MRI Data'!$A:$P,AW$10+3,FALSE)),0,VLOOKUP($B15,'MRI Data'!$A:$P,AW$10+3,FALSE)) -> 5417.43 | AW15: =SUM(AU15:AV15) -> 5417.43 | AX15: 5417 | AY15: =+AW15-AX15 -> 0.43 | BA15: =+AR15+AW15 -> 27087.15 | BB15: =+AS15+AX15 -> 27085 | BC15: =+BA15-BB15 -> 2.15 | BD15: =IF(ISERROR(VLOOKUP($B15,'MRI Data'!$A:$P,BF$10+3,FALSE)),0,VLOOKUP($B15,'MRI Data'!$A:$P,BF$10+3,FALSE)) -> 5417.43 | BF15: =SUM(BD15:BE15) -> 5417.43 | BG15: 5417 | BH15: =+BF15-BG15 -> 0.43 | BJ15: =+BA15+BF15 -> 32504.58 | BK15: =+BB15+BG15 -> 32502 | BL15: =+BJ15-BK15 -> 2.58 | BM15: =IF(ISERROR(VLOOKUP($B15,'MRI Data'!$A:$P,BO$10+3,FALSE)),0,VLOOKUP($B15,'MRI Data'!$A:$P,BO$10+3,FALSE)) -> 5417.43 | BO15: =SUM(BM15:BN15) -> 5417.43 | BP15: 5417 | BQ15: =+BO15-BP15 -> 0.43 | BS15: =+BJ15+BO15 -> 37922.01 | BT15: =+BK15+BP15 -> 37919 | BU15: =+BS15-BT15 -> 3.01 | BV15: =IF(ISERROR(VLOOKUP($B15,'MRI Data'!$A:$P,BX$10+3,FALSE)),0,VLOOKUP($B15,'MRI Data'!$A:$P,BX$10+3,FALSE)) -> 5417.43 | BX15: =SUM(BV15:BW15) -> 5417.43 | BY15: 5417 | BZ15: =+BX15-BY15 -> 0.43 | CB15: =+BS15+BX15 -> 43339.44 | CC15: =+BT15+BY15 -> 43336 | CD15: =+CB15-CC15 -> 3.44 | CE15: =IF(ISERROR(VLOOKUP($B15,'MRI Data'!$A:$P,CG$10+3,FALSE)),0,VLOOKUP($B15,'MRI Data'!$A:$P,CG$10+3,FALSE)) -> 5417.43 | CG15: =SUM(CE15:CF15) -> 5417.43 | CH15: 5417 | CI15: =+CG15-CH15 -> 0.43 | CK15: =+CB15+CG15 -> 48756.87 | CL15: =+CC15+CH15 -> 48753 | CM15: =+CK15-CL15 -> 3.87 | CN15: =IF(ISERROR(VLOOKUP($B15,'MRI Data'!$A:$P,CP$10+3,FALSE)),0,VLOOKUP($B15,'MRI Data'!$A:$P,CP$10+3,FALSE)) -> 5417.43 | CP15: =SUM(CN15:CO15) -> 5417.43 | CQ15: 5417 | CR15: =+CP15-CQ15 -> 0.43 | CT15: =+CK15+CP15 -> 54174.3 | CU15: =+CL15+CQ15 -> 54170 | CV15: =+CT15-CU15 -> 4.3 | CW15: =IF(ISERROR(VLOOKUP($B15,'MRI Data'!$A:$P,CY$10+3,FALSE)),0,VLOOKUP($B15,'MRI Data'!$A:$P,CY$10+3,FALSE)) -> 5417.43 | CY15: =SUM(CW15:CX15) -> 5417.43 | CZ15: 5417 | DA15: =+CY15-CZ15 -> 0.43 | DC15: =+CT15+CY15 -> 59591.73 | DD15: =+CU15+CZ15 -> 59587 | DE15: =+DC15-DD15 -> 4.73 | DF15: =IF(ISERROR(VLOOKUP($B15,'MRI Data'!$A:$P,DH$10+3,FALSE)),0,VLOOKUP($B15,'MRI Data'!$A:$P,DH$10+3,FALSE)) -> 5417.43 | DH15: =SUM(DF15:DG15) -> 5417.43 | DI15: 5417 | DJ15: =+DH15-DI15 -> 0.43 | DL15: =+DC15+DH15 -> 65009.16 | DM15: =+DD15+DI15 -> 65004 | DN15: =+DL15-DM15 -> 5.16 | DQ15: =+DM15 -> 65004 | DR15: 0
A16: 3 | B16: 621201-000004 | C16: Java City Bakery Café | D16: 34700 | E16: 41820 | F16: Occupied | G16: 1064 | H16: 1320 | I16: =HLOOKUP(I$10,M$10:DI$53,ROW()-9,FALSE) -> 6490 | K16: =IF(ISERROR(VLOOKUP($B16,'MRI Data'!$A:$P,M$10+3,FALSE)),0,VLOOKUP($B16,'MRI Data'!$A:$P,M$10+3,FALSE)) -> 6490 | M16: =SUM(K16:L16) -> 6490 | N16: 6490 | O16: =+M16-N16 -> 0 | Q16: =+M16 -> 6490 | R16: =+N16 -> 6490 | S16: =O16 -> 0 | T16: =IF(ISERROR(VLOOKUP($B16,'MRI Data'!$A:$P,V$10+3,FALSE)),0,VLOOKUP($B16,'MRI Data'!$A:$P,V$10+3,FALSE)) -> 6490 | V16: =SUM(T16:U16) -> 6490 | W16: 6490 | X16: =+V16-W16 -> 0 | Z16: =+Q16+V16 -> 12980 | AA16: =+R16+W16 -> 12980 | AB16: =+Z16-AA16 -> 0 | AC16: =IF(ISERROR(VLOOKUP($B16,'MRI Data'!$A:$P,AE$10+3,FALSE)),0,VLOOKUP($B16,'MRI Data'!$A:$P,AE$10+3,FALSE)) -> 6490 | AE16: =SUM(AC16:AD16) -> 6490 | AF16: 6490 | AG16: =+AE16-AF16 -> 0 | AI16: =+Z16+AE16 -> 19470 | AJ16: =+AA16+AF16 -> 19470 | AK16: =+AI16-AJ16 -> 0 | AL16: =IF(ISERROR(VLOOKUP($B16,'MRI Data'!$A:$P,AN$10+3,FALSE)),0,VLOOKUP($B16,'MRI Data'!$A:$P,AN$10+3,FALSE)) -> 6490 | AN16: =SUM(AL16:AM16) -> 6490 | AO16: 6490 | AP16: =+AN16-AO16 -> 0 | AR16: =+AI16+AN16 -> 25960 | AS16: =+AJ16+AO16 -> 25960 | AT16: =+AR16-AS16 -> 0 | AU16: =IF(ISERROR(VLOOKUP($B16,'MRI Data'!$A:$P,AW$10+3,FALSE)),0,VLOOKUP($B16,'MRI Data'!$A:$P,AW$10+3,FALSE)) -> 6490 | AW16: =SUM(AU16:AV16) -> 6490 | AX16: 6490 | AY16: =+AW16-AX16 -> 0 | BA16: =+AR16+AW16 -> 32450 | BB16: =+AS16+AX16 -> 32450 | BC16: =+BA16-BB16 -> 0 | BD16: =IF(ISERROR(VLOOKUP($B16,'MRI Data'!$A:$P,BF$10+3,FALSE)),0,VLOOKUP($B16,'MRI Data'!$A:$P,BF$10+3,FALSE)) -> 6490 | BF16: =SUM(BD16:BE16) -> 6490 | BG16: 6490 | BH16: =+BF16-BG16 -> 0 | BJ16: =+BA16+BF16 -> 38940 | BK16: =+BB16+BG16 -> 38940 | BL16: =+BJ16-BK16 -> 0 | BM16: =IF(ISERROR(VLOOKUP($B16,'MRI Data'!$A:$P,BO$10+3,FALSE)),0,VLOOKUP($B16,'MRI Data'!$A:$P,BO$10+3,FALSE)) -> 6490 | BO16: =SUM(BM16:BN16) -> 6490 | BP16: 6490 | BQ16: =+BO16-BP16 -> 0 | BS16: =+BJ16+BO16 -> 45430 | BT16: =+BK16+BP16 -> 45430 | BU16: =+BS16-BT16 -> 0 | BV16: =IF(ISERROR(VLOOKUP($B16,'MRI Data'!$A:$P,BX$10+3,FALSE)),0,VLOOKUP($B16,'MRI Data'!$A:$P,BX$10+3,FALSE)) -> 6490 | BX16: =SUM(BV16:BW16) -> 6490 | BY16: 6490 | BZ16: =+BX16-BY16 -> 0 | CB16: =+BS16+BX16 -> 51920 | CC16: =+BT16+BY16 -> 51920 | CD16: =+CB16-CC16 -> 0 | CE16: =IF(ISERROR(VLOOKUP($B16,'MRI Data'!$A:$P,CG$10+3,FALSE)),0,VLOOKUP($B16,'MRI Data'!$A:$P,CG$10+3,FALSE)) -> 6490 | CG16: =SUM(CE16:CF16) -> 6490 | CH16: 6490 | CI16: =+CG16-CH16 -> 0 | CK16: =+CB16+CG16 -> 58410 | CL16: =+CC16+CH16 -> 58410 | CM16: =+CK16-CL16 -> 0 | CN16: =IF(ISERROR(VLOOKUP($B16,'MRI Data'!$A:$P,CP$10+3,FALSE)),0,VLOOKUP($B16,'MRI Data'!$A:$P,CP$10+3,FALSE)) -> 6490 | CP16: =SUM(CN16:CO16) -> 6490 | CQ16: 6490 | CR16: =+CP16-CQ16 -> 0 | CT16: =+CK16+CP16 -> 64900 | CU16: =+CL16+CQ16 -> 64900 | CV16: =+CT16-CU16 -> 0 | CW16: =IF(ISERROR(VLOOKUP($B16,'MRI Data'!$A:$P,CY$10+3,FALSE)),0,VLOOKUP($B16,'MRI Data'!$A:$P,CY$10+3,FALSE)) -> 6490 | CY16: =SUM(CW16:CX16) -> 6490 | CZ16: 6490 | DA16: =+CY16-CZ16 -> 0 | DC16: =+CT16+CY16 -> 71390 | DD16: =+CU16+CZ16 -> 71390 | DE16: =+DC16-DD16 -> 0 | DF16: =IF(ISERROR(VLOOKUP($B16,'MRI Data'!$A:$P,DH$10+3,FALSE)),0,VLOOKUP($B16,'MRI Data'!$A:$P,DH$10+3,FALSE)) -> 6490 | DH16: =SUM(DF16:DG16) -> 6490 | DI16: 6490 | DJ16: =+DH16-DI16 -> 0 | DL16: =+DC16+DH16 -> 77880 | DM16: =+DD16+DI16 -> 77880 | DN16: =+DL16-DM16 -> 0 | DQ16: =+DM16 -> 77880 | DR16: 0
A17: =+A16+1 -> 4 | B17: 621201-000005 | C17: Just Alterations | D17: 35217 | E17: 41243 | F17: Occupied | G17: 1032A | H17: 650 | I17: =HLOOKUP(I$10,M$10:DI$53,ROW()-9,FALSE) -> 3690.92 | K17: =IF(ISERROR(VLOOKUP($B17,'MRI Data'!$A:$P,M$10+3,FALSE)),0,VLOOKUP($B17,'MRI Data'!$A:$P,M$10+3,FALSE)) -> 3549 | M17: =SUM(K17:L17) -> 3549 | N17: 3549 | O17: =+M17-N17 -> 0 | Q17: =+M17 -> 3549 | R17: =+N17 -> 3549 | S17: =O17 -> 0 | T17: =IF(ISERROR(VLOOKUP($B17,'MRI Data'!$A:$P,V$10+3,FALSE)),0,VLOOKUP($B17,'MRI Data'!$A:$P,V$10+3,FALSE)) -> 3549 | V17: =SUM(T17:U17) -> 3549 | W17: 3549 | X17: =+V17-W17 -> 0 | Z17: =+Q17+V17 -> 7098 | AA17: =+R17+W17 -> 7098 | AB17: =+Z17-AA17 -> 0 | AC17: =IF(ISERROR(VLOOKUP($B17,'MRI Data'!$A:$P,AE$10+3,FALSE)),0,VLOOKUP($B17,'MRI Data'!$A:$P,AE$10+3,FALSE)) -> 3549 | AE17: =SUM(AC17:AD17) -> 3549 | AF17: 3549 | AG17: =+AE17-AF17 -> 0 | AI17: =+Z17+AE17 -> 10647 | AJ17: =+AA17+AF17 -> 10647 | AK17: =+AI17-AJ17 -> 0 | AL17: =IF(ISERROR(VLOOKUP($B17,'MRI Data'!$A:$P,AN$10+3,FALSE)),0,VLOOKUP($B17,'MRI Data'!$A:$P,AN$10+3,FALSE)) -> 3549 | AN17: =SUM(AL17:AM17) -> 3549 | AO17: 3549 | AP17: =+AN17-AO17 -> 0 | AR17: =+AI17+AN17 -> 14196 | AS17: =+AJ17+AO17 -> 14196 | AT17: =+AR17-AS17 -> 0 | AU17: =IF(ISERROR(VLOOKUP($B17,'MRI Data'!$A:$P,AW$10+3,FALSE)),0,VLOOKUP($B17,'MRI Data'!$A:$P,AW$10+3,FALSE)) -> 3549 | AW17: =SUM(AU17:AV17) -> 3549 | AX17: 3549 | AY17: =+AW17-AX17 -> 0 | BA17: =+AR17+AW17 -> 17745 | BB17: =+AS17+AX17 -> 17745 | BC17: =+BA17-BB17 -> 0 | BD17: =IF(ISERROR(VLOOKUP($B17,'MRI Data'!$A:$P,BF$10+3,FALSE)),0,VLOOKUP($B17,'MRI Data'!$A:$P,BF$10+3,FALSE)) -> 3690.92 | BF17: =SUM(BD17:BE17) -> 3690.92 | BG17: 3691 | BH17: =+BF17-BG17 -> -0.08 | BJ17: =+BA17+BF17 -> 21435.92 | BK17: =+BB17+BG17 -> 21436 | BL17: =+BJ17-BK17 -> -0.08 | BM17: =IF(ISERROR(VLOOKUP($B17,'MRI Data'!$A:$P,BO$10+3,FALSE)),0,VLOOKUP($B17,'MRI Data'!$A:$P,BO$10+3,FALSE)) -> 3690.92 | BO17: =SUM(BM17:BN17) -> 3690.92 | BP17: 3691 | BQ17: =+BO17-BP17 -> -0.08 | BS17: =+BJ17+BO17 -> 25126.84 | BT17: =+BK17+BP17 -> 25127 | BU17: =+BS17-BT17 -> -0.16 | BV17: =IF(ISERROR(VLOOKUP($B17,'MRI Data'!$A:$P,BX$10+3,FALSE)),0,VLOOKUP($B17,'MRI Data'!$A:$P,BX$10+3,FALSE)) -> 3690.92 | BX17: =SUM(BV17:BW17) -> 3690.92 | BY17: 3691 | BZ17: =+BX17-BY17 -> -0.08 | CB17: =+BS17+BX17 -> 28817.76 | CC17: =+BT17+BY17 -> 28818 | CD17: =+CB17-CC17 -> -0.24 | CE17: =IF(ISERROR(VLOOKUP($B17,'MRI Data'!$A:$P,CG$10+3,FALSE)),0,VLOOKUP($B17,'MRI Data'!$A:$P,CG$10+3,FALSE)) -> 3690.92 | CG17: =SUM(CE17:CF17) -> 3690.92 | CH17: 3691 | CI17: =+CG17-CH17 -> -0.08 | CK17: =+CB17+CG17 -> 32508.68 | CL17: =+CC17+CH17 -> 32509 | CM17: =+CK17-CL17 -> -0.32 | CN17: =IF(ISERROR(VLOOKUP($B17,'MRI Data'!$A:$P,CP$10+3,FALSE)),0,VLOOKUP($B17,'MRI Data'!$A:$P,CP$10+3,FALSE)) -> 3690.92 | CP17: =SUM(CN17:CO17) -> 3690.92 | CQ17: 3691 | CR17: =+CP17-CQ17 -> -0.08 | CT17: =+CK17+CP17 -> 36199.6 | CU17: =+CL17+CQ17 -> 36200 | CV17: =+CT17-CU17 -> -0.4 | CW17: =IF(ISERROR(VLOOKUP($B17,'MRI Data'!$A:$P,CY$10+3,FALSE)),0,VLOOKUP($B17,'MRI Data'!$A:$P,CY$10+3,FALSE)) -> 3690.92 | CY17: =SUM(CW17:CX17) -> 3690.92 | CZ17: 3691 | DA17: =+CY17-CZ17 -> -0.08 | DC17: =+CT17+CY17 -> 39890.52 | DD17: =+CU17+CZ17 -> 39891 | DE17: =+DC17-DD17 -> -0.48 | DF17: =IF(ISERROR(VLOOKUP($B17,'MRI Data'!$A:$P,DH$10+3,FALSE)),0,VLOOKUP($B17,'MRI Data'!$A:$P,DH$10+3,FALSE)) -> 3690.92 | DH17: =SUM(DF17:DG17) -> 3690.92 | DI17: 3691 | DJ17: =+DH17-DI17 -> -0.08 | DL17: =+DC17+DH17 -> 43581.44 | DM17: =+DD17+DI17 -> 43582 | DN17: =+DL17-DM17 -> -0.56 | DQ17: =+DM17 -> 43582 | DR17: 0
A18: =+A17+1 -> 5 | B18: 621201-000006 | C18: Pacific Coast Floral | D18: 33574 | E18: 41090 | F18: Occupied | G18: 1072 | H18: 1080 | I18: =HLOOKUP(I$10,M$10:DI$53,ROW()-9,FALSE) -> 4825.85 | K18: =IF(ISERROR(VLOOKUP($B18,'MRI Data'!$A:$P,M$10+3,FALSE)),0,VLOOKUP($B18,'MRI Data'!$A:$P,M$10+3,FALSE)) -> 4554.24 | M18: =SUM(K18:L18) -> 4554.24 | N18: 4860 | O18: =+M18-N18 -> -305.76 | Q18: =+M18 -> 4554.24 | R18: =+N18 -> 4860 | S18: =O18 -> -305.76 | T18: =IF(ISERROR(VLOOKUP($B18,'MRI Data'!$A:$P,V$10+3,FALSE)),0,VLOOKUP($B18,'MRI Data'!$A:$P,V$10+3,FALSE)) -> 4860 | V18: =SUM(T18:U18) -> 4860 | W18: 4860 | X18: =+V18-W18 -> 0 | Z18: =+Q18+V18 -> 9414.24 | AA18: =+R18+W18 -> 9720 | AB18: =+Z18-AA18 -> -305.76 | AC18: =IF(ISERROR(VLOOKUP($B18,'MRI Data'!$A:$P,AE$10+3,FALSE)),0,VLOOKUP($B18,'MRI Data'!$A:$P,AE$10+3,FALSE)) -> 4860 | AE18: =SUM(AC18:AD18) -> 4860 | AF18: 4860 | AG18: =+AE18-AF18 -> 0 | AI18: =+Z18+AE18 -> 14274.24 | AJ18: =+AA18+AF18 -> 14580 | AK18: =+AI18-AJ18 -> -305.76 | AL18: =IF(ISERROR(VLOOKUP($B18,'MRI Data'!$A:$P,AN$10+3,FALSE)),0,VLOOKUP($B18,'MRI Data'!$A:$P,AN$10+3,FALSE)) -> 4860 | AN18: =SUM(AL18:AM18) -> 4860 | AO18: 4860 | AP18: =+AN18-AO18 -> 0 | AR18: =+AI18+AN18 -> 19134.24 | AS18: =+AJ18+AO18 -> 19440 | AT18: =+AR18-AS18 -> -305.76 | AU18: =IF(ISERROR(VLOOKUP($B18,'MRI Data'!$A:$P,AW$10+3,FALSE)),0,VLOOKUP($B18,'MRI Data'!$A:$P,AW$10+3,FALSE)) -> 4860 | AV18: =-12150+6075 -> -6075 | AW18: =SUM(AU18:AV18) -> -1215 | AX18: 4860 | AY18: =+AW18-AX18 -> -6075 | BA18: =+AR18+AW18 -> 17919.24 | BB18: =+AS18+AX18 -> 24300 | BC18: =+BA18-BB18 -> -6380.76 | BD18: =IF(ISERROR(VLOOKUP($B18,'MRI Data'!$A:$P,BF$10+3,FALSE)),0,VLOOKUP($B18,'MRI Data'!$A:$P,BF$10+3,FALSE)) -> -9720 | BE18: 18711 | BF18: =SUM(BD18:BE18) -> 8991 | BG18: 4860 | BH18: =+BF18-BG18 -> 4131 | BJ18: =+BA18+BF18 -> 26910.24 | BK18: =+BB18+BG18 -> 29160 | BL18: =+BJ18-BK18 -> -2249.76 | BM18: =IF(ISERROR(VLOOKUP($B18,'MRI Data'!$A:$P,BO$10+3,FALSE)),0,VLOOKUP($B18,'MRI Data'!$A:$P,BO$10+3,FALSE)) -> 4860 | BN18: 0 | BO18: =SUM(BM18:BN18) -> 4860 | BP18: 4860 | BQ18: =+BO18-BP18 -> 0 | BS18: =+BJ18+BO18 -> 31770.24 | BT18: =+BK18+BP18 -> 34020 | BU18: =+BS18-BT18 -> -2249.76 | BV18: =IF(ISERROR(VLOOKUP($B18,'MRI Data'!$A:$P,BX$10+3,FALSE)),0,VLOOKUP($B18,'MRI Data'!$A:$P,BX$10+3,FALSE)) -> 4860 | BW18: 0 | BX18: =SUM(BV18:BW18) -> 4860 | BY18: 4860 | BZ18: =+BX18-BY18 -> 0 | CB18: =+BS18+BX18 -> 36630.24 | CC18: =+BT18+BY18 -> 38880 | CD18: =+CB18-CC18 -> -2249.76 | CE18: =IF(ISERROR(VLOOKUP($B18,'MRI Data'!$A:$P,CG$10+3,FALSE)),0,VLOOKUP($B18,'MRI Data'!$A:$P,CG$10+3,FALSE)) -> 4860 | CF18: 0 | CG18: =SUM(CE18:CF18) -> 4860 | CH18: 4860 | CI18: =+CG18-CH18 -> 0 | CK18: =+CB18+CG18 -> 41490.24 | CL18: =+CC18+CH18 -> 43740 | CM18: =+CK18-CL18 -> -2249.76 | CN18: =IF(ISERROR(VLOOKUP($B18,'MRI Data'!$A:$P,CP$10+3,FALSE)),0,VLOOKUP($B18,'MRI Data'!$A:$P,CP$10+3,FALSE)) -> -980.2 | CO18: 2920.1 | CP18: =SUM(CN18:CO18) -> 1939.9 | CQ18: 4860 | CR18: =+CP18-CQ18 -> -2920.1 | CT18: =+CK18+CP18 -> 43430.14 | CU18: =+CL18+CQ18 -> 48600 | CV18: =+CT18-CU18 -> -5169.86 | CW18: =IF(ISERROR(VLOOKUP($B18,'MRI Data'!$A:$P,CY$10+3,FALSE)),0,VLOOKUP($B18,'MRI Data'!$A:$P,CY$10+3,FALSE)) -> 3492.4 | CX18: =-2920.1+3603.9 -> 683.8 | CY18: =SUM(CW18:CX18) -> 4176.2 | CZ18: 4860 | DA18: =+CY18-CZ18 -> -683.8 | DC18: =+CT18+CY18 -> 47606.34 | DD18: =+CU18+CZ18 -> 53460 | DE18: =+DC18-DD18 -> -5853.66 | DF18: =IF(ISERROR(VLOOKUP($B18,'MRI Data'!$A:$P,DH$10+3,FALSE)),0,VLOOKUP($B18,'MRI Data'!$A:$P,DH$10+3,FALSE)) -> 5174.2 | DG18: =-3603.9+3255.55 -> -348.35 | DH18: =SUM(DF18:DG18) -> 4825.85 | DI18: 4860 | DJ18: =+DH18-DI18 -> -34.15 | DL18: =+DC18+DH18 -> 52432.19 | DM18: =+DD18+DI18 -> 58320 | DN18: =+DL18-DM18 -> -5887.81 | DO18: Tenant on rent relief 7/09-12/09 pay greater of 10% of sales or 50% of base rent. TT security deposit $5,346 was applied to the Deferral amount. TT repay 1/2 of the deferral amount in a promissory note. TT rent relief extended 01/10-6/10 pay greater of 20% of sales or 50% of base rent. TT repay 1/2 of the deferral amount in a promissory note. | DQ18: =+DM18 -> 58320 | DR18: -5888 | DS18: Tenant on rent relief 7/09-12/09 pay greater of 10% of sales or 50% of base rent. TT security deposit $5,346 was applied to the Deferral amount. TT repay 1/2 of the deferral amount in a promissory note. TT rent relief extended 01/10-6/10 pay greater of 20% of sales or 50% of base rent. TT repay 1/2 of the deferral amount in a promissory note.
A19: =+A18+1 -> 6 | B19: 621201-000008 | C19: Photo Lab - The | D19: 35217 | E19: 41060 | F19: Occupied | G19: 1048 | H19: 900 | I19: =HLOOKUP(I$10,M$10:DI$53,ROW()-9,FALSE) -> -875 | K19: =IF(ISERROR(VLOOKUP($B19,'MRI Data'!$A:$P,M$10+3,FALSE)),0,VLOOKUP($B19,'MRI Data'!$A:$P,M$10+3,FALSE)) -> -2475 | L19: 4950 | M19: =SUM(K19:L19) -> 2475 | N19: 4950 | O19: =+M19-N19 -> -2475 | Q19: =+M19 -> 2475 | R19: =+N19 -> 4950 | S19: =O19 -> -2475 | T19: =IF(ISERROR(VLOOKUP($B19,'MRI Data'!$A:$P,V$10+3,FALSE)),0,VLOOKUP($B19,'MRI Data'!$A:$P,V$10+3,FALSE)) -> 2475 | V19: =SUM(T19:U19) -> 2475 | W19: 4950 | X19: =+V19-W19 -> -2475 | Z19: =+Q19+V19 -> 4950 | AA19: =+R19+W19 -> 9900 | AB19: =+Z19-AA19 -> -4950 | AC19: =IF(ISERROR(VLOOKUP($B19,'MRI Data'!$A:$P,AE$10+3,FALSE)),0,VLOOKUP($B19,'MRI Data'!$A:$P,AE$10+3,FALSE)) -> 2475 | AE19: =SUM(AC19:AD19) -> 2475 | AF19: 4950 | AG19: =+AE19-AF19 -> -2475 | AI19: =+Z19+AE19 -> 7425 | AJ19: =+AA19+AF19 -> 14850 | AK19: =+AI19-AJ19 -> -7425 | AL19: =IF(ISERROR(VLOOKUP($B19,'MRI Data'!$A:$P,AN$10+3,FALSE)),0,VLOOKUP($B19,'MRI Data'!$A:$P,AN$10+3,FALSE)) -> 2475 | AN19: =SUM(AL19:AM19) -> 2475 | AO19: 4950 | AP19: =+AN19-AO19 -> -2475 | AR19: =+AI19+AN19 -> 9900 | AS19: =+AJ19+AO19 -> 19800 | AT19: =+AR19-AS19 -> -9900 | AU19: =IF(ISERROR(VLOOKUP($B19,'MRI Data'!$A:$P,AW$10+3,FALSE)),0,VLOOKUP($B19,'MRI Data'!$A:$P,AW$10+3,FALSE)) -> 2475 | AW19: =SUM(AU19:AV19) -> 2475 | AX19: 4950 | AY19: =+AW19-AX19 -> -2475 | BA19: =+AR19+AW19 -> 12375 | BB19: =+AS19+AX19 -> 24750 | BC19: =+BA19-BB19 -> -12375 | BD19: =IF(ISERROR(VLOOKUP($B19,'MRI Data'!$A:$P,BF$10+3,FALSE)),0,VLOOKUP($B19,'MRI Data'!$A:$P,BF$10+3,FALSE)) -> 2659.39 | BF19: =SUM(BD19:BE19) -> 2659.39 | BG19: 4950 | BH19: =+BF19-BG19 -> -2290.61 | BJ19: =+BA19+BF19 -> 15034.39 | BK19: =+BB19+BG19 -> 29700 | BL19: =+BJ19-BK19 -> -14665.61 | BM19: =IF(ISERROR(VLOOKUP($B19,'MRI Data'!$A:$P,BO$10+3,FALSE)),0,VLOOKUP($B19,'MRI Data'!$A:$P,BO$10+3,FALSE)) -> 4950 | BN19: 2771.57 | BO19: =SUM(BM19:BN19) -> 7721.57 | BP19: 4950 | BQ19: =+BO19-BP19 -> 2771.57 | BS19: =+BJ19+BO19 -> 22755.96 | BT19: =+BK19+BP19 -> 34650 | BU19: =+BS19-BT19 -> -11894.04 | BV19: =IF(ISERROR(VLOOKUP($B19,'MRI Data'!$A:$P,BX$10+3,FALSE)),0,VLOOKUP($B19,'MRI Data'!$A:$P,BX$10+3,FALSE)) -> 7721.57 | BW19: =-2772 -> -2772 | BX19: =SUM(BV19:BW19) -> 4949.57 | BY19: 4950 | BZ19: =+BX19-BY19 -> -0.43 | CB19: =+BS19+BX19 -> 27705.53 | CC19: =+BT19+BY19 -> 39600 | CD19: =+CB19-CC19 -> -11894.47 | CE19: =IF(ISERROR(VLOOKUP($B19,'MRI Data'!$A:$P,CG$10+3,FALSE)),0,VLOOKUP($B19,'MRI Data'!$A:$P,CG$10+3,FALSE)) -> 4950 | CF19: 0 | CG19: =SUM(CE19:CF19) -> 4950 | CH19: 4950 | CI19: =+CG19-CH19 -> 0 | CK19: =+CB19+CG19 -> 32655.53 | CL19: =+CC19+CH19 -> 44550 | CM19: =+CK19-CL19 -> -11894.47 | CN19: =IF(ISERROR(VLOOKUP($B19,'MRI Data'!$A:$P,CP$10+3,FALSE)),0,VLOOKUP($B19,'MRI Data'!$A:$P,CP$10+3,FALSE)) -> 4950 | CO19: 0 | CP19: =SUM(CN19:CO19) -> 4950 | CQ19: 4950 | CR19: =+CP19-CQ19 -> 0 | CT19: =+CK19+CP19 -> 37605.53 | CU19: =+CL19+CQ19 -> 49500 | CV19: =+CT19-CU19 -> -11894.47 | CW19: =IF(ISERROR(VLOOKUP($B19,'MRI Data'!$A:$P,CY$10+3,FALSE)),0,VLOOKUP($B19,'MRI Data'!$A:$P,CY$10+3,FALSE)) -> 4950 | CX19: 0 | CY19: =SUM(CW19:CX19) -> 4950 | CZ19: 4950 | DA19: =+CY19-CZ19 -> 0 | DC19: =+CT19+CY19 -> 42555.53 | DD19: =+CU19+CZ19 -> 54450 | DE19: =+DC19-DD19 -> -11894.47 | DF19: =IF(ISERROR(VLOOKUP($B19,'MRI Data'!$A:$P,DH$10+3,FALSE)),0,VLOOKUP($B19,'MRI Data'!$A:$P,DH$10+3,FALSE)) -> -4875 | DG19: 4000 | DH19: =SUM(DF19:DG19) -> -875 | DI19: 5100 | DJ19: =+DH19-DI19 -> -5975 | DL19: =+DC19+DH19 -> 41680.53 | DM19: =+DD19+DI19 -> 59550 | DN19: =+DL19-DM19 -> -17869.47 | DO19: Tenant on rent relief 5/09-12/09 pay the greater of 10% of sales or 50% of base rent. Per 6th Amendment dated 5/14/10, tenant on rent relief 3/10-9/10 pay the greater of 15% of sales or 50% of base rent. Retained SD $4K. | DQ19: =+DM19 -> 59550 | DR19: -17869 | DS19: Tenant on rent relief 5/09-12/09 pay the greater of 10% of sales or 50% of base rent. Per 6th Amendment dated 5/14/10, tenant on rent relief 3/10-9/10 pay the greater of 15% of sales or 50% of base rent. Retained SD $4K.
A20: =+A19+1 -> 7 | B20: 621201-S44199 | C20: Salon "L" | D20: 37838 | E20: 40786 | F20: Occupied | G20: 1040 | H20: 1500 | I20: =HLOOKUP(I$10,M$10:DI$53,ROW()-9,FALSE) -> 6468.75 | K20: =IF(ISERROR(VLOOKUP($B20,'MRI Data'!$A:$P,M$10+3,FALSE)),0,VLOOKUP($B20,'MRI Data'!$A:$P,M$10+3,FALSE)) -> 6250 | M20: =SUM(K20:L20) -> 6250 | N20: 6250 | O20: =+M20-N20 -> 0 | Q20: =+M20 -> 6250 | R20: =+N20 -> 6250 | S20: =O20 -> 0 | T20: =IF(ISERROR(VLOOKUP($B20,'MRI Data'!$A:$P,V$10+3,FALSE)),0,VLOOKUP($B20,'MRI Data'!$A:$P,V$10+3,FALSE)) -> 6250 | V20: =SUM(T20:U20) -> 6250 | W20: 6250 | X20: =+V20-W20 -> 0 | Z20: =+Q20+V20 -> 12500 | AA20: =+R20+W20 -> 12500 | AB20: =+Z20-AA20 -> 0 | AC20: =IF(ISERROR(VLOOKUP($B20,'MRI Data'!$A:$P,AE$10+3,FALSE)),0,VLOOKUP($B20,'MRI Data'!$A:$P,AE$10+3,FALSE)) -> 6468.75 | AE20: =SUM(AC20:AD20) -> 6468.75 | AF20: 6469 | AG20: =+AE20-AF20 -> -0.25 | AI20: =+Z20+AE20 -> 18968.75 | AJ20: =+AA20+AF20 -> 18969 | AK20: =+AI20-AJ20 -> -0.25 | AL20: =IF(ISERROR(VLOOKUP($B20,'MRI Data'!$A:$P,AN$10+3,FALSE)),0,VLOOKUP($B20,'MRI Data'!$A:$P,AN$10+3,FALSE)) -> 6468.75 | AN20: =SUM(AL20:AM20) -> 6468.75 | AO20: 6469 | AP20: =+AN20-AO20 -> -0.25 | AR20: =+AI20+AN20 -> 25437.5 | AS20: =+AJ20+AO20 -> 25438 | AT20: =+AR20-AS20 -> -0.5 | AU20: =IF(ISERROR(VLOOKUP($B20,'MRI Data'!$A:$P,AW$10+3,FALSE)),0,VLOOKUP($B20,'MRI Data'!$A:$P,AW$10+3,FALSE)) -> 6468.75 | AV20: =-12828.13+1737.62 -> -11090.51 | AW20: =SUM(AU20:AV20) -> -4621.76 | AX20: 6469 | AY20: =+AW20-AX20 -> -11090.76 | BA20: =+AR20+AW20 -> 20815.74 | BB20: =+AS20+AX20 -> 31907 | BC20: =+BA20-BB20 -> -11091.26 | BD20: =IF(ISERROR(VLOOKUP($B20,'MRI Data'!$A:$P,BF$10+3,FALSE)),0,VLOOKUP($B20,'MRI Data'!$A:$P,BF$10+3,FALSE)) -> -8640.5 | BE20: 26200 | BF20: =SUM(BD20:BE20) -> 17559.5 | BG20: 6469 | BH20: =+BF20-BG20 -> 11090.5 | BJ20: =+BA20+BF20 -> 38375.24 | BK20: =+BB20+BG20 -> 38376 | BL20: =+BJ20-BK20 -> -0.76 | BM20: =IF(ISERROR(VLOOKUP($B20,'MRI Data'!$A:$P,BO$10+3,FALSE)),0,VLOOKUP($B20,'MRI Data'!$A:$P,BO$10+3,FALSE)) -> 6250 | BN20: 219 | BO20: =SUM(BM20:BN20) -> 6469 | BP20: 6469 | BQ20: =+BO20-BP20 -> 0 | BS20: =+BJ20+BO20 -> 44844.24 | BT20: =+BK20+BP20 -> 44845 | BU20: =+BS20-BT20 -> -0.76 | BV20: =IF(ISERROR(VLOOKUP($B20,'MRI Data'!$A:$P,BX$10+3,FALSE)),0,VLOOKUP($B20,'MRI Data'!$A:$P,BX$10+3,FALSE)) -> 7794.17 | BW20: -1325 | BX20: =SUM(BV20:BW20) -> 6469.17 | BY20: 6469 | BZ20: =+BX20-BY20 -> 0.17 | CB20: =+BS20+BX20 -> 51313.41 | CC20: =+BT20+BY20 -> 51314 | CD20: =+CB20-CC20 -> -0.59 | CE20: =IF(ISERROR(VLOOKUP($B20,'MRI Data'!$A:$P,CG$10+3,FALSE)),0,VLOOKUP($B20,'MRI Data'!$A:$P,CG$10+3,FALSE)) -> 6250 | CF20: =219 -> 219 | CG20: =SUM(CE20:CF20) -> 6469 | CH20: 6469 | CI20: =+CG20-CH20 -> 0 | CK20: =+CB20+CG20 -> 57782.41 | CL20: =+CC20+CH20 -> 57783 | CM20: =+CK20-CL20 -> -0.59 | CN20: =IF(ISERROR(VLOOKUP($B20,'MRI Data'!$A:$P,CP$10+3,FALSE)),0,VLOOKUP($B20,'MRI Data'!$A:$P,CP$10+3,FALSE)) -> 6250 | CO20: =219 -> 219 | CP20: =SUM(CN20:CO20) -> 6469 | CQ20: 6469 | CR20: =+CP20-CQ20 -> 0 | CT20: =+CK20+CP20 -> 64251.41 | CU20: =+CL20+CQ20 -> 64252 | CV20: =+CT20-CU20 -> -0.59 | CW20: =IF(ISERROR(VLOOKUP($B20,'MRI Data'!$A:$P,CY$10+3,FALSE)),0,VLOOKUP($B20,'MRI Data'!$A:$P,CY$10+3,FALSE)) -> 6250 | CX20: 218.75 | CY20: =SUM(CW20:CX20) -> 6468.75 | CZ20: 6469 | DA20: =+CY20-CZ20 -> -0.25 | DC20: =+CT20+CY20 -> 70720.16 | DD20: =+CU20+CZ20 -> 70721 | DE20: =+DC20-DD20 -> -0.84 | DF20: =IF(ISERROR(VLOOKUP($B20,'MRI Data'!$A:$P,DH$10+3,FALSE)),0,VLOOKUP($B20,'MRI Data'!$A:$P,DH$10+3,FALSE)) -> 6250 | DG20: 218.75 | DH20: =SUM(DF20:DG20) -> 6468.75 | DI20: 6469 | DJ20: =+DH20-DI20 -> -0.25 | DL20: =+DC20+DH20 -> 77188.91 | DM20: =+DD20+DI20 -> 77190 | DN20: =+DL20-DM20 -> -1.09 | DO20: Tenant on rent relief 8/09-12/09 pay greater of 10% of sales or 50% of base rent. TT repay the deferral amount in a promissory note. | DQ20: =+DM20 -> 77190 | DR20: 0
A21: =+A20+1 -> 8 | B21: 621201-000007 | C21: Sapori Restaurant Italiano | D21: 32674 | E21: 42735 | F21: Occupied | G21: 1080 | H21: 2742 | I21: =HLOOKUP(I$10,M$10:DI$53,ROW()-9,FALSE) -> 11425 | K21: =IF(ISERROR(VLOOKUP($B21,'MRI Data'!$A:$P,M$10+3,FALSE)),0,VLOOKUP($B21,'MRI Data'!$A:$P,M$10+3,FALSE)) -> 12770.87 | M21: =SUM(K21:L21) -> 12770.87 | N21: 12771 | O21: =+M21-N21 -> -0.13 | Q21: =+M21 -> 12770.87 | R21: =+N21 -> 12771 | S21: =O21 -> -0.13 | T21: =IF(ISERROR(VLOOKUP($B21,'MRI Data'!$A:$P,V$10+3,FALSE)),0,VLOOKUP($B21,'MRI Data'!$A:$P,V$10+3,FALSE)) -> 12770.87 | V21: =SUM(T21:U21) -> 12770.87 | W21: 12771 | X21: =+V21-W21 -> -0.13 | Z21: =+Q21+V21 -> 25541.74 | AA21: =+R21+W21 -> 25542 | AB21: =+Z21-AA21 -> -0.26 | AC21: =IF(ISERROR(VLOOKUP($B21,'MRI Data'!$A:$P,AE$10+3,FALSE)),0,VLOOKUP($B21,'MRI Data'!$A:$P,AE$10+3,FALSE)) -> 12770.87 | AE21: =SUM(AC21:AD21) -> 12770.87 | AF21: 12771 | AG21: =+AE21-AF21 -> -0.13 | AI21: =+Z21+AE21 -> 38312.61 | AJ21: =+AA21+AF21 -> 38313 | AK21: =+AI21-AJ21 -> -0.39 | AL21: =IF(ISERROR(VLOOKUP($B21,'MRI Data'!$A:$P,AN$10+3,FALSE)),0,VLOOKUP($B21,'MRI Data'!$A:$P,AN$10+3,FALSE)) -> 12770.87 | AN21: =SUM(AL21:AM21) -> 12770.87 | AO21: 12771 | AP21: =+AN21-AO21 -> -0.13 | AR21: =+AI21+AN21 -> 51083.48 | AS21: =+AJ21+AO21 -> 51084 | AT21: =+AR21-AS21 -> -0.52 | AU21: =IF(ISERROR(VLOOKUP($B21,'MRI Data'!$A:$P,AW$10+3,FALSE)),0,VLOOKUP($B21,'MRI Data'!$A:$P,AW$10+3,FALSE)) -> 12770.87 | AW21: =SUM(AU21:AV21) -> 12770.87 | AX21: 12771 | AY21: =+AW21-AX21 -> -0.13 | BA21: =+AR21+AW21 -> 63854.35 | BB21: =+AS21+AX21 -> 63855 | BC21: =+BA21-BB21 -> -0.65 | BD21: =IF(ISERROR(VLOOKUP($B21,'MRI Data'!$A:$P,BF$10+3,FALSE)),0,VLOOKUP($B21,'MRI Data'!$A:$P,BF$10+3,FALSE)) -> 12770.87 | BF21: =SUM(BD21:BE21) -> 12770.87 | BG21: 12771 | BH21: =+BF21-BG21 -> -0.13 | BJ21: =+BA21+BF21 -> 76625.22 | BK21: =+BB21+BG21 -> 76626 | BL21: =+BJ21-BK21 -> -0.78 | BM21: =IF(ISERROR(VLOOKUP($B21,'MRI Data'!$A:$P,BO$10+3,FALSE)),0,VLOOKUP($B21,'MRI Data'!$A:$P,BO$10+3,FALSE)) -> 11425 | BO21: =SUM(BM21:BN21) -> 11425 | BP21: 12771 | BQ21: =+BO21-BP21 -> -1346 | BS21: =+BJ21+BO21 -> 88050.22 | BT21: =+BK21+BP21 -> 89397 | BU21: =+BS21-BT21 -> -1346.78 | BV21: =IF(ISERROR(VLOOKUP($B21,'MRI Data'!$A:$P,BX$10+3,FALSE)),0,VLOOKUP($B21,'MRI Data'!$A:$P,BX$10+3,FALSE)) -> 11425 | BX21: =SUM(BV21:BW21) -> 11425 | BY21: 12771 | BZ21: =+BX21-BY21 -> -1346 | CB21: =+BS21+BX21 -> 99475.22 | CC21: =+BT21+BY21 -> 102168 | CD21: =+CB21-CC21 -> -2692.78 | CE21: =IF(ISERROR(VLOOKUP($B21,'MRI Data'!$A:$P,CG$10+3,FALSE)),0,VLOOKUP($B21,'MRI Data'!$A:$P,CG$10+3,FALSE)) -> 11425 | CG21: =SUM(CE21:CF21) -> 11425 | CH21: 12771 | CI21: =+CG21-CH21 -> -1346 | CK21: =+CB21+CG21 -> 110900.22 | CL21: =+CC21+CH21 -> 114939 | CM21: =+CK21-CL21 -> -4038.78 | CN21: =IF(ISERROR(VLOOKUP($B21,'MRI Data'!$A:$P,CP$10+3,FALSE)),0,VLOOKUP($B21,'MRI Data'!$A:$P,CP$10+3,FALSE)) -> 11425 | CP21: =SUM(CN21:CO21) -> 11425 | CQ21: 12771 | CR21: =+CP21-CQ21 -> -1346 | CT21: =+CK21+CP21 -> 122325.22 | CU21: =+CL21+CQ21 -> 127710 | CV21: =+CT21-CU21 -> -5384.78 | CW21: =IF(ISERROR(VLOOKUP($B21,'MRI Data'!$A:$P,CY$10+3,FALSE)),0,VLOOKUP($B21,'MRI Data'!$A:$P,CY$10+3,FALSE)) -> 11425 | CY21: =SUM(CW21:CX21) -> 11425 | CZ21: 12771 | DA21: =+CY21-CZ21 -> -1346 | DC21: =+CT21+CY21 -> 133750.22 | DD21: =+CU21+CZ21 -> 140481 | DE21: =+DC21-DD21 -> -6730.78 | DF21: =IF(ISERROR(VLOOKUP($B21,'MRI Data'!$A:$P,DH$10+3,FALSE)),0,VLOOKUP($B21,'MRI Data'!$A:$P,DH$10+3,FALSE)) -> 11425 | DH21: =SUM(DF21:DG21) -> 11425 | DI21: 12771 | DJ21: =+DH21-DI21 -> -1346 | DL21: =+DC21+DH21 -> 145175.22 | DM21: =+DD21+DI21 -> 153252 | DN21: =+DL21-DM21 -> -8076.78 | DO21: Per 7th Amendment dated 10/13/09, tenant renewed eff 1/1/10 @ $50/sf vs. Plan @ $56/sf | DQ21: =+DM21 -> 153252 | DR21: =(11425-12771)*6 -> -8076 | DS21: Per 7th Amendment dated 10/13/09, tenant renewed eff 1/1/10 @ $50/sf vs. Plan @ $56/sf
A22: =+A21+1 -> 9 | C22: Sapori Restaurant Italiano-Patio | D22: 39234 | E22: 42735 | F22: Occupied | G22: 1080A | H22: 1309 | I22: =HLOOKUP(I$10,M$10:DI$53,ROW()-9,FALSE) -> 0.0001 | K22: =IF(ISERROR(VLOOKUP($B22,'MRI Data'!$A:$P,M$10+3,FALSE)),0,VLOOKUP($B22,'MRI Data'!$A:$P,M$10+3,FALSE)) -> 0 | L22: 0.0001 | M22: =SUM(K22:L22) -> 0.0001 | N22: 0 | O22: =+M22-N22 -> 0.0001 | Q22: =+M22 -> 0.0001 | R22: =+N22 -> 0 | S22: =O22 -> 0.0001 | T22: =IF(ISERROR(VLOOKUP($B22,'MRI Data'!$A:$P,V$10+3,FALSE)),0,VLOOKUP($B22,'MRI Data'!$A:$P,V$10+3,FALSE)) -> 0 | U22: 0.0001 | V22: =SUM(T22:U22) -> 0.0001 | W22: 0 | X22: =+V22-W22 -> 0.0001 | Z22: =+Q22+V22 -> 0.0002 | AA22: =+R22+W22 -> 0 | AB22: =+Z22-AA22 -> 0.0002 | AC22: =IF(ISERROR(VLOOKUP($B22,'MRI Data'!$A:$P,AE$10+3,FALSE)),0,VLOOKUP($B22,'MRI Data'!$A:$P,AE$10+3,FALSE)) -> 0 | AD22: 0.0001 | AE22: =SUM(AC22:AD22) -> 0.0001 | AF22: 0 | AG22: =+AE22-AF22 -> 0.0001 | AI22: =+Z22+AE22 -> 0.0003 | AJ22: =+AA22+AF22 -> 0 | AK22: =+AI22-AJ22 -> 0.0003 | AL22: =IF(ISERROR(VLOOKUP($B22,'MRI Data'!$A:$P,AN$10+3,FALSE)),0,VLOOKUP($B22,'MRI Data'!$A:$P,AN$10+3,FALSE)) -> 0 | AM22: 0.0001 | AN22: =SUM(AL22:AM22) -> 0.0001 | AO22: 0 | AP22: =+AN22-AO22 -> 0.0001 | AR22: =+AI22+AN22 -> 0.0004 | AS22: =+AJ22+AO22 -> 0 | AT22: =+AR22-AS22 -> 0.0004 | AU22: =IF(ISERROR(VLOOKUP($B22,'MRI Data'!$A:$P,AW$10+3,FALSE)),0,VLOOKUP($B22,'MRI Data'!$A:$P,AW$10+3,FALSE)) -> 0 | AV22: 0.0001 | AW22: =SUM(AU22:AV22) -> 0.0001 | AX22: 0 | AY22: =+AW22-AX22 -> 0.0001 | BA22: =+AR22+AW22 -> 0.0005 | BB22: =+AS22+AX22 -> 0 | BC22: =+BA22-BB22 -> 0.0005 | BD22: =IF(ISERROR(VLOOKUP($B22,'MRI Data'!$A:$P,BF$10+3,FALSE)),0,VLOOKUP($B22,'MRI Data'!$A:$P,BF$10+3,FALSE)) -> 0 | BE22: 0.0001 | BF22: =SUM(BD22:BE22) -> 0.0001 | BG22: 0 | BH22: =+BF22-BG22 -> 0.0001 | BJ22: =+BA22+BF22 -> 0.0006 | BK22: =+BB22+BG22 -> 0 | BL22: =+BJ22-BK22 -> 0.0006 | BM22: =IF(ISERROR(VLOOKUP($B22,'MRI Data'!$A:$P,BO$10+3,FALSE)),0,VLOOKUP($B22,'MRI Data'!$A:$P,BO$10+3,FALSE)) -> 0 | BN22: 0.0001 | BO22: =SUM(BM22:BN22) -> 0.0001 | BP22: 0 | BQ22: =+BO22-BP22 -> 0.0001 | BS22: =+BJ22+BO22 -> 0.0007 | BT22: =+BK22+BP22 -> 0 | BU22: =+BS22-BT22 -> 0.0007 | BV22: =IF(ISERROR(VLOOKUP($B22,'MRI Data'!$A:$P,BX$10+3,FALSE)),0,VLOOKUP($B22,'MRI Data'!$A:$P,BX$10+3,FALSE)) -> 0 | BW22: 0.0001 | BX22: =SUM(BV22:BW22) -> 0.0001 | BY22: 0 | BZ22: =+BX22-BY22 -> 0.0001 | CB22: =+BS22+BX22 -> 0.0008 | CC22: =+BT22+BY22 -> 0 | CD22: =+CB22-CC22 -> 0.0008 | CE22: =IF(ISERROR(VLOOKUP($B22,'MRI Data'!$A:$P,CG$10+3,FALSE)),0,VLOOKUP($B22,'MRI Data'!$A:$P,CG$10+3,FALSE)) -> 0 | CF22: 0.0001 | CG22: =SUM(CE22:CF22) -> 0.0001 | CH22: 0 | CI22: =+CG22-CH22 -> 0.0001 | CK22: =+CB22+CG22 -> 0.0009 | CL22: =+CC22+CH22 -> 0 | CM22: =+CK22-CL22 -> 0.0009 | CN22: =IF(ISERROR(VLOOKUP($B22,'MRI Data'!$A:$P,CP$10+3,FALSE)),0,VLOOKUP($B22,'MRI Data'!$A:$P,CP$10+3,FALSE)) -> 0 | CO22: 0.0001 | CP22: =SUM(CN22:CO22) -> 0.0001 | CQ22: 0 | CR22: =+CP22-CQ22 -> 0.0001 | CT22: =+CK22+CP22 -> 0.001 | CU22: =+CL22+CQ22 -> 0 | CV22: =+CT22-CU22 -> 0.001 | CW22: =IF(ISERROR(VLOOKUP($B22,'MRI Data'!$A:$P,CY$10+3,FALSE)),0,VLOOKUP($B22,'MRI Data'!$A:$P,CY$10+3,FALSE)) -> 0 | CX22: 0.0001 | CY22: =SUM(CW22:CX22) -> 0.0001 | CZ22: 0 | DA22: =+CY22-CZ22 -> 0.0001 | DC22: =+CT22+CY22 -> 0.0011 | DD22: =+CU22+CZ22 -> 0 | DE22: =+DC22-DD22 -> 0.0011 | DF22: =IF(ISERROR(VLOOKUP($B22,'MRI Data'!$A:$P,DH$10+3,FALSE)),0,VLOOKUP($B22,'MRI Data'!$A:$P,DH$10+3,FALSE)) -> 0 | DG22: 0.0001 | DH22: =SUM(DF22:DG22) -> 0.0001 | DI22: 0 | DJ22: =+DH22-DI22 -> 0.0001 | DL22: =+DC22+DH22 -> 0.0012 | DM22: =+DD22+DI22 -> 0 | DN22: =+DL22-DM22 -> 0.0012 | DQ22: =+DM22 -> 0 | DR22: 0
A23: =+A22+1 -> 10 | C23: Vacant | F23: Vacant | G23: 1024 | H23: 1200 | I23: =HLOOKUP(I$10,M$10:DI$53,ROW()-9,FALSE) -> 0 | K23: =IF(ISERROR(VLOOKUP($B23,'MRI Data'!$A:$P,M$10+3,FALSE)),0,VLOOKUP($B23,'MRI Data'!$A:$P,M$10+3,FALSE)) -> 0 | M23: =SUM(K23:L23) -> 0 | N23: 0 | O23: =+M23-N23 -> 0 | Q23: =+M23 -> 0 | R23: =+N23 -> 0 | S23: =O23 -> 0 | T23: =IF(ISERROR(VLOOKUP($B23,'MRI Data'!$A:$P,V$10+3,FALSE)),0,VLOOKUP($B23,'MRI Data'!$A:$P,V$10+3,FALSE)) -> 0 | V23: =SUM(T23:U23) -> 0 | W23: 0 | X23: =+V23-W23 -> 0 | Z23: =+Q23+V23 -> 0 | AA23: =+R23+W23 -> 0 | AB23: =+Z23-AA23 -> 0 | AC23: =IF(ISERROR(VLOOKUP($B23,'MRI Data'!$A:$P,AE$10+3,FALSE)),0,VLOOKUP($B23,'MRI Data'!$A:$P,AE$10+3,FALSE)) -> 0 | AE23: =SUM(AC23:AD23) -> 0 | AF23: 0 | AG23: =+AE23-AF23 -> 0 | AI23: =+Z23+AE23 -> 0 | AJ23: =+AA23+AF23 -> 0 | AK23: =+AI23-AJ23 -> 0 | AL23: =IF(ISERROR(VLOOKUP($B23,'MRI Data'!$A:$P,AN$10+3,FALSE)),0,VLOOKUP($B23,'MRI Data'!$A:$P,AN$10+3,FALSE)) -> 0 | AN23: =SUM(AL23:AM23) -> 0 | AO23: 0 | AP23: =+AN23-AO23 -> 0 | AR23: =+AI23+AN23 -> 0 | AS23: =+AJ23+AO23 -> 0 | AT23: =+AR23-AS23 -> 0 | AU23: =IF(ISERROR(VLOOKUP($B23,'MRI Data'!$A:$P,AW$10+3,FALSE)),0,VLOOKUP($B23,'MRI Data'!$A:$P,AW$10+3,FALSE)) -> 0 | AW23: =SUM(AU23:AV23) -> 0 | AX23: 0 | AY23: =+AW23-AX23 -> 0 | BA23: =+AR23+AW23 -> 0 | BB23: =+AS23+AX23 -> 0 | BC23: =+BA23-BB23 -> 0 | BD23: =IF(ISERROR(VLOOKUP($B23,'MRI Data'!$A:$P,BF$10+3,FALSE)),0,VLOOKUP($B23,'MRI Data'!$A:$P,BF$10+3,FALSE)) -> 0 | BF23: =SUM(BD23:BE23) -> 0 | BG23: 5500 | BH23: =+BF23-BG23 -> -5500 | BJ23: =+BA23+BF23 -> 0 | BK23: =+BB23+BG23 -> 5500 | BL23: =+BJ23-BK23 -> -5500 | BM23: =IF(ISERROR(VLOOKUP($B23,'MRI Data'!$A:$P,BO$10+3,FALSE)),0,VLOOKUP($B23,'MRI Data'!$A:$P,BO$10+3,FALSE)) -> 0 | BO23: =SUM(BM23:BN23) -> 0 | BP23: 5500 | BQ23: =+BO23-BP23 -> -5500 | BS23: =+BJ23+BO23 -> 0 | BT23: =+BK23+BP23 -> 11000 | BU23: =+BS23-BT23 -> -11000 | BV23: =IF(ISERROR(VLOOKUP($B23,'MRI Data'!$A:$P,BX$10+3,FALSE)),0,VLOOKUP($B23,'MRI Data'!$A:$P,BX$10+3,FALSE)) -> 0 | BX23: =SUM(BV23:BW23) -> 0 | BY23: 5500 | BZ23: =+BX23-BY23 -> -5500 | CB23: =+BS23+BX23 -> 0 | CC23: =+BT23+BY23 -> 16500 | CD23: =+CB23-CC23 -> -16500 | CE23: =IF(ISERROR(VLOOKUP($B23,'MRI Data'!$A:$P,CG$10+3,FALSE)),0,VLOOKUP($B23,'MRI Data'!$A:$P,CG$10+3,FALSE)) -> 0 | CG23: =SUM(CE23:CF23) -> 0 | CH23: 5500 | CI23: =+CG23-CH23 -> -5500 | CK23: =+CB23+CG23 -> 0 | CL23: =+CC23+CH23 -> 22000 | CM23: =+CK23-CL23 -> -22000 | CN23: =IF(ISERROR(VLOOKUP($B23,'MRI Data'!$A:$P,CP$10+3,FALSE)),0,VLOOKUP($B23,'MRI Data'!$A:$P,CP$10+3,FALSE)) -> 0 | CP23: =SUM(CN23:CO23) -> 0 | CQ23: 5500 | CR23: =+CP23-CQ23 -> -5500 | CT23: =+CK23+CP23 -> 0 | CU23: =+CL23+CQ23 -> 27500 | CV23: =+CT23-CU23 -> -27500 | CW23: =IF(ISERROR(VLOOKUP($B23,'MRI Data'!$A:$P,CY$10+3,FALSE)),0,VLOOKUP($B23,'MRI Data'!$A:$P,CY$10+3,FALSE)) -> 0 | CY23: =SUM(CW23:CX23) -> 0 | CZ23: 5500 | DA23: =+CY23-CZ23 -> -5500 | DC23: =+CT23+CY23 -> 0 | DD23: =+CU23+CZ23 -> 33000 | DE23: =+DC23-DD23 -> -33000 | DF23: =IF(ISERROR(VLOOKUP($B23,'MRI Data'!$A:$P,DH$10+3,FALSE)),0,VLOOKUP($B23,'MRI Data'!$A:$P,DH$10+3,FALSE)) -> 0 | DH23: =SUM(DF23:DG23) -> 0 | DI23: 5500 | DJ23: =+DH23-DI23 -> -5500 | DL23: =+DC23+DH23 -> 0 | DM23: =+DD23+DI23 -> 38500 | DN23: =+DL23-DM23 -> -38500 | DO23: Space vacant, planned for occupancy 12/09 | DQ23: =+DM23 -> 38500 | DR23: -38500 | DS23: Space vacant, planned for occupancy 12/09
A24: =+A23+1 -> 11 | I24: =HLOOKUP(I$10,M$10:DI$53,ROW()-9,FALSE) -> 0 | M24: =SUM(K24:L24) -> 0 | O24: =+M24-N24 -> 0 | Q24: =+M24 -> 0 | R24: =+N24 -> 0 | S24: =O24 -> 0 | V24: =SUM(T24:U24) -> 0 | X24: =+V24-W24 -> 0 | Z24: =+Q24+V24 -> 0 | AA24: =+R24+W24 -> 0 | AB24: =+Z24-AA24 -> 0 | AE24: =SUM(AC24:AD24) -> 0 | AG24: =+AE24-AF24 -> 0 | AI24: =+Z24+AE24 -> 0 | AJ24: =+AA24+AF24 -> 0 | AK24: =+AI24-AJ24 -> 0 | AN24: =SUM(AL24:AM24) -> 0 | AP24: =+AN24-AO24 -> 0 | AR24: =+AI24+AN24 -> 0 | AS24: =+AJ24+AO24 -> 0 | AT24: =+AR24-AS24 -> 0 | AW24: =SUM(AU24:AV24) -> 0 | AY24: =+AW24-AX24 -> 0 | BA24: =+AR24+AW24 -> 0 | BB24: =+AS24+AX24 -> 0 | BC24: =+BA24-BB24 -> 0 | BF24: =SUM(BD24:BE24) -> 0 | BH24: =+BF24-BG24 -> 0 | BJ24: =+BA24+BF24 -> 0 | BK24: =+BB24+BG24 -> 0 | BL24: =+BJ24-BK24 -> 0 | BO24: =SUM(BM24:BN24) -> 0 | BQ24: =+BO24-BP24 -> 0 | BS24: =+BJ24+BO24 -> 0 | BT24: =+BK24+BP24 -> 0 | BU24: =+BS24-BT24 -> 0 | BX24: =SUM(BV24:BW24) -> 0 | BZ24: =+BX24-BY24 -> 0 | CB24: =+BS24+BX24 -> 0 | CC24: =+BT24+BY24 -> 0 | CD24: =+CB24-CC24 -> 0 | CG24: =SUM(CE24:CF24) -> 0 | CI24: =+CG24-CH24 -> 0 | CK24: =+CB24+CG24 -> 0 | CL24: =+CC24+CH24 -> 0 | CM24: =+CK24-CL24 -> 0 | CP24: =SUM(CN24:CO24) -> 0 | CR24: =+CP24-CQ24 -> 0 | CT24: =+CK24+CP24 -> 0 | CU24: =+CL24+CQ24 -> 0 | CV24: =+CT24-CU24 -> 0 | CY24: =SUM(CW24:CX24) -> 0 | DA24: =+CY24-CZ24 -> 0 | DC24: =+CT24+CY24 -> 0 | DD24: =+CU24+CZ24 -> 0 | DE24: =+DC24-DD24 -> 0 | DH24: =SUM(DF24:DG24) -> 0 | DJ24: =+DH24-DI24 -> 0 | DL24: =+DC24+DH24 -> 0 | DM24: =+DD24+DI24 -> 0 | DN24: =+DL24-DM24 -> 0 | DQ24: =+DM24 -> 0 | DR24: 0
A25: =+A24+1 -> 12 | I25: =HLOOKUP(I$10,M$10:DI$53,ROW()-9,FALSE) -> 0 | M25: =SUM(K25:L25) -> 0 | O25: =+M25-N25 -> 0 | Q25: =+M25 -> 0 | R25: =+N25 -> 0 | S25: =O25 -> 0 | V25: =SUM(T25:U25) -> 0 | X25: =+V25-W25 -> 0 | Z25: =+Q25+V25 -> 0 | AA25: =+R25+W25 -> 0 | AB25: =+Z25-AA25 -> 0 | AE25: =SUM(AC25:AD25) -> 0 | AG25: =+AE25-AF25 -> 0 | AI25: =+Z25+AE25 -> 0 | AJ25: =+AA25+AF25 -> 0 | AK25: =+AI25-AJ25 -> 0 | AN25: =SUM(AL25:AM25) -> 0 | AP25: =+AN25-AO25 -> 0 | AR25: =+AI25+AN25 -> 0 | AS25: =+AJ25+AO25 -> 0 | AT25: =+AR25-AS25 -> 0 | AW25: =SUM(AU25:AV25) -> 0 | AY25: =+AW25-AX25 -> 0 | BA25: =+AR25+AW25 -> 0 | BB25: =+AS25+AX25 -> 0 | BC25: =+BA25-BB25 -> 0 | BF25: =SUM(BD25:BE25) -> 0 | BH25: =+BF25-BG25 -> 0 | BJ25: =+BA25+BF25 -> 0 | BK25: =+BB25+BG25 -> 0 | BL25: =+BJ25-BK25 -> 0 | BO25: =SUM(BM25:BN25) -> 0 | BQ25: =+BO25-BP25 -> 0 | BS25: =+BJ25+BO25 -> 0 | BT25: =+BK25+BP25 -> 0 | BU25: =+BS25-BT25 -> 0 | BX25: =SUM(BV25:BW25) -> 0 | BZ25: =+BX25-BY25 -> 0 | CB25: =+BS25+BX25 -> 0 | CC25: =+BT25+BY25 -> 0 | CD25: =+CB25-CC25 -> 0 | CG25: =SUM(CE25:CF25) -> 0 | CI25: =+CG25-CH25 -> 0 | CK25: =+CB25+CG25 -> 0 | CL25: =+CC25+CH25 -> 0 | CM25: =+CK25-CL25 -> 0 | CP25: =SUM(CN25:CO25) -> 0 | CR25: =+CP25-CQ25 -> 0 | CT25: =+CK25+CP25 -> 0 | CU25: =+CL25+CQ25 -> 0 | CV25: =+CT25-CU25 -> 0 | CY25: =SUM(CW25:CX25) -> 0 | DA25: =+CY25-CZ25 -> 0 | DC25: =+CT25+CY25 -> 0 | DD25: =+CU25+CZ25 -> 0 | DE25: =+DC25-DD25 -> 0 | DH25: =SUM(DF25:DG25) -> 0 | DJ25: =+DH25-DI25 -> 0 | DL25: =+DC25+DH25 -> 0 | DM25: =+DD25+DI25 -> 0 | DN25: =+DL25-DM25 -> 0 | DQ25: =+DM25 -> 0 | DR25: 0
A26: =+A25+1 -> 13 | I26: =HLOOKUP(I$10,M$10:DI$53,ROW()-9,FALSE) -> 0 | M26: =SUM(K26:L26) -> 0 | O26: =+M26-N26 -> 0 | Q26: =+M26 -> 0 | R26: =+N26 -> 0 | S26: =O26 -> 0 | V26: =SUM(T26:U26) -> 0 | X26: =+V26-W26 -> 0 | Z26: =+Q26+V26 -> 0 | AA26: =+R26+W26 -> 0 | AB26: =+Z26-AA26 -> 0 | AE26: =SUM(AC26:AD26) -> 0 | AG26: =+AE26-AF26 -> 0 | AI26: =+Z26+AE26 -> 0 | AJ26: =+AA26+AF26 -> 0 | AK26: =+AI26-AJ26 -> 0 | AN26: =SUM(AL26:AM26) -> 0 | AP26: =+AN26-AO26 -> 0 | AR26: =+AI26+AN26 -> 0 | AS26: =+AJ26+AO26 -> 0 | AT26: =+AR26-AS26 -> 0 | AW26: =SUM(AU26:AV26) -> 0 | AY26: =+AW26-AX26 -> 0 | BA26: =+AR26+AW26 -> 0 | BB26: =+AS26+AX26 -> 0 | BC26: =+BA26-BB26 -> 0 | BF26: =SUM(BD26:BE26) -> 0 | BH26: =+BF26-BG26 -> 0 | BJ26: =+BA26+BF26 -> 0 | BK26: =+BB26+BG26 -> 0 | BL26: =+BJ26-BK26 -> 0 | BO26: =SUM(BM26:BN26) -> 0 | BQ26: =+BO26-BP26 -> 0 | BS26: =+BJ26+BO26 -> 0 | BT26: =+BK26+BP26 -> 0 | BU26: =+BS26-BT26 -> 0 | BX26: =SUM(BV26:BW26) -> 0 | BZ26: =+BX26-BY26 -> 0 | CB26: =+BS26+BX26 -> 0 | CC26: =+BT26+BY26 -> 0 | CD26: =+CB26-CC26 -> 0 | CG26: =SUM(CE26:CF26) -> 0 | CI26: =+CG26-CH26 -> 0 | CK26: =+CB26+CG26 -> 0 | CL26: =+CC26+CH26 -> 0 | CM26: =+CK26-CL26 -> 0 | CP26: =SUM(CN26:CO26) -> 0 | CR26: =+CP26-CQ26 -> 0 | CT26: =+CK26+CP26 -> 0 | CU26: =+CL26+CQ26 -> 0 | CV26: =+CT26-CU26 -> 0 | CY26: =SUM(CW26:CX26) -> 0 | DA26: =+CY26-CZ26 -> 0 | DC26: =+CT26+CY26 -> 0 | DD26: =+CU26+CZ26 -> 0 | DE26: =+DC26-DD26 -> 0 | DH26: =SUM(DF26:DG26) -> 0 | DJ26: =+DH26-DI26 -> 0 | DL26: =+DC26+DH26 -> 0 | DM26: =+DD26+DI26 -> 0 | DN26: =+DL26-DM26 -> 0 | DQ26: =+DM26 -> 0 | DR26: 0
A27: =+A26+1 -> 14 | I27: =HLOOKUP(I$10,M$10:DI$53,ROW()-9,FALSE) -> 0 | M27: =SUM(K27:L27) -> 0 | O27: =+M27-N27 -> 0 | Q27: =+M27 -> 0 | R27: =+N27 -> 0 | S27: =O27 -> 0 | V27: =SUM(T27:U27) -> 0 | X27: =+V27-W27 -> 0 | Z27: =+Q27+V27 -> 0 | AA27: =+R27+W27 -> 0 | AB27: =+Z27-AA27 -> 0 | AE27: =SUM(AC27:AD27) -> 0 | AG27: =+AE27-AF27 -> 0 | AI27: =+Z27+AE27 -> 0 | AJ27: =+AA27+AF27 -> 0 | AK27: =+AI27-AJ27 -> 0 | AN27: =SUM(AL27:AM27) -> 0 | AP27: =+AN27-AO27 -> 0 | AR27: =+AI27+AN27 -> 0 | AS27: =+AJ27+AO27 -> 0 | AT27: =+AR27-AS27 -> 0 | AW27: =SUM(AU27:AV27) -> 0 | AY27: =+AW27-AX27 -> 0 | BA27: =+AR27+AW27 -> 0 | BB27: =+AS27+AX27 -> 0 | BC27: =+BA27-BB27 -> 0 | BF27: =SUM(BD27:BE27) -> 0 | BH27: =+BF27-BG27 -> 0 | BJ27: =+BA27+BF27 -> 0 | BK27: =+BB27+BG27 -> 0 | BL27: =+BJ27-BK27 -> 0 | BO27: =SUM(BM27:BN27) -> 0 | BQ27: =+BO27-BP27 -> 0 | BS27: =+BJ27+BO27 -> 0 | BT27: =+BK27+BP27 -> 0 | BU27: =+BS27-BT27 -> 0 | BX27: =SUM(BV27:BW27) -> 0 | BZ27: =+BX27-BY27 -> 0 | CB27: =+BS27+BX27 -> 0 | CC27: =+BT27+BY27 -> 0 | CD27: =+CB27-CC27 -> 0 | CG27: =SUM(CE27:CF27) -> 0 | CI27: =+CG27-CH27 -> 0 | CK27: =+CB27+CG27 -> 0 | CL27: =+CC27+CH27 -> 0 | CM27: =+CK27-CL27 -> 0 | CP27: =SUM(CN27:CO27) -> 0 | CR27: =+CP27-CQ27 -> 0 | CT27: =+CK27+CP27 -> 0 | CU27: =+CL27+CQ27 -> 0 | CV27: =+CT27-CU27 -> 0 | CY27: =SUM(CW27:CX27) -> 0 | DA27: =+CY27-CZ27 -> 0 | DC27: =+CT27+CY27 -> 0 | DD27: =+CU27+CZ27 -> 0 | DE27: =+DC27-DD27 -> 0 | DH27: =SUM(DF27:DG27) -> 0 | DJ27: =+DH27-DI27 -> 0 | DL27: =+DC27+DH27 -> 0 | DM27: =+DD27+DI27 -> 0 | DN27: =+DL27-DM27 -> 0 | DQ27: =+DM27 -> 0 | DR27: 0
