Workbook

Sheet Executive Summary
A1: Executive Summary
A2: Coconut Grove
A3: March 2026
A6: Operations Manager | B6: Danielle Cebrero
A7: Assistant Property Manager: | B7: Audrey Verrette | G7: Square Feet: | H7: 50133
G8: % Leased: | H8: 0.8141
G9: % Occupied: | H9: 0.8141
A12: CASH | B12: Monthly Actual | C12: Monthly Budget | D12: Variance | E12: % Change | F12: YTD Actual | G12: YTD Budget | H12: Variance | I12: % Change
A13: Total Income | B13: 352489.67 | C13: 312627 | D13: =+B13-C13 -> 39862.67 | E13: =IF(C13=0,"N/A",D13/C13) -> 0.12750872 | F13: 943201.72 | G13: 937277 | H13: =+F13-G13 -> 5924.72 | I13: =IF(G13=0,"N/A",H13/G13) -> 0.0063212049
A14: Total Operating Expenses | B14: 113264.03 | C14: 114768.91 | D14: =+C14-B14 -> 1504.88 | E14: =IF(C14=0,"N/A",D14/C14) -> 0.013112262 | F14: 412739.25 | G14: 454327.83 | H14: =+G14-F14 -> 41588.58 | I14: =IF(G14=0,"N/A",H14/G14) -> 0.091538702
A15: Net Operating Income | B15: =+B13-B14 -> 239225.64 | C15: =+C13-C14 -> 197858.09 | D15: =+B15-C15 -> 41367.55 | E15: =IF(C15=0,"N/A",D15/C15) -> 0.20907687 | F15: =+F13-F14 -> 530462.47 | G15: =+G13-G14 -> 482949.17 | H15: =+F15-G15 -> 47513.3 | I15: =IF(G15=0,"N/A",H15/G15) -> 0.098381575
A16: Total Owners Expense | B16: -728448.65 | C16: 7175 | D16: =C16-B16 -> 735623.65 | E16: =IF(C16=0,"N/A",D16/C16) -> 102.52594 | F16: -709164.27 | G16: 15825 | H16: =G16-F16 -> 724989.27 | I16: =IF(G16=0,"N/A",H16/G16) -> 45.812908
A17: Adjusted Net Operating Income | B17: =+B15-B16 -> 967674.29 | C17: =+C15-C16 -> 190683.09 | D17: =+D15+D16 -> 776991.2 | E17: =IF(C17=0,"N/A",D17/C17) -> 4.0747777 | F17: =+F15-F16 -> 1239626.7 | G17: =+G15-G16 -> 467124.17 | H17: =+H15+H16 -> 772502.57 | I17: =IF(G17=0,"N/A",H17/G17) -> 1.6537414
A18: Corporate G&A Expenses | B18: 24080.69 | C18: 16936 | D18: =C18-B18 -> -7144.69 | E18: =IF(C18=0,"N/A",D18/C18) -> -0.42186408 | F18: 55327.67 | G18: 50774 | H18: =+G18-F18 -> -4553.67 | I18: =IF(G18=0,"N/A",H18/G18) -> -0.089685075
A19: Interest Expense | B19: 132418.95 | C19: 160833 | D19: =C19-B19 -> 28414.05 | E19: =IF(C19=0,"N/A",D19/C19) -> 0.17666803 | F19: 431956.33 | G19: 482499 | H19: =+G19-F19 -> 50542.67 | I19: =IF(G19=0,"N/A",H19/G19) -> 0.10475186
A20: Net Income after G&A & Interest | B20: =+B17-B18-B19 -> 811174.65 | C20: =+C17-C18-C19 -> 12914.09 | D20: =+D17+D18+D19 -> 798260.56 | E20: =IF(C20=0,"N/A",D20/C20) -> 61.813148 | F20: =+F17-F18-F19 -> 752342.74 | G20: =+G17-G18-G19 -> -66148.83 | H20: =+H17+H18+H19 -> 818491.57 | I20: =IF(G20=0,"N/A",H20/G20) -> -12.373485
A21: Revenue (per cash income statement)
A22: MTD Revenue variance is over budget due to: - $47.5k - Insurance payment from Fosters received in March and applied to February past due balances. - $6.4k - Higher than allocated parking income. - $6k - Kona Gear PCR payment ($3.5k) and unbudgeted marketing income ($2.3k) plus GET. Offset by: - ($15k) - Island Lava Java 2/26 PCR not received.
A23: YTD Revenue variance is over budget due to: - $24.7k - Higher than allocated parking income. Offset by: - ($16.5k) - Island Lava Java 2/26 PCR not received.
A24: Operating Expenses (per cash income statement)
A25: MTD Expenses variance is minimal.
A26: YTD Expenses are under budget due to: - $10.3k - Lower than allocated property insurance. - $17.3k - Timing of security invoices, will be paid in April. - $6k - Refund for duplicate payment of plumbing invoices (paid by SVN and Athena) offset by plumbing repair. - $16k - Contingency not full utilized for landscape consumables. Offset by: - ($8k) - Higher than allocated beekeeping ($4k) and parking lot light repairs ($4k). | K26: =31.8+34+74-47 -> 92.8 | L26: =4+3.3+8.2+37+13.5 -> 66 | M26: =43652+159+9294+4177+16851 -> 74133 | N26: =26+24+10+23-13-15+4+5 -> 64 | P26: =43652+1559.45+9294.52+4177.85+5166.54 -> 63850.36
A27: Owner Expenses
A28: MTD Owner expenses variance is under budget due to: - $731.6k - Foster's restoration work offset by insurance payment. - $4k - Contingencies not fully utilized for general repairs/maint., legal and professional fees.
A29: YTD Owner expenses variance is over budget due to: - $722.8k - Foster's restoration work offset by insurance payment. - $2.2k - Contingencies not fully utilized for general repairs/maint., marketing and postage/shipping fees.
A32: New Leases
A33: Chong Quin Hot Pot (old Outback space) | B33: Term: 10 years w/2 5-yr Options Rent: $13,000 YR 1-2 with increases in years 3 & 6 RCD: Earlier of Open for Business or 240 days from Possession Estimated RCD: 6/25/26 Lease has been fully executed and tenant is designing space for permitting. Tenant has finalized plans and submitting to County for permits. Satisfaction of Contingencies letter sent 10/28/25. Tenant has paid first month's rent and Security Deposit. Tenant has submitted plans and is in Health Department for permitting. Minor issue surfaced on enclosing the patio and mechanical drawings have been resubmitted to the County of Hawaii, EPIC. Paper plans were also sent express mail to Kona for hand delivery and processing at the State of Hawaii, Department of Health, Sanitation Branch. The EPIC review was completed fairly quick and returned to tenant in early March. Tenant distributed the comments by EPIC to their engineers and are awaiting revisions.
A34: Bowls Superfoods (old Bongo Bens) | B34: Term: 10 years w/2 5-yr Options Rent: $8,979/mo ($3.00psf) with 3% annual increases plus 5% Percentage Rent and NNNs RCD: Earlier of Open for Business or 180 days from obtaining permits TIA: $193K LOI is being finalized and then lease will be negotiated.
A35: Executed Renewals (12 months from current period)
A36: ABC Store 75 (SF 3,000) | B36: Lease Expiration Date: 12/31/2030 Rent: $8.00 PSF Option: Tenant has one (1) remaining, five (5) year option. Notice due 120 days prior to expiration. Notes: Tenant exercised one of its remaining two options to extend the term at $8/PSF. Second Amendment was executed on 7/17/25. New lease term commenced 1/1/2026.
A37: Kona Gear (SF 962) | B37: Lease Expiration Date: 3/31/2029 Rent: $6.70 PSF for 3 years/$80.40 PSF, plus NNNs Percentage Rent: Remains at 10%, including the 1% marketing fee Option: Tenant has one (1) remaining, three (3) year option with a 3% Base Rent increase. Termination Option: 150-day notice with a $10,000 termination fee/buyout. Notes: Landlord to repair ceiling leak and plumbing in Laverne's space. New lease term commences 4/1/2026
A38: Renewals (12 months from current period)
A39: Big Island Running (525 sf) | B39: Renewal Period: 11/1/24-10/31/2029 Rent: $2,625/mo. - $5.00 psf, Annual 3% Increases Option: One (1), Five (5) year option Management sent tenant LOI on January 11, 2024. Off is One (1), Five (5) year renewal at $6.00 PSF with 3% Annual Increases. Offer included One (1), Five (5) Year Option at FMV. Tenant countered at $5.00 PSF. Landlord agreed and Amendment was signed on 2/7/2024.
A40: Café Kona (SF 994) | B40: Lease Expiration Date: 8/31/2026 Rent: $3.67 PSF Option: Tenant has one (1) remaining, five (5) year option at FMV. Notice due 270 days prior to expiration. Notes: Tenant would like to renew but has concerns regarding parking rates. They feel more comfortable knowing that Foster's will reopen. Pending receipt of FMV offer from Tenant. Management continues to check-in.
A41: Gross Sales Reporting (Trends & Issues)
A42: Sales for several stores were down 5-10%, but we had a jump in sales from ABC, Oceans, Gecko, Cafe Kona, and Kona Gear: - ABC Stores: $585,537 for March 2026, Up 10.7% from March 2025. - Ocean's: $167,370 for March 2026, Up 16.7% from March 2025. - Gecko Girlz: $70,010 for March 2026, Up 29.5% from March 2025. - Cafe Kona: $33,602 for March 2026, Up 5% from March 2025. - Kona Gear: $126,901 for March 2026, Up 21.5% from March 2025. - Big Island Running: $67,502 for March 2026, Down 9.2% from March 2025. - Kanaka Kava: $27,847 for March 2026, Down 5.1% from March 2025. - Humpy's: $291,360 for March 2026, Down 11% from March 2025. - Laverne's: $91,203 for March 2026, Down 4% from March 2025. - Island Lava Java: $493,692 for March 2026, Down 3.4% from March 2025. - Gypsea Gelato: $61,004 for March 2026, Down 0.3% from March 2025. - Taka Sushi: $23,889 for March 2026, Down 63.6% from March 2025. Tenant was closed for vacation in February and March was slow.
A43: Tenant Issues
A44: Parking: Parking rates were updated mid year and we have seen consistent growth in Parking Revenue since the change. Parking revenue is up almost 100% from $18k in 2024 to $35k in 2025. Parking complaints have greatly reduced. Now the Village Businesses are concerned parking rates are too high in the Village. A portion of the 2024 parking revenue was applied to tenant accounts to help offset NNN charges. Coconut Grove Marketplace is very competitive. There is a parking ordinance being circulated through the County Council limiting rates to be charged. Humpy's and Laverne's: Third Amendment has been fully executed. Beginning July 1, 2025, and expiring on August 31, 2026, the Monthly Gross Rent that shall be due and payable shall equal the greater of (i) ten percent (10%) of gross sales plus sales tax on that amount and (ii) twenty-five thousand and 0/100 dollars ($25,000.00) each month (the “New Conditional Rent”). On September 1, 2026, Tenant shall resume paying Monthly Minimum Rent, Percentage Rent, and all Additional Rent due under the Lease. Landlord applied $11k security deposit to Humpy's outstanding balance. The remaining balance of $110,521.46 will be deferred through 8/31/26. Humpy's is looking to assign lease/sell the business; CEO of TS Restaurants liked the space and location. SVN waiting to hear back. Fosters - Kitchen fire occurred 7/1/25. Kona Pele and Tasty Kona were affected but were able to reopen within a day or two. Management worked with several vendors in both tenant spaces to mitigate damage. Kona Haven was able to reopen on 7/3/25. Fosters is undergoing insurance investigation and may be closed for several months. The cause of the fire seems to be from a fryer spark. Rents will be paid via the Insurance companies in the meantime. Final insurance inspection completed and rebuilding process will begin. Fosters has complained about parking and sent a breach of contract notice to Landlord. Response was sent to tenant's attorney on 9/12. The insurance company has released rent and NNN through the end of 2025. Demo has been completed and restoration planning has begun. Fosters is still complaining about parking and may use in renegotiation of opening back up. Landlord is negotiating restructure with tenant.
A45: Foster's Fire
A46: Foster's Kitchen fire incident was reported on 7/1/25, and Foster's has been closed since that date. Tasty Kona and Café Kona were closed until 7/5/25 due to water damage and electrical concerns. The fire and water damage remediation work has been completed, and the restoration proposals are being reviewed by the adjuster. Insurance payment of $250K was received to cover rent from the date of the incident to December 2025 as well as some of the cleaning and demo work. Management received an additional $190k to cover restoration costs and 2026 rent and impounds. Contract was signed and deposit check was mailed to Premier Hawaii Restoration.
...

Sheet Tenant Delinquency
A1: Executive Summary
A2: Coconut Grove
A3: ='Executive Summary'!A3 -> March 2026
A6: Operations Manager: | B6: Danielle Cebrero | G6: Square Feet: | H6: ='Executive Summary'!H7 -> 50133
A7: Assistant Property Manager: | B7: Audrey Verrette | G7: % Leased: | H7: 0.8141
G8: %Occupied | H8: 0.8141
A10: Tenant Delinquency
A12: Tenant | B12: Over $2,500 | C12: Action Taken / Legal Update
A13: Lucasie | B13: 5326.26 | C13: Balance due reflects 5/25, 8/25 and 1/26 NNN short pays offset by PYC credit. Management revised 2024 PYC which resulted in a credit of $1k. Working with Nir Levav to pay the remaining balance. | P13: 39
A14: Fosters | B14: =8874.14+280.79+5959.05 -> 15113.98 | C14: Balance due reflected 2023 and 2024 PYC charges ($15K) as well as 1/26 and 2/26 charges ($48K) - insurance payment received after cycle close. Landlord working with tenant on new agreement.
A15: Ocean's | B15: 4613.6 | C15: Balance due reflects 2024 PYC charge. Shirley Hull advised she is unable to pay the additional $1k each month towards the balance as she planned. Management asked if she can at least pay a couple of hundred dollars each month and Shirley said she will do what she can.
A16: Café Kona | B16: 6958.31 | C16: Balance due reflects 2024 PYC. Tenant is paying towards balance each month.
A17: Total | B17: =SUM(B13:B16) -> 32012.15
A42: Sales are up for December at Coconut Grove Marketplace: - Big Island Running: $80,252 for December 2025, Up 8.7% from December 2024. - Cafe Kona: $33,801 for December 2025, Up 1.7% from December 2024. - ABC Stores: $537,658 for December 2025, Up 2.6% from December 2024. - Kona Gear: $80,995 for December 2025, Up 9.2% from December 2024. - Kanaka Kava: $29,195 for December 2025, Up 1.5% from December 2024. - Ocean's: $142,623 for December 2025, Down 2.7% from December 2024. - Island Lava Java: $473,006 for December 2025, Down 3.8% from December 2024. - Gecko Girlz: $55,513 for December 2025, Up 10.5% from December 2024. - Taka Sushi: $64,208 for December 2025, Up 2.4% from December 2024.
A44: Parking: Parking rates were updated mid year and we have seen consistent growth in Parking Revenue since the change. Parking revenue is up almost 100% from $18k in 2024 to $35k in 2025. Parking complaints have greatly reduced. Now the Village Businesses are concerned parking rates are too high in the Village. A portion of the 2024 parking revenue was applied to tenant accounts to help offset NNN charges. Coconut Grove Marketplace is very competitive. There is a parking ordinance being circulated through the County Council limiting rates to be charged. Humpy's and Laverne's: Third Amendment has been fully executed. Beginning July 1, 2025, and expiring on August 31, 2026, the Monthly Gross Rent that shall be due and payable shall equal the greater of (i) ten percent (10%) of gross sales plus sales tax on that amount and (ii) twenty-five thousand and 0/100 dollars ($25,000.00) each month (the “New Conditional Rent”). On September 1, 2026, Tenant shall resume paying Monthly Minimum Rent, Percentage Rent, and all Additional Rent due under the Lease. Landlord applied $11k security deposit to Humpy's outstanding balance. The remaining balance of $110,521.46 will be deferred through 8/31/26. Humpy's is looking to assign lease/sell the business; CEO of TS Restaurants liked the space and location. SVN waiting to hear back. Fosters - Kitchen fire occurred 7/1/25. Kona Pele and Tasty Kona were affected but were able to reopen within a day or two. Management worked with several vendors in both tenant spaces to mitigate damage. Kona Haven was able to reopen on 7/3/25. Fosters is undergoing insurance investigation and may be closed for several months. The cause of the fire seems to be from a fryer spark. Rents will be paid via the Insurance companies in the meantime. Final insurance inspection completed and rebuilding process will begin. Fosters has complained about parking and sent a breach of contract notice to Landlord. Response was sent to tenant's attorney on 9/12. The insurance company has released rent and NNN through the end of 2025. Demo has been completed and restoration planning has begun. Fosters is still complaining about parking and may use in renegotiation of opening back up. Landlord is negotiating restructure with tenant. Outback - PYC is resolved, termination fee was received, premises was returned to Landlord October 2025. Kona Gear - SVN has replaced ceiling tiles and will keep track of any new leaks.

Sheet COVID 19-Rent Recovery
A2: Covid 10 - Deferred Rent Notes
A3: Coconut Grove
A4: ='Executive Summary'!A3 -> March 2026
A7: Operations Manager: | B7: Danielle Cebrero | G7: Square Feet: | H7: 50133
A8: Assistant Property Manager: | B8: Audrey Verrette | G8: % Leased: | H8: ='Executive Summary'!H8 -> 0.8141
A12: Tenant | B12: Outstanding | D12: Rent Recovery Agreement
A13: Taka Sushi | B13: =R13 -> 9303.525 | D13: Past due balance due to delayed opening. Tenant will pay back $26,581.50 beginning January 1, 2023 over the remainder of the term at $443.03/mo. | M13: RRC CALC. | N13: 26581.5 | O13: =N13/60 -> 443.025 | P13: 39 | Q13: =O13*P13 -> 17277.975 | R13: =N13-Q13 -> 9303.525
A14: Total: | B14: =SUM(B13:B13) -> 9303.525

Sheet Tenant COI Tracking 
A1: Executive Summary
A2: Coconut Grove
A3: ='Executive Summary'!A3 -> March 2026
A8: Operations Manager: | B8: Danielle Cebrero | E8: Square Feet: | G8: 50133
A9: Assistant Property Manager: | B9: Audrey Verrette | E9: % Leased: | G9: 0.8141
E10: % Occupied: | G10: 0.8141
A12: Group | B12: Tracked | C12: COI on File | D12: COI in Compliance | E12: DOC on File | F12: DOC in Compliance | G12: Notes
A14: Coconut Grove Retail XIII LLC | B14: ABC Stores #75 | C14: Yes | D14: Yes | E14: Yes | F14: Yes
A15: Coconut Grove Retail XIII LLC | B15: Big Island Running Company | C15: Yes | D15: Yes | E15: Yes | F15: Yes
A16: Coconut Grove Retail XIII LLC | B16: Kona Haven USA Corp./Cafe Kona | C16: Yes | D16: Yes | E16: Yes | F16: Yes
A17: Coconut Grove Retail XIII LLC | B17: Colors of Paradise Gallery | C17: yes | D17: yes | E17: yes | F17: yes
A18: Coconut Grove Retail XIII LLC | B18: Foster's Kitchen | C18: Yes | D18: Yes | E18: Yes | F18: Yes
A19: Coconut Grove Retail XIII LLC | B19: Gecko Girlz | C19: Yes | D19: Yes | E19: Yes | F19: Yes
A20: Coconut Grove Retail XIII LLC | B20: Gypsea Gelato | C20: Yes | D20: Yes | E20: Yes | F20: Yes
A21: Coconut Grove Retail XIII LLC | B21: Humpy's Big Island Alehouse | C21: Yes | D21: No | E21: Yes | F21: No | G21: Tenant COI and endorsement pages are expired. Management following up on renewal.
A22: Coconut Grove Retail XIII LLC | B22: Island Lava Java | C22: Yes | D22: Yes | E22: Yes | F22: Yes
A23: Coconut Grove Retail XIII LLC | B23: Jack's Diving Locker | C23: Yes | D23: No | E23: Yes | F23: Yes | G23: Tenant COI not in compliance for GL policy, no plate glass coverage. Management following up on docs.
A24: Coconut Grove Retail XIII LLC | B24: Kanaka Kava, Inc. | C24: Yes | D24: No | E24: Yes | F24: No | G24: Tenant COI expired. Management following up on renewal.
A25: Coconut Grove Retail XIII LLC | B25: Kona Gear | C25: Yes | D25: Yes | E25: Yes | F25: No | G25: Tenant DOC/ WOS expired. Management following up on renewal.
A26: Coconut Grove Retail XIII LLC | B26: Lucasie | C26: Yes | D26: No | E26: Yes | F26: Yes | G26: Tenant is in compliance with the exception of Auto Coverage. Management to follow up on policy.
A27: Coconut Grove Retail XIII LLC | B27: Laverne's | C27: Yes | D27: No | E27: Yes | F27: No | G27: Tenant COI and endorsement pages are expired. Management following up on renewal.
A28: Coconut Grove Retail XIII LLC | B28: Oceans Sports Bar and Grill | C28: Yes | D28: Yes | E28: Yes | F28: Yes
A29: Coconut Grove Retail XIII LLC | B29: Q Pot Kona | C29: Yes | D29: Yes | E29: Yes | F29: Yes
A30: Coconut Grove Retail XIII LLC | B30: Taka Sushi | C30: Yes | D30: No | E30: Yes | F30: No | G30: COI and additional endorsement pages expired. Management following up on renewal.
A44: Parking: Parking rates were updated mid year and we have seen consistent growth in Parking Revenue since the change. Parking revenue is up almost 100% from $18k in 2024 to $35k in 2025. Parking complaints have greatly reduced. Now the Village Businesses are concerned parking rates are too high in the Village. A portion of the 2024 parking revenue was applied to tenant accounts to help offset NNN charges. Coconut Grove Marketplace is very competitive. There is a parking ordinance being circulated through the County Council limiting rates to be charged. Humpy's and Laverne's: Third Amendment has been fully executed. Beginning July 1, 2025, and expiring on August 31, 2026, the Monthly Gross Rent that shall be due and payable shall equal the greater of (i) ten percent (10%) of gross sales plus sales tax on that amount and (ii) twenty-five thousand and 0/100 dollars ($25,000.00) each month (the “New Conditional Rent”). On September 1, 2026, Tenant shall resume paying Monthly Minimum Rent, Percentage Rent, and all Additional Rent due under the Lease. Landlord applied $11k security deposit to Humpy's outstanding balance. The remaining balance of $110,521.46 will be deferred through 8/31/26. Humpy's is looking to assign lease/sell the business; CEO of TS Restaurants liked the space and location. SVN waiting to hear back. Fosters - Kitchen fire occurred 7/1/25. Kona Pele and Tasty Kona were affected but were able to reopen within a day or two. Management worked with several vendors in both tenant spaces to mitigate damage. Kona Haven was able to reopen on 7/3/25. Fosters is undergoing insurance investigation and may be closed for several months. The cause of the fire seems to be from a fryer spark. Rents will be paid via the Insurance companies in the meantime. Final insurance inspection completed and rebuilding process will begin. Fosters has complained about parking and sent a breach of contract notice to Landlord. Response was sent to tenant's attorney on 9/12. The insurance company has released rent and NNN through the end of 2025. Demo has been completed and restoration planning has begun. Fosters is still complaining about parking and may use in renegotiation of opening back up. Landlord is negotiating restructure with tenant. Outback - PYC is resolved, termination fee was received, premises was returned to Landlord October 2025. Kona Gear - SVN has replaced ceiling tiles and will keep track of any new leaks.

Sheet Tenant Maintenance Tracking
A1: Executive Summary
A2: Coconut Grove
A3: March 2026
A6: Operations Manager: | B6: Danielle Cebrero | C6: Square Feet: | D6: 50133
A7: Assistant Property Manager: | B7: Audrey Verrette | C7: % Leased: | D7: 0.8141
C8: %Occupied: | D8: 0.8141 | E8: c
A10: Tenant | B10: Service | C10: Doc on File | D10: Doc in Compliance | E10: Notes
A12: Cafe Kona | B12: Hood | C12: No | D12: No | E12: Management requested docs from tenant.
A13: Jack's Dive Locker | B13: HVAC | C13: No | D13: No | E13: Management requested docs from tenant.
A14: Foster's Kitchen | B14: Grease Interceptor | C14: No | D14: No | E14: Management requested docs from tenant.
A15: Foster's Kitchen | B15: Hood | C15: No | D15: No | E15: Management requested docs from tenant.
A16: Gecko Girlz | B16: Grease Interceptor | C16: No | D16: No | E16: Management requested docs from tenant.
A17: Humpy's Big Island Alehouse | B17: Grease Interceptor | C17: No | D17: No | E17: Management requested docs from tenant.
A18: Humpy's Big Island Alehouse | B18: Hood | C18: No | D18: No | E18: Management requested docs from tenant.
A19: Island Lava Java | B19: Hood | C19: No | D19: No | E19: Management requested docs from tenant.
A20: Kanaka Kava, Inc. | B20: Grease Interceptor | C20: No | D20: No | E20: Management requested docs from tenant.
A21: Laverne's | B21: Grease Interceptor | C21: No | D21: No | E21: Management requested docs from tenant.
A22: Laverne's | B22: Hood | C22: No | D22: No | E22: Management requested docs from tenant.
... A28: Taka Sushi | B28: Hood | C28: No | D28: No | E28: Management requested docs from tenant.
A42: Sales are up for December at Coconut Grove Marketplace: - Big Island Running: $80,252 for December 2025, Up 8.7% from December 2024. - Cafe Kona: $33,801 for December 2025, Up 1.7% from December 2024. - ABC Stores: $537,658 for December 2025, Up 2.6% from December 2024. - Kona Gear: $80,995 for December 2025, Up 9.2% from December 2024. - Kanaka Kava: $29,195 for December 2025, Up 1.5% from December 2024. - Ocean's: $142,623 for December 2025, Down 2.7% from December 2024. - Island Lava Java: $473,006 for December 2025, Down 3.8% from December 2024. - Gecko Girlz: $55,513 for December 2025, Up 10.5% from December 2024. - Taka Sushi: $64,208 for December 2025, Up 2.4% from December 2024.
A44: Parking: Parking rates were updated mid year and we have seen consistent growth in Parking Revenue since the change. Parking revenue is up almost 100% from $18k in 2024 to $35k in 2025. Parking complaints have greatly reduced. Now the Village Businesses are concerned parking rates are too high in the Village. A portion of the 2024 parking revenue was applied to tenant accounts to help offset NNN charges. Coconut Grove Marketplace is very competitive. There is a parking ordinance being circulated through the County Council limiting rates to be charged. Humpy's and Laverne's: Third Amendment has been fully executed. Beginning July 1, 2025, and expiring on August 31, 2026, the Monthly Gross Rent that shall be due and payable shall equal the greater of (i) ten percent (10%) of gross sales plus sales tax on that amount and (ii) twenty-five thousand and 0/100 dollars ($25,000.00) each month (the “New Conditional Rent”). On September 1, 2026, Tenant shall resume paying Monthly Minimum Rent, Percentage Rent, and all Additional Rent due under the Lease. Landlord applied $11k security deposit to Humpy's outstanding balance. The remaining balance of $110,521.46 will be deferred through 8/31/26. Humpy's is looking to assign lease/sell the business; CEO of TS Restaurants liked the space and location. SVN waiting to hear back. Fosters - Kitchen fire occurred 7/1/25. Kona Pele and Tasty Kona were affected but were able to reopen within a day or two. Management worked with several vendors in both tenant spaces to mitigate damage. Kona Haven was able to reopen on 7/3/25. Fosters is undergoing insurance investigation and may be closed for several months. The cause of the fire seems to be from a fryer spark. Rents will be paid via the Insurance companies in the meantime. Final insurance inspection completed and rebuilding process will begin. Fosters has complained about parking and sent a breach of contract notice to Landlord. Response was sent to tenant's attorney on 9/12. The insurance company has released rent and NNN through the end of 2025. Demo has been completed and restoration planning has begun. Fosters is still complaining about parking and may use in renegotiation of opening back up. Landlord is negotiating restructure with tenant. Outback - PYC is resolved, termination fee was received, premises was returned to Landlord October 2025. Kona Gear - SVN has replaced ceiling tiles and will keep track of any new leaks.

Sheet Fosters Rebuild Costs
A1: Fosters Rebuild Insurance Tracker
A2: Coconut Grove
A3: As of 10/2/26
A11: Payments Received | D11: Notes
A13: 45964 | B13: 250000
A14: 46080 | B14: 190223.76
A15: 46090 | B15: 861186.79
A16: Requested | B16: 94192.24 | D16: Remainng aout for Loss of Rent. Brad Processing.
A17: Total | B17: =SUM(B13:B16) -> 1395602.8
D19: =B16+B14 -> 284416
A20: Expenses to Date
A21: Fosters Mechanical fee | B21: 2094.24 | D21: =B13+B15 -> 1111186.8
A22: Dry off panel board from water, turn on circuit breakers 50% Dep | B22: 16906.75
A23: Diagnose a problem | B23: 393.4
A24: Foster Fire Claim | B24: 1947.64
A25: Foster Restoration - Premier Demolition | B25: 68652
A26: Foster Restoration | B26: 3597.72
A27: Café Kona Restoration | B27: 8609.08
A28: Foster Insurance claim | B28: 1162.3
A29: Foster Restoration - Premier | B29: 129574.83
A30: Kitchen Equipment | B30: 197088.93
A31: Foster Restoration - Premier | B31: 18717.43
A32: Additional Kitchen Equipment | B32: =54338.32+55661.68 -> 110000
A33: Foster Restoration - Premier | B33: 6500
A34: Bargreen Elligson INC Kitchen Equipment | B34: 2855.5
A35: SCL Builders LLC | B35: 230591.1
A36: Foster Restoration - Premier | B36: 54543.25
A37: Koa Architects LLC | B37: 13089
A38: Bargreen Elligson INC | B38: 416.98
A39: Grase Trap | B39: 57580
A45: Total | B45: =SUM(B21:B42) -> 924320.15 | D45: =D21-B45 -> 186866.64
A47: Future Expenses
A48: SCL Builders LLC | B48: =57580+29633.5 -> 87213.5
A49: SCL Builders LLC | B49: =172944.33*2 -> 345888.66
A50: Construction Management Fee | B50: =B45*0.05 -> 46216.008
A52: Total | B52: =SUM(B48:B51) -> 479318.17 | D52: =B52-D45 -> 292451.53
A54: Rent and NNN To Date
A55: 45809 | B55: 25907.06
A56: 45839 | B56: 25907.06
A57: 45870 | B57: 25907.06
...

Sheet Distributions
A1: Fosters Rebuild Insurance Tracker
A2: Coconut Grove
A3: As of 10/2/26
A11: Payments Received | D11: Notes
A13: 45964 | B13: 250000 | D13: Is this construction?
A14: 46080 | B14: 190223.76 | D14: Loss of rent payment.
A15: 46090 | B15: 861186.79 | D15: Construction Costs
A16: Requested | B16: 94192.24 | D16: Remainng amout for Loss of Rent. Brad Processing.
A17: Total | B17: =SUM(B13:B16) -> 1395602.8
