Workbook
Name _1: #REF!
Name _1: #REF!
Name _1_245118304: #REF!
Name _1_245118304: #REF!
Name _10: #REF!
Name _10: #REF!
Name _10: #REF!
Name _10: #REF!
Name _10: #REF!
Name _10: #REF!
Name _10: #REF!
Name _10: #REF!
Name _10: #REF!
Name _10: #REF!
Name _10_245118304: #REF!
Name _10_245118304BDR: #REF!
Name _11_245118304BDR: #REF!
Name _12_245118304BDR: #REF!
Name _13_245118304BDR: #REF!
Name _14_245118304BDR: #REF!
Name _14_245118304BDR: #REF!
Name _15_245118304BDR: #REF!
Name _15_265329000: #REF!
Name _16_245118304BDR: #REF!
Name _17_245118304BDR: #REF!
Name _18_245118304BDR: #REF!
Name _19_245118304BDR: #REF!
Name _2: #REF!
Name _2: #REF!
Name _2_245118304: #REF!
Name _2_245118304BDR: #REF!
Name _20_245118304BDR: #REF!
Name _21_265329000: #REF!
Name _21_265329000: #REF!
Name _22_265329000: #REF!
Name _23_265329000: #REF!
Name _24_265329000: #REF!
Name _25_265329000: #REF!
Name _26_265329000: #REF!
Name _27_265329000: #REF!
Name _28_265329000: #REF!
Name _29_265329000: #REF!
Name _3_245118304: #REF!
Name _3_265329000: #REF!
Name _30_265329000: #REF!
Name _4_245118304: #REF!
Name _5_245118304: #REF!
Name _5_245118304: #REF!
Name _6_245118304: #REF!
Name _7_245118304: #REF!
Name _7_245118304: #REF!
Name _8_245118304: #REF!
Name _9_245118304: #REF!
Name _dat1: #REF!
Name _dat1: #REF!
Name account_data: #REF!
Name account_data: #REF!
Name Actual_Sqft: #REF!
Name Actual_Sqft: #REF!
Name Actual_Sqft: #REF!

Sheet Pet-cash
A1: MONTHLY REPORTING REQUIREMENTS | E1: Site Reports
A6: REGENCY BRESSI, LLC
A8: Petty Cash Reconciliation
A10: For the month ended :
A11: 40816
A14: Beginning Cash Balance | F14: 0
A16: Add
A17: Funding from Chase Account | F17: 0
A20: Deduct
A21: Current Month Receipts
A23: Description | B23: Amount
F30: =SUM(B24:B30) -> 0
A35: Ending Cash Balance | F35: =SUM(F14+F17-F30) -> 0
A49: 9 | D49: MRI Implementation for Cornerstone

Sheet Bank Rec
D3: Athena Management, Inc
D4: REGENCY BRESSI, LLC - #3502
D5: Bank Reconciliation
D6: ='Pet-cash'!$A$11 -> 40816
F10: BANK NAME: | H10: JP Morgan Chase
F12: ACCOUNT #: | H12: 937301091
B13: BANK STATEMENT
B15: Bank Balance | C15: 40770 | H15: 341284.95
B17: Plus: Deposits in Transit | H17: 0
B19: Less: Outstanding Checks (See Outstanding Check Listing) | H19: 25631.26
B21: Adjustment:
B23: Adjusted Bank Balance | H23: =+H15+H17-H19 -> 315653.69
B25: GENERAL LEDGER
B28: Balance per General Ledger A/C #1020-000: | H28: 315653.69
B30: BANK REC ADJUSTMENTS TO BE RECORDED ON CASH BKS IN NEXT MONTH
F32: DIVIDEND PAID | H32: 0
F33: SWEEP FEE | H33: 0
F34: ANALYSIS CHARGE | H34: 0
H38: =+H28+H32+H33+H34 -> 315653.69
B41: Prepared by: | E41: Prelim Approval:
B42: Date: | E42: Final Approval:
E43: Date:

Sheet Sec-Dep
A1: MONTHLY REPORTING REQUIREMENTS | E1: Site Reports
A5: REGENCY BRESSI, LLC
A7: Security Deposit Cash Account- Account 21100000
A9: Statutory Report for the period ending:
A10: ='Pet-cash'!$A$11 -> 40816
B12: Date | C12: Property Name | D12: Amount Earned
B13: 39659 | C13: Board and Brew | D13: 5445
B14: 39673 | C14: Cha Dry Cleaners | D14: 4925.75
B15: 39873 | C15: Carisbad Optometry | D15: 3714.75
B16: 39904 | C16: Happiness Nails | D16: 4346.25
B17: 39934 | C17: Xtreme Frozen Yogurt | D17: 3479
B18: 39996 | C18: Jojo Be, LLC | D18: 5554.5
B19: 40081 | C19: Tomaso Restaurant Group | D19: 12608.4
B20: 40118 | C20: FROOTS 4 U, LLC | D20: 3981.2
B21: 40126 | C21: Postal Annex | D21: 3339
B22: 40155 | C22: Kyss Boutique, LLC | D22: 4991.2
B23: 40228 | C23: Perfectly at Home | D23: 8428
B24: 40366 | C24: Premier Food Concepts | D24: 8583.25
... B31: 40718 | C31: Elevation Burger | D31: 6610.1
B37: Total | D37: =SUM(D13:D36) -> 108922.86
B44: 10 | E44: MRI Implementation for Cornerstone

Sheet Util-Dep
A1: MONTHLY REPORTING REQUIREMENTS | D1: Site Reports
A5: REGENCY BRESSI, LLC
A7: Utility Deposits
A9: As of:_________
B12: Utility Company | D12: Total Deposit | G12: Total
B26: Total per GL | D26: =SUM(D13:D25) -> 0
A33: 11 | D33: MRI Implementation for Cornerstone
G39: SKYLINE Implementation for Cornerstone

Sheet All-Doubt
A1: MONTHLY REPORTING REQUIREMENTS Site Reports
A4: REGENCY BRESSI, LLC
A6: Allowance for Doubtful Accounts - 10900000
A8: As of
A9: ='Pet-cash'!$A$11 -> 40816
A11: The Property Manager has performed a review of all delinquent rents with the following findings and
A12: recommendations.
A15: Tenant Name | B15: Amount Reserved | D15: Comments/Status of Collection
A16: Kyss Boutique | B16: 3673.12 | D16: Tenant downsize. Suggest to write-off balance.
A17: JPMorgan Chase | B17: 19043.71 | D17: Review tenant account to confirm correct charges.
A18: Hendo's Local Pizza | B18: 1767.21 | D18: Review tenant account to confirm correct charges.
A20: Total Reserve per G/L | B20: =SUM(B16:B19) -> 24484.04
A39: 12 | D39: MRI Implementation for Cornerstone

Sheet Bad-D
A1: MONTHLY REPORTING REQUIREMENTS | D1: Site Reports
A5: REGENCY BRESSI, LLC
A7: YTD Bad Debt Write-Offs
A9: As of:
A10: ='Pet-cash'!$A$11 -> 40816
A12: Name of Tenant | B12: Total Write-off | D12: Reason for Write-off
A13: (List by Tenant) | B13: (Total of all charges) | D13: (Summary of Reasons)
A24: Total Accounts written off YTD | B24: =SUM(B13:B23) -> 0
A26: *YTD Bad Expense per the G/L should equal the sum of:
A27: (1) All direct write-offs of accounts receivable balances (amounts NOT previously reserved).
A28: (2) The Net Current Year provision to account 1090 - Allowance for Doubtful Accounts.
A33: 13 | D33: MRI Implementation for Cornerstone
G39: SKYLINE Implementation for Cornerstone

Sheet Receiv
A1: MONTHLY REPORTING REQUIREMENTS | D1: Site Reports
A5: REGENCY BRESSI, LLC
A7: Other Receivables - Account 11000000
A9: As of
A10: ='Pet-cash'!$A$11 -> 40816
A12: Receivable Due From | B12: Total Amount | D12: Description
A13: ELEVATION BURGER | B13: 2214 | D13: MONUMENT SIGN REIMBURSEMENTS
A14: TOMMY V'S | B14: 2214 | D14: MONUMENT SIGN REIMBURSEMENTS
A15: THE BAR METHOD | B15: 2214 | D15: MONUMENT SIGN REIMBURSEMENTS
A16: CHASE BANK | B16: 10000 | D16: MONUMENT SIGN REIMBURSEMENTS
A17: SUPERCUTS | B17: 2214 | D17: MONUMENT SIGN REIMBURSEMENTS
A18: EUROPEAN WAX CENTER | B18: 2214 | D18: MONUMENT SIGN REIMBURSEMENTS
A25: General Ledger Balance | B25: =SUM(B13:B24) -> 21070
A29: 16 | D29: MRI Implementation for Cornerstone
G36: SKYLINE Implementation for Cornerstone

Sheet PreP-Ins
A1: MONTHLY REPORTING REQUIREMENTS | I1: Site Reports
A5: REGENCY BRESSI, LLC
A7: Prepaid Insurance - Account 11200000
A9: As of :
A10: ='Pet-cash'!$A$11 -> 40816
A12: Prepaid To: | B12: Period | C12: Days/Mo | D12: Total Amount Paid | F12: Monthly Exp | G12: YTD Exp | H12: Prepaid Bal | I12: Description
A14: Marsh USA | B14: 5/24/11-2/15/13 | C14: 633 | D14: 1089 | F14: =D14/C14*30 -> 51.611374 | G14: =D14/C14*(8+30+31+31+30) -> 223.64929 | H14: =+D14-G14 -> 865.35071 | I14: Pollution Legal Liability Insurance
A15: Marsh USA | B15: 8/01/11-8/01/12 | C15: 12 | D15: 46441 | F15: =+D15/12 -> 3870.0833 | G15: =+F15*2 -> 7740.1667 | H15: =+D15-G15 -> 38700.833 | I15: Property Insurance
A16: Marsh USA | B16: 8/01/11-8/01/12 | C16: 12 | D16: 8885 | F16: =+D16/12 -> 740.41667 | G16: =+F16*2 -> 1480.8333 | H16: =+D16-G16 -> 7404.1667 | I16: General Liability Insurance
A17: Marsh USA | B17: 8/01/11-8/01/12 | C17: 12 | D17: 3993 | F17: =+D17/12 -> 332.75 | G17: =+F17*2 -> 665.5 | H17: =+D17-G17 -> 3327.5 | I17: Excess Liability Insurance
A28: General Ledger Balance | H28: =SUM(H14:H27) -> 50297.851
A35: 18 | I35: MRI Implementation for Cornerstone
L37: SKYLINE Implementation for Cornerstone

Sheet PreP-Other
A1: MONTHLY REPORTING REQUIREMENTS | D1: Site Reports
A5: REGENCY BRESSI, LLC
A7: Other Prepaids - Account 11300000
A9: As of :
A10: ='Pet-cash'!$A$11 -> 40816
A12: Prepaid To: | B12: Total Amount | D12: Description
A29: General Ledger Balance | B29: =SUM(B13:B28) -> 0
A36: 18 | D36: MRI Implementation for Cornerstone
G38: SKYLINE Implementation for Cornerstone

Sheet O-Asset
A1: MONTHLY REPORTING REQUIREMENTS | E1: Site Reports
E2: \
A5: "Property Name"
A7: Other Assets - Account 11900000
A9: As of:
A10: ='Pet-cash'!A11:F11 -> 40816
A12: Definition | B12: Total Amount | D12: Description
D13: <Type Of Asset>
A28: General Ledger Balance | B28: =SUM(B14:B27) -> 0
A31: 19 | D31: MRI Implementation for Cornerstone
G39: SKYLINE Implementation for Cornerstone

Sheet TT-Costs
A1: MONTHLY REPORTING REQUIREMENTS | E1: Site Reports
E2: \
A5: REGENCY BRESSI, LLC
A7: Tenant Installation Cost - Account 13200000
A9: As of: 9/30/11
A12: Tenant | B12: Total Amount | D12: Description
A14: 4G Wireless | B14: 45570 | D14: Tenant Improvement Reimbursement
A15: Hendo's Local Pizza & Pint | B15: 42315 | D15: Tenant Improvement Reimbursement
A16: Supercuts | B16: 26000 | D16: Tenant Improvement Reimbursement
A25: General Ledger Balance | B25: =SUM(B14:B24) -> 113885
A28: 19 | D28: MRI Implementation for Cornerstone
G36: SKYLINE Implementation for Cornerstone

Sheet Leas-Costs
A1: MONTHLY REPORTING REQUIREMENTS | G1: Site Reports
A4: "Property Name"
A6: Leasing Costs Schedule - 13250000
A8: As of: 9/30/11
A10: Tenant | B10: Broker(s) Name | C10: Lease Terms Start Date | D10: Lease Terms End Date | E10: Actual $ MTD | F10: Actual $ YTD | G10: YTD Budget | K10: Actual vs. Budget
A61: Total | E61: =SUM(E12:E25) -> 0 | F61: =SUM(F12:F60) -> 0 | G61: =SUM(G11:G23) -> 0 | K61: =SUM(K11:K23) -> 0
A63: Note: This schedule should include not only new monthly expenditures, but also a history of what has been spent YTD (a carry forward type schedule).
A64: 20 | F64: MRI Implementation for Cornerstone

Sheet Amort-Leas
A1: MONTHLY REPORTING REQUIREMENTS | J1: Site Reports
A4: REGENCY BRESSI, LLC
A6: Amortization Lease Costs - 13350000
A8: As of: 9/30/11
A10: Tenant | B10: Amount | C10: Life/Term | D10: # of Months | E10: Monthly Depr/Amort Exp | F10: Total Lease Cost Paid | J10: YTD Expense | K10: Accum Depreciation
B66: =SUM(B12:B63) -> 0 | E66: =SUM(E12:E65) -> 0 | F66: =SUM(F12:F65) -> 0 | J66: =SUM(J12:J65) -> 0 | K66: =SUM(K12:K65) -> 0
A74: 21 | F74: MRI Implementation for Cornerstone

Sheet Amort-Finance
A1: MONTHLY REPORTING REQUIREMENTS | J1: Site Reports
A4: REGENCY BRESSI, LLC
A6: Amortization Finance Costs - 13910000
A8: As of: 9/30/11
A10: Loan | B10: Amount | C10: Life/Term | D10: # of Months | E10: Monthly Depr/Amort Exp | F10: Total Lease Cost Paid | J10: YTD Expense | K10: Accum Depreciation
A11: Midland Loan #770000314 | B11: 173042.12 | C11: 5 | D11: =5*12 -> 60 | E11: =+B11/D11 -> 2884.0353 | J11: =+E11*1 -> 2884.0353 | K11: =-E11*1 -> -2884.0353
B66: =SUM(B11:B63) -> 173042.12 | C66: 5 | D66: =SUM(D11:D63) -> 60 | E66: =SUM(E11:E63) -> 2884.0353 | F66: =SUM(F11:F63) -> 0 | G66: =SUM(G11:G63) -> 0 | H66: =SUM(H11:H63) -> 0 | I66: =SUM(I11:I63) -> 0 | J66: =SUM(J11:J63) -> 2884.0353 | K66: =SUM(K11:K63) -> -2884.0353
A74: 21 | F74: MRI Implementation for Cornerstone

Sheet Free-R
A1: MONTHLY REPORTING REQUIREMENTS | F1: Site Reports
A5: REGENCY BRESSI, LLC
A7: Free Rent
A9: As of: 9/30/11
A14: Tenant | B14: Commence Date | C14: Expiration Date | D14: Commence Date | E14: Expiration Date | F14: Unamortized Balance | G14: Amortization
A15: <List by Tenant> | F15: (Calculation of net amortized
F16: free rent Tenant Balance
F17: in Account 1195)
A27: Total | F27: =SUM(F15:F26) -> 0 | G27: =SUM(G15:G26) -> 0
A29: Note: This schedule should include not only new monthly expenditures, but also a history of what has been spent to Date (a carry forward type schedule).
A31: 22 | F31: MRI Implementation for Cornerstone

Sheet Accr-Sale
A1: MONTHLY REPORTING REQUIREMENTS | C1: Site Reports
A5: <Enter Property Name Here>
A7: Accrued Sales Tax - Account 20300000
A9: As of:_________
A13: Name of Taxing Authority | B13: Aging of Balance Due 30, 60 or 90 day | C13: Current Balance per the GL
A24: Total | B24: =SUM(B14:B23) -> 0 | C24: =SUM(C14:C23) -> 0
A33: 23 | C33: MRI Implementation for Cornerstone

Sheet Accr-Leas
A1: MONTHLY REPORTING REQUIREMENTS | E1: Site Reports
A5: REGENCY BRESSI, LLC
A7: Accrued Leasing Commission - Account 20600000
A9: As of
A10: ='Pet-cash'!$A$11 -> 40816
A12: Broker Name | B12: Amount Due | C12: Due Date | D12: Tenant Name | E12: Lease Effective Date | F12: Lease Expiration Date
A25: Total | B25: =SUM(B13:B24) -> 0
A27: *Total must tie to balance per the G\L.
A34: 24 | E34: MRI Implementation for Cornerstone

Sheet Mgmt-Fee
A1: MONTHLY REPORTING REQUIREMENTS | E1: Site Reports
A4: REGENCY BRESSI, LLC
A6: Management Fee - Account 2094000
A8: For the month ending:
A9: ='Pet-cash'!$A$11 -> 40816
C14: Basis for Calculation | D14: Management Fee % | E14: Fee Due
B15: January
B16: February
B17: March
B18: April
B19: May
B20: June
B21: July | C21: 390331.42 | D21: 0.025 | E21: =C21*D21 -> 9758.2855
B22: August | C22: 296986.19 | D22: 0.025 | E22: =C22*D22 -> 7424.6548
B23: September | C23: 299807.31 | D23: 0.025 | E23: =C23*D23 -> 7495.1827
B24: October
B25: November
B26: December
B27: Total | E27: =SUM(E15:E26) -> 24678.123
A34: 27 | E34: MRI Implementation for Cornerstone

Sheet Accr Ins
A1: MONTHLY REPORTING REQUIREMENTS | G1: Site Reports
A5: REGENCY BRESSI, LLC
A7: Prepaid Insurance - Account 2100000
A9: As of :
A10: ='Pet-cash'!$A$11 -> 40816
A12: CoverageType | B12: Preminum Commence Date | C12: Premium Expiration Date | D12: Number of Months | E12: Amount Due | F12: Monthly Amortization | G12: Accumulated Insurance Exp. | H12: General Ledger Balance | I12: Months Remaining
A13: Property Insurance
A14: Liability Premium
A15: Umbrella Premium
A16: Property/All Risk Premium
A17: General Liability Premium
A18: Environmental Premium
A21: Total | E21: =SUM(E13:E20) -> 0 | F21: =SUM(F13:F20) -> 0 | G21: =SUM(G13:G20) -> 0 | H21: =SUM(H13:H20) -> 0
A23: Note: This schedule should include not only new monthly expenditures, but also a history of what has been spent to Date (a carry forward type schedule).
A25: 22 | H25: MRI Implementation for Cornerstone

Sheet O-Liabil
A1: MONTHLY REPORTING REQUIREMENTS | C1: Site Reports
A5: REGENCY BRESSI, LLC
A7: Other Liabilities - Account 21000000
A9: As of
A10: ='Pet-cash'!$A$11 -> 40816
A13: Vendor Name | B13: Amount Accrued | C13: Description of Work - Type of Expense
C14: LNR Contribution to Grand Opening Fund
C15: Grand Opening Fund
C16: Promotional Fund
C17: Property/Liability Insurance (see Accr Ins)
B18: 2065.48 | C18: Tommy V, May Late Fee
B19: 2156.47 | C19: Souplantation, May Rent
B20: 1789.51 | C20: Community Utility Billing Services 07/11
B21: 1709.7 | C21: Community Utility Billing Services 08/11
C22: 2011 Estimated CAM Rec
B23: =SUM(B14:B16) -> 0
A30: Total | B30: =SUM(B14:B29) -> 7721.16

Sheet Legal-Fee
A1: MONTHLY REPORTING REQUIREMENTS | E1: Site Reports
A5: "Property Name"
A7: Legal Fees- Account 61600000
A9: Period ending:
A12: Name of Law Firm | B12: Date Paid | C12: Total Amount Paid | D12: Professional Fees | E12: Out of Pocket Expenses | I12: Allocation of Total
A29: Total | C29: =SUM(C13:C28) -> 0 | D29: =SUM(D13:D28) -> 0 | E29: =SUM(E13:E28) -> 0 | I29: =SUM(I13:I28) -> 0
A31: Note: Total must tie to YTD expense per G/L.
A33: 28 | E33: MRI Implementation for Cornerstone

Sheet Leas-Costs (2)
A1: MONTHLY REPORTING REQUIREMENTS | F1: Home Office Reports
A5: <Enter Property Name Here>
A7: Leasing Costs Schedule - 13250000
A9: As of:_________
A12: Tenant | B12: Broker(s) Name | C12: Lease Terms Start Date | D12: Lease Terms End Date | E12: Actual $ MTD | F12: Actual $ YTD | G12: YTD Budget | K12: Actual vs. Budget
A13: List by Tenant | B13: Broker/Cost Descr.*
A27: Total | E27: =SUM(E13:E26) -> 0 | F27: =SUM(F13:F26) -> 0 | G27: =SUM(G13:G26) -> 0 | K27: =SUM(K13:K26) -> 0
A29: Note: This schedule should include not only new monthly expenditures, but also a history of what has been spent to date (a carry forward type schedule).
A31: 37 | F31: MRI Implementation for Cornerstone

Sheet Legal-Fee (2)
A1: MONTHLY REPORTING REQUIREMENTS | E1: Home Office Reports
A5: <Enter Property Name Here>
A7: Legal Fees
A9: As of:____________
A12: Name of Law Firm | B12: Date Paid | C12: Total Amount Paid | D12: Professional Fees | E12: Out of Pocket Expenses | I12: Allocation of Total
A27: Total | C27: =SUM(C13:C26) -> 0 | D27: =SUM(D13:D26) -> 0 | E27: =SUM(E13:E26) -> 0 | I27: =SUM(I13:I26) -> 0
A29: Note: Total must tie to YTD expense per G/L.
A32: 38 | E32: MRI Implementation for Cornerstone

Sheet Fixed
A1: MONTHLY REPORTING REQUIREMENTS | G1: Home Office Reports
A5: Fixed Asset Identification Form
A6: Property Name:
A7: Property #
A8: Month:
A10: MRI | D10: Suite | E10: Project Description/include Job Ledger | I10: Placed in Service
A11: Account # | C11: Account Name | D11: Number | E11: (Tenant Name if applicable) | G11: Amount | I11: (A)
A30: (A) TI's=lease start date All Other=Date project/fixed asset was placed in service (not final invoice payment date).
A33: 39 | E33: SKYLINE Implementation for Cornerstone

Sheet Chk list
A1: MONTHLY REPORTING REQUIREMENTS | K1: Home Office Reports
A5: MRI - PRE-CLOSE AUDIT CHECKLIST
A6: For the period ending:
C8:  Compare the cash balance from the Bank Reconciliation to the General Ledger Cash account (A/C 1020)
C10:  Compare the Cash Receipts Journal to the Total Cash Receipts per the G/L (A/C 1020)
C12:  Compare the cash balance from the Bank Reconciliation to the General Ledger Cash account (A/C 1025)
C14:  Compare the A/P Check Register to the Total Cash Disbursed per the G/L (A/C 1020).
C16:  Compare the Net Change Column of the CM Ledger to the Net Total of Accounts Receivable and Prepaid Rent (A/C 1080 & 2040).
C18:  Compare the totals on the Aged Delinquencies Report to the accounts receivable (A/C 1080) balance per the General Ledger
C20:  Compare over 90 days balance per Aged Delinquencies to Reserve for Doubtful Accounts (A/C 1090) and prepare Journal Entry
C22:  Compare the balance on the A/P Open Invoice Report to the accounts payable (A/C 2020) balance on the General Ledger.
C24:  Compare the security deposit balance on the CM Security Deposits Ledger to the Security Deposit G/L account (A/C 2110)
C26:  Test Real Estate Tax Expense (A/C 6010) for correct number of months expense.
C28:  Test Accrued Real Estate Taxes (A/C 2070) for correct number of the months expense.
C30:  Test Insurance Expense (A/C 6060) for correct number of months expense.
... C51: DO NOT PROCEED WITH THE CLOSE IF THE ABOVE CHECKLIST IS NOT COMPLETE AND RECONCILED.
L54: MRI Implementation for Cornerstone

Sheet 10420
A1: ='Review Comments'!B9 -> COCONUT GROVE RETAIL XIII, LLC
A2: ESCROW- GROUND RENT- 10450
A3: ='Review Comments'!B11 -> FOR THE MONTH 07/31/2026
A9: Origination Date | C9: Description | E9: Amount | F9: Total Amount
A11: 42978 | C11: Escrow Ground Rent | E11: 17605.67 | F11: =E11 -> 17605.67
A12: 43038 | C12: 09/17 Mortgage Payment | E12: 8802.83 | F12: =F11+E12 -> 26408.5
C17: Account Total: | F17: =F12 -> 26408.5

Sheet Review Comments
B2: Monthly Financial Analysis
B3: Review Comments
A9: Property: | B9: COCONUT GROVE RETAIL XIII, LLC
A11: Month: | B11: FOR THE MONTH 07/31/2026
A13: Books | B13: Accrual / Cash
A16: 1.
A19: 2.
A22: 3.
A25: 4.
A28: 5.
A31: 6.
A34: 7.
A37: 8.
A40: 9.

Sheet TB 
A1: Database: ATHENA | B1: Trial Balance | E1: Page: | F1: 1
A2: ENTITY: 165 | B2: Athena Property Management | E2: Date: | F2: 46239.7
B3: COCONUT GROVE RETAIL XIII, LLC | E3: Time: | F3: 46239.7
A6: Accrual | B6: Year to Date Balances for period 07/26
B7: Report includes an open period. Entries are not final.
A9: Account | B9: Description | C9: Debit | E9: Credit
A12: No Department
A14: 10175-000000 | B14: CASH OPERATING-MECHANICS BANK | C14: 228492.74 | G14: =C14-E14 -> 228492.74
A15: 12010-000000 | B15: ACCOUNTS RECEIVABLE | C15: 122046.05 | G15: =C15-E15 -> 122046.05
A16: 12100-000000 | B16: LOAN RECEIVABLE | C16: 160000 | G16: =C16-E16 -> 160000
A17: 12410-000000 | B17: ALLOWANCE FOR BAD DEBT | E17: 7086.08 | G17: =C17-E17 -> -7086.08
A18: 13100-000000 | B18: MISCELLANEOUS DEPOSITS | C18: 150 | G18: =C18-E18 -> 150
A19: 14000-000000 | B19: LAND COSTS | C19: 4369592.2 | G19: =C19-E19 -> 4369592.2
A20: 15000-000000 | B20: BUILDING | C20: 17478369 | G20: =C20-E20 -> 17478369
A21: 15010-000000 | B21: BUILDING IMPROVEMENTS | C21: 2052989.6 | G21: =C21-E21 -> 2052989.6
A22: 15100-000000 | B22: TENANT IMPROVEMENTS | C22: 237334.8 | G22: =C22-E22 -> 237334.8
A23: 15400-000000 | B23: CAPITAL IMPROVEMENT | C23: 11648 | G23: =C23-E23 -> 11648
A24: 15500-000000 | B24: CONSTRUCTION IN PROGRESS | C24: 2200 | G24: =C24-E24 -> 2200
A25: 16500-000000 | B25: LEASING COMMISSIONS | C25: 239044.55 | G25: =C25-E25 -> 239044.55
A26: 16700-000000 | B26: REFINANCE COSTS | C26: 355176.83 | G26: =C26-E26 -> 355176.83
A27: 17600-000000 | B27: LOAN FEES | C27: 442910.74 | G27: =C27-E27 -> 442910.74
A28: 18300-000000 | B28: ACCUM DEPR-BUILDING | E28: 3314956 | G28: =C28-E28 -> -3314956
A29: 18500-000000 | B29: ACCUM DEPR-TENANT IMPROVEMENTS | C29: 130514 | G29: =C29-E29 -> 130514
A30: 18900-000000 | B30: ACCUM AMORT-LOAN FEES | E30: 144746.19 | G30: =C30-E30 -> -144746.19
A31: 20100-000000 | B31: ACCOUNTS PAYABLE | E31: 19358.47 | G31: =C31-E31 -> -19358.47
A32: 20650-000000 | B32: ACCRUED OPERATING EXP | E32: 9365.57 | G32: =C32-E32 -> -9365.57
A33: 20660-000000 | B33: ACCRUED INTEREST EXPENSE | E33: 139242.09 | G33: =C33-E33 -> -139242.09
A34: 20800-000000 | B34: TENANT SECURITY DEPOSIT | E34: 149779.54 | G34: =C34-E34 -> -149779.54
A35: 20900-000000 | B35: PREPAID RENT | E35: 142581.84 | G35: =C35-E35 -> -142581.84
A36: 25420-000000 | B36: NOTES PAYABLE-MORGAN STANLEY | E36: 28000000 | G36: =C36-E36 -> -28000000
A37: 25500-000000 | B37: AP - AFFILIATES | E37: 66144.74 | G37: =C37-E37 -> -66144.74
A38: 30400-000000 | B38: PRIOR YR RETAINED EARNING | E38: 7824551.2 | G38: =C38-E38 -> -7824551.2
A39: 35000-000000 | B39: OWNER'S DISTRIBUTION | C39: 14597709 | G39: =C39-E39 -> 14597709
A40: 36000-000000 | B40: OWNER'S CONTRIBUTION | E40: 342383.2 | G40: =C40-E40 -> -342383.2
A41: 40100-000000 | B41: BASE RENTAL INCOME | E41: 1059750.4 | G41: =C41-E41 -> -1059750.4
A42: 40102-000000 | B42: RENT DEFERRAL | C42: 65479.31 | G42: =C42-E42 -> 65479.31
A43: 40106-000000 | B43: DEFERRED RENT RECOVERY | E43: 2961.63 | G43: =C43-E43 -> -2961.63
A44: 40110-000000 | B44: PERCENTAGE RENT | E44: 302030.92 | G44: =C44-E44 -> -302030.92
A45: 40129-000000 | B45: PARKING RENT | E45: 261747.56 | G45: =C45-E45 -> -261747.56
A46: 40140-000000 | B46: COMMON AREA INCOME | E46: 298223.66 | G46: =C46-E46 -> -298223.66
...

Sheet 10410
A1: ='Review Comments'!B9 -> COCONUT GROVE RETAIL XIII, LLC
A2: PROPERTY TAX RESERVE- 10410
A3: ='Review Comments'!B11 -> FOR THE MONTH 07/31/2026
A9: Origination Date | C9: Description | E9: Amount | F9: Total Amount
A11: 42978 | C11: Escrow Property Tax Reserve | E11: 32580.99 | F11: =+E11 -> 32580.99
A12: 43038 | C12: 09/17 Mortgage Payment | E12: 12531.15 | F12: =F11+E12 -> 45112.14
A13: 43068 | C13: 10/17 Mortgage Payment | E13: 12531.15 | F13: =F12+E13 -> 57643.29
A14: 43098 | C14: 11/17 Mortgage Payment | E14: 12531.15 | F14: =F13+E14 -> 70174.44
A15: 43117 | C15: 12/17 Mortgage Payment | E15: 12531.15 | F15: =F14+E15 -> 82705.59
A16: 43159 | C16: 01/18 Mortgage Payment | E16: 12531.15 | F16: =F15+E16 -> 95236.74
A17: 43151 | C17: Tax Payment #75009025000 | E17: -45856.41 | F17: =F16+E17 -> 49380.33
A18: 43151 | C18: Tax Payment #75009027000 | E18: -9144.41 | F18: =F17+E18 -> 40235.92
A19: 43151 | C19: Tax Payment #75009028000 | E19: -19884.82 | F19: =F18+E19 -> 20351.1
A20: 43190 | C20: 02/18 Mortgage Payment | E20: 12531.15 | F20: =F19+E20 -> 32882.25
A21: 43220 | C21: 03/18 Mortgage Payment | E21: 12531.15 | F21: =F20+E21 -> 45413.4
A22: 43251 | C22: 04/18 Mortgage Payment | E22: 12531.15 | F22: =F21+E22 -> 57944.55
A23: 43281 | C23: 05/18 Mortgage Payment | E23: 12531.15 | F23: =F22+E23 -> 70475.7
... A137: 45509 | C137: 07/24 MORTGAGE PMT | E137: 15658.43 | F137: =F136+E137 -> 130345.02
A138: 45497 | C138: 24/25 1ST PROP TAX 7500902500 | E138: -57695.79 | F138: =F137+E138 -> 72649.23 | H138: p
A139: 45497 | C139: 24/25 1ST PROP TAX 7500902700 | E139: -12344.81 | F139: =F138+E139 -> 60304.42
A140: 45497 | C140: 24/25 1ST PROP TAX 7500902800 | E140: -26240.25 | F140: =F139+E140 -> 34064.17
A141: 9/6/2024 | C141: CAPITAL DISBURSEMENT | E141: -34064.17 | F141: =F140+E141 -> -7.2759576e-11
C143: Account Total: | F143: =F141 -> -7.2759576e-11

Sheet 10530
A1: ='Review Comments'!B9 -> COCONUT GROVE RETAIL XIII, LLC
A2: LOAN RESERVES - TI/LC 10530
A3: ='Review Comments'!B11 -> FOR THE MONTH 07/31/2026
A9: Origination Date | C9: Description | E9: Amount | F9: Total Amount
H10: Beginning Bal | I10: =151900.41 -> 151900.41 | J10: =I10+20.78+38.96-24208.19 -> 127751.96 | K10: TI
A11: 42719 | C11: Escrow-TI/LC Holdback (Loan Reserve) | F11: =+E11 -> 0 | H11: Beginning Bal | I11: 334767.5 | J11: =I11+45.79+85.86 -> 334899.15 | K11: TI/ LC
I13: Acct# 10530 | J13: =F34 -> 0 | K13: TI& TI/LC BAL
I14: Acct# 10520 | J14: ='10470'!F65 -> 0
I15: Acct# 10510 | J15: ='10490'!F40 -> 1.2369128e-10
I16: Acct# 10420 | J16: ='10420'!F17 -> 26408.5
J18: =SUM(J13:J17) -> 26408.5
J33: =SUM(J13:J16) -> 26408.5 | K33: Bank Reserve act bal
C34: Account Total: | F34: =SUM(F11:F33) -> 0
A45: Origination Date
E52: çç CASH BOOK BALANCE

Sheet 10450
A1: ='Review Comments'!B9 -> COCONUT GROVE RETAIL XIII, LLC
A2: ESCROW GROUND RENT- 10450
A3: ='Review Comments'!B11 -> FOR THE MONTH 07/31/2026
A9: Origination Date | C9: Description | E9: Amount | F9: Total Amount
A11: 42978 | C11: Escrow Ground Rent | F11: 17605.67
A12: 43038 | C12: 09/17 Mortgage Payment | E12: 8802.83 | F12: =F11+E12 -> 26408.5
A13: 43068 | C13: 10/17 Mortgage Payment | E13: 8802.83 | F13: =F12+E13 -> 35211.33
A14: 43098 | C14: 11/17 Mortgage Payment | E14: 8802.83 | F14: =F13+E14 -> 44014.16
A15: 43117 | C15: 12/17 Mortgage Payment | E15: -35211.33 | F15: =F14+E15 -> 8802.83
A16: 43117 | C16: 12/17 Mortgage Payment | E16: 8802.83 | F16: =F15+E16 -> 17605.66
A17: 43131 | C17: Marcella Gregory pmt | E17: -8802.83 | F17: =F16+E17 -> 8802.83
A18: 43159 | C18: 01/18 Mortgage Payment | E18: 8802.83 | F18: =F17+E18 -> 17605.66
A19: 43159 | C19: Marcella Gregory pmt | E19: -8802.83 | F19: =F18+E19 -> 8802.83
A20: 43190 | C20: 02/18 Mortgage Payment | E20: 8802.83 | F20: =F19+E20 -> 17605.66
A21: 43190 | C21: Marcella Gregory pmt | E21: -8802.83 | F21: =F20+E21 -> 8802.83
A22: 43220 | C22: 03/18 Mortgage Payment | E22: 8802.83 | F22: =F21+E22 -> 17605.66
A23: 43220 | C23: Marcella Gregory pmt | E23: -8802.83 | F23: =F22+E23 -> 8802.83
... A85: 44165 | C85: Marcella Gregory pmt | E85: -8802.83 | F85: =F84+E85 -> 8802.83
A86: 44169 | C86: 11/20 Mortgage Payment | E86: 8802.83 | F86: =F83+E86 -> 17605.66
A87: 44196 | C87: Marcella Gregory pmt | E87: -8802.83 | F87: =F86+E87 -> 8802.83
A88: 44201 | C88: 12/20 Mortgage Payment | E88: 8802.83 | F88: =F85+E88 -> 17605.66
A89: 44227 | C89: Marcella Gregory pmt | E89: -8802.83 | F89: =F88+E89 -> 8802.83
A90: 44232 | C90: 1/21 Mortgage Payment | E90: 8802.83 | F90: =F87+E90 -> 17605.66
A91: 44255 | C91: Marcella Gregory pmt | E91: -8802.83 | F91: =F90+E91 -> 8802.83
A92: 44260 | C92: 1/21 Mortgage Payment | E92: 8802.83 | F92: =F91+E92 -> 17605.66
A93: 44286 | C93: Marcella Gregory pmt | E93: -8802.83 | F93: =F92+E93 -> 8802.83
A94: 44291 | C94: 3/21 Mortgage Payment | E94: 8802.83 | F94: =F93+E94 -> 17605.66
A95: 44316 | C95: Marcella Gregory pmt | E95: -8802.83 | F95: =F94+E95 -> 8802.83
A96: 44321 | C96: 4/21 Mortgage Payment | E96: 8802.83 | F96: =F95+E96 -> 17605.66
A97: 44346 | C97: Marcella Gregory pmt | E97: -8802.83 | F97: =F96+E97 -> 8802.83
A98: 44351 | C98: 5/21 Mortgage Payment | E98: 8802.83 | F98: =F97+E98 -> 17605.66
A99: 44377 | C99: Marcella Gregory pmt | E99: -8802.83 | F99: =F98+E99 -> 8802.83
A100: 44379 | C100: 06/21 Mortgage Payment | E100: 8802.83 | F100: =F99+E100 -> 17605.66
A101: 44407 | C101: Marcella Gregory pmt | E101: -8802.83 | F101: =F100+E101 -> 8802.83
A102: 44413 | C102: 07/21 Mortgage Payment | E102: 8802.83 | F102: =F101+E102 -> 17605.66
... A174: 45534 | C174: MARCELLA GREGORY PMT | E174: -8802.83 | F174: =F173+E174 -> 0
C178: Account Total: | F178: =F174 -> 0

Sheet 10460
A1: ='Review Comments'!B9 -> COCONUT GROVE RETAIL XIII, LLC
A2: ESCROW- INSURANCE ACT- 10460
A3: ='Review Comments'!B11 -> FOR THE MONTH 07/31/2026
A9: Origination Date | C9: Description | E9: Amount | F9: Total Amount
A11: 42978 | C11: Escrow Insurance | F11: 27653.6
A12: 43038 | C12: 09/17 Mortgage Payment | E12: 2880.58 | F12: =F11+E12 -> 30534.18
A13: 43068 | C13: 10/17 Mortgage Payment | E13: 2880.58 | F13: =F12+E13 -> 33414.76
A14: 43098 | C14: 11/17 Mortgage Payment | E14: 2880.58 | F14: =F13+E14 -> 36295.34
A15: 43117 | C15: 12/17 Mortgage Payment | E15: 2880.58 | F15: =F14+E15 -> 39175.92
A16: 43159 | C16: 01/18 Mortgage Payment | E16: 2880.58 | F16: =F15+E16 -> 42056.5
A17: 43159 | C17: Annual Premium 12/31/17-12/31/18 | E17: -27045 | F17: =F16+E17 -> 15011.5
A18: 43159 | C18: Add'l Insurance | E18: -901.65 | F18: =F17+E18 -> 14109.85
A19: 43188 | C19: 02/18 Mortgage Payment | E19: 2880.58 | F19: =F18+E19 -> 16990.43
A20: 43188 | C20: Add'l Insurance | E20: -51.29 | F20: =F19+E20 -> 16939.14
A21: 43220 | C21: 03/18 Mortgage Payment | E21: 2880.58 | F21: =F20+E21 -> 19819.72
A22: 43251 | C22: 04/18 Mortgage Payment | E22: 2880.58 | F22: =F21+E22 -> 22700.3
A23: 43281 | C23: 05/18 Mortgage Payment | E23: 2880.58 | F23: =F22+E23 -> 25580.88
... A60: 44232 | C60: 1/21 Mortgage Payment | E60: 3236.94 | F60: =F59+E60 -> 39532.8
A61: 2/11/21 | C61: Annual Premium 12/31/20-12/31/21 | E61: -29925.76 | F61: =F60+E61 -> 9607.04
A62: 44260 | C62: 2/21 Mortgage Payment | E62: 3236.94 | F62: =F61+E62 -> 12843.98
A63: 44291 | C63: 3/21 Mortgage Payment | E63: 3236.94 | F63: =F62+E63 -> 16080.92
A64: 44291 | C64: Annual Premium 12/31/20-12/31/21 | E64: -486 | F64: =F63+E64 -> 15594.92
A65: 44321 | C65: 4/21 Mortgage Payment | E65: 3236.94 | F65: =F64+E65 -> 18831.86
A66: 44351 | C66: 5/21 Mortgage Payment | E66: 3236.94 | F66: =F65+E66 -> 22068.8
A67: 44379 | C67: 06/21 Mortgage Payment | E67: 3236.94 | F67: =F66+E67 -> 25305.74
A68: 44413 | C68: 07/21 Mortgage Payment | E68: 3236.94 | F68: =F67+E68 -> 28542.68
A69: 44442 | C69: 08/21 Mortgage Payment | E69: 2661.03 | F69: =F68+E69 -> 31203.71
A70: 44474 | C70: 09/21 Mortgage Payment | E70: 2661.03 | F70: =F69+E70 -> 33864.74
A71: 44505 | C71: 10/21 Mortgage Payment | E71: 2661.03 | F71: =F70+E71 -> 36525.77
A72: 44536 | C72: 11/21 Mortgage Payment | E72: 2661.03 | F72: =F71+E72 -> 39186.8
A73: 44592 | C73: 12/21 Mortgage Payment | E73: 2661.03 | F73: =F72+E73 -> 41847.83
... A114: 45541 | C114: CAPITAL DISBURSEMENT | E114: -61823.99 | F114: =F113+E114 -> 0
C116: Account Total: | F116: =F114 -> 0

Sheet 10470
A1: ='Review Comments'!B9 -> COCONUT GROVE RETAIL XIII, LLC
A2: ESCROW- OTHER
A3: ='Review Comments'!B11 -> FOR THE MONTH 07/31/2026
A9: Origination Date | C9: Description | E9: Amount | F9: Total Amount
A11: 42978 | C11: Escrow Other | E11: 45746.93 | F11: =E11 -> 45746.93
A12: 43038 | C12: 09/17 Mortgage Payment | E12: 4985.73 | F12: =F11+E12 -> 50732.66
A13: 43068 | C13: 10/17 Mortgage Payment | E13: 4985.73 | F13: =F12+E13 -> 55718.39
A14: 43098 | C14: 11/17 Mortgage Payment | E14: 4985.73 | F14: =F13+E14 -> 60704.12
A15: 43117 | C15: 12/17 Mortgage Payment | E15: 4985.73 | F15: =F14+E15 -> 65689.85
A16: 43159 | C16: 01/18 Mortgage Payment | E16: 4985.73 | F16: =F15+E16 -> 70675.58
A17: 43190 | C17: 02/18 Mortgage Payment | E17: 4985.73 | F17: =F16+E17 -> 75661.31
A18: 43220 | C18: 03/18 Mortgage Payment | E18: 4985.73 | F18: =F17+E18 -> 80647.04
A19: 43251 | C19: 04/18 Mortgage Payment | E19: 4985.73 | F19: =F18+E19 -> 85632.77
A20: 43281 | C20: 05/18 Mortgage Payment | E20: 4985.73 | F20: =F19+E20 -> 90618.5
A21: 43312 | C21: 06/18 Mortgage Payment | E21: 4985.73 | F21: =F20+E21 -> 95604.23
A22: 43343 | C22: 07/18 Mortgage Payment | E22: 4985.73 | F22: =F21+E22 -> 100589.96
A23: 43373 | C23: 08/18 Mortgage Payment | E23: 4985.73 | F23: =F22+E23 -> 105575.69
... A63: 45541 | C63: CAPITAL DISBURSEMENT | E63: -285061.99 | F63: =F62+E63 -> 0
C65: Account Total: | F65: =F63 -> 0

Sheet 10490
A1: ='Review Comments'!B9 -> COCONUT GROVE RETAIL XIII, LLC
A2: CAPITAL EXP HOLDBACK-10490
A3: ='Review Comments'!B11 -> FOR THE MONTH 07/31/2026
A9: Origination Date | C9: Description | E9: Amount | F9: Total Amount
A11: 42978 | C11: Escrow Cap Exp Holdback | E11: 85920 | F11: =+E11 -> 85920
A12: 43038 | C12: 09/17 Mortgage Payment | E12: 797.71 | F12: =F11+E12 -> 86717.71 | H12: Total reserve & Other/ repair | I12: =F40+'10450'!F178+'10470'!F65 -> 1.2369128e-10
A13: 43068 | C13: 10/17 Mortgage Payment | E13: 797.71 | F13: =F12+E13 -> 87515.42
A14: 43098 | C14: 11/17 Mortgage Payment | E14: 797.71 | F14: =F13+E14 -> 88313.13
A15: 43117 | C15: 12/17 Mortgage Payment | E15: 797.71 | F15: =F14+E15 -> 89110.84
A16: 43159 | C16: 01/18 Mortgage Payment | E16: 797.71 | F16: =F15+E16 -> 89908.55
A17: 43190 | C17: 02/18 Mortgage Payment | E17: 797.71 | F17: =F16+E17 -> 90706.26
A18: 43220 | C18: 03/18 Mortgage Payment | E18: 797.71 | F18: =F17+E18 -> 91503.97
A19: 43251 | C19: 04/18 Mortgage Payment | E19: 797.71 | F19: =F18+E19 -> 92301.68
A20: 43281 | C20: 05/18 Mortgage Payment | E20: 797.71 | F20: =F19+E20 -> 93099.39
A21: 43312 | C21: 06/18 Mortgage Payment | E21: 797.71 | F21: =F20+E21 -> 93897.1
A22: 43343 | C22: 07/18 Mortgage Payment | E22: 797.71 | F22: =F21+E22 -> 94694.81
A23: 43373 | C23: 08/18 Mortgage Payment | E23: 797.71 | F23: =F22+E23 -> 95492.52
A24: 43404 | C24: 09/18 Mortgage Payment | E24: 797.71 | F24: =F23+E24 -> 96290.23
... A38: 45541 | C38: CAPITAL DISBURSEMENT | E38: -19145.04 | F38: =F37+E38 -> 1.2369128e-10
C40: Account Total: | F40: =F38 -> 1.2369128e-10

Sheet Summary
A2: Property# | B2: 165
A3: Property Name | B3: COCONUT GROVE RETAIL XIII, LLC
A4: Month | B4: 46234
A6: Account# | B6: Account Name | C6: Balance from Schedule | D6: Balance from TB | E6: Balance | F6: Comments
A7: 10410-000000 | B7: ESCROW-PROPERTY TAX | C7: 0 | D7: {=IFERROR(INDEX('TB '!G:G,MATCH(A7,'TB '!A:A,0),0),0)} -> 0 | E7: =C7-D7 -> 0
A8: 10420-000000 | B8: ESCROW-RESERVE ACT | C8: 0 | D8: {=IFERROR(INDEX('TB '!G:G,MATCH(A8,'TB '!A:A,0),0),0)} -> 0 | E8: =C8-D8 -> 0
A9: 10432-000000 | B9: ESCROW-LC RESERVE | C9: 0 | D9: {=IFERROR(INDEX('TB '!G:G,MATCH(A9,'TB '!A:A,0),0),0)} -> 0 | E9: =C9-D9 -> 0
A10: 10445-000000 | B10: ESCROW-CASH MANAGEMENT | C10: 0 | D10: {=IFERROR(INDEX('TB '!G:G,MATCH(A10,'TB '!A:A,0),0),0)} -> 0 | E10: =C10-D10 -> 0
A11: 12020-000000 | B11: ACCOUNTS RECEIVABLE OTHER | C11: ='12020'!E13 -> 0 | D11: {=IFERROR(INDEX('TB '!G:G,MATCH(A11,'TB '!A:A,0),0),0)} -> 0 | E11: =C11-D11 -> 0
A12: 12100-000000 | B12: LOAN RECEIVABLE | C12: ='12100'!E13 -> 160000 | D12: {=IFERROR(INDEX('TB '!G:G,MATCH(A12,'TB '!A:A,0),0),0)} -> 160000 | E12: =C12-D12 -> 0
A13: 12410-000000 | B13: ALLOWANCE FOR BAD DEBT | C13: ='12410 '!G33 -> 7086.08 | D13: {=IFERROR(INDEX('TB '!G:G,MATCH(A13,'TB '!A:A,0),0),0)} -> -7086.08 | E13: =C13+D13 -> 0
A14: 13000-000000 | B14: SUSPENSE | C14: ='13000'!F13 -> 0 | D14: {=IFERROR(INDEX('TB '!G:G,MATCH(A14,'TB '!A:A,0),0),0)} -> 0 | E14: =C14-D14 -> 0
A15: 13100-000000 | B15: MISC DEPOSIT | C15: ='13100'!F23 -> 150 | D15: {=IFERROR(INDEX('TB '!G:G,MATCH(A15,'TB '!A:A,0),0),0)} -> 150 | E15: =C15-D15 -> 0
A16: 13120-000000 | B16: PREPAID PROPERTY TAXES | C16: ='Tax '!G16 -> 0 | D16: {=IFERROR(INDEX('TB '!G:G,MATCH(A16,'TB '!A:A,0),0),0)} -> 0 | E16: =C16-D16 -> 0
A17: 13130-000000 | B17: PREPAID PROPERTY TAXES | C17: ='13130'!F16 -> 0 | D17: {=IFERROR(INDEX('TB '!G:G,MATCH(A17,'TB '!A:A,0),0),0)} -> 0
A18: 13150-000000 | B18: FROM 801 MAIN STREET | C18: 0 | D18: {=IFERROR(INDEX('TB '!G:G,MATCH(A18,'TB '!A:A,0),0),0)} -> 0 | E18: =C18-D18 -> 0
A19: 14000-000000 | B19: LAND COSTS | C19: ='Fixed Asset'!F13 -> 4369592.2 | D19: {=IFERROR(INDEX('TB '!G:G,MATCH(A19,'TB '!A:A,0),0),0)} -> 4369592.2 | E19: =C19-D19 -> 0
A20: 15000-000000 | B20: BUILDING | C20: ='Fixed Asset'!F18 -> 17478369 | D20: {=IFERROR(INDEX('TB '!G:G,MATCH(A20,'TB '!A:A,0),0),0)} -> 17478369 | E20: =C20-D20 -> 0
A21: 15010-000000 | B21: BUILDING IMPROVEMENTS | C21: ='Fixed Asset'!F141 -> 2052989.6 | D21: {=IFERROR(INDEX('TB '!G:G,MATCH(A21,'TB '!A:A,0),0),0)} -> 2052989.6 | E21: =C21-D21 -> 0
A22: 15100-000000 | B22: TENANT IMPROVEMENTS | C22: ='Fixed Asset'!F154 -> 237334.8 | D22: {=IFERROR(INDEX('TB '!G:G,MATCH(A22,'TB '!A:A,0),0),0)} -> 237334.8 | E22: =C22-D22 -> 0
A23: 16500-000000 | B23: LEASING COMMISSIONS | C23: ='Fixed Asset'!F201 -> 239044.55 | D23: {=IFERROR(INDEX('TB '!G:G,MATCH(A23,'TB '!A:A,0),0),0)} -> 239044.55 | E23: =C23-D23 -> 0
A24: 17600-000000 | B24: LOAN FEES | C24: ='Fixed Asset'!F219 -> 442910.74 | D24: {=IFERROR(INDEX('TB '!G:G,MATCH(A24,'TB '!A:A,0),0),0)} -> 442910.74 | E24: =C24-D24 -> 0
A25: 18100-000000 | B25: ACCUMULATED DEPRECIATION | C25: 0 | D25: {=IFERROR(INDEX('TB '!G:G,MATCH(A25,'TB '!A:A,0),0),0)} -> 0 | E25: =C25-D25 -> 0
A26: 18200-000000 | B26: ACCUMULATED AMORTIZATION | C26: 0 | D26: {=IFERROR(INDEX('TB '!G:G,MATCH(A26,'TB '!A:A,0),0),0)} -> 0 | E26: =C26-D26 -> 0
A27: 20100-000000 | B27: ACCOUNTS PAYABLE | C27: ='20100'!F19 -> -19358.47 | D27: {=IFERROR(INDEX('TB '!G:G,MATCH(A27,'TB '!A:A,0),0),0)} -> -19358.47 | E27: =C27-D27 -> 0
A28: 20650-000000 | B28: ACCRUED OPERATING EXP | C28: ='20650'!T47 -> 9365.57 | D28: {=IFERROR(INDEX('TB '!G:G,MATCH(A28,'TB '!A:A,0),0),0)} -> -9365.57 | E28: =-C28-D28 -> 0
A29: 20660-000000 | B29: ACCRUED INTEREST EXPENSE | C29: ='20660'!G13 -> 139242.09 | D29: {=-IFERROR(INDEX('TB '!G:G,MATCH(A29,'TB '!A:A,0),0),0)} -> 139242.09 | E29: =C29-D29 -> 0
A30: 20800-000000 | B30: TENANT SECURITY DEPOSIT | C30: 0 | D30: {=IFERROR(INDEX('TB '!G:G,MATCH(A30,'TB '!A:A,0),0),0)} -> -149779.54 | E30: =C30-D30 -> 149779.54 | F30: NA
A31: 20900-000000 | B31: PREPAID RENT | C31: 0 | D31: {=IFERROR(INDEX('TB '!G:G,MATCH(A31,'TB '!A:A,0),0),0)} -> -142581.84 | E31: =C31-D31 -> 142581.84 | F31: NA
A32: 23800-000000 | B32: NOTES PAYABLE-GOLDMAN SACHS | C32: 0 | D32: {=IFERROR(INDEX('TB '!G:G,MATCH(A32,'TB '!A:A,0),0),0)} -> 0 | E32: =C32-D32 -> 0
A33: 25500-000000 | B33: AP - AFFILIATES | C33: 0 | D33: {=IFERROR(INDEX('TB '!G:G,MATCH(A33,'TB '!A:A,0),0),0)} -> -66144.74 | E33: =C33-D33 -> 66144.74 | F33: NA
A34: 25910-000000 | B34: NOTE PAYABLE-OSTERMAN | C34: 0 | D34: {=IFERROR(INDEX('TB '!G:G,MATCH(A34,'TB '!A:A,0),0),0)} -> 0 | E34: =C34-D34 -> 0
A35: 30100-000000 | B35: EQUITY | C35: 0 | D35: {=IFERROR(INDEX('TB '!G:G,MATCH(A35,'TB '!A:A,0),0),0)} -> 0 | E35: =C35-D35 -> 0
A36: 30400-000000 | B36: PRIOR YR RETAINED EARNING | C36: 0 | D36: {=IFERROR(INDEX('TB '!G:G,MATCH(A36,'TB '!A:A,0),0),0)} -> -7824551.2 | E36: =C36-D36 -> 7824551.2 | F36: NA
A37: 35000-000000 | B37: OWNER'S DISTRIBUTION | C37: ='35000'!E95 -> 14597709 | D37: {=IFERROR(INDEX('TB '!G:G,MATCH(A37,'TB '!A:A,0),0),0)} -> 14597709 | E37: =C37-D37 -> 0
A38: 36000-000000 | B38: OWNER'S CONTRIBUTION | C38: ='36000'!E20 -> -342383.2 | D38: {=IFERROR(INDEX('TB '!G:G,MATCH(A38,'TB '!A:A,0),0),0)} -> -342383.2 | E38: =C38-D38 -> 0
A39: 40250-000000 | B39: MISCELLANEOUS INCOME | C39: 0 | D39: {=IFERROR(INDEX('TB '!G:G,MATCH(A39,'TB '!A:A,0),0),0)} -> -10500 | E39: =C39-D39 -> 10500 | F39: NA
A40: 70300-000000 | B40: BAD DEBT EXPENSE | C40: ='12410 '!H33 -> 0 | D40: {=IFERROR(INDEX('TB '!G:G,MATCH(A40,'TB '!A:A,0),0),0)} -> 0 | E40: =C40-D40 -> 0
A42: Insurance
A43: 50111-000000 | B43: INSURANCE-PROPERTY | C43: ='INSURANCE '!C20 -> 126056.83 | D43: {=IFERROR(INDEX('TB '!G:G,MATCH(A43,'TB '!A:A,0),0),0)} -> 126056.83 | E43: =C43-D43 -> 0
...

Sheet 12020
A1: ='Review Comments'!B9 -> COCONUT GROVE RETAIL XIII, LLC
A2: ACCOUNTS RECEIVABLE OTHER- 12020
A3: ='Review Comments'!B11 -> FOR THE MONTH 07/31/2026
A7: Origination Date | C7: Description | E7: Total Amount
C13: Account Total: | E13: =SUM(E9:E11) -> 0
C15: 12020-000000 | D15: 0 | E15: {=IFERROR(INDEX('TB '!G:G,MATCH(12020,'TB '!A:A,0),0),0)} -> 0
C16: S/B zero | D16: =+D13-D15 -> 0 | E16: =E13-E15 -> 0

Sheet 13000 (2)
A1: ='Review Comments'!B9 -> COCONUT GROVE RETAIL XIII, LLC
A2: SUSPENSE - 13000
A3: ='Review Comments'!B11 -> FOR THE MONTH 07/31/2026
A6: Date | C6: Tenant | D6: Vendor | F6: Amount | H6: Description
A8: 44033 | C8: Sotherbys (New Tenant) | F8: 0 | H8: 1st month rent and security deposit
A9: 44406 | C9: Kana Haven (Café Kona) | D9: Big Island Electric Inc | F9: 480.54 | H9: Tenant is not billed yet
A10: 44462 | C10: Fosters Kitchen | D10: TARYN BREEN | F10: -394.12 | H10: tenant charged
A11: 44469 | C11: Fosters Kitchen | D11: TARYN BREEN | F11: 394.12 | H11: exp paid
D13: TOTAL Per Accrual | F13: =SUM(F8:F12) -> 480.54
A18: Date | C18: Tenant | D18: Vendor | F18: Amount | H18: Description
A20: 44033 | C20: Sotherbys (New Tenant) | F20: 0 | H20: 1st month rent and security deposit
A21: 44376 | C21: Foster Kitchen | D21: Bsc Kona LLC | F21: 1136.13 | H21: Tenant was billed not paid yet
A22: 44376 | C22: Foster Kitchen | D22: Bsc Kona LLC | F22: 1385.55 | H22: Tenant was billed not paid yet
A23: 43308 | C23: MF Kona, LLC | D23: Big Island Electric Inc | H23: Tenant was billed in 07/18,
A24: 43308 | C24: MF Kona, LLC | D24: Big Island Electric Inc | H24: Tenant was billed in 07/18,
A25: 43308 | C25: MF Kona, LLC | D25: Big Island Electric Inc | H25: Tenant was billed in 07/18,
A26: 43308 | C26: MF Kona, LLC | D26: Big Island Electric Inc | H26: Tenant was billed in 07/18,
A27: 43308 | C27: MF Kona, LLC | D27: Big Island Electric Inc | H27: Tenant was billed in 07/18,
A28: 44406 | C28: Kana Haven (Café Kona) | D28: Big Island Electric Inc | F28: 480.54 | H28: Tenant is not billed yet
A29: 44433 | C29: Foster Kitchen | D29: Bsc Kona LLC | F29: -2521.68 | H29: CASH RECIPTS
A30: 44462 | C30: Fosters Kitchen | D30: TARYN BREEN | F30: -394.12 | H30: CASH RECIPTS
A31: 44469 | C31: Fosters Kitchen | D31: TARYN BREEN | F31: 394.12 | H31: Exp paid
D33: TOTAL Per Cash | F33: =SUM(F20:F32) -> 480.54

Sheet 12410
A1: ='Review Comments'!B9 -> COCONUT GROVE RETAIL XIII, LLC
A2: BAD DEBT RESERVE - 12410
A3: ='Review Comments'!B11 -> FOR THE MONTH 07/31/2026
A6: Tenant Name | B6: O/S AR Balance | C6: Less Security Deposit | D6: Adjusted O/S Balance | E6: Beginning Bal | F6: Current Reserve | G6: Ending Bal | H6: Bad Debt Exp #70300 | I6: Comments/Status of Collection | K6: Prior | L6: 12584.32 | M6: 8717.22 | N6: 5111.25
B7: 0 | G7: =SUM(E7:F7) -> 0 | H7: =G7 -> 0
A8: Gecko Girlz | B8: 0 | C8: -7044.8 | D8: 0 | E8: 0 | F8: =D8-E8 -> 0 | G8: =E8+F8 -> 0 | H8: =-G8+5539.52 -> 5539.52 | I8: ($5,539.52) reserved in 2020 | K8: New Bal | L8: 8717.22 | M8: 3605.97 | N8: -5539.52
A9: Bongo Bens | B9: 0 | C9: 0 | D9: =B9+C9 -> 0 | E9: 0 | F9: =D9-E9 -> 0 | G9: =E9+F9 -> 0 | H9: 0 | K9: Adj | L9: =+L8-L6 -> -3867.1 | M9: =+M6+M8 -> 12323.19 | N9: =+N6+N8 -> -428.27
A10: Humpy's Big Island Alehouse | B10: 45204.79 | C10: -11000 | D10: =B10+C10 -> 34204.79 | E10: 154866.78 | F10: =D10-E10 -> -120661.99 | G10: =E10+F10 -> 34204.79 | H10: =-G10+100013.47+64010.01 -> 129818.69 | I10: ($164,023.48) reserved in 2020 | K10: add: 3mths | L10: 3605.97
A11: Big Island Running | C11: -1585.93 | D11: 0 | E11: 0 | F11: =D11-E11 -> 0 | G11: =E11+F11 -> 0 | H11: =-G11 -> 0 | K11: balance | L11: =+L9+L10 -> -261.13
A12: Colors of Paradise Gallery | B12: =19598.69+2737.56+2145.33+2145.33 -> 26626.91 | C12: -2123.64 | D12: =B12+C12 -> 24503.27 | E12: 24503.27 | F12: =D12-E12 -> 0 | G12: =E12+F12 -> 24503.27 | H12: =-G12+9910.1 -> -14593.17 | I12: ($9,910.10) reserved in 2020
A13: Island Lava Java | C13: -20937.35 | D13: =B13+C13 -> -20937.35 | E13: -17219.18 | F13: =D13-E13 -> -3718.17 | G13: =E13+F13 -> -20937.35 | H13: =-G13+83766.22-83766.22 -> 20937.35 | I13: ($83,766.22) reserved in 2020
A14: Lavernes | B14: =10097.75+6997.72 -> 17095.47 | C14: -30857.87 | D14: 0 | E14: 32375.84 | F14: =D14-E14 -> -32375.84 | G14: =E14+F14 -> 0 | H14: =-G14+49193.79 -> 49193.79 | I14: ($49,193.79) reserved in 2020 | K14: Prior | L14: 49468.93
A15: Kona Gear | B15: =40460.31+8.26 -> 40468.57 | C15: -7184.49 | D15: =B15+C15 -> 33284.08 | E15: 33284.08 | F15: =D15-E15 -> 0 | G15: =E15+F15 -> 33284.08 | H15: =-G15+18769.72 -> -14514.36 | I15: ($18,769.72) reserved in 2020 | K15: New Bal | L15: 42668.31
A16: Jacks Dive Locker | B16: 0 | D16: =B16+C16 -> 0 | E16: 0 | F16: =D16-E16 -> 0 | G16: =E16+F16 -> 0 | H16: =-G16+24425.06 -> 24425.06 | I16: ($24,425.06) reserved in 2020 | K16: Adj | L16: =+L15-L14 -> -6800.62
A17: Fosters Kitchen | B17: 0 | C17: -12641.5 | D17: 0 | E17: 22142.42 | F17: =D17-E17 -> -22142.42 | G17: =E17+F17 -> 0 | H17: =-G17 -> 0 | K17: add: 3mths | L17: 20401.86
A18: ABC Store | B18: 0 | C18: 0 | D18: =B18+C18 -> 0 | E18: 46527 | F18: =D18-E18 -> -46527 | G18: =E18+F18 -> 0 | H18: =-G18+46870.01+2598.92+47967.84 -> 97436.77 | I18: ($49,468.93) reserved in 2020 | K18: balance | L18: =+L16+L17 -> 13601.24
A19: Oceans Sports Bar and Grill | B19: =4593.84+49269.94+4605.74 -> 58469.52 | C19: 0 | D19: =B19+C19 -> 58469.52 | E19: 58469.52 | F19: =D19-E19 -> 0 | G19: =E19+F19 -> 58469.52 | H19: =-G19+39309.92 -> -19159.6 | I19: ($39,309.92) reserved in 2020
A20: Café Kona | B20: 33597.36 | C20: -2116.11 | D20: =B20+C20 -> 31481.25 | E20: 31713.04 | F20: =D20-E20 -> -231.79 | G20: =E20+F20 -> 31481.25 | H20: =-G20+18708.57 -> -12772.68 | I20: ($18,708.57) reserved in 2020
D21: =B21+C21 -> 0 | E21: 0 | F21: =D21-E21 -> 0 | G21: =E21+F21 -> 0 | H21: =-G21 -> 0
D22: =B22+C22 -> 0 | F22: =D22-E22 -> 0 | G22: =E22+F22 -> 0 | H22: =-G22 -> 0
D23: =B23+C23 -> 0 | F23: =D23-E23 -> 0 | G23: =E23+F23 -> 0 | H23: =-G23 -> 0
D24: =B24+C24 -> 0 | F24: =D24-E24 -> 0 | G24: =E24+F24 -> 0 | H24: =-G24 -> 0
D25: =B25+C25 -> 0 | F25: =D25-E25 -> 0 | G25: =E25+F25 -> 0 | H25: =-G25 -> 0
D26: =B26+C26 -> 0 | F26: =D26-E26 -> 0 | G26: =E26+F26 -> 0 | H26: =-G26 -> 0
A28: Total Reserve per G/L | B28: =SUM(B7:B27) -> 221462.62 | D28: =SUM(D7:D27) -> 161005.56 | E28: =SUM(E7:E27) -> 386662.77 | F28: =SUM(F7:F27) -> -225657.21 | G28: =SUM(G7:G27) -> 161005.56 | H28: =SUM(H7:H27) -> 266311.37
G29: =+G28-D28 -> 0
J32: 19626.81
J33: 8669.57
J34: 42669.89
J35: =SUM(J32:J34) -> 70966.27
J36: =J35/6 -> 11827.712 | L36: =J36*2 -> 23655.423 | M36: =J35-L36 -> 47310.847

Sheet 12500
A1: ='Review Comments'!B9 -> COCONUT GROVE RETAIL XIII, LLC
A2: INTEREST RATE CAP- 12500
A3: ='Review Comments'!B11 -> FOR THE MONTH 07/31/2026
A9: Origination Date | C9: Description | E9: Amount | F9: Total Amount
A11: 42719 | C11: Interest Rate Cap Cost | F11: =+E11 -> 0
C15: Account Total: | F15: =SUM(F11:F14) -> 0

Sheet 12410 
A1: ='Review Comments'!B9 -> COCONUT GROVE RETAIL XIII, LLC
A2: BAD DEBT RESERVE - 12410
A3: ='Review Comments'!B11 -> FOR THE MONTH 07/31/2026
A6: Tenant Name | B6: O/S AR Balance | C6: Less Security Deposit | D6: Adjusted O/S Balance | E6: Beginning Bal | F6: Current Reserve | G6: Ending Bal | H6: Bad Debt Exp | I6: Comments/Status of Collection | K6: Prior | L6: 12584.32 | M6: 8717.22 | N6: 5111.25
G7: 12410-000000 | H7: 70300-000000
B8: 0 | E8: 0 | G8: =SUM(E8:F8) -> 0
A9: Lucasie Ltd | B9: 4288.87 | C9: -4713.8 | D9: =IF((B9+C9)>0,B9+C9,0) -> 0 | E9: 0 | F9: =D9-E9 -> 0 | G9: =E9+F9 -> 0
A10: Taka Sushi | B10: 0 | C10: 0 | D10: =IF((B10+C10)>0,B10+C10,0) -> 0 | E10: 0 | F10: =D10-E10 -> 0 | G10: =E10+F10 -> 0 | I10: (8,825.41) 2022, 2023 Rent Abatement-8,825.41 | K10: New Bal | L10: 8717.22 | M10: 3605.97 | N10: -5539.52
A11: Gecko Girlz | B11: 0 | C11: 0 | D11: =IF((B11+C11)>0,B11+C11,0) -> 0 | E11: 0 | F11: =D11-E11 -> 0 | G11: =E11+F11 -> 0
A12: Bongo Bens | B12: 0 | C12: 0 | D12: =IF((B12+C12)>0,B12+C12,0) -> 0 | E12: 0 | F12: =D12-E12 -> 0 | G12: =E12+F12 -> 0 | K12: Adj | L12: =+L10-L6 -> -3867.1 | M12: =+M6+M10 -> 12323.19 | N12: =+N6+N10 -> -428.27
A13: Humpy's Big Island Alehouse | B13: 0 | C13: 0 | D13: =IF((B13+C13)>0,B13+C13,0) -> 0 | E13: 0 | F13: =D13-E13 -> 0 | G13: =E13+F13 -> 0 | K13: add: 3mths | L13: 3605.97
A14: Big Island Running | C14: 0 | D14: =IF((B14+C14)>0,B14+C14,0) -> 0 | E14: 0 | F14: =D14-E14 -> 0 | G14: =E14+F14 -> 0 | K14: balance | L14: =+L12+L13 -> -261.13
A15: Colors of Paradise Gallery | B15: 0 | C15: 0 | D15: =IF((B15+C15)>0,B15+C15,0) -> 0 | E15: 0 | F15: =D15-E15 -> 0 | G15: =E15+F15 -> 0 | I15: ($9,910.10) reserved in 2020, (24502.96) 2022 , ADJ in 07.23 $24,502.96 & $12,237.40
A16: Island Lava Java | C16: 0 | D16: =IF((B16+C16)>0,B16+C16,0) -> 0 | E16: 0 | F16: =D16-E16 -> 0 | G16: =E16+F16 -> 0
A17: Lavernes | C17: 0 | D17: =IF((B17+C17)>0,B17+C17,0) -> 0 | E17: 0 | F17: 0 | G17: =E17+F17 -> 0 | K17: Prior | L17: 49468.93
A18: Kona Gear | B18: 0 | C18: 0 | D18: =IF((B18+C18)>0,B18+C18,0) -> 0 | E18: 0 | F18: =D18-E18 -> 0 | G18: =E18+F18 -> 0 | K18: New Bal | L18: 42668.31
A19: Jacks Dive Locker | B19: 0 | C19: 0 | D19: =IF((B19+C19)>0,B19+C19,0) -> 0 | E19: 0 | F19: =D19-E19 -> 0 | G19: =E19+F19 -> 0 | K19: Adj | L19: =+L18-L17 -> -6800.62
A20: Fosters Kitchen | B20: 15113.98 | C20: -12641.5 | D20: =IF((B20+C20)>0,B20+C20,0) -> 2472.48 | E20: 5569.78 | F20: =D20-E20 -> -3097.3 | G20: =E20+F20 -> 2472.48 | K20: add: 3mths | L20: 20401.86
A21: ABC Store | B21: 0 | C21: 0 | D21: =IF((B21+C21)>0,B21+C21,0) -> 0 | E21: 1930.38 | F21: =D21-E21 -> -1930.38 | G21: =E21+F21 -> 0 | K21: balance | L21: =+L19+L20 -> 13601.24
A22: Oceans Sports Bar and Grill | B22: 4613.6 | C22: 0 | D22: =IF((B22+C22)>0,B22+C22,0) -> 4613.6 | E22: 4813.6 | F22: =D22-E22 -> -200 | G22: =E22+F22 -> 4613.6
A23: Kanaka Kava | B23: 0 | C23: 0 | D23: =IF((B23+C23)>0,B23+C23,0) -> 0 | E23: 0 | G23: =E23+F23 -> 0
C24: 0 | D24: =IF((B24+C24)>0,B24+C24,0) -> 0 | E24: 0 | G24: =E24+F24 -> 0 | I24: ($18,708.57) reserved in 2021
C25: 0 | D25: =IF((B25+C25)>0,B25+C25,0) -> 0 | E25: 0 | G25: =E25+F25 -> 0 | I25: ($18,708.57) reserved in 2022
C26: 0 | D26: =IF((B26+C26)>0,B26+C26,0) -> 0 | E26: 0 | G26: =E26+F26 -> 0 | I26: ($18,708.57) reserved in 2023
C27: 0 | D27: =IF((B27+C27)>0,B27+C27,0) -> 0 | E27: 0 | G27: =E27+F27 -> 0 | I27: ($18,708.57) reserved in 2024
C28: 0 | D28: =IF((B28+C28)>0,B28+C28,0) -> 0 | E28: 0 | G28: =E28+F28 -> 0 | I28: ($18,708.57) reserved in 2025
C29: 0 | D29: =IF((B29+C29)>0,B29+C29,0) -> 0 | E29: 0 | G29: =E29+F29 -> 0 | I29: ($18,708.57) reserved in 2026
A30: CAFE KONA | B30: 6958.31 | C30: -22116.11 | D30: =IF((B30+C30)>0,B30+C30,0) -> 0 | E30: 0 | F30: =D30-E30 -> 0 | G30: =E30+F30 -> 0
A31: Outback Steakhouse | B31: 0 | C31: 0 | D31: =IF((B31+C31)>0,B31+C31,0) -> 0 | E31: 0 | F31: =D31-E31 -> 0 | G31: =E31+F31 -> 0 | H31: =F31+6408.23+2552.35-872.78+1745.56-9833.36 -> 0
A33: Total Reserve per G/L | B33: =SUM(B8:B32) -> 30974.76 | C33: =SUM(C8:C32) -> -39471.41 | D33: =SUM(D8:D32) -> 7086.08 | E33: =SUM(E8:E32) -> 12313.76 | F33: =SUM(F8:F32) -> -5227.68 | G33: =SUM(G8:G32) -> 7086.08 | H33: =SUM(H8:H32) -> 0
F35: PER TB | G35: {=IFERROR(INDEX('TB '!G:G,MATCH(G7,'TB '!A:A,0),0),0)} -> -7086.08 | H35: {=IFERROR(INDEX('TB '!G:G,MATCH(H7,'TB '!A:A,0),0),0)} -> 0
F36: S/B zero | G36: =-G35-G33 -> 0 | H36: =+H33-H35 -> 0

Sheet 12100
A1: ='Review Comments'!B9 -> COCONUT GROVE RETAIL XIII, LLC
A2: LOAN RECEIVABLE - 12100
A3: ='Review Comments'!B11 -> FOR THE MONTH 07/31/2026
A9: Origination Date | C9: Description | E9: Amount | F9: Comment
A11: 45981 | C11: SHORT TERM LOAN PAYMENT | E11: 160000
C13: Account Total | E13: =SUM(E11:E12) -> 160000
D15: 12100-000000 | E15: {=IFERROR(INDEX('TB '!G:G,MATCH(D15,'TB '!A:A,0),0),0)} -> 160000
D16: S/B zero | E16: =E15-E13 -> 0

Sheet 13000
A1: ='Review Comments'!B9 -> COCONUT GROVE RETAIL XIII, LLC
A2: SUSPENSE - 13000
A3: ='Review Comments'!B11 -> FOR THE MONTH 07/31/2026
A6: Date | C6: Tenant | D6: Vendor | F6: Amount | H6: Description
J8: IF BALANCE IS 0 DELETE HISTORY
D13: TOTAL Per Accrual | F13: =SUM(F8:F10) -> 0
A18: Date | C18: Tenant | D18: Vendor | F18: Amount | H18: Description
J20: NOTE:
A21: 46199 | C21: ISLAND LAVA JAVA | D21: JW CLEANING SYSTEMS LLC | F21: 226.54 | H21: 6104 6/24/2026 TBB ISLAND LAVA JAVA JW CLEANING SYSTEMS LLC | J21: IF BALANCE IS 0 DELETE HISTORY
D25: TOTAL Per Cash | F25: =SUM(F20:F23) -> 226.54
D28: 13000-000000 | F28: {=IFERROR(INDEX('TB '!G:G,MATCH(D28,'TB '!A:A,0),0),0)} -> 0 | H28: Per CM ledger
C29: Invoices paid but not billed to Tenants | D29: S/B zero | F29: =F13-F28 -> 0 | H29: Difference

Sheet 13100
A1: ='Review Comments'!B9 -> COCONUT GROVE RETAIL XIII, LLC
A2: MISC DEPOSIT-13100
A3: ='Review Comments'!B11 -> FOR THE MONTH 07/31/2026
F7: 13100-000000
A9: Origination Date | C9: Vendor | D9: Description | F9: Amount | G9: Comment
A11: 46022 | D11: 00127459 Cash Recpt NON-TENANT | F11: 150
A12: 43068 | C12: Hawaii Electric Light Co, Inc | D12: Acct# 201014742377 | F12: 0 | G12: SD Applied
A13: 43068 | C13: Hawaii Electric Light Co, Inc | D13: Acct# 201014743508 | F13: 0 | G13: SD Applied
A14: 43068 | C14: Hawaii Electric Light Co, Inc | D14: Acct# 201014744019 | F14: 0 | G14: SD Applied
A15: 43068 | C15: Hawaii Electric Light Co, Inc | D15: Acct# 201014744704 | F15: =-530+74.31+74.46+74.39+74.46-267.62+500 -> 0 | G15: SD Applied
A16: 43068 | C16: Hawaii Electric Light Co, Inc | D16: Acct# 201014744977 | F16: 0 | G16: SD Applied
A17: 43068 | C17: Hawaii Electric Light Co, Inc | D17: Acct# 201014745941 | F17: 0 | G17: SD Applied
A18: 43068 | C18: Hawaii Electric Light Co, Inc | D18: Acct# 201014746048 | F18: =500-500 -> 0 | G18: SD Applied
A19: 43087 | C19: Hawaii Electric Light Co, Inc | D19: Acct# 201014743508 | F19: 0 | G19: SD Applied
A20: 43087 | C20: Hawaii Electric Light Co, Inc | D20: Acct# 201014746048 | F20: 0 | G20: SD Applied
D23: Account Total | F23: =SUM(F11:F22) -> 150
E25: 13100-000000 | F25: {=IFERROR(INDEX('TB '!G:G,MATCH(E25,'TB '!A:A,0),0),0)} -> 150
E26: S/B zero | F26: =F25-F23 -> 0

Sheet 13130
A1: ='Review Comments'!B9 -> COCONUT GROVE RETAIL XIII, LLC
A2: PREPAID EXPENSE-13130
A3: ='Review Comments'!B11 -> FOR THE MONTH 07/31/2026
A9: Origination Date | C9: Vendor | D9: Description | F9: Amount | G9: Comment
D16: Account Total | F16: =SUM(F10:F15) -> 0
E18: 13130-000000 | F18: {=IFERROR(INDEX('TB '!G:G,MATCH(E18,'TB '!A:A,0),0),0)} -> 0
E19: S/B zero | F19: =F18-F16 -> 0

Sheet Fixed Asset
A1: ='Review Comments'!B9 -> COCONUT GROVE RETAIL XIII, LLC
A2: FIXED ASSETS SCHEDULE
A3: ='Review Comments'!B11 -> FOR THE MONTH 07/31/2026
A9: Origination Date | C9: Account Number | D9: Description | E9: Lease Term | F9: Amount
A11: 42978 | C11: 14000 | D11: Land Costs | F11: 18505428
A12: 43100 | D12: Adjust 2017 Recording of Property Purchase - CPA AJE | F12: -14135836
F13: =SUM(F11:F12) -> 4369592.2
A16: 42978 | C16: 15000 | D16: Building | F16: 3265663.7
A17: 43100 | D17: Adjust 2017 Recording of Property Purchase - CPA AJE | F17: 14212705
F18: =SUM(F16:F17) -> 17478369
C21: 15010 | D21: Building Improvement
A22: 43279 | D22: Elevator Upgrades - Otis Elevator Company (Owners paid) | F22: 77883
A23: 43341 | D23: Replace Parking Lot Light 50% Dep - Big Island Electric | F23: 13385.41
A24: 43341 | D24: Replace Parking Lot Light 50% Final Pmt - Big Island Electric | F24: 13385.41
A25: 43402 | D25: New Elevator Cab - Otis Elevator Company | F25: 17366
A26: 43456 | D26: Pre-construction Research - Tinguely Development (Inv #18-320-01) | F26: 2200
A27: 43465 | D27: 2018 CPA AJE #3 - To expense Minor Capitalized Items | F27: =-13385.41-13385.41 -> -26770.82
A28: 43465 | D28: 2018 CPA AJE #4 - To Reclass CIP | F28: -2200
A29: 43494 | D29: Exterior Paint - Kawika's Painting (Inv #38-11-25) | F29: 31022.1
A30: 43494 | D30: Exterior Paint - Kawika's Painting (Inv #38-12-13) | F30: 9900
A31: 43494 | D31: Pre-construction Research - Tinguely Development (Inv #18-405-01) | F31: 2311.6
A32: 43522 | D32: Security Camera Equipment 50% Dep. - Elite Interactive Solutions (Inv. 165-010819) | F32: 34169.35
A33: 43522 | D33: Fire Monitor System - 50% Dep. - Pacific Rim Fire Protection | F33: 10371.65
A34: 43532 | D34: Pre-construction Research - Tinguely Development | F34: 1100
A35: 43532 | D35: Development Permit/ Constr. V-Ball Design - Tinguely Development (Inv #18-405-03 R1) | F35: 3500
A36: 43538 | D36: Development Permit/ Constr. V-Ball Design - Tinguely Development (Inv #18-405-02 R3) | F36: 7250.86
A37: 43538 | D37: Exterior Paint and Sprinkler Piping - Kawika's Painting (Inv. #39-02-09) | F37: 68868.77
A38: 43546 | D38: Construction Management Fee - Athena Management | F38: 21317.41
A39: 43546 | D39: Elevator Upgrades - Otis Elevator Company | F39: 77883
... A139: 46141 | D139: 6050 4/23/2026 ELEVATOR MOD PAY APP 2 OTIS ELEVATOR COMPANY | F139: 58984.23
F141: =SUM(F22:F139) -> 2052989.6
C144: 15100 | D144: Tenant Improvement
A145: 44347 | D145: Gecko Girlz - TI Reimb | E145: 06/19/2025-06/18/2030 | F145: 35000
A146: 45258 | D146: Taka Sushi | E146: 01/01/2023-12/31/2027 | F146: 10740
A147: 45562 | D147: 5471 9/11/2024 HUMPY'S RENO | E147: 09/01/2022-08/31/2032 | F147: 804
A148: 45562 | D148: 5470 9/11/2024 HUMPY'S RENOVATION | E148: 09/01/2022-08/31/2032 | F148: 69294.33
A149: 45562 | D149: 5469 9/11/2024 HUMPY'S RENOVATION | E149: 09/01/2022-08/31/2032 | F149: 98991.9
A150: 45562 | D150: 5468 9/11/2024 HUMPY'S RENO APP1 | E150: 09/01/2022-08/31/2032 | F150: 29697.57
A151: 45594 | D151: 5516 10/24/2024 HUMPY'S TI REIMB | E151: 09/01/2022-08/31/2032 | F151: 125000
A152: 45657 | D152: CPA YEAR AJE # 7 | F152: -804
...

Sheet 16500
A1: Coconut Grove Retail
A2: LEASING COMMISSIONS - 16500
A3: FOR THE MONTH ENDED 05/31/2026
A9: Origination Date | B9: Vendor | C9: Lease Term | D9: Description | E9: Amount | F9: Total Amount
G10: Comments
D11: OpeningBalanceforYear | E11: 104056.53
A12: 45960 | B12: ISLAND LAVA JAVA | C12: 06/01/2032-5/31/2037 | D12: 5873 10/29/2025 ISLAND LAVA JAVA | E12: 17028.55 | F12: =E11+E12 -> 121085.08
A13: 45982 | B13: HOT POT SVN GO COMMERCIAL | C13: 6/25/2026-6/30/2036 | D13: 5900 11/20/2025 LC1ST 1/2 Q | E13: 92878.96 | F13: =F12+E13 -> 213964.04
A14: 46014 | B14: ABC STORE | C14: 01/01/2026-12/31/2030 | D14: 5918 12/18/2025 ABC LC RNWL | E14: 21600 | F14: =F13+E14 -> 235564.04
A15: 46101 | B15: KONA GE | C15: 4/1/2026-3/31/2029 | D15: 5996 3/5/2026 4/26-3/29 RNWL | E15: 3480.51 | F15: =F14+E15 -> 239044.55
D18: Account Total: | F18: =F15 -> 239044.55
E20: =RIGHT(A2,5)&"-000000" -> 16500-000000 | F20: {=IFERROR(INDEX('TB '!G:G,MATCH(E20,'TB '!A:A,0),0),0)} -> 239044.55
E21: S/B zero | F21: =+F18-F20 -> 0

Sheet 17600
A1: ='Review Comments'!B9 -> COCONUT GROVE RETAIL XIII, LLC
A2: LOAN FEES - 17600
A3: ='Review Comments'!B11 -> FOR THE MONTH 07/31/2026
A9: Origination Date | C9: Description | E9: Amount | F9: Comment
A11: 45657 | C11: TO CAPITALIZE LOAN FEES ORGINATED FROM NEW LOAN | E11: 442910.74
C13: Account Total | E13: =SUM(E11:E12) -> 442910.74
D15: 17600-000000 | E15: {=IFERROR(INDEX('TB '!G:G,MATCH(D15,'TB '!A:A,0),0),0)} -> 442910.74
D16: S/B zero | E16: =E15-E13 -> 0

Sheet 15500
A1: ='Review Comments'!B9 -> COCONUT GROVE RETAIL XIII, LLC
A2: CIP- 15500
A3: ='Review Comments'!B11 -> FOR THE MONTH 07/31/2026
A9: Date | C9: Description | D9: Vendor | E9: Total Amount
D33: Account Total: | E33: =SUM(E11:E32) -> 0

Sheet 13000-
A1: ='Review Comments'!B9 -> COCONUT GROVE RETAIL XIII, LLC
A2: SUSPENSE-13000
A3: FOR THE ONE MONTH ENDED 01/31/17
B7: Date | C7: Tenant | D7: Description | F7: Amount | G7: Comment
D11: Account Total per Cash | F11: =SUM(F9:F10) -> 0

Sheet 17650
A1: ='Review Comments'!B9 -> COCONUT GROVE RETAIL XIII, LLC
A2: LOAN COSTS-17650
A3: ='Review Comments'!B11 -> FOR THE MONTH 07/31/2026
A9: Origination Date | C9: Vendor | D9: Description | F9: Amount | G9: Comment
A11: 43068 | C11: Hawaii Electric Light Co, Inc | D11: Acct# 201014742377 | F11: 0 | G11: SD Applied
A12: 43068 | C12: Hawaii Electric Light Co, Inc | D12: Acct# 201014743508 | F12: 0 | G12: SD Applied
A13: 43068 | C13: Hawaii Electric Light Co, Inc | D13: Acct# 201014744019 | F13: 0 | G13: SD Applied
